Workbook

Sheet Points 3D
A1: Collez ici vos points 3D relevés dans les colonnes X, Y, Z.
A2: X | B2: Y | C2: Z
A3: 100 | B3: 200 | C3: 10
A4: 101 | B4: 200.5 | C4: 10.2
A5: 100.5 | B5: 201 | C5: 10.1
A6: 99.5 | B6: 199.5 | C6: 9.9
A7: 100 | B7: 199 | C7: 9.8

Sheet 1_PlanMoyen
A1: Calcul du centre de gravité (moyenne)
A3: Moyenne X | B3: Moyenne Y | C3: Moyenne Z
A4: =AVERAGE('Points 3D'!A3:A1002) | B4: =AVERAGE('Points 3D'!B3:B1002) | C4: =AVERAGE('Points 3D'!C3:C1002)

Sheet 2_Projection
A1: Projection des points dans le plan moyen | D1: Instructions :
A2: X' | B2: Y' | D2: Cette feuille doit être remplie avec les coordonnées projetées (X', Y')
A3: X' | B3: Y' | D3: Les colonnes X', Y' doivent être calculées par projection sur un plan
A4: ='Points 3D'!A4 - '1_PlanMoyen'!A4 | B4: ='Points 3D'!B4 - '1_PlanMoyen'!B4 | D4: Le plan est défini par la moyenne des points et une orientation fixe ou calculée manuellement
A5: ='Points 3D'!A5 - '1_PlanMoyen'!A4 | B5: ='Points 3D'!B5 - '1_PlanMoyen'!B4 | D5: Pour un plan horizontal : X' = X - moyenne(X), Y' = Y - moyenne(Y)
A6: ='Points 3D'!A6 - '1_PlanMoyen'!A4 | B6: ='Points 3D'!B6 - '1_PlanMoyen'!B4
A7: ='Points 3D'!A7 - '1_PlanMoyen'!A4 | B7: ='Points 3D'!B7 - '1_PlanMoyen'!B4
A8: ='Points 3D'!A8 - '1_PlanMoyen'!A4 | B8: ='Points 3D'!B8 - '1_PlanMoyen'!B4
A9: ='Points 3D'!A9 - '1_PlanMoyen'!A4 | B9: ='Points 3D'!B9 - '1_PlanMoyen'!B4
A10: ='Points 3D'!A10 - '1_PlanMoyen'!A4 | B10: ='Points 3D'!B10 - '1_PlanMoyen'!B4
A11: ='Points 3D'!A11 - '1_PlanMoyen'!A4 | B11: ='Points 3D'!B11 - '1_PlanMoyen'!B4
A12: ='Points 3D'!A12 - '1_PlanMoyen'!A4 | B12: ='Points 3D'!B12 - '1_PlanMoyen'!B4
A13: ='Points 3D'!A13 - '1_PlanMoyen'!A4 | B13: ='Points 3D'!B13 - '1_PlanMoyen'!B4
A14: ='Points 3D'!A14 - '1_PlanMoyen'!A4 | B14: ='Points 3D'!B14 - '1_PlanMoyen'!B4
A15: ='Points 3D'!A15 - '1_PlanMoyen'!A4 | B15: ='Points 3D'!B15 - '1_PlanMoyen'!B4
A16: ='Points 3D'!A16 - '1_PlanMoyen'!A4 | B16: ='Points 3D'!B16 - '1_PlanMoyen'!B4
A17: ='Points 3D'!A17 - '1_PlanMoyen'!A4 | B17: ='Points 3D'!B17 - '1_PlanMoyen'!B4
A18: ='Points 3D'!A18 - '1_PlanMoyen'!A4 | B18: ='Points 3D'!B18 - '1_PlanMoyen'!B4
A19: ='Points 3D'!A19 - '1_PlanMoyen'!A4 | B19: ='Points 3D'!B19 - '1_PlanMoyen'!B4
A20: ='Points 3D'!A20 - '1_PlanMoyen'!A4 | B20: ='Points 3D'!B20 - '1_PlanMoyen'!B4
A21: ='Points 3D'!A21 - '1_PlanMoyen'!A4 | B21: ='Points 3D'!B21 - '1_PlanMoyen'!B4
A22: ='Points 3D'!A22 - '1_PlanMoyen'!A4 | B22: ='Points 3D'!B22 - '1_PlanMoyen'!B4
A23: ='Points 3D'!A23 - '1_PlanMoyen'!A4 | B23: ='Points 3D'!B23 - '1_PlanMoyen'!B4
A24: ='Points 3D'!A24 - '1_PlanMoyen'!A4 | B24: ='Points 3D'!B24 - '1_PlanMoyen'!B4
A25: ='Points 3D'!A25 - '1_PlanMoyen'!A4 | B25: ='Points 3D'!B25 - '1_PlanMoyen'!B4
A26: ='Points 3D'!A26 - '1_PlanMoyen'!A4 | B26: ='Points 3D'!B26 - '1_PlanMoyen'!B4
A27: ='Points 3D'!A27 - '1_PlanMoyen'!A4 | B27: ='Points 3D'!B27 - '1_PlanMoyen'!B4
A28: ='Points 3D'!A28 - '1_PlanMoyen'!A4 | B28: ='Points 3D'!B28 - '1_PlanMoyen'!B4
A29: ='Points 3D'!A29 - '1_PlanMoyen'!A4 | B29: ='Points 3D'!B29 - '1_PlanMoyen'!B4
A30: ='Points 3D'!A30 - '1_PlanMoyen'!A4 | B30: ='Points 3D'!B30 - '1_PlanMoyen'!B4
A31: ='Points 3D'!A31 - '1_PlanMoyen'!A4 | B31: ='Points 3D'!B31 - '1_PlanMoyen'!B4
A32: ='Points 3D'!A32 - '1_PlanMoyen'!A4 | B32: ='Points 3D'!B32 - '1_PlanMoyen'!B4
A33: ='Points 3D'!A33 - '1_PlanMoyen'!A4 | B33: ='Points 3D'!B33 - '1_PlanMoyen'!B4
A34: ='Points 3D'!A34 - '1_PlanMoyen'!A4 | B34: ='Points 3D'!B34 - '1_PlanMoyen'!B4
A35: ='Points 3D'!A35 - '1_PlanMoyen'!A4 | B35: ='Points 3D'!B35 - '1_PlanMoyen'!B4
A36: ='Points 3D'!A36 - '1_PlanMoyen'!A4 | B36: ='Points 3D'!B36 - '1_PlanMoyen'!B4
A37: ='Points 3D'!A37 - '1_PlanMoyen'!A4 | B37: ='Points 3D'!B37 - '1_PlanMoyen'!B4
A38: ='Points 3D'!A38 - '1_PlanMoyen'!A4 | B38: ='Points 3D'!B38 - '1_PlanMoyen'!B4
A39: ='Points 3D'!A39 - '1_PlanMoyen'!A4 | B39: ='Points 3D'!B39 - '1_PlanMoyen'!B4
A40: ='Points 3D'!A40 - '1_PlanMoyen'!A4 | B40: ='Points 3D'!B40 - '1_PlanMoyen'!B4
...

Sheet 3_Cercle_2D
A1: Collez ici les coordonnées projetées (X' et Y') des points (à remplir depuis '2_Projection')
D2: Formules LSQ sur X' et Y' :
A3: X' | B3: Y'
D4: Somme(2X) | E4: Somme(2Y) | F4: Somme(1)
D5: =2*SUM(A4:A1003) | E5: =2*SUM(B4:B1003) | F5: =COUNTA(A4:A1003)
D6: Somme(X^2 + Y^2)
D7: =SUMPRODUCT(A4:A1003,A4:A1003)+SUMPRODUCT(B4:B1003,B4:B1003)
D9: Centre X | E9: Centre Y | F9: Rayon
D10: =AVERAGE(A4:A1003) | E10: =AVERAGE(B4:B1003) | F10: =SQRT(AVERAGE((A4:A1003-D10)^2+(B4:B1003-E10)^2))

Sheet 4_Resultats
A2: Centre_X | B2: Centre_Y | C2: Centre_Z | D2: Rayon | E2: Plan_Norm_X | F2: Plan_Norm_Y | G2: Plan_Norm_Z
A3: 100.39662 | B3: 199.92025 | C3: 10.012062 | D3: 0.90724241 | E3: -0.11033734 | F3: -0.12286994 | G3: 0.98627007
