Workbook
Name cintre: 'Résultats observations'!$W$4
Name date: 'Résultats observations'!$A:$A
Name DH_BD: 'Résultats observations'!$DD:$DD
Name DH_BG: 'Résultats observations'!$CL:$CL
Name DH_HD: 'Résultats observations'!$CX:$CX
Name DH_HG: 'Résultats observations'!$CR:$CR
Name DH_ID: 'Résultats observations'!$DA:$DA
Name DH_IG: 'Résultats observations'!$CO:$CO
Name DHhaut: 'Résultats observations'!$CU:$CU
Name dist: 'Résultats observations'!$D:$D
Name DPM_BD: 'Résultats observations'!$DC:$DC
Name DPM_BG: 'Résultats observations'!$CK:$CK
Name DPM_HD: 'Résultats observations'!$CW:$CW
Name DPM_HG: 'Résultats observations'!$CQ:$CQ
Name DPM_ID: 'Résultats observations'!$CZ:$CZ
Name DPM_IG: 'Résultats observations'!$CN:$CN
Name DPMhaut: 'Résultats observations'!$CT:$CT
Name DZ_BD: 'Résultats observations'!$BM:$BM
Name DZ_BG: 'Résultats observations'!$AU:$AU
Name DZ_HD: 'Résultats observations'!$BG:$BG
Name DZ_HG: 'Résultats observations'!$BA:$BA
Name DZ_ID: 'Résultats observations'!$BJ:$BJ
Name DZ_IG: 'Résultats observations'!$AX:$AX
Name DZhaut: 'Résultats observations'!$BD:$BD
Name Ecart_BD: 'Résultats observations'!$AN:$AN
Name Ecart_BG: 'Résultats observations'!$AI:$AI
Name Ecart_HD: 'Résultats observations'!$AL:$AL
Name Ecart_HG: 'Résultats observations'!$AK:$AK
Name Ecart_ID: 'Résultats observations'!$AM:$AM
Name Ecart_IG: 'Résultats observations'!$AJ:$AJ
Name Ecart_LB: 'Résultats observations'!$AQ:$AQ
Name Ecart_LH: 'Résultats observations'!$AO:$AO
Name Ecart_LI: 'Résultats observations'!$AP:$AP
Name excav: 'Résultats observations'!$A$7
Name front: 'Résultats observations'!$C:$C
Name galerie: 'Résultats observations'!$G$4
Name jours: 'Résultats observations'!$B:$B
Name N_DEST: #REF!
Name N_SOURCE: #REF!
Name PM: 'Résultats observations'!$W$6
Name Xbasdroit: 'Résultats observations'!$W:$W
Name Xbasgauche: 'Résultats observations'!$E:$E
Name Xhaut: 'Résultats observations'!$N:$N
Name Xhautdroit: 'Résultats observations'!$Q:$Q
Name Xhautgauche: 'Résultats observations'!$K:$K
Name Xinterdroit: 'Résultats observations'!$T:$T
Name Xintergauche: 'Résultats observations'!$H:$H
Name Ybasdroit: 'Résultats observations'!$X:$X
Name Ybasgauche: 'Résultats observations'!$F:$F
Name Yhaut: 'Résultats observations'!$O:$O
Name Yhautdroit: 'Résultats observations'!$R:$R
Name Yhautgauche: 'Résultats observations'!$L:$L
Name Yinterdroit: 'Résultats observations'!$U:$U
Name Yintergauche: 'Résultats observations'!$I:$I
Name Zbasdroit: 'Résultats observations'!$Y:$Y
Name Zbasgauche: 'Résultats observations'!$G:$G
Name Zhaut: 'Résultats observations'!$P:$P
Name Zhautdroit: 'Résultats observations'!$S:$S
Name Zhautgauche: 'Résultats observations'!$M:$M
Name Zinterdroit: 'Résultats observations'!$V:$V

Sheet Résultats observations
F1: CONVERGENCE T12T13 - PM169.2
A6: Date point 0 | V6: PM = | W6: 169.2
A7: 43599
A8: Date | B8: Jours | C8: Front | D8: Dist | E8: Point bas gauche | H8: Point intermédiaire gauche | K8: Point haut gauche | N8: Point centre haut | Q8: Point haut droit | T8: Point intermédiaire droit | W8: Point bas droit | AI8: Différences | AS8: Point bas gauche | AV8: Point intermédiaire gauche | AY8: Point haut gauche | BB8: Point centre haut | BE8: Point haut droit | BH8: Point intermédiaire droit | BK8: Point bas droit | BO8: Point bas gauche | BR8: Point intermédiaire gauche | BU8: Point haut gauche | BX8: Point centre haut | CA8: Point haut droit | CD8: Point intermédiaire droit | CG8: Point bas droit | CK8: Point bas gauche | CN8: Point intermédiaire gauche | CQ8: Point haut gauche | CT8: Point centre haut | CW8: Point haut droit | CZ8: Point intermédiaire droit | DC8: Point bas droit
E9: X | F9: Y | G9: Z | K9: X | L9: Y | M9: Z | N9: X | O9: Y | P9: Z | Q9: X | R9: Y | S9: Z | W9: X | X9: Y | Y9: Z | Z9: BG | AA9: IG | AB9: HG | AC9: HD | AD9: ID | AE9: BD | AF9: LH | AG9: LI | AH9: LB | AI9: BG | AJ9: IG | AK9: HG | AL9: HD | AM9: ID | AN9: BD | AO9: LH | AP9: LI | AQ9: LB | AS9: DX | AT9: DY | AU9: DZ | AV9: DX | AW9: DY | AX9: DZ | AY9: DX | AZ9: DY | BA9: DZ | BB9: DX | BC9: DY | BD9: DZ | BE9: DX | BF9: DY | BG9: DZ | BH9: DX | BI9: DY | BJ9: DZ | BK9: DX | BL9: DY | BM9: DZ | BO9: PM | BP9: H | BQ9: V | BR9: PM | BS9: H | BT9: V | BU9: PM | BV9: H | BW9: V | BX9: PM | BY9: H | BZ9: V | CA9: PM | CB9: H | CC9: V | CD9: PM | CE9: H | CF9: V | CG9: PM | CH9: H | CI9: V | CK9: DPM | CL9: DH | CM9: DZ | CN9: DPM | CO9: DH | CP9: DZ | CQ9: DPM | CR9: DH | CS9: DZ | CT9: DPM | CU9: DH | CV9: DZ | CW9: DPM | CX9: DH | CY9: DZ | CZ9: DPM | DA9: DH | DB9: DZ | DC9: DPM | DD9: DH | DE9: DZ
A10: 43599 | B10: 0 | C10: 170.4 | D10: =C10-PM -> 1.2 | E10: 823219.58 | F10: 1091508.6 | G10: -125.01 | H10: 823219.25 | I10: 1091508.9 | J10: -123.0233 | K10: 823219.64 | L10: 1091508 | M10: -120.8816 | N10: 823220.9 | O10: 1091504.8 | P10: -119.5003 | Q10: 823222.38 | R10: 1091502.2 | S10: -120.8674 | T10: 823222.79 | U10: 1091501.3 | V10: -123.0174 | W10: 823222.71 | X10: 1091501.6 | Y10: -124.9382 | Z10: =IF(Xhaut="","",SQRT(((Xbasgauche-Xhaut)^2+(Ybasgauche-Yhaut)^2)+(Zbasgauche-Zhaut)^2)) -> 6.8169513 | AA10: =IF(Xhaut="","",SQRT(((Xintergauche-Xhaut)^2+(Yintergauche-Yhaut)^2)+(Zintergauche-Zhaut)^2)) -> 5.6663715 | AB10: =IF(Xhaut="","",SQRT(((Xhautgauche-Xhaut)^2+(Yhautgauche-Yhaut)^2)+(Zhautgauche-Zhaut)^2)) -> 3.7325253 | AC10: =IF(Xhaut="","",SQRT(((Xhautdroit-Xhaut)^2+(Yhautdroit-Yhaut)^2)+(Zhautdroit-Zhaut)^2)) -> 3.2976888 | AD10: =IF(Xhaut="","",SQRT(((Xinterdroit-Xhaut)^2+(Yinterdroit-Yhaut)^2)+(Zinterdroit-Zhaut)^2)) -> 5.3172661 | AE10: =IF(Xhaut="","",SQRT(((Xbasdroit-Xhaut)^2+(Ybasdroit-Yhaut)^2)+(Zbasdroit-Zhaut)^2)) -> 6.5580053 | AF10: =IF(Xhautdroit="","",SQRT(((Xhautdroit-Xhautgauche)^2+(Yhautdroit-Yhautgauche)^2)+(Zhautdroit-Zhautgauche)^2)) -> 6.4516036 | AG10: =IF(Xinterdroit="","",SQRT(((Xinterdroit-Xintergauche)^2+(Yinterdroit-Yintergauche)^2)+(Zinterdroit-Zintergauche)^2)) -> 8.4123915 | AH10: =IF(Xbasdroit="","",SQRT(((Xbasdroit-Xbasgauche)^2+(Ybasdroit-Ybasgauche)^2)+(Zbasdroit-Zbasgauche)^2)) -> 7.6480182 | AI10: 0 | AJ10: 0 | AK10: 0 | AL10: 0 | AM10: 0 | AN10: 0 | AO10: 0 | AP10: 0 | AQ10: 0 | AS10: 0 | AT10: 0 | AU10: 0 | AV10: 0 | AW10: 0 | AX10: 0 | AY10: 0 | AZ10: 0 | BA10: 0 | BB10: 0 | BC10: 0 | BD10: 0 | BE10: 0 | BF10: 0 | BG10: 0 | BH10: 0 | BI10: 0 | BJ10: 0 | BK10: 0 | BL10: 0 | BM10: 0 | BO10: 169.37506 | BP10: -3.7738522 | BQ10: -1.1608706 | BR10: 169.21189 | BS10: -4.2118592 | BT10: 0.8274611 | BU10: 169.19146 | BV10: -3.2408001 | BW10: 2.9693654 | BX10: 168.96361 | BY10: 0.2192351 | BZ10: 4.3529439 | CA10: 169.20119 | CB10: 3.2107806 | CC10: 2.9834681 | CD10: 169.19335 | CE10: 4.2005098 | CF10: 0.83354652 | CG10: 169.25872 | CH10: 3.872944 | CI10: -1.0879072 | CK10: 0 | CL10: 0 | CM10: 0 | CN10: 0 | CO10: 0 | CP10: 0 | CQ10: 0 | CR10: 0 | CS10: 0 | CT10: 0 | CU10: 0 | CV10: 0 | CW10: 0 | CX10: 0 | CY10: 0 | CZ10: 0 | DA10: 0 | DB10: 0 | DC10: 0 | DD10: 0 | DE10: 0
A11: 43600 | B11: =A11-A10 -> 1 | C11: 170.4 | D11: =C11-PM -> 1.2 | E11: 823219.58 | F11: 1091508.6 | G11: -125.0099 | H11: 823219.25 | I11: 1091508.9 | J11: -123.0234 | K11: 823219.64 | L11: 1091508 | M11: -120.8816 | N11: 823220.9 | O11: 1091504.8 | P11: -119.501 | Q11: 823222.38 | R11: 1091502.2 | S11: -120.8675 | T11: 823222.79 | U11: 1091501.3 | V11: -123.0176 | W11: 823222.71 | X11: 1091501.6 | Y11: -124.9384 | Z11: =IF(Xhaut="","",SQRT(((Xbasgauche-Xhaut)^2+(Ybasgauche-Yhaut)^2)+(Zbasgauche-Zhaut)^2)) -> 6.8159709 | AA11: =IF(Xhaut="","",SQRT(((Xintergauche-Xhaut)^2+(Yintergauche-Yhaut)^2)+(Zintergauche-Zhaut)^2)) -> 5.6658822 | AB11: =IF(Xhaut="","",SQRT(((Xhautgauche-Xhaut)^2+(Yhautgauche-Yhaut)^2)+(Zhautgauche-Zhaut)^2)) -> 3.7323049 | AC11: =IF(Xhaut="","",SQRT(((Xhautdroit-Xhaut)^2+(Yhautdroit-Yhaut)^2)+(Zhautdroit-Zhaut)^2)) -> 3.2975404 | AD11: =IF(Xhaut="","",SQRT(((Xinterdroit-Xhaut)^2+(Yinterdroit-Yhaut)^2)+(Zinterdroit-Zhaut)^2)) -> 5.3167728 | AE11: =IF(Xhaut="","",SQRT(((Xbasdroit-Xhaut)^2+(Ybasdroit-Yhaut)^2)+(Zbasdroit-Zhaut)^2)) -> 6.557888 | AF11: =IF(Xhautdroit="","",SQRT(((Xhautdroit-Xhautgauche)^2+(Yhautdroit-Yhautgauche)^2)+(Zhautdroit-Zhautgauche)^2)) -> 6.451694 | AG11: =IF(Xinterdroit="","",SQRT(((Xinterdroit-Xintergauche)^2+(Yinterdroit-Yintergauche)^2)+(Zinterdroit-Zintergauche)^2)) -> 8.411993 | AH11: =IF(Xbasdroit="","",SQRT(((Xbasdroit-Xbasgauche)^2+(Ybasdroit-Ybasgauche)^2)+(Zbasdroit-Zbasgauche)^2)) -> 7.6479271 | AI11: =IF(Z11="","",(Z11-Z$10)*1000) -> -0.98041207 | AJ11: =IF(AA11="","",(AA11-AA$10)*1000) -> -0.48933959 | AK11: =IF(AB11="","",(AB11-AB$10)*1000) -> -0.22036814 | AL11: =IF(AC11="","",(AC11-AC$10)*1000) -> -0.148348 | AM11: =IF(AD11="","",(AD11-AD$10)*1000) -> -0.49324904 | AN11: =IF(AE11="","",(AE11-AE$10)*1000) -> -0.11729645 | AO11: =IF(AF11="","",(AF11-AF$10)*1000) -> 0.090345954 | AP11: =IF(AG11="","",(AG11-AG$10)*1000) -> -0.39843061 | AQ11: =IF(AH11="","",(AH11-AH$10)*1000) -> -0.091110943 | AS11: =IF(E11="","",(E11-E$10)*1000) -> -0.49999997 | AT11: =IF(F11="","",(F11-F$10)*1000) -> -0.80000004 | AU11: =IF(G11="","",(G11-G$10)*1000) -> 0.1 | AV11: =IF(H11="","",(H11-H$10)*1000) -> -0.099999947 | AW11: =IF(I11="","",(I11-I$10)*1000) -> -0.19999989 | AX11: =IF(J11="","",(J11-J$10)*1000) -> -0.1 | AY11: =IF(K11="","",(K11-K$10)*1000) -> -0.10000006 | AZ11: =IF(L11="","",(L11-L$10)*1000) -> 0 | ... BM11: =IF(Y11="","",(Y11-Y$10)*1000) -> -0.2 | BO11: 169.37426 | BP11: -3.7733385 | BQ11: -1.1607626 | BR11: 169.21172 | BS11: -4.2117202 | BT11: 0.82736285 | BU11: 169.19136 | BV11: -3.2408424 | BW11: 2.9693664 | BX11: 168.96308 | BY11: 0.21920504 | BZ11: 4.3522492 | CA11: 169.20106 | CB11: 3.2108289 | CC11: 2.9833694 | CD11: 169.19303 | CE11: 4.2002501 | CF11: 0.83334972 | CG11: 169.25896 | CH11: 3.8733849 | CI11: -1.0881096 | CK11: =IF(BO11="","",(BO11-BO$10)*1000) -> -0.79126762 | CL11: =IF(BP11="","",(BP11-BP$10)*1000) -> 0.51370768 | CM11: =IF(BQ11="","",(BQ11-BQ$10)*1000) -> 0.10791268 | CN11: =IF(BR11="","",(BR11-BR$10)*1000) -> -0.17515951 | CO11: =IF(BS11="","",(BS11-BS$10)*1000) -> 0.13899313 | CP11: =IF(BT11="","",(BT11-BT$10)*1000) -> -0.098248405 | CQ11: =IF(BU11="","",(BU11-BU$10)*1000) -> -0.090629262 | CR11: =IF(BV11="","",(BV11-BV$10)*1000) -> -0.042265228 | ... DE11: =IF(CI11="","",(CI11-CI$10)*1000) -> -0.20235721
A12: 43601 | B12: =A12-A$10 -> 2 | C12: 170.4 | D12: =C12-PM -> 1.2 | E12: 823219.58 | F12: 1091508.6 | G12: -125.0097 | H12: 823219.25 | I12: 1091508.9 | J12: -123.0229 | K12: 823219.64 | L12: 1091508 | M12: -120.8815 | N12: 823220.9 | O12: 1091504.8 | P12: -119.5006 | Q12: 823222.38 | R12: 1091502.2 | S12: -120.8671 | T12: 823222.79 | U12: 1091501.3 | V12: -123.0171 | W12: 823222.71 | X12: 1091501.6 | Y12: -124.9379 | Z12: =IF(Xhaut="","",SQRT(((Xbasgauche-Xhaut)^2+(Ybasgauche-Yhaut)^2)+(Zbasgauche-Zhaut)^2)) -> 6.8165732 | AA12: =IF(Xhaut="","",SQRT(((Xintergauche-Xhaut)^2+(Yintergauche-Yhaut)^2)+(Zintergauche-Zhaut)^2)) -> 5.6661983 | AB12: =IF(Xhaut="","",SQRT(((Xhautgauche-Xhaut)^2+(Yhautgauche-Yhaut)^2)+(Zhautgauche-Zhaut)^2)) -> 3.7321368 | AC12: =IF(Xhaut="","",SQRT(((Xhautdroit-Xhaut)^2+(Yhautdroit-Yhaut)^2)+(Zhautdroit-Zhaut)^2)) -> 3.2974612 | AD12: =IF(Xhaut="","",SQRT(((Xinterdroit-Xhaut)^2+(Yinterdroit-Yhaut)^2)+(Zinterdroit-Zhaut)^2)) -> 5.3167422 | AE12: =IF(Xhaut="","",SQRT(((Xbasdroit-Xhaut)^2+(Ybasdroit-Yhaut)^2)+(Zbasdroit-Zhaut)^2)) -> 6.5576249 | AF12: =IF(Xhautdroit="","",SQRT(((Xhautdroit-Xhautgauche)^2+(Yhautdroit-Yhautgauche)^2)+(Zhautdroit-Zhautgauche)^2)) -> 6.4513266 | AG12: =IF(Xinterdroit="","",SQRT(((Xinterdroit-Xintergauche)^2+(Yinterdroit-Yintergauche)^2)+(Zinterdroit-Zintergauche)^2)) -> 8.4124953 | AH12: =IF(Xbasdroit="","",SQRT(((Xbasdroit-Xbasgauche)^2+(Ybasdroit-Ybasgauche)^2)+(Zbasdroit-Zbasgauche)^2)) -> 7.6482919 | AI12: =IF(Z12="","",(Z12-Z$10)*1000) -> -0.37805926 | AJ12: =IF(AA12="","",(AA12-AA$10)*1000) -> -0.1732519 | AK12: =IF(AB12="","",(AB12-AB$10)*1000) -> -0.38849707 | AL12: =IF(AC12="","",(AC12-AC$10)*1000) -> -0.22751861 | AM12: =IF(AD12="","",(AD12-AD$10)*1000) -> -0.5238222 | AN12: =IF(AE12="","",(AE12-AE$10)*1000) -> -0.38031176 | AO12: =IF(AF12="","",(AF12-AF$10)*1000) -> -0.27700355 | AP12: =IF(AG12="","",(AG12-AG$10)*1000) -> 0.10384985 | AQ12: =IF(AH12="","",(AH12-AH$10)*1000) -> 0.27377404 | AS12: =IF(E12="","",(E12-E$10)*1000) -> 0.10000006 | AT12: =IF(F12="","",(F12-F$10)*1000) -> 0.10000006 | AU12: =IF(G12="","",(G12-G$10)*1000) -> 0.3 | AV12: =IF(H12="","",(H12-H$10)*1000) -> 0.10000006 | AW12: =IF(I12="","",(I12-I$10)*1000) -> 0.30000019 | AX12: =IF(J12="","",(J12-J$10)*1000) -> 0.4 | AY12: =IF(K12="","",(K12-K$10)*1000) -> -0.30000007 | AZ12: =IF(L12="","",(L12-L$10)*1000) -> -0.49999985 | ... BM12: =IF(Y12="","",(Y12-Y$10)*1000) -> 0.3 | BO12: 169.37519 | BP12: -3.7739006 | BQ12: -1.1605719 | BR12: 169.21211 | BS12: -4.2120888 | BT12: 0.82785892 | BU12: 169.19097 | BV12: -3.2404737 | BW12: 2.9694703 | BX12: 168.96303 | BY12: 0.21929567 | BZ12: 4.3526497 | CA12: 169.20106 | CB12: 3.2108289 | CC12: 2.9837694 | CD12: 169.19308 | CE12: 4.200383 | CF12: 0.83384924 | CG12: 169.25873 | CH12: 3.8731675 | CI12: -1.0876073 | CK12: =IF(BO12="","",(BO12-BO$10)*1000) -> 0.13289449 | CL12: =IF(BP12="","",(BP12-BP$10)*1000) -> -0.048364034 | CM12: =IF(BQ12="","",(BQ12-BQ$10)*1000) -> 0.29867106 | CN12: =IF(BR12="","",(BR12-BR$10)*1000) -> 0.21742494 | CO12: =IF(BS12="","",(BS12-BS$10)*1000) -> -0.22962256 | CP12: =IF(BT12="","",(BT12-BT$10)*1000) -> 0.39782575 | CQ12: =IF(BU12="","",(BU12-BU$10)*1000) -> -0.48321362 | CR12: =IF(BV12="","",(BV12-BV$10)*1000) -> 0.32635025 | ... DE12: =IF(CI12="","",(CI12-CI$10)*1000) -> 0.29993901
A13: 43605 | B13: =A13-A$10 -> 6 | C13: 170.4 | D13: =C13-PM -> 1.2 | E13: 823219.58 | F13: 1091508.6 | G13: -125.0101 | H13: 823219.25 | I13: 1091508.9 | J13: -123.0234 | K13: 823219.64 | L13: 1091508 | M13: -120.882 | N13: 823220.9 | O13: 1091504.8 | P13: -119.501 | Q13: 823222.38 | R13: 1091502.2 | S13: -120.8677 | T13: 823222.79 | U13: 1091501.3 | V13: -123.0176 | W13: 823222.71 | X13: 1091501.6 | Y13: -124.9384 | Z13: =IF(Xhaut="","",SQRT(((Xbasgauche-Xhaut)^2+(Ybasgauche-Yhaut)^2)+(Zbasgauche-Zhaut)^2)) -> 6.8162802 | AA13: =IF(Xhaut="","",SQRT(((Xintergauche-Xhaut)^2+(Yintergauche-Yhaut)^2)+(Zintergauche-Zhaut)^2)) -> 5.6663332 | AB13: =IF(Xhaut="","",SQRT(((Xhautgauche-Xhaut)^2+(Yhautgauche-Yhaut)^2)+(Zhautgauche-Zhaut)^2)) -> 3.7322074 | AC13: =IF(Xhaut="","",SQRT(((Xhautdroit-Xhaut)^2+(Yhautdroit-Yhaut)^2)+(Zhautdroit-Zhaut)^2)) -> 3.2974544 | AD13: =IF(Xhaut="","",SQRT(((Xinterdroit-Xhaut)^2+(Yinterdroit-Yhaut)^2)+(Zinterdroit-Zhaut)^2)) -> 5.3170472 | AE13: =IF(Xhaut="","",SQRT(((Xbasdroit-Xhaut)^2+(Ybasdroit-Yhaut)^2)+(Zbasdroit-Zhaut)^2)) -> 6.5575764 | AF13: =IF(Xhautdroit="","",SQRT(((Xhautdroit-Xhautgauche)^2+(Yhautdroit-Yhautgauche)^2)+(Zhautdroit-Zhautgauche)^2)) -> 6.451284 | AG13: =IF(Xinterdroit="","",SQRT(((Xinterdroit-Xintergauche)^2+(Yinterdroit-Yintergauche)^2)+(Zinterdroit-Zintergauche)^2)) -> 8.4128937 | AH13: =IF(Xbasdroit="","",SQRT(((Xbasdroit-Xbasgauche)^2+(Ybasdroit-Ybasgauche)^2)+(Zbasdroit-Zbasgauche)^2)) -> 7.6476427 | AI13: =IF(Z13="","",(Z13-Z$10)*1000) -> -0.67114094 | AJ13: =IF(AA13="","",(AA13-AA$10)*1000) -> -0.03835169 | AK13: =IF(AB13="","",(AB13-AB$10)*1000) -> -0.31784918 | AL13: =IF(AC13="","",(AC13-AC$10)*1000) -> -0.23439664 | AM13: =IF(AD13="","",(AD13-AD$10)*1000) -> -0.21890559 | AN13: =IF(AE13="","",(AE13-AE$10)*1000) -> -0.42888979 | AO13: =IF(AF13="","",(AF13-AF$10)*1000) -> -0.31963211 | AP13: =IF(AG13="","",(AG13-AG$10)*1000) -> 0.50220497 | AQ13: =IF(AH13="","",(AH13-AH$10)*1000) -> -0.37545667 | AS13: =IF(E13="","",(E13-E$10)*1000) -> -0.29999996 | AT13: =IF(F13="","",(F13-F$10)*1000) -> -0.69999998 | AU13: =IF(G13="","",(G13-G$10)*1000) -> -0.1 | AV13: =IF(H13="","",(H13-H$10)*1000) -> 0.20000001 | AW13: =IF(I13="","",(I13-I$10)*1000) -> 0.30000019 | AX13: =IF(J13="","",(J13-J$10)*1000) -> -0.1 | AY13: =IF(K13="","",(K13-K$10)*1000) -> -0.30000007 | AZ13: =IF(L13="","",(L13-L$10)*1000) -> -0.59999991 | ... BM13: =IF(Y13="","",(Y13-Y$10)*1000) -> -0.2 | BO13: 169.37449 | BP13: -3.7733446 | BQ13: -1.1609649 | BR13: 169.2122 | BS13: -4.2120465 | BT13: 0.82735802 | BU13: 169.19093 | BV13: -3.2403831 | BW13: 2.9689707 | BX13: 168.96308 | BY13: 0.21942856 | BZ13: 4.3522492 | CA13: 169.20093 | CB13: 3.2108773 | CC13: 2.9831707 | CD13: 169.19331 | CE13: 4.200824 | CF13: 0.83334688 | CG13: 169.25855 | CH13: 3.873083 | CI13: -1.0881055 | CK13: =IF(BO13="","",(BO13-BO$10)*1000) -> -0.56774397 | CL13: =IF(BP13="","",(BP13-BP$10)*1000) -> 0.50760883 | CM13: =IF(BQ13="","",(BQ13-BQ$10)*1000) -> -0.09432256 | CN13: =IF(BR13="","",(BR13-BR$10)*1000) -> 0.3080541 | CO13: =IF(BS13="","",(BS13-BS$10)*1000) -> -0.18735738 | CP13: =IF(BT13="","",(BT13-BT$10)*1000) -> -0.10308054 | CQ13: =IF(BU13="","",(BU13-BU$10)*1000) -> -0.52547885 | CR13: =IF(BV13="","",(BV13-BV$10)*1000) -> 0.41697952 | ... DE13: =IF(CI13="","",(CI13-CI$10)*1000) -> -0.1982484
A14: 43607 | B14: =A14-A$10 -> 8 | C14: 172.28 | D14: =C14-PM -> 3.08 | E14: 823219.58 | F14: 1091508.6 | G14: -125.01 | H14: 823219.25 | I14: 1091508.9 | J14: -123.023 | K14: 823219.64 | L14: 1091508 | M14: -120.882 | N14: 823220.9 | O14: 1091504.8 | P14: -119.502 | Q14: 823222.38 | R14: 1091502.2 | S14: -120.868 | T14: 823222.79 | U14: 1091501.3 | V14: -123.017 | W14: 823222.71 | X14: 1091501.6 | Y14: -124.938 | Z14: =IF(Xhaut="","",SQRT(((Xbasgauche-Xhaut)^2+(Ybasgauche-Yhaut)^2)+(Zbasgauche-Zhaut)^2)) -> 6.8144215 | AA14: =IF(Xhaut="","",SQRT(((Xintergauche-Xhaut)^2+(Yintergauche-Yhaut)^2)+(Zintergauche-Zhaut)^2)) -> 5.6650411 | AB14: =IF(Xhaut="","",SQRT(((Xhautgauche-Xhaut)^2+(Yhautgauche-Yhaut)^2)+(Zhautgauche-Zhaut)^2)) -> 3.7311254 | AC14: =IF(Xhaut="","",SQRT(((Xhautdroit-Xhaut)^2+(Yhautdroit-Yhaut)^2)+(Zhautdroit-Zhaut)^2)) -> 3.2967341 | AD14: =IF(Xhaut="","",SQRT(((Xinterdroit-Xhaut)^2+(Yinterdroit-Yhaut)^2)+(Zinterdroit-Zhaut)^2)) -> 5.3148307 | AE14: =IF(Xhaut="","",SQRT(((Xbasdroit-Xhaut)^2+(Ybasdroit-Yhaut)^2)+(Zbasdroit-Zhaut)^2)) -> 6.5562212 | AF14: =IF(Xhautdroit="","",SQRT(((Xhautdroit-Xhautgauche)^2+(Yhautdroit-Yhautgauche)^2)+(Zhautdroit-Zhautgauche)^2)) -> 6.4500522 | AG14: =IF(Xinterdroit="","",SQRT(((Xinterdroit-Xintergauche)^2+(Yinterdroit-Yintergauche)^2)+(Zinterdroit-Zintergauche)^2)) -> 8.41086 | AH14: =IF(Xbasdroit="","",SQRT(((Xbasdroit-Xbasgauche)^2+(Ybasdroit-Ybasgauche)^2)+(Zbasdroit-Zbasgauche)^2)) -> 7.6456255 | AI14: =IF(Z14="","",(Z14-Z$10)*1000) -> -2.5297503 | AJ14: =IF(AA14="","",(AA14-AA$10)*1000) -> -1.3304148 | AK14: =IF(AB14="","",(AB14-AB$10)*1000) -> -1.3998391 | AL14: =IF(AC14="","",(AC14-AC$10)*1000) -> -0.95461562 | AM14: =IF(AD14="","",(AD14-AD$10)*1000) -> -2.435402 | AN14: =IF(AE14="","",(AE14-AE$10)*1000) -> -1.7840823 | AO14: =IF(AF14="","",(AF14-AF$10)*1000) -> -1.5514604 | AP14: =IF(AG14="","",(AG14-AG$10)*1000) -> -1.5314583 | AQ14: =IF(AH14="","",(AH14-AH$10)*1000) -> -2.3926835 | AS14: =IF(E14="","",(E14-E$10)*1000) -> 0.20000001 | AT14: =IF(F14="","",(F14-F$10)*1000) -> -2.9 | AU14: =IF(G14="","",(G14-G$10)*1000) -> 0 | AV14: =IF(H14="","",(H14-H$10)*1000) -> 0.20000001 | AW14: =IF(I14="","",(I14-I$10)*1000) -> -0.89999987 | AX14: =IF(J14="","",(J14-J$10)*1000) -> 0.3 | AY14: =IF(K14="","",(K14-K$10)*1000) -> -0.70000009 | AZ14: =IF(L14="","",(L14-L$10)*1000) -> -2.2 | ... BM14: =IF(Y14="","",(Y14-Y$10)*1000) -> 0.2 | BO14: 169.37401 | BP14: -3.7711395 | BQ14: -1.1608601 | BR14: 169.21169 | BS14: -4.210959 | BT14: 0.82776309 | BU14: 169.18989 | BV14: -3.2391021 | BW14: 2.9689811 | BX14: 168.96261 | BY14: 0.21997843 | BZ14: 4.3512539 | CA14: 169.2008 | CB14: 3.2109257 | CC14: 2.982872 | CD14: 169.19199 | CE14: 4.1998758 | CF14: 0.83396011 | CG14: 169.25824 | CH14: 3.8732703 | CI14: -1.0877024 | CK14: =IF(BO14="","",(BO14-BO$10)*1000) -> -1.0444324 | CL14: =IF(BP14="","",(BP14-BP$10)*1000) -> 2.7127773 | CM14: =IF(BQ14="","",(BQ14-BQ$10)*1000) -> 0.010444324 | CN14: =IF(BR14="","",(BR14-BR$10)*1000) -> -0.19912833 | CO14: =IF(BS14="","",(BS14-BS$10)*1000) -> 0.90019313 | CP14: =IF(BT14="","",(BT14-BT$10)*1000) -> 0.30199128 | CQ14: =IF(BU14="","",(BU14-BU$10)*1000) -> -1.5642389 | CR14: =IF(BV14="","",(BV14-BV$10)*1000) -> 1.6979861 | ... DE14: =IF(CI14="","",(CI14-CI$10)*1000) -> 0.20483214
A15: 43621 | B15: =A15-A$10 -> 22 | C15: 176.25 | D15: =C15-PM -> 7.05 | E15: 823219.58 | F15: 1091508.6 | G15: -125.009 | H15: 823219.25 | I15: 1091508.9 | J15: -123.0228 | K15: 823219.64 | L15: 1091508 | M15: -120.8818 | N15: 823220.9 | O15: 1091504.8 | P15: -119.5031 | Q15: 823222.38 | R15: 1091502.2 | S15: -120.8679 | T15: 823222.79 | U15: 1091501.3 | V15: -123.0166 | W15: 823222.71 | X15: 1091501.6 | Y15: -124.9383 | Z15: =IF(Xhaut="","",SQRT(((Xbasgauche-Xhaut)^2+(Ybasgauche-Yhaut)^2)+(Zbasgauche-Zhaut)^2)) -> 6.8114936 | AA15: =IF(Xhaut="","",SQRT(((Xintergauche-Xhaut)^2+(Yintergauche-Yhaut)^2)+(Zintergauche-Zhaut)^2)) -> 5.6616438 | AB15: =IF(Xhaut="","",SQRT(((Xhautgauche-Xhaut)^2+(Yhautgauche-Yhaut)^2)+(Zhautgauche-Zhaut)^2)) -> 3.7283692 | AC15: =IF(Xhaut="","",SQRT(((Xhautdroit-Xhaut)^2+(Yhautdroit-Yhaut)^2)+(Zhautdroit-Zhaut)^2)) -> 3.2954347 | AD15: =IF(Xhaut="","",SQRT(((Xinterdroit-Xhaut)^2+(Yinterdroit-Yhaut)^2)+(Zinterdroit-Zhaut)^2)) -> 5.3125535 | AE15: =IF(Xhaut="","",SQRT(((Xbasdroit-Xhaut)^2+(Ybasdroit-Yhaut)^2)+(Zbasdroit-Zhaut)^2)) -> 6.5540468 | AF15: =IF(Xhautdroit="","",SQRT(((Xhautdroit-Xhautgauche)^2+(Yhautdroit-Yhautgauche)^2)+(Zhautdroit-Zhautgauche)^2)) -> 6.4466932 | AG15: =IF(Xinterdroit="","",SQRT(((Xinterdroit-Xintergauche)^2+(Yinterdroit-Yintergauche)^2)+(Zinterdroit-Zintergauche)^2)) -> 8.405806 | AH15: =IF(Xbasdroit="","",SQRT(((Xbasdroit-Xbasgauche)^2+(Ybasdroit-Ybasgauche)^2)+(Zbasdroit-Zbasgauche)^2)) -> 7.6408498 | AI15: =IF(Z15="","",(Z15-Z$10)*1000) -> -5.4576836 | AJ15: =IF(AA15="","",(AA15-AA$10)*1000) -> -4.7277779 | AK15: =IF(AB15="","",(AB15-AB$10)*1000) -> -4.1560392 | AL15: =IF(AC15="","",(AC15-AC$10)*1000) -> -2.254053 | AM15: =IF(AD15="","",(AD15-AD$10)*1000) -> -4.7126077 | AN15: =IF(AE15="","",(AE15-AE$10)*1000) -> -3.958436 | AO15: =IF(AF15="","",(AF15-AF$10)*1000) -> -4.9103924 | AP15: =IF(AG15="","",(AG15-AG$10)*1000) -> -6.5854613 | AQ15: =IF(AH15="","",(AH15-AH$10)*1000) -> -7.1683986 | AS15: =IF(E15="","",(E15-E$10)*1000) -> 2.2 | AT15: =IF(F15="","",(F15-F$10)*1000) -> -4 | AU15: =IF(G15="","",(G15-G$10)*1000) -> 1 | AV15: =IF(H15="","",(H15-H$10)*1000) -> 2.2 | AW15: =IF(I15="","",(I15-I$10)*1000) -> -3.3 | AX15: =IF(J15="","",(J15-J$10)*1000) -> 0.5 | AY15: =IF(K15="","",(K15-K$10)*1000) -> 1.5 | AZ15: =IF(L15="","",(L15-L$10)*1000) -> -3.5999999 | ... BM15: =IF(Y15="","",(Y15-Y$10)*1000) -> -0.1 | BO15: 169.37536 | BP15: -3.7692972 | BQ15: -1.1598736 | BR15: 169.21249 | BS15: -4.2079386 | BT15: 0.82795511 | BU15: 169.19129 | BV15: -3.2369035 | BW15: 2.9691671 | BX15: 168.96394 | BY15: 0.21971832 | BZ15: 4.3501406 | CA15: 169.20233 | CB15: 3.2097653 | CC15: 2.9829567 | CD15: 169.19426 | CE15: 4.1978454 | CF15: 0.8343374 | CG15: 169.25905 | CH15: 3.8703401 | CI15: -1.0880105 | CK15: =IF(BO15="","",(BO15-BO$10)*1000) -> 0.30323448 | CL15: =IF(BP15="","",(BP15-BP$10)*1000) -> 4.5550026 | CM15: =IF(BQ15="","",(BQ15-BQ$10)*1000) -> 0.99696766 | CN15: =IF(BR15="","",(BR15-BR$10)*1000) -> 0.59909087 | CO15: =IF(BS15="","",(BS15-BS$10)*1000) -> 3.9205982 | CP15: =IF(BT15="","",(BT15-BT$10)*1000) -> 0.49400909 | CQ15: =IF(BU15="","",(BU15-BU$10)*1000) -> -0.16210912 | CR15: =IF(BV15="","",(BV15-BV$10)*1000) -> 3.8966293 | ... DE15: =IF(CI15="","",(CI15-CI$10)*1000) -> -0.10331596
A16: 43637 | B16: =A16-A$10 -> 38 | C16: 181.24 | D16: =C16-PM -> 12.04 | E16: 823219.58 | F16: 1091508.6 | G16: -125.009 | H16: 823219.25 | I16: 1091508.9 | J16: -123.023 | K16: 823219.64 | L16: 1091508 | M16: -120.881 | N16: 823220.9 | O16: 1091504.8 | P16: -119.505 | Q16: 823222.38 | R16: 1091502.2 | S16: -120.868 | T16: 823222.79 | U16: 1091501.3 | V16: -123.017 | W16: 823222.7 | X16: 1091501.6 | Y16: -124.936 | Z16: =IF(Xhaut="","",SQRT(((Xbasgauche-Xhaut)^2+(Ybasgauche-Yhaut)^2)+(Zbasgauche-Zhaut)^2)) -> 6.8080214 | AA16: =IF(Xhaut="","",SQRT(((Xintergauche-Xhaut)^2+(Yintergauche-Yhaut)^2)+(Zintergauche-Zhaut)^2)) -> 5.6589579 | AB16: =IF(Xhaut="","",SQRT(((Xhautgauche-Xhaut)^2+(Yhautgauche-Yhaut)^2)+(Zhautgauche-Zhaut)^2)) -> 3.7255095 | AC16: =IF(Xhaut="","",SQRT(((Xhautdroit-Xhaut)^2+(Yhautdroit-Yhaut)^2)+(Zhautdroit-Zhaut)^2)) -> 3.2947003 | AD16: =IF(Xhaut="","",SQRT(((Xinterdroit-Xhaut)^2+(Yinterdroit-Yhaut)^2)+(Zinterdroit-Zhaut)^2)) -> 5.311526 | AE16: =IF(Xhaut="","",SQRT(((Xbasdroit-Xhaut)^2+(Ybasdroit-Yhaut)^2)+(Zbasdroit-Zhaut)^2)) -> 6.5500649 | AF16: =IF(Xhautdroit="","",SQRT(((Xhautdroit-Xhautgauche)^2+(Yhautdroit-Yhautgauche)^2)+(Zhautdroit-Zhautgauche)^2)) -> 6.4446738 | AG16: =IF(Xinterdroit="","",SQRT(((Xinterdroit-Xintergauche)^2+(Yinterdroit-Yintergauche)^2)+(Zinterdroit-Zintergauche)^2)) -> 8.4036681 | AH16: =IF(Xbasdroit="","",SQRT(((Xbasdroit-Xbasgauche)^2+(Ybasdroit-Ybasgauche)^2)+(Zbasdroit-Zbasgauche)^2)) -> 7.6366992 | AI16: =IF(Z16="","",(Z16-Z$10)*1000) -> -8.9298504 | AJ16: =IF(AA16="","",(AA16-AA$10)*1000) -> -7.4136014 | AK16: =IF(AB16="","",(AB16-AB$10)*1000) -> -7.0157771 | AL16: =IF(AC16="","",(AC16-AC$10)*1000) -> -2.9884674 | AM16: =IF(AD16="","",(AD16-AD$10)*1000) -> -5.7401095 | AN16: =IF(AE16="","",(AE16-AE$10)*1000) -> -7.9403649 | AO16: =IF(AF16="","",(AF16-AF$10)*1000) -> -6.9297833 | AP16: =IF(AG16="","",(AG16-AG$10)*1000) -> -8.7233937 | AQ16: =IF(AH16="","",(AH16-AH$10)*1000) -> -11.319009 | AS16: =IF(E16="","",(E16-E$10)*1000) -> 0.20000001 | AT16: =IF(F16="","",(F16-F$10)*1000) -> -6.8999999 | AU16: =IF(G16="","",(G16-G$10)*1000) -> 1 | AV16: =IF(H16="","",(H16-H$10)*1000) -> 0.20000001 | AW16: =IF(I16="","",(I16-I$10)*1000) -> -4.8999998 | AX16: =IF(J16="","",(J16-J$10)*1000) -> 0.3 | AY16: =IF(K16="","",(K16-K$10)*1000) -> -0.70000009 | AZ16: =IF(L16="","",(L16-L$10)*1000) -> -5.2 | ... BM16: =IF(Y16="","",(Y16-Y$10)*1000) -> 2.2 | BO16: 169.37232 | BP16: -3.7675143 | BQ16: -1.1598432 | BR16: 169.21 | BS16: -4.2073338 | BT16: 0.82777999 | BU16: 169.18862 | BV16: -3.2363832 | BW16: 2.9699938 | BX16: 168.96122 | BY16: 0.21822684 | BZ16: 4.3482678 | CA16: 169.19983 | CB16: 3.2082678 | CC16: 2.9828817 | CD16: 169.19144 | CE16: 4.1963116 | CF16: 0.83396556 | CG16: 169.2563 | CH16: 3.8679546 | CI16: -1.085683 | CK16: =IF(BO16="","",(BO16-BO$10)*1000) -> -2.7350222 | CL16: =IF(BP16="","",(BP16-BP$10)*1000) -> 6.3379451 | CM16: =IF(BQ16="","",(BQ16-BQ$10)*1000) -> 1.0273502 | CN16: =IF(BR16="","",(BR16-BR$10)*1000) -> -1.8897291 | CO16: =IF(BS16="","",(BS16-BS$10)*1000) -> 4.5253616 | CP16: =IF(BT16="","",(BT16-BT$10)*1000) -> 0.31889729 | CQ16: =IF(BU16="","",(BU16-BU$10)*1000) -> -2.8322419 | CR16: =IF(BV16="","",(BV16-BV$10)*1000) -> 4.4168627 | ... DE16: =IF(CI16="","",(CI16-CI$10)*1000) -> 2.2241777
A17: 43641 | B17: =A17-A$10 -> 42 | C17: 182.12 | D17: =C17-PM -> 12.92 | E17: 823219.58 | F17: 1091508.6 | G17: -125.01 | H17: 823219.25 | I17: 1091508.9 | J17: -123.024 | K17: 823219.64 | L17: 1091508 | M17: -120.882 | N17: 823220.89 | O17: 1091504.8 | P17: -119.507 | Q17: 823222.37 | R17: 1091502.2 | S17: -120.869 | T17: 823222.78 | U17: 1091501.3 | V17: -123.017 | W17: 823222.7 | X17: 1091501.6 | Y17: -124.937 | Z17: =IF(Xhaut="","",SQRT(((Xbasgauche-Xhaut)^2+(Ybasgauche-Yhaut)^2)+(Zbasgauche-Zhaut)^2)) -> 6.807213 | AA17: =IF(Xhaut="","",SQRT(((Xintergauche-Xhaut)^2+(Yintergauche-Yhaut)^2)+(Zintergauche-Zhaut)^2)) -> 5.6573183 | AB17: =IF(Xhaut="","",SQRT(((Xhautgauche-Xhaut)^2+(Yhautgauche-Yhaut)^2)+(Zhautgauche-Zhaut)^2)) -> 3.724274 | AC17: =IF(Xhaut="","",SQRT(((Xhautdroit-Xhaut)^2+(Yhautdroit-Yhaut)^2)+(Zhautdroit-Zhaut)^2)) -> 3.2947361 | AD17: =IF(Xhaut="","",SQRT(((Xinterdroit-Xhaut)^2+(Yinterdroit-Yhaut)^2)+(Zinterdroit-Zhaut)^2)) -> 5.3105598 | AE17: =IF(Xhaut="","",SQRT(((Xbasdroit-Xhaut)^2+(Ybasdroit-Yhaut)^2)+(Zbasdroit-Zhaut)^2)) -> 6.5499982 | AF17: =IF(Xhautdroit="","",SQRT(((Xhautdroit-Xhautgauche)^2+(Yhautdroit-Yhautgauche)^2)+(Zhautdroit-Zhautgauche)^2)) -> 6.4441927 | AG17: =IF(Xinterdroit="","",SQRT(((Xinterdroit-Xintergauche)^2+(Yinterdroit-Yintergauche)^2)+(Zinterdroit-Zintergauche)^2)) -> 8.4027616 | AH17: =IF(Xbasdroit="","",SQRT(((Xbasdroit-Xbasgauche)^2+(Ybasdroit-Ybasgauche)^2)+(Zbasdroit-Zbasgauche)^2)) -> 7.6380206 | AI17: =IF(Z17="","",(Z17-Z$10)*1000) -> -9.7382832 | AJ17: =IF(AA17="","",(AA17-AA$10)*1000) -> -9.0532751 | AK17: =IF(AB17="","",(AB17-AB$10)*1000) -> -8.2512494 | AL17: =IF(AC17="","",(AC17-AC$10)*1000) -> -2.9526524 | AM17: =IF(AD17="","",(AD17-AD$10)*1000) -> -6.7063038 | AN17: =IF(AE17="","",(AE17-AE$10)*1000) -> -8.0070057 | AO17: =IF(AF17="","",(AF17-AF$10)*1000) -> -7.4109738 | AP17: =IF(AG17="","",(AG17-AG$10)*1000) -> -9.6298324 | AQ17: =IF(AH17="","",(AH17-AH$10)*1000) -> -9.9976096 | AS17: =IF(E17="","",(E17-E$10)*1000) -> -1.8 | AT17: =IF(F17="","",(F17-F$10)*1000) -> -5.9 | AU17: =IF(G17="","",(G17-G$10)*1000) -> 0 | AV17: =IF(H17="","",(H17-H$10)*1000) -> -0.80000004 | AW17: =IF(I17="","",(I17-I$10)*1000) -> -4.8999998 | AX17: =IF(J17="","",(J17-J$10)*1000) -> -0.7 | AY17: =IF(K17="","",(K17-K$10)*1000) -> -2.7000001 | AZ17: =IF(L17="","",(L17-L$10)*1000) -> -5.2 | ... BM17: =IF(Y17="","",(Y17-Y$10)*1000) -> 1.2 | BO17: 169.37093 | BP17: -3.7692659 | BQ17: -1.1608293 | BR17: 169.20909 | BS17: -4.2077564 | BT17: 0.82678906 | BU17: 169.18681 | BV17: -3.2372285 | BW17: 2.9690119 | BX17: 168.95983 | BY17: 0.21647524 | BZ17: 4.3462817 | CA17: 169.19934 | CB17: 3.2069388 | CC17: 2.9818866 | CD17: 169.19096 | CE17: 4.1949827 | CF17: 0.8339704 | CG17: 169.2554 | CH17: 3.8675319 | CI17: -1.086674 | CK17: =IF(BO17="","",(BO17-BO$10)*1000) -> -4.1250222 | CL17: =IF(BP17="","",(BP17-BP$10)*1000) -> 4.5863491 | CM17: =IF(BQ17="","",(BQ17-BQ$10)*1000) -> 0.041250222 | CN17: =IF(BR17="","",(BR17-BR$10)*1000) -> -2.7960291 | CO17: =IF(BS17="","",(BS17-BS$10)*1000) -> 4.1027096 | CP17: =IF(BT17="","",(BT17-BT$10)*1000) -> -0.67203971 | CQ17: =IF(BU17="","",(BU17-BU$10)*1000) -> -4.6447419 | CR17: =IF(BV17="","",(BV17-BV$10)*1000) -> 3.5715577 | ... DE17: =IF(CI17="","",(CI17-CI$10)*1000) -> 1.2332407
A18: 43643 | B18: =A18-A$10 -> 44 | C18: 183.33 | D18: =C18-PM -> 14.13 | E18: 823219.58 | F18: 1091508.6 | G18: -125.01 | H18: 823219.25 | I18: 1091508.9 | J18: -123.023 | K18: 823219.64 | L18: 1091508 | M18: -120.882 | N18: 823220.89 | O18: 1091504.8 | P18: -119.507 | Q18: 823222.37 | R18: 1091502.2 | S18: -120.869 | T18: 823222.78 | U18: 1091501.3 | V18: -123.018 | W18: 823222.7 | X18: 1091501.6 | Y18: -124.937 | Z18: =IF(Xhaut="","",SQRT(((Xbasgauche-Xhaut)^2+(Ybasgauche-Yhaut)^2)+(Zbasgauche-Zhaut)^2)) -> 6.807213 | AA18: =IF(Xhaut="","",SQRT(((Xintergauche-Xhaut)^2+(Yintergauche-Yhaut)^2)+(Zintergauche-Zhaut)^2)) -> 5.6577148 | AB18: =IF(Xhaut="","",SQRT(((Xhautgauche-Xhaut)^2+(Yhautgauche-Yhaut)^2)+(Zhautgauche-Zhaut)^2)) -> 3.724274 | AC18: =IF(Xhaut="","",SQRT(((Xhautdroit-Xhaut)^2+(Yhautdroit-Yhaut)^2)+(Zhautdroit-Zhaut)^2)) -> 3.2939443 | AD18: =IF(Xhaut="","",SQRT(((Xinterdroit-Xhaut)^2+(Yinterdroit-Yhaut)^2)+(Zinterdroit-Zhaut)^2)) -> 5.3112208 | AE18: =IF(Xhaut="","",SQRT(((Xbasdroit-Xhaut)^2+(Ybasdroit-Yhaut)^2)+(Zbasdroit-Zhaut)^2)) -> 6.5495122 | AF18: =IF(Xhautdroit="","",SQRT(((Xhautdroit-Xhautgauche)^2+(Yhautdroit-Yhautgauche)^2)+(Zhautdroit-Zhautgauche)^2)) -> 6.4432872 | AG18: =IF(Xinterdroit="","",SQRT(((Xinterdroit-Xintergauche)^2+(Yinterdroit-Yintergauche)^2)+(Zinterdroit-Zintergauche)^2)) -> 8.4040881 | AH18: =IF(Xbasdroit="","",SQRT(((Xbasdroit-Xbasgauche)^2+(Ybasdroit-Ybasgauche)^2)+(Zbasdroit-Zbasgauche)^2)) -> 7.637108 | AI18: =IF(Z18="","",(Z18-Z$10)*1000) -> -9.7382831 | AJ18: =IF(AA18="","",(AA18-AA$10)*1000) -> -8.6567229 | AK18: =IF(AB18="","",(AB18-AB$10)*1000) -> -8.2512492 | AL18: =IF(AC18="","",(AC18-AC$10)*1000) -> -3.7444651 | AM18: =IF(AD18="","",(AD18-AD$10)*1000) -> -6.0453037 | AN18: =IF(AE18="","",(AE18-AE$10)*1000) -> -8.4930545 | AO18: =IF(AF18="","",(AF18-AF$10)*1000) -> -8.3164262 | AP18: =IF(AG18="","",(AG18-AG$10)*1000) -> -8.3033496 | AQ18: =IF(AH18="","",(AH18-AH$10)*1000) -> -10.910139 | AS18: =IF(E18="","",(E18-E$10)*1000) -> -1.8 | AT18: =IF(F18="","",(F18-F$10)*1000) -> -6.8999999 | AU18: =IF(G18="","",(G18-G$10)*1000) -> 0 | AV18: =IF(H18="","",(H18-H$10)*1000) -> -1.8 | AW18: =IF(I18="","",(I18-I$10)*1000) -> -4.8999998 | AX18: =IF(J18="","",(J18-J$10)*1000) -> 0.3 | AY18: =IF(K18="","",(K18-K$10)*1000) -> -2.7000001 | AZ18: =IF(L18="","",(L18-L$10)*1000) -> -6.1999999 | ... BM18: =IF(Y18="","",(Y18-Y$10)*1000) -> 1.2 | BO18: 169.37051 | BP18: -3.7683596 | BQ18: -1.1608251 | BR18: 169.20819 | BS18: -4.2081791 | BT18: 0.82779812 | BU18: 169.18639 | BV18: -3.2363222 | BW18: 2.9690161 | BX18: 168.9594 | BY18: 0.21738153 | BZ18: 4.346286 | CA18: 169.19934 | CB18: 3.2069388 | CC18: 2.9818866 | CD18: 169.19054 | CE18: 4.195889 | CF18: 0.83297462 | CG18: 169.2554 | CH18: 3.8675319 | CI18: -1.086674 | CK18: =IF(BO18="","",(BO18-BO$10)*1000) -> -4.5476222 | CL18: =IF(BP18="","",(BP18-BP$10)*1000) -> 5.4926411 | CM18: =IF(BQ18="","",(BQ18-BQ$10)*1000) -> 0.045476222 | CN18: =IF(BR18="","",(BR18-BR$10)*1000) -> -3.7023291 | CO18: =IF(BS18="","",(BS18-BS$10)*1000) -> 3.6800576 | CP18: =IF(BT18="","",(BT18-BT$10)*1000) -> 0.33702329 | CQ18: =IF(BU18="","",(BU18-BU$10)*1000) -> -5.0674419 | CR18: =IF(BV18="","",(BV18-BV$10)*1000) -> 4.4778497 | ... DE18: =IF(CI18="","",(CI18-CI$10)*1000) -> 1.2332407
A19: 43647 | B19: =A19-A$10 -> 48 | C19: 184.2 | D19: =C19-PM -> 15 | E19: 823219.58 | F19: 1091508.6 | G19: -125.0097 | H19: 823219.25 | I19: 1091508.9 | J19: -123.0235 | K19: 823219.64 | L19: 1091508 | M19: -120.882 | N19: 823220.89 | O19: 1091504.8 | P19: -119.508 | Q19: 823222.37 | R19: 1091502.2 | S19: -120.8692 | T19: 823222.78 | U19: 1091501.3 | V19: -123.0174 | W19: 823222.7 | X19: 1091501.6 | Y19: -124.9369 | Z19: =IF(Xhaut="","",SQRT(((Xbasgauche-Xhaut)^2+(Ybasgauche-Yhaut)^2)+(Zbasgauche-Zhaut)^2)) -> 6.8055674 | AA19: =IF(Xhaut="","",SQRT(((Xintergauche-Xhaut)^2+(Yintergauche-Yhaut)^2)+(Zintergauche-Zhaut)^2)) -> 5.6558038 | AB19: =IF(Xhaut="","",SQRT(((Xhautgauche-Xhaut)^2+(Yhautgauche-Yhaut)^2)+(Zhautgauche-Zhaut)^2)) -> 3.722904 | AC19: =IF(Xhaut="","",SQRT(((Xhautdroit-Xhaut)^2+(Yhautdroit-Yhaut)^2)+(Zhautdroit-Zhaut)^2)) -> 3.2942706 | AD19: =IF(Xhaut="","",SQRT(((Xinterdroit-Xhaut)^2+(Yinterdroit-Yhaut)^2)+(Zinterdroit-Zhaut)^2)) -> 5.3102701 | AE19: =IF(Xhaut="","",SQRT(((Xbasdroit-Xhaut)^2+(Ybasdroit-Yhaut)^2)+(Zbasdroit-Zhaut)^2)) -> 6.5486279 | AF19: =IF(Xhautdroit="","",SQRT(((Xhautdroit-Xhautgauche)^2+(Yhautdroit-Yhautgauche)^2)+(Zhautdroit-Zhautgauche)^2)) -> 6.4429897 | AG19: =IF(Xinterdroit="","",SQRT(((Xinterdroit-Xintergauche)^2+(Yinterdroit-Yintergauche)^2)+(Zinterdroit-Zintergauche)^2)) -> 8.4021904 | AH19: =IF(Xbasdroit="","",SQRT(((Xbasdroit-Xbasgauche)^2+(Ybasdroit-Ybasgauche)^2)+(Zbasdroit-Zbasgauche)^2)) -> 7.6361527 | AI19: =IF(Z19="","",(Z19-Z$10)*1000) -> -11.383933 | AJ19: =IF(AA19="","",(AA19-AA$10)*1000) -> -10.567756 | AK19: =IF(AB19="","",(AB19-AB$10)*1000) -> -9.6213039 | AL19: =IF(AC19="","",(AC19-AC$10)*1000) -> -3.4181352 | AM19: =IF(AD19="","",(AD19-AD$10)*1000) -> -6.9960128 | AN19: =IF(AE19="","",(AE19-AE$10)*1000) -> -9.3773463 | AO19: =IF(AF19="","",(AF19-AF$10)*1000) -> -8.6139264 | AP19: =IF(AG19="","",(AG19-AG$10)*1000) -> -10.201102 | AQ19: =IF(AH19="","",(AH19-AH$10)*1000) -> -11.865452 | AS19: =IF(E19="","",(E19-E$10)*1000) -> -2.2999999 | AT19: =IF(F19="","",(F19-F$10)*1000) -> -6.8999999 | AU19: =IF(G19="","",(G19-G$10)*1000) -> 0.3 | AV19: =IF(H19="","",(H19-H$10)*1000) -> -2 | AW19: =IF(I19="","",(I19-I$10)*1000) -> -5.9 | AX19: =IF(J19="","",(J19-J$10)*1000) -> -0.2 | AY19: =IF(K19="","",(K19-K$10)*1000) -> -3 | AZ19: =IF(L19="","",(L19-L$10)*1000) -> -6.1999999 | ... BM19: =IF(Y19="","",(Y19-Y$10)*1000) -> 1.3 | BO19: 169.3701 | BP19: -3.7686616 | BQ19: -1.160521 | BR19: 169.20767 | BS19: -4.2075386 | BT19: 0.82730331 | BU19: 169.18616 | BV19: -3.2365397 | BW19: 2.9690184 | BX19: 168.95923 | BY19: 0.21608876 | BZ19: 4.3452877 | CA19: 169.19861 | CB19: 3.2061537 | CC19: 2.9816939 | CD19: 169.19072 | CE19: 4.1945418 | CF19: 0.83357275 | CG19: 169.25528 | CH19: 3.866372 | CI19: -1.0865728 | CK19: =IF(BO19="","",(BO19-BO$10)*1000) -> -4.9585222 | CL19: =IF(BP19="","",(BP19-BP$10)*1000) -> 5.1906861 | CM19: =IF(BQ19="","",(BQ19-BQ$10)*1000) -> 0.34958522 | CN19: =IF(BR19="","",(BR19-BR$10)*1000) -> -4.2217291 | CO19: =IF(BS19="","",(BS19-BS$10)*1000) -> 4.3205606 | CP19: =IF(BT19="","",(BT19-BT$10)*1000) -> -0.15778271 | CQ19: =IF(BU19="","",(BU19-BU$10)*1000) -> -5.2970419 | CR19: =IF(BV19="","",(BV19-BV$10)*1000) -> 4.2604257 | ... DE19: =IF(CI19="","",(CI19-CI$10)*1000) -> 1.3344517
A20: 43649 | B20: =A20-A$10 -> 50 | C20: 184.2 | D20: =C20-PM -> 15 | E20: 823219.58 | F20: 1091508.6 | G20: -125.0092 | H20: 823219.25 | I20: 1091508.9 | J20: -123.0227 | K20: 823219.64 | L20: 1091508 | M20: -120.8807 | N20: 823220.89 | O20: 1091504.8 | P20: -119.507 | Q20: 823222.37 | R20: 1091502.2 | S20: -120.8685 | T20: 823222.78 | U20: 1091501.3 | V20: -123.0168 | W20: 823222.7 | X20: 1091501.6 | Y20: -124.9366 | Z20: =IF(Xhaut="","",SQRT(((Xbasgauche-Xhaut)^2+(Ybasgauche-Yhaut)^2)+(Zbasgauche-Zhaut)^2)) -> 6.8060101 | AA20: =IF(Xhaut="","",SQRT(((Xintergauche-Xhaut)^2+(Yintergauche-Yhaut)^2)+(Zintergauche-Zhaut)^2)) -> 5.6559572 | AB20: =IF(Xhaut="","",SQRT(((Xhautgauche-Xhaut)^2+(Yhautgauche-Yhaut)^2)+(Zhautgauche-Zhaut)^2)) -> 3.7229617 | AC20: =IF(Xhaut="","",SQRT(((Xhautdroit-Xhaut)^2+(Yhautdroit-Yhaut)^2)+(Zhautdroit-Zhaut)^2)) -> 3.2942598 | AD20: =IF(Xhaut="","",SQRT(((Xinterdroit-Xhaut)^2+(Yinterdroit-Yhaut)^2)+(Zinterdroit-Zhaut)^2)) -> 5.3110526 | AE20: =IF(Xhaut="","",SQRT(((Xbasdroit-Xhaut)^2+(Ybasdroit-Yhaut)^2)+(Zbasdroit-Zhaut)^2)) -> 6.5496113 | AF20: =IF(Xhautdroit="","",SQRT(((Xhautdroit-Xhautgauche)^2+(Yhautdroit-Yhautgauche)^2)+(Zhautdroit-Zhautgauche)^2)) -> 6.4430734 | AG20: =IF(Xinterdroit="","",SQRT(((Xinterdroit-Xintergauche)^2+(Yinterdroit-Yintergauche)^2)+(Zinterdroit-Zintergauche)^2)) -> 8.4029711 | AH20: =IF(Xbasdroit="","",SQRT(((Xbasdroit-Xbasgauche)^2+(Ybasdroit-Ybasgauche)^2)+(Zbasdroit-Zbasgauche)^2)) -> 7.6370224 | AI20: =IF(Z20="","",(Z20-Z$10)*1000) -> -10.94117 | AJ20: =IF(AA20="","",(AA20-AA$10)*1000) -> -10.414362 | AK20: =IF(AB20="","",(AB20-AB$10)*1000) -> -9.5636155 | AL20: =IF(AC20="","",(AC20-AC$10)*1000) -> -3.4289907 | AM20: =IF(AD20="","",(AD20-AD$10)*1000) -> -6.213455 | AN20: =IF(AE20="","",(AE20-AE$10)*1000) -> -8.3939027 | AO20: =IF(AF20="","",(AF20-AF$10)*1000) -> -8.5302113 | AP20: =IF(AG20="","",(AG20-AG$10)*1000) -> -9.420317 | AQ20: =IF(AH20="","",(AH20-AH$10)*1000) -> -10.995734 | AS20: =IF(E20="","",(E20-E$10)*1000) -> -1.8 | AT20: =IF(F20="","",(F20-F$10)*1000) -> -5.9 | AU20: =IF(G20="","",(G20-G$10)*1000) -> 0.8 | AV20: =IF(H20="","",(H20-H$10)*1000) -> -1.4 | AW20: =IF(I20="","",(I20-I$10)*1000) -> -4.8999998 | AX20: =IF(J20="","",(J20-J$10)*1000) -> 0.6 | AY20: =IF(K20="","",(K20-K$10)*1000) -> -2.8 | AZ20: =IF(L20="","",(L20-L$10)*1000) -> -5.2 | ... BM20: =IF(Y20="","",(Y20-Y$10)*1000) -> 1.6 | BO20: 169.37106 | BP20: -3.7695378 | BQ20: -1.1600306 | BR20: 169.20872 | BS20: -4.2083726 | BT20: 0.82809281 | BU20: 169.18664 | BV20: -3.2370895 | BW20: 2.9703136 | BX20: 168.96008 | BY20: 0.21593147 | BZ20: 4.3462792 | CA20: 169.19905 | CB20: 3.2061415 | CC20: 2.9823895 | CD20: 169.19104 | CE20: 4.1945779 | CF20: 0.83416961 | CG20: 169.25572 | CH20: 3.8663598 | CI20: -1.0862772 | CK20: =IF(BO20="","",(BO20-BO$10)*1000) -> -3.9982222 | CL20: =IF(BP20="","",(BP20-BP$10)*1000) -> 4.3144621 | CM20: =IF(BQ20="","",(BQ20-BQ$10)*1000) -> 0.83998222 | CN20: =IF(BR20="","",(BR20-BR$10)*1000) -> -3.1707291 | CO20: =IF(BS20="","",(BS20-BS$10)*1000) -> 3.4866016 | CP20: =IF(BT20="","",(BT20-BT$10)*1000) -> 0.63170729 | CQ20: =IF(BU20="","",(BU20-BU$10)*1000) -> -4.8199419 | CR20: =IF(BV20="","",(BV20-BV$10)*1000) -> 3.7105517 | ... DE20: =IF(CI20="","",(CI20-CI$10)*1000) -> 1.6299817
A21: 43650 | B21: =A21-A$10 -> 51 | C21: 184.2 | D21: =C21-PM -> 15 | E21: 823219.58 | F21: 1091508.6 | G21: -125.01 | H21: 823219.25 | I21: 1091508.9 | J21: -123.024 | K21: 823219.64 | L21: 1091508 | M21: -120.882 | N21: 823220.89 | O21: 1091504.8 | P21: -119.509 | Q21: 823222.37 | R21: 1091502.2 | S21: -120.869 | T21: 823222.78 | U21: 1091501.3 | V21: -123.017 | W21: 823222.7 | X21: 1091501.6 | Y21: -124.937 | Z21: =IF(Xhaut="","",SQRT(((Xbasgauche-Xhaut)^2+(Ybasgauche-Yhaut)^2)+(Zbasgauche-Zhaut)^2)) -> 6.8044839 | AA21: =IF(Xhaut="","",SQRT(((Xintergauche-Xhaut)^2+(Yintergauche-Yhaut)^2)+(Zintergauche-Zhaut)^2)) -> 5.6549111 | AB21: =IF(Xhaut="","",SQRT(((Xhautgauche-Xhaut)^2+(Yhautgauche-Yhaut)^2)+(Zhautgauche-Zhaut)^2)) -> 3.7218035 | AC21: =IF(Xhaut="","",SQRT(((Xhautdroit-Xhaut)^2+(Yhautdroit-Yhaut)^2)+(Zhautdroit-Zhaut)^2)) -> 3.2934603 | AD21: =IF(Xhaut="","",SQRT(((Xinterdroit-Xhaut)^2+(Yinterdroit-Yhaut)^2)+(Zinterdroit-Zhaut)^2)) -> 5.3092381 | AE21: =IF(Xhaut="","",SQRT(((Xbasdroit-Xhaut)^2+(Ybasdroit-Yhaut)^2)+(Zbasdroit-Zhaut)^2)) -> 6.5483403 | AF21: =IF(Xhautdroit="","",SQRT(((Xhautdroit-Xhautgauche)^2+(Yhautdroit-Yhautgauche)^2)+(Zhautdroit-Zhautgauche)^2)) -> 6.4419573 | AG21: =IF(Xinterdroit="","",SQRT(((Xinterdroit-Xintergauche)^2+(Yinterdroit-Yintergauche)^2)+(Zinterdroit-Zintergauche)^2)) -> 8.4013681 | AH21: =IF(Xbasdroit="","",SQRT(((Xbasdroit-Xbasgauche)^2+(Ybasdroit-Ybasgauche)^2)+(Zbasdroit-Zbasgauche)^2)) -> 7.6361955 | AI21: =IF(Z21="","",(Z21-Z$10)*1000) -> -12.467407 | AJ21: =IF(AA21="","",(AA21-AA$10)*1000) -> -11.460493 | AK21: =IF(AB21="","",(AB21-AB$10)*1000) -> -10.721812 | AL21: =IF(AC21="","",(AC21-AC$10)*1000) -> -4.228419 | AM21: =IF(AD21="","",(AD21-AD$10)*1000) -> -8.0279863 | AN21: =IF(AE21="","",(AE21-AE$10)*1000) -> -9.6649259 | AO21: =IF(AF21="","",(AF21-AF$10)*1000) -> -9.6463196 | AP21: =IF(AG21="","",(AG21-AG$10)*1000) -> -11.023359 | AQ21: =IF(AH21="","",(AH21-AH$10)*1000) -> -11.822646 | AS21: =IF(E21="","",(E21-E$10)*1000) -> -1.8 | AT21: =IF(F21="","",(F21-F$10)*1000) -> -6.8999999 | AU21: =IF(G21="","",(G21-G$10)*1000) -> 0 | AV21: =IF(H21="","",(H21-H$10)*1000) -> -1.8 | AW21: =IF(I21="","",(I21-I$10)*1000) -> -5.9 | AX21: =IF(J21="","",(J21-J$10)*1000) -> -0.7 | AY21: =IF(K21="","",(K21-K$10)*1000) -> -2.7000001 | AZ21: =IF(L21="","",(L21-L$10)*1000) -> -6.1999999 | ... BM21: =IF(Y21="","",(Y21-Y$10)*1000) -> 1.2 | BO21: 169.37051 | BP21: -3.7683596 | BQ21: -1.1608251 | BR21: 169.20777 | BS21: -4.2072728 | BT21: 0.82680235 | BU21: 169.18639 | BV21: -3.2363222 | BW21: 2.9690161 | BX21: 168.96025 | BY21: 0.21556895 | BZ21: 4.3442775 | CA21: 169.19886 | CB21: 3.2056099 | CC21: 2.9818914 | CD21: 169.19138 | CE21: 4.1940764 | CF21: 0.83396617 | CG21: 169.25582 | CH21: 3.8666256 | CI21: -1.0866782 | CK21: =IF(BO21="","",(BO21-BO$10)*1000) -> -4.5476245 | CL21: =IF(BP21="","",(BP21-BP$10)*1000) -> 5.4926415 | CM21: =IF(BQ21="","",(BQ21-BQ$10)*1000) -> 0.045476245 | CN21: =IF(BR21="","",(BR21-BR$10)*1000) -> -4.1249725 | CO21: =IF(BS21="","",(BS21-BS$10)*1000) -> 4.5863495 | CP21: =IF(BT21="","",(BT21-BT$10)*1000) -> -0.65875027 | CQ21: =IF(BU21="","",(BU21-BU$10)*1000) -> -5.067431 | CR21: =IF(BV21="","",(BV21-BV$10)*1000) -> 4.4778502 | ... DE21: =IF(CI21="","",(CI21-CI$10)*1000) -> 1.2290141
A22: 43655 | B22: =A22-A$10 -> 56 | C22: 184.2 | D22: =C22-PM -> 15 | E22: 823219.58 | F22: 1091508.6 | G22: -125.0097 | H22: 823219.25 | I22: 1091508.9 | J22: -123.0231 | K22: 823219.64 | L22: 1091508 | M22: -120.8818 | N22: 823220.89 | O22: 1091504.8 | P22: -119.5088 | Q22: 823222.37 | R22: 1091502.2 | S22: -120.8694 | T22: 823222.78 | U22: 1091501.3 | V22: -123.0171 | W22: 823222.7 | X22: 1091501.6 | Y22: -124.9364 | Z22: =IF(Xhaut="","",SQRT(((Xbasgauche-Xhaut)^2+(Ybasgauche-Yhaut)^2)+(Zbasgauche-Zhaut)^2)) -> 6.8039048 | AA22: =IF(Xhaut="","",SQRT(((Xintergauche-Xhaut)^2+(Yintergauche-Yhaut)^2)+(Zintergauche-Zhaut)^2)) -> 5.6548835 | AB22: =IF(Xhaut="","",SQRT(((Xhautgauche-Xhaut)^2+(Yhautgauche-Yhaut)^2)+(Zhautgauche-Zhaut)^2)) -> 3.721534 | AC22: =IF(Xhaut="","",SQRT(((Xhautdroit-Xhaut)^2+(Yhautdroit-Yhaut)^2)+(Zhautdroit-Zhaut)^2)) -> 3.2938879 | AD22: =IF(Xhaut="","",SQRT(((Xinterdroit-Xhaut)^2+(Yinterdroit-Yhaut)^2)+(Zinterdroit-Zhaut)^2)) -> 5.3093651 | AE22: =IF(Xhaut="","",SQRT(((Xbasdroit-Xhaut)^2+(Ybasdroit-Yhaut)^2)+(Zbasdroit-Zhaut)^2)) -> 6.5473843 | AF22: =IF(Xhautdroit="","",SQRT(((Xhautdroit-Xhautgauche)^2+(Yhautdroit-Yhautgauche)^2)+(Zhautdroit-Zhautgauche)^2)) -> 6.4417864 | AG22: =IF(Xinterdroit="","",SQRT(((Xinterdroit-Xintergauche)^2+(Yinterdroit-Yintergauche)^2)+(Zinterdroit-Zintergauche)^2)) -> 8.4017274 | AH22: =IF(Xbasdroit="","",SQRT(((Xbasdroit-Xbasgauche)^2+(Ybasdroit-Ybasgauche)^2)+(Zbasdroit-Zbasgauche)^2)) -> 7.6342916 | AI22: =IF(Z22="","",(Z22-Z$10)*1000) -> -13.046454 | AJ22: =IF(AA22="","",(AA22-AA$10)*1000) -> -11.488018 | AK22: =IF(AB22="","",(AB22-AB$10)*1000) -> -10.991282 | AL22: =IF(AC22="","",(AC22-AC$10)*1000) -> -3.8008537 | AM22: =IF(AD22="","",(AD22-AD$10)*1000) -> -7.9009893 | AN22: =IF(AE22="","",(AE22-AE$10)*1000) -> -10.620962 | AO22: =IF(AF22="","",(AF22-AF$10)*1000) -> -9.8172541 | AP22: =IF(AG22="","",(AG22-AG$10)*1000) -> -10.664015 | AQ22: =IF(AH22="","",(AH22-AH$10)*1000) -> -13.726532 | AS22: =IF(E22="","",(E22-E$10)*1000) -> -2.2999999 | AT22: =IF(F22="","",(F22-F$10)*1000) -> -8.9 | AU22: =IF(G22="","",(G22-G$10)*1000) -> 0.3 | AV22: =IF(H22="","",(H22-H$10)*1000) -> -0.89999998 | AW22: =IF(I22="","",(I22-I$10)*1000) -> -5.9 | AX22: =IF(J22="","",(J22-J$10)*1000) -> 0.2 | AY22: =IF(K22="","",(K22-K$10)*1000) -> -2.1 | AZ22: =IF(L22="","",(L22-L$10)*1000) -> -7.1999999 | ... BM22: =IF(Y22="","",(Y22-Y$10)*1000) -> 1.8 | BO22: 169.36921 | BP22: -3.7667583 | BQ22: -1.1605121 | BR22: 169.20858 | BS22: -4.2068924 | BT22: 0.82769419 | BU22: 169.18651 | BV22: -3.2351624 | BW22: 2.9692149 | BX22: 168.95964 | BY22: 0.21639071 | BZ22: 4.3444836 | CA22: 169.19862 | CB22: 3.2066007 | CC22: 2.9814938 | CD22: 169.1906 | CE22: 4.1948136 | CF22: 0.83387402 | CG22: 169.25518 | CH22: 3.8663298 | CI22: -1.0860718 | CK22: =IF(BO22="","",(BO22-BO$10)*1000) -> -5.8460746 | CL22: =IF(BP22="","",(BP22-BP$10)*1000) -> 7.0938997 | CM22: =IF(BQ22="","",(BQ22-BQ$10)*1000) -> 0.35846075 | CN22: =IF(BR22="","",(BR22-BR$10)*1000) -> -3.3093097 | CO22: =IF(BS22="","",(BS22-BS$10)*1000) -> 4.9667363 | CP22: =IF(BT22="","",(BT22-BT$10)*1000) -> 0.2330931 | CQ22: =IF(BU22="","",(BU22-BU$10)*1000) -> -4.9463078 | CR22: =IF(BV22="","",(BV22-BV$10)*1000) -> 5.6377334 | ... DE22: =IF(CI22="","",(CI22-CI$10)*1000) -> 1.8353582
A23: 43657 | B23: =A23-A$10 -> 58 | C23: 185.03 | D23: =C23-PM -> 15.83 | E23: 823219.58 | F23: 1091508.6 | G23: -125.0099 | H23: 823219.25 | I23: 1091508.9 | J23: -123.0235 | K23: 823219.64 | L23: 1091508 | M23: -120.8826 | N23: 823220.89 | O23: 1091504.8 | P23: -119.5098 | Q23: 823222.37 | R23: 1091502.2 | S23: -120.8701 | T23: 823222.78 | U23: 1091501.3 | V23: -123.0174 | W23: 823222.7 | X23: 1091501.6 | Y23: -124.9365 | Z23: =IF(Xhaut="","",SQRT(((Xbasgauche-Xhaut)^2+(Ybasgauche-Yhaut)^2)+(Zbasgauche-Zhaut)^2)) -> 6.8031616 | AA23: =IF(Xhaut="","",SQRT(((Xintergauche-Xhaut)^2+(Yintergauche-Yhaut)^2)+(Zintergauche-Zhaut)^2)) -> 5.6536669 | AB23: =IF(Xhaut="","",SQRT(((Xhautgauche-Xhaut)^2+(Yhautgauche-Yhaut)^2)+(Zhautgauche-Zhaut)^2)) -> 3.7213592 | AC23: =IF(Xhaut="","",SQRT(((Xhautdroit-Xhaut)^2+(Yhautdroit-Yhaut)^2)+(Zhautdroit-Zhaut)^2)) -> 3.2935393 | AD23: =IF(Xhaut="","",SQRT(((Xinterdroit-Xhaut)^2+(Yinterdroit-Yhaut)^2)+(Zinterdroit-Zhaut)^2)) -> 5.3080638 | AE23: =IF(Xhaut="","",SQRT(((Xbasdroit-Xhaut)^2+(Ybasdroit-Yhaut)^2)+(Zbasdroit-Zhaut)^2)) -> 6.5464723 | AF23: =IF(Xhautdroit="","",SQRT(((Xhautdroit-Xhautgauche)^2+(Yhautdroit-Yhautgauche)^2)+(Zhautdroit-Zhautgauche)^2)) -> 6.4414471 | AG23: =IF(Xinterdroit="","",SQRT(((Xinterdroit-Xintergauche)^2+(Yinterdroit-Yintergauche)^2)+(Zinterdroit-Zintergauche)^2)) -> 8.3995345 | AH23: =IF(Xbasdroit="","",SQRT(((Xbasdroit-Xbasgauche)^2+(Ybasdroit-Ybasgauche)^2)+(Zbasdroit-Zbasgauche)^2)) -> 7.6338427 | AI23: =IF(Z23="","",(Z23-Z$10)*1000) -> -13.78966 | AJ23: =IF(AA23="","",(AA23-AA$10)*1000) -> -12.704687 | AK23: =IF(AB23="","",(AB23-AB$10)*1000) -> -11.166079 | AL23: =IF(AC23="","",(AC23-AC$10)*1000) -> -4.1494602 | AM23: =IF(AD23="","",(AD23-AD$10)*1000) -> -9.2023099 | AN23: =IF(AE23="","",(AE23-AE$10)*1000) -> -11.532925 | AO23: =IF(AF23="","",(AF23-AF$10)*1000) -> -10.156504 | AP23: =IF(AG23="","",(AG23-AG$10)*1000) -> -12.856972 | AQ23: =IF(AH23="","",(AH23-AH$10)*1000) -> -14.175459 | AS23: =IF(E23="","",(E23-E$10)*1000) -> -0.60000003 | AT23: =IF(F23="","",(F23-F$10)*1000) -> -8.9 | AU23: =IF(G23="","",(G23-G$10)*1000) -> 0.1 | AV23: =IF(H23="","",(H23-H$10)*1000) -> 0.69999998 | AW23: =IF(I23="","",(I23-I$10)*1000) -> -6.8999999 | AX23: =IF(J23="","",(J23-J$10)*1000) -> -0.2 | AY23: =IF(K23="","",(K23-K$10)*1000) -> -0.60000003 | AZ23: =IF(L23="","",(L23-L$10)*1000) -> -7.1999999 | ... BM23: =IF(Y23="","",(Y23-Y$10)*1000) -> 1.7 | BO23: 169.37083 | BP23: -3.7662211 | BQ23: -1.1607283 | BR23: 169.20965 | BS23: -4.2054005 | BT23: 0.82728349 | BU23: 169.18783 | BV23: -3.2344377 | BW23: 2.9684017 | BX23: 168.9606 | BY23: 0.21716978 | BZ23: 4.343474 | CA23: 169.19942 | CB23: 3.206534 | CC23: 2.9807858 | CD23: 169.19153 | CE23: 4.1944751 | CF23: 0.83356472 | CG23: 169.25585 | CH23: 3.8663115 | CI23: -1.0861786 | CK23: =IF(BO23="","",(BO23-BO$10)*1000) -> -4.2208222 | CL23: =IF(BP23="","",(BP23-BP$10)*1000) -> 7.6311491 | CM23: =IF(BQ23="","",(BQ23-BQ$10)*1000) -> 0.14220822 | CN23: =IF(BR23="","",(BR23-BR$10)*1000) -> -2.2396291 | CO23: =IF(BS23="","",(BS23-BS$10)*1000) -> 6.4586426 | CP23: =IF(BT23="","",(BT23-BT$10)*1000) -> -0.17760371 | CQ23: =IF(BU23="","",(BU23-BU$10)*1000) -> -3.6291419 | CR23: =IF(BV23="","",(BV23-BV$10)*1000) -> 6.3623407 | ... DE23: =IF(CI23="","",(CI23-CI$10)*1000) -> 1.7286527
... A32: 43689 | B32: =A32-A$10 -> 90 | C32: 194.79 | D32: =C32-PM -> 25.59 | E32: 823219.58 | F32: 1091508.6 | G32: -125.0102 | H32: 823219.25 | I32: 1091508.9 | J32: -123.0239 | K32: 823219.64 | L32: 1091508 | M32: -120.8828 | N32: 823220.89 | O32: 1091504.8 | P32: -119.5138 | Q32: 823222.37 | R32: 1091502.2 | S32: -120.8722 | T32: 823222.78 | U32: 1091501.3 | V32: -123.0178 | W32: 823222.7 | X32: 1091501.6 | Y32: -124.9364 | Z32: =IF(Xhaut="","",SQRT(((Xbasgauche-Xhaut)^2+(Ybasgauche-Yhaut)^2)+(Zbasgauche-Zhaut)^2)) -> 6.7993252 | AA32: =IF(Xhaut="","",SQRT(((Xintergauche-Xhaut)^2+(Yintergauche-Yhaut)^2)+(Zintergauche-Zhaut)^2)) -> 5.6502664 | AB32: =IF(Xhaut="","",SQRT(((Xhautgauche-Xhaut)^2+(Yhautgauche-Yhaut)^2)+(Zhautgauche-Zhaut)^2)) -> 3.718823 | AC32: =IF(Xhaut="","",SQRT(((Xhautdroit-Xhaut)^2+(Yhautdroit-Yhaut)^2)+(Zhautdroit-Zhaut)^2)) -> 3.2910806 | AD32: =IF(Xhaut="","",SQRT(((Xinterdroit-Xhaut)^2+(Yinterdroit-Yhaut)^2)+(Zinterdroit-Zhaut)^2)) -> 5.3048465 | AE32: =IF(Xhaut="","",SQRT(((Xbasdroit-Xhaut)^2+(Ybasdroit-Yhaut)^2)+(Zbasdroit-Zhaut)^2)) -> 6.5418247 | AF32: =IF(Xhautdroit="","",SQRT(((Xhautdroit-Xhautgauche)^2+(Yhautdroit-Yhautgauche)^2)+(Zhautdroit-Zhautgauche)^2)) -> 6.4383029 | AG32: =IF(Xinterdroit="","",SQRT(((Xinterdroit-Xintergauche)^2+(Yinterdroit-Yintergauche)^2)+(Zinterdroit-Zintergauche)^2)) -> 8.3968787 | AH32: =IF(Xbasdroit="","",SQRT(((Xbasdroit-Xbasgauche)^2+(Ybasdroit-Ybasgauche)^2)+(Zbasdroit-Zbasgauche)^2)) -> 7.6300868 | AI32: =IF(Z32="","",(Z32-Z$10)*1000) -> -17.626105 | AJ32: =IF(AA32="","",(AA32-AA$10)*1000) -> -16.105178 | AK32: =IF(AB32="","",(AB32-AB$10)*1000) -> -13.702285 | AL32: =IF(AC32="","",(AC32-AC$10)*1000) -> -6.6081369 | AM32: =IF(AD32="","",(AD32-AD$10)*1000) -> -12.4196 | AN32: =IF(AE32="","",(AE32-AE$10)*1000) -> -16.180507 | AO32: =IF(AF32="","",(AF32-AF$10)*1000) -> -13.30078 | AP32: =IF(AG32="","",(AG32-AG$10)*1000) -> -15.512729 | AQ32: =IF(AH32="","",(AH32-AH$10)*1000) -> -17.931397 | AS32: =IF(E32="","",(E32-E$10)*1000) -> 0.20000001 | AT32: =IF(F32="","",(F32-F$10)*1000) -> -10.9 | AU32: =IF(G32="","",(G32-G$10)*1000) -> -0.2 | AV32: =IF(H32="","",(H32-H$10)*1000) -> 1.5 | AW32: =IF(I32="","",(I32-I$10)*1000) -> -8.9 | AX32: =IF(J32="","",(J32-J$10)*1000) -> -0.6 | AY32: =IF(K32="","",(K32-K$10)*1000) -> -0.50000008 | AZ32: =IF(L32="","",(L32-L$10)*1000) -> -9.2 | ... BM32: =IF(Y32="","",(Y32-Y$10)*1000) -> 1.8 | BO32: 169.3705 | BP32: -3.7636172 | BQ32: -1.161025 | BR32: 169.20949 | BS32: -4.2031592 | BT32: 0.82688512 | BU32: 169.1869 | BV32: -3.2322204 | BW32: 2.968211 | BX32: 168.9598 | BY32: 0.21723644 | BZ32: 4.339482 | CA32: 169.19886 | CB32: 3.2056099 | CC32: 2.9786914 | CD32: 169.19053 | CE32: 4.1937867 | CF32: 0.83317475 | CG32: 169.25444 | CH32: 3.8653211 | CI32: -1.0860644 | CK32: =IF(BO32="","",(BO32-BO$10)*1000) -> -4.5524222 | CL32: =IF(BP32="","",(BP32-BP$10)*1000) -> 10.235001 | CM32: =IF(BQ32="","",(BQ32-BQ$10)*1000) -> -0.15447578 | CN32: =IF(BR32="","",(BR32-BR$10)*1000) -> -2.4021291 | CO32: =IF(BS32="","",(BS32-BS$10)*1000) -> 8.6999776 | CP32: =IF(BT32="","",(BT32-BT$10)*1000) -> -0.57597871 | CQ32: =IF(BU32="","",(BU32-BU$10)*1000) -> -4.5528419 | CR32: =IF(BV32="","",(BV32-BV$10)*1000) -> 8.5797067 | ... DE32: =IF(CI32="","",(CI32-CI$10)*1000) -> 1.8427917
A33: 43690 | B33: =A33-A$10 -> 91 | C33: 194.79 | D33: =C33-PM -> 25.59 | E33: 823219.58 | F33: 1091508.6 | G33: -125.01 | H33: 823219.25 | I33: 1091508.9 | J33: -123.0234 | N33: 823220.89 | O33: 1091504.8 | P33: -119.5136 | Q33: 823222.37 | R33: 1091502.2 | S33: -120.8726 | T33: 823222.78 | U33: 1091501.3 | V33: -123.0176 | W33: 823222.7 | X33: 1091501.6 | Y33: -124.9359 | Z33: =IF(Xhaut="","",SQRT(((Xbasgauche-Xhaut)^2+(Ybasgauche-Yhaut)^2)+(Zbasgauche-Zhaut)^2)) -> 6.7992289 | AA33: =IF(Xhaut="","",SQRT(((Xintergauche-Xhaut)^2+(Yintergauche-Yhaut)^2)+(Zintergauche-Zhaut)^2)) -> 5.6506045 | AC33: =IF(Xhaut="","",SQRT(((Xhautdroit-Xhaut)^2+(Yhautdroit-Yhaut)^2)+(Zhautdroit-Zhaut)^2)) -> 3.2908789 | AD33: =IF(Xhaut="","",SQRT(((Xinterdroit-Xhaut)^2+(Yinterdroit-Yhaut)^2)+(Zinterdroit-Zhaut)^2)) -> 5.3043835 | AE33: =IF(Xhaut="","",SQRT(((Xbasdroit-Xhaut)^2+(Ybasdroit-Yhaut)^2)+(Zbasdroit-Zhaut)^2)) -> 6.5412167 | AG33: =IF(Xinterdroit="","",SQRT(((Xinterdroit-Xintergauche)^2+(Yinterdroit-Yintergauche)^2)+(Zinterdroit-Zintergauche)^2)) -> 8.3969448 | AH33: =IF(Xbasdroit="","",SQRT(((Xbasdroit-Xbasgauche)^2+(Ybasdroit-Ybasgauche)^2)+(Zbasdroit-Zbasgauche)^2)) -> 7.629354 | AI33: =IF(Z33="","",(Z33-Z$10)*1000) -> -17.722443 | AJ33: =IF(AA33="","",(AA33-AA$10)*1000) -> -15.767087 | AK33: =IF(AB33="","",(AB33-AB$10)*1000) | AL33: =IF(AC33="","",(AC33-AC$10)*1000) -> -6.8098943 | AM33: =IF(AD33="","",(AD33-AD$10)*1000) -> -12.882573 | AN33: =IF(AE33="","",(AE33-AE$10)*1000) -> -16.78854 | AO33: =IF(AF33="","",(AF33-AF$10)*1000) | AP33: =IF(AG33="","",(AG33-AG$10)*1000) -> -15.44662 | AQ33: =IF(AH33="","",(AH33-AH$10)*1000) -> -18.664157 | AS33: =IF(E33="","",(E33-E$10)*1000) -> 1.7 | AT33: =IF(F33="","",(F33-F$10)*1000) -> -12.9 | AU33: =IF(G33="","",(G33-G$10)*1000) -> 0 | AV33: =IF(H33="","",(H33-H$10)*1000) -> 3.2 | AW33: =IF(I33="","",(I33-I$10)*1000) -> -9.8999999 | AX33: =IF(J33="","",(J33-J$10)*1000) -> -0.1 | AY33: =IF(K33="","",(K33-K$10)*1000) | AZ33: =IF(L33="","",(L33-L$10)*1000) | ... BM33: =IF(Y33="","",(Y33-Y$10)*1000) -> 2.3 | BO33: 169.37131 | BP33: -3.7618051 | BQ33: -1.1608331 | BR33: 169.21048 | BS33: -4.2012625 | BT33: 0.82737521 | BX33: 168.95978 | BY33: 0.21965294 | BZ33: 4.3396822 | CA33: 169.19793 | CB33: 3.2076037 | CC33: 2.9783007 | CD33: 169.18941 | CE33: 4.1954724 | CF33: 0.83338592 | CG33: 169.25332 | CH33: 3.8670069 | CI33: -1.0855532 | CK33: =IF(BO33="","",(BO33-BO$10)*1000) -> -3.7424222 | CL33: =IF(BP33="","",(BP33-BP$10)*1000) -> 12.047159 | CM33: =IF(BQ33="","",(BQ33-BQ$10)*1000) -> 0.037424222 | CN33: =IF(BR33="","",(BR33-BR$10)*1000) -> -1.4109291 | CO33: =IF(BS33="","",(BS33-BS$10)*1000) -> 10.596666 | CP33: =IF(BT33="","",(BT33-BT$10)*1000) -> -0.085890709 | CQ33: =IF(BU33="","",(BU33-BU$10)*1000) | CR33: =IF(BV33="","",(BV33-BV$10)*1000) | ... DE33: =IF(CI33="","",(CI33-CI$10)*1000) -> 2.3539637
A34: 43696 | B34: =A34-A$10 -> 97 | C34: 195.4 | D34: =C34-PM -> 26.2 | E34: 823219.58 | F34: 1091508.6 | G34: -125.0092 | H34: 823219.25 | I34: 1091508.9 | J34: -123.0236 | N34: 823220.89 | O34: 1091504.8 | P34: -119.5145 | Q34: 823222.37 | R34: 1091502.2 | S34: -120.8722 | T34: 823222.78 | U34: 1091501.3 | V34: -123.0174 | W34: 823222.7 | X34: 1091501.6 | Y34: -124.9355 | Z34: =IF(Xhaut="","",SQRT(((Xbasgauche-Xhaut)^2+(Ybasgauche-Yhaut)^2)+(Zbasgauche-Zhaut)^2)) -> 6.7971166 | AA34: =IF(Xhaut="","",SQRT(((Xintergauche-Xhaut)^2+(Yintergauche-Yhaut)^2)+(Zintergauche-Zhaut)^2)) -> 5.6486409 | AC34: =IF(Xhaut="","",SQRT(((Xhautdroit-Xhaut)^2+(Yhautdroit-Yhaut)^2)+(Zhautdroit-Zhaut)^2)) -> 3.2905434 | AD34: =IF(Xhaut="","",SQRT(((Xinterdroit-Xhaut)^2+(Yinterdroit-Yhaut)^2)+(Zinterdroit-Zhaut)^2)) -> 5.3040843 | AE34: =IF(Xhaut="","",SQRT(((Xbasdroit-Xhaut)^2+(Ybasdroit-Yhaut)^2)+(Zbasdroit-Zhaut)^2)) -> 6.5405195 | AG34: =IF(Xinterdroit="","",SQRT(((Xinterdroit-Xintergauche)^2+(Yinterdroit-Yintergauche)^2)+(Zinterdroit-Zintergauche)^2)) -> 8.3955732 | AH34: =IF(Xbasdroit="","",SQRT(((Xbasdroit-Xbasgauche)^2+(Ybasdroit-Ybasgauche)^2)+(Zbasdroit-Zbasgauche)^2)) -> 7.6287673 | AI34: =IF(Z34="","",(Z34-Z$10)*1000) -> -19.83467 | AJ34: =IF(AA34="","",(AA34-AA$10)*1000) -> -17.730598 | AK34: =IF(AB34="","",(AB34-AB$10)*1000) | AL34: =IF(AC34="","",(AC34-AC$10)*1000) -> -7.1453705 | AM34: =IF(AD34="","",(AD34-AD$10)*1000) -> -13.181745 | AN34: =IF(AE34="","",(AE34-AE$10)*1000) -> -17.485726 | AO34: =IF(AF34="","",(AF34-AF$10)*1000) | AP34: =IF(AG34="","",(AG34-AG$10)*1000) -> -16.818249 | AQ34: =IF(AH34="","",(AH34-AH$10)*1000) -> -19.250829 | AS34: =IF(E34="","",(E34-E$10)*1000) -> 0.60000003 | AT34: =IF(F34="","",(F34-F$10)*1000) -> -10.4 | AU34: =IF(G34="","",(G34-G$10)*1000) -> 0.8 | AV34: =IF(H34="","",(H34-H$10)*1000) -> 2.1 | AW34: =IF(I34="","",(I34-I$10)*1000) -> -8.2 | AX34: =IF(J34="","",(J34-J$10)*1000) -> -0.3 | AY34: =IF(K34="","",(K34-K$10)*1000) | AZ34: =IF(L34="","",(L34-L$10)*1000) | ... BM34: =IF(Y34="","",(Y34-Y$10)*1000) -> 2.7 | BO34: 169.3712 | BP34: -3.7642 | BQ34: -1.16 | BR34: 169.2103 | BS34: -4.2035 | BT34: 0.8272 | BX34: 168.9609 | BY34: 0.2159 | BZ34: 4.3388 | CA34: 169.2 | CB34: 3.2037 | CC34: 2.9787 | CD34: 169.1917 | CE34: 4.192 | CF34: 0.8336 | CG34: 169.2557 | CH34: 3.8634 | CI34: -1.0852 | CK34: =IF(BO34="","",(BO34-BO$10)*1000) -> -3.8556222 | CL34: =IF(BP34="","",(BP34-BP$10)*1000) -> 9.6522421 | CM34: =IF(BQ34="","",(BQ34-BQ$10)*1000) -> 0.87055622 | CN34: =IF(BR34="","",(BR34-BR$10)*1000) -> -1.5902291 | CO34: =IF(BS34="","",(BS34-BS$10)*1000) -> 8.3591536 | CP34: =IF(BT34="","",(BT34-BT$10)*1000) -> -0.26109771 | CQ34: =IF(BU34="","",(BU34-BU$10)*1000) | CR34: =IF(BV34="","",(BV34-BV$10)*1000) | ... DE34: =IF(CI34="","",(CI34-CI$10)*1000) -> 2.7072027
