Workbook
Name cintre: 'Résultats observations'!#REF!
Name cintre: 'Résultats observations'!#REF!
Name date: 'Résultats observations'!$A:$A
Name DH_BD: 'Résultats observations'!#REF!
Name DH_BD: 'Résultats observations'!#REF!
Name DH_BG: 'Résultats observations'!#REF!
Name DH_BG: 'Résultats observations'!#REF!
Name DH_HD: 'Résultats observations'!$BW:$BW
Name DH_HG: 'Résultats observations'!$BQ:$BQ
Name DH_ID: 'Résultats observations'!$BZ:$BZ
Name DH_IG: 'Résultats observations'!$BN:$BN
Name DHhaut: 'Résultats observations'!$BT:$BT
Name dist: 'Résultats observations'!$D:$D
Name DPM_BD: 'Résultats observations'!#REF!
Name DPM_BD: 'Résultats observations'!#REF!
Name DPM_BG: 'Résultats observations'!#REF!
Name DPM_BG: 'Résultats observations'!#REF!
Name DPM_HD: 'Résultats observations'!$BV:$BV
Name DPM_HG: 'Résultats observations'!$BP:$BP
Name DPM_ID: 'Résultats observations'!$BY:$BY
Name DPM_IG: 'Résultats observations'!$BM:$BM
Name DPMhaut: 'Résultats observations'!$BS:$BS
Name DZ_BD: 'Résultats observations'!#REF!
Name DZ_BD: 'Résultats observations'!#REF!
Name DZ_BG: 'Résultats observations'!#REF!
Name DZ_BG: 'Résultats observations'!#REF!
Name DZ_HD: 'Résultats observations'!$AR:$AR
Name DZ_HG: 'Résultats observations'!$AL:$AL
Name DZ_ID: 'Résultats observations'!$AU:$AU
Name DZ_IG: 'Résultats observations'!$AI:$AI
Name DZhaut: 'Résultats observations'!$AO:$AO
Name Ecart_BD: 'Résultats observations'!#REF!
Name Ecart_BD: 'Résultats observations'!#REF!
Name Ecart_BG: 'Résultats observations'!#REF!
Name Ecart_BG: 'Résultats observations'!#REF!
Name Ecart_HD: 'Résultats observations'!$AB:$AB
Name Ecart_HG: 'Résultats observations'!$AA:$AA
Name Ecart_ID: 'Résultats observations'!$AC:$AC
Name Ecart_IG: 'Résultats observations'!$Z:$Z
Name Ecart_LB: 'Résultats observations'!#REF!
Name Ecart_LB: 'Résultats observations'!#REF!
Name Ecart_LH: 'Résultats observations'!$AD:$AD
Name Ecart_LI: 'Résultats observations'!$AE:$AE
Name excav: 'Résultats observations'!$A$7
Name front: 'Résultats observations'!$C:$C
Name galerie: 'Résultats observations'!#REF!
Name galerie: 'Résultats observations'!#REF!
Name jours: 'Résultats observations'!$B:$B
Name PM: 'Résultats observations'!$P$6
Name Xbasdroit: 'Résultats observations'!#REF!
Name Xbasdroit: 'Résultats observations'!#REF!
Name Xbasgauche: 'Résultats observations'!#REF!
Name Xbasgauche: 'Résultats observations'!#REF!
Name Xhaut: 'Résultats observations'!$K:$K
Name Xhautdroit: 'Résultats observations'!$N:$N
Name Xhautgauche: 'Résultats observations'!$H:$H
Name Xinterdroit: 'Résultats observations'!$Q:$Q
Name Xintergauche: 'Résultats observations'!$E:$E
Name Ybasdroit: 'Résultats observations'!#REF!
Name Ybasdroit: 'Résultats observations'!#REF!

Sheet Résultats observations
A6: Date point 0 | O6: PM = | P6: 170.4
A7: =A10 -> 43655
A8: Date | B8: Jours | C8: Front | D8: Dist | E8: Point intermédiaire gauche | H8: Point haut gauche | K8: Point centre haut | N8: Point haut droit | Q8: Point intermédiaire droit | AG8: Point intermédiaire gauche | AJ8: Point haut gauche | AM8: Point centre haut | AP8: Point haut droit | AS8: Point intermédiaire droit | AW8: Point intermédiaire gauche | AZ8: Point haut gauche | BC8: Point centre haut | BF8: Point haut droit | BI8: Point intermédiaire droit | BM8: Point intermédiaire gauche | BP8: Point haut gauche | BS8: Point centre haut | BV8: Point haut droit | BY8: Point intermédiaire droit
H9: X | I9: Y | J9: Z | K9: X | L9: Y | M9: Z | N9: X | O9: Y | P9: Z | T9: IG | U9: HG | V9: HD | W9: ID | X9: LH | Y9: LI | Z9: IG | AA9: HG | AB9: HD | AC9: ID | AD9: LH | AE9: LI | AG9: DX | AH9: DY | AI9: DZ | AJ9: DX | AK9: DY | AL9: DZ | AM9: DX | AN9: DY | AO9: DZ | AP9: DX | AQ9: DY | AR9: DZ | AS9: DX | AT9: DY | AU9: DZ | AW9: PM | AX9: H | AY9: V | AZ9: PM | BA9: H | BB9: V | BC9: PM | BD9: H | BE9: V | BF9: PM | BG9: H | BH9: V | BI9: PM | BJ9: H | BK9: V | BM9: DPM | BN9: DH | BO9: DZ | BP9: DPM | BQ9: DH | BR9: DZ | BS9: DPM | BT9: DH | BU9: DZ | BV9: DPM | BW9: DH | BX9: DZ | BY9: DPM | BZ9: DH | CA9: DZ
A10: 43655 | B10: 0 | C10: 184.3 | D10: =C10-PM -> 13.9 | E10: 823220.73 | F10: 1091507.9 | G10: -122.34745 | H10: 823221.65 | I10: 1091506.7 | J10: -121.07765 | K10: 823222.3 | L10: 1091505.3 | M10: -120.4067 | N10: 823222.81 | O10: 1091504.7 | P10: -121.09895 | Q10: 823223.22 | R10: 1091503.2 | S10: -122.24595 | T10: =IF(Xhaut="","",SQRT(((Xintergauche-Xhaut)^2+(Yintergauche-Yhaut)^2)+(Zintergauche-Zhaut)^2)) -> 3.5993378 | U10: =IF(Xhaut="","",SQRT(((Xhautgauche-Xhaut)^2+(Yhautgauche-Yhaut)^2)+(Zhautgauche-Zhaut)^2)) -> 1.6599261 | V10: =IF(Xhaut="","",SQRT(((Xhautdroit-Xhaut)^2+(Yhautdroit-Yhaut)^2)+(Zhautdroit-Zhaut)^2)) -> 1.0254438 | W10: =IF(Xhaut="","",SQRT(((Xinterdroit-Xhaut)^2+(Yinterdroit-Yhaut)^2)+(Zinterdroit-Zhaut)^2)) -> 2.9084967 | X10: =IF(Xhautdroit="","",SQRT(((Xhautdroit-Xhautgauche)^2+(Yhautdroit-Yhautgauche)^2)+(Zhautdroit-Zhautgauche)^2)) -> 2.2529149 | Y10: =IF(Xinterdroit="","",SQRT(((Xinterdroit-Xintergauche)^2+(Yinterdroit-Yintergauche)^2)+(Zinterdroit-Zintergauche)^2)) -> 5.274692 | Z10: 0 | AA10: 0 | AB10: 0 | AC10: 0 | AD10: 0 | AE10: 0 | AG10: 0 | AH10: 0 | AI10: 0 | AJ10: 0 | AK10: 0 | AL10: 0 | AM10: 0 | AN10: 0 | AO10: 0 | AP10: 0 | AQ10: 0 | AR10: 0 | AS10: 0 | AT10: 0 | AU10: 0 | AW10: 170.1097 | AX10: -2.6293 | AY10: 1.4943 | AZ10: 170.4293 | BA10: -1.1342 | BB10: 2.7609 | BC10: 170.4392 | BD10: 0.3841 | BE10: 3.4318 | BF10: 170.6642 | BG10: 1.1063 | BH10: 2.7373 | BI10: 170.3948 | BJ10: 2.6367 | BK10: 1.593 | BM10: 0 | BN10: 0 | BO10: 0 | BP10: 0 | BQ10: 0 | BR10: 0 | BS10: 0 | BT10: 0 | BU10: 0 | BV10: 0 | BW10: 0 | BX10: 0 | BY10: 0 | BZ10: 0 | CA10: 0
A11: 43657 | B11: =A11-$A$10 -> 2 | C11: 185.03 | D11: =C11-PM -> 14.63 | E11: 823220.73 | F11: 1091507.9 | G11: -122.3476 | H11: 823221.65 | I11: 1091506.7 | J11: -121.078 | K11: 823222.31 | L11: 1091505.3 | M11: -120.4071 | N11: 823222.81 | O11: 1091504.7 | P11: -121.0992 | Q11: 823223.22 | R11: 1091503.2 | S11: -122.2461 | T11: =IF(Xhaut="","",SQRT(((Xintergauche-Xhaut)^2+(Yintergauche-Yhaut)^2)+(Zintergauche-Zhaut)^2)) -> 3.599419 | U11: =IF(Xhaut="","",SQRT(((Xhautgauche-Xhaut)^2+(Yhautgauche-Yhaut)^2)+(Zhautgauche-Zhaut)^2)) -> 1.6600124 | V11: =IF(Xhaut="","",SQRT(((Xhautdroit-Xhaut)^2+(Yhautdroit-Yhaut)^2)+(Zhautdroit-Zhaut)^2)) -> 1.0251691 | W11: =IF(Xhaut="","",SQRT(((Xinterdroit-Xhaut)^2+(Yinterdroit-Yhaut)^2)+(Zinterdroit-Zhaut)^2)) -> 2.9082632 | X11: =IF(Xhautdroit="","",SQRT(((Xhautdroit-Xhautgauche)^2+(Yhautdroit-Yhautgauche)^2)+(Zhautdroit-Zhautgauche)^2)) -> 2.2526825 | Y11: =IF(Xinterdroit="","",SQRT(((Xinterdroit-Xintergauche)^2+(Yinterdroit-Yintergauche)^2)+(Zinterdroit-Zintergauche)^2)) -> 5.274907 | Z11: =IF(T11="","",(T11-T$10)*1000) -> 0.081236089 | AA11: =IF(U11="","",(U11-U$10)*1000) -> 0.086295387 | AB11: =IF(V11="","",(V11-V$10)*1000) -> -0.27464097 | AC11: =IF(W11="","",(W11-W$10)*1000) -> -0.23352312 | AD11: =IF(X11="","",(X11-X$10)*1000) -> -0.23236683 | AE11: =IF(Y11="","",(Y11-Y$10)*1000) -> 0.21494242 | AG11: =IF(E11="","",(E11-E$10)*1000) -> 0.59999991 | AH11: =IF(F11="","",(F11-F$10)*1000) -> -0.09999983 | AI11: =IF(G11="","",(G11-G$10)*1000) -> -0.15 | AJ11: =IF(H11="","",(H11-H$10)*1000) -> 0.75000001 | AK11: =IF(I11="","",(I11-I$10)*1000) -> -0.19999989 | AL11: =IF(J11="","",(J11-J$10)*1000) -> -0.35 | AM11: =IF(K11="","",(K11-K$10)*1000) -> 0.60000003 | AN11: =IF(L11="","",(L11-L$10)*1000) -> -0.40000002 | ... AU11: =IF(S11="","",(S11-S$10)*1000) -> -0.15 | AW11: 170.1102 | AX11: -2.6288 | AY11: 1.4942 | AZ11: 170.4299 | BA11: -1.1337 | BB11: 2.7606 | BC11: 170.4396 | BD11: 0.3847 | BE11: 3.4314 | BF11: 170.6649 | BG11: 1.1069 | BH11: 2.737 | BI11: 170.3958 | BJ11: 2.6373 | BK11: 1.5928 | BM11: =IF(AW11="","",(AW11-AW$10)*1000) -> 0.5 | BN11: =IF(AX11="","",(AX11-AX$10)*1000) -> 0.5 | BO11: =IF(AY11="","",(AY11-AY$10)*1000) -> -0.1 | BP11: =IF(AZ11="","",(AZ11-AZ$10)*1000) -> 0.6 | BQ11: =IF(BA11="","",(BA11-BA$10)*1000) -> 0.5 | BR11: =IF(BB11="","",(BB11-BB$10)*1000) -> -0.3 | BS11: =IF(BC11="","",(BC11-BC$10)*1000) -> 0.4 | BT11: =IF(BD11="","",(BD11-BD$10)*1000) -> 0.6 | ... CA11: =IF(BK11="","",(BK11-BK$10)*1000) -> -0.2
A12: 43661 | B12: =A12-$A$10 -> 6 | C12: 187.2 | D12: =C12-PM -> 16.8 | E12: 823220.73 | F12: 1091507.9 | G12: -122.3482 | H12: 823221.66 | I12: 1091506.7 | J12: -121.0783 | K12: 823222.31 | L12: 1091505.3 | M12: -120.4076 | N12: 823222.81 | O12: 1091504.7 | P12: -121.0997 | Q12: 823223.22 | R12: 1091503.2 | S12: -122.2469 | T12: =IF(Xhaut="","",SQRT(((Xintergauche-Xhaut)^2+(Yintergauche-Yhaut)^2)+(Zintergauche-Zhaut)^2)) -> 3.5991258 | U12: =IF(Xhaut="","",SQRT(((Xhautgauche-Xhaut)^2+(Yhautgauche-Yhaut)^2)+(Zhautgauche-Zhaut)^2)) -> 1.6598054 | V12: =IF(Xhaut="","",SQRT(((Xhautdroit-Xhaut)^2+(Yhautdroit-Yhaut)^2)+(Zhautdroit-Zhaut)^2)) -> 1.0255112 | W12: =IF(Xhaut="","",SQRT(((Xinterdroit-Xhaut)^2+(Yinterdroit-Yhaut)^2)+(Zinterdroit-Zhaut)^2)) -> 2.9079827 | X12: =IF(Xhautdroit="","",SQRT(((Xhautdroit-Xhautgauche)^2+(Yhautdroit-Yhautgauche)^2)+(Zhautdroit-Zhautgauche)^2)) -> 2.2531815 | Y12: =IF(Xinterdroit="","",SQRT(((Xinterdroit-Xintergauche)^2+(Yinterdroit-Yintergauche)^2)+(Zinterdroit-Zintergauche)^2)) -> 5.2737909 | Z12: =IF(T12="","",(T12-T$10)*1000) -> -0.21191044 | AA12: =IF(U12="","",(U12-U$10)*1000) -> -0.12063458 | AB12: =IF(V12="","",(V12-V$10)*1000) -> 0.06742101 | AC12: =IF(W12="","",(W12-W$10)*1000) -> -0.51402381 | AD12: =IF(X12="","",(X12-X$10)*1000) -> 0.26664726 | AE12: =IF(Y12="","",(Y12-Y$10)*1000) -> -0.9011185 | AG12: =IF(E12="","",(E12-E$10)*1000) -> 1.2999999 | AH12: =IF(F12="","",(F12-F$10)*1000) -> 2.3283064e-07 | AI12: =IF(G12="","",(G12-G$10)*1000) -> -0.75 | AJ12: =IF(H12="","",(H12-H$10)*1000) -> 1.0500001 | AK12: =IF(I12="","",(I12-I$10)*1000) -> 0 | AL12: =IF(J12="","",(J12-J$10)*1000) -> -0.65 | AM12: =IF(K12="","",(K12-K$10)*1000) -> 1 | AN12: =IF(L12="","",(L12-L$10)*1000) -> -2.3283064e-07 | ... AU12: =IF(S12="","",(S12-S$10)*1000) -> -0.95 | AW12: 170.1109 | AX12: -2.6287 | AY12: 1.4936 | AZ12: 170.4303 | BA12: -1.1338 | BB12: 2.7603 | BC12: 170.4401 | BD12: 0.3845 | BE12: 3.4309 | BF12: 170.6649 | BG12: 1.1071 | BH12: 2.7365 | BI12: 170.395 | BJ12: 2.6364 | BK12: 1.592 | BM12: =IF(AW12="","",(AW12-AW$10)*1000) -> 1.2 | BN12: =IF(AX12="","",(AX12-AX$10)*1000) -> 0.6 | BO12: =IF(AY12="","",(AY12-AY$10)*1000) -> -0.7 | BP12: =IF(AZ12="","",(AZ12-AZ$10)*1000) -> 1 | BQ12: =IF(BA12="","",(BA12-BA$10)*1000) -> 0.4 | BR12: =IF(BB12="","",(BB12-BB$10)*1000) -> -0.6 | BS12: =IF(BC12="","",(BC12-BC$10)*1000) -> 0.9 | BT12: =IF(BD12="","",(BD12-BD$10)*1000) -> 0.4 | ... CA12: =IF(BK12="","",(BK12-BK$10)*1000) -> -1
A13: 43663 | B13: =A13-$A$10 -> 8 | C13: 188.17 | D13: =C13-PM -> 17.77 | E13: 823220.73 | F13: 1091507.9 | G13: -122.3483 | H13: 823221.65 | I13: 1091506.7 | J13: -121.0792 | K13: 823222.31 | L13: 1091505.3 | M13: -120.4082 | N13: 823222.81 | O13: 1091504.7 | P13: -121.0998 | Q13: 823223.22 | R13: 1091503.2 | S13: -122.2462 | T13: =IF(Xhaut="","",SQRT(((Xintergauche-Xhaut)^2+(Yintergauche-Yhaut)^2)+(Zintergauche-Zhaut)^2)) -> 3.5983676 | U13: =IF(Xhaut="","",SQRT(((Xhautgauche-Xhaut)^2+(Yhautgauche-Yhaut)^2)+(Zhautgauche-Zhaut)^2)) -> 1.659627 | V13: =IF(Xhaut="","",SQRT(((Xhautdroit-Xhaut)^2+(Yhautdroit-Yhaut)^2)+(Zhautdroit-Zhaut)^2)) -> 1.0252682 | W13: =IF(Xhaut="","",SQRT(((Xinterdroit-Xhaut)^2+(Yinterdroit-Yhaut)^2)+(Zinterdroit-Zhaut)^2)) -> 2.90811 | X13: =IF(Xhautdroit="","",SQRT(((Xhautdroit-Xhautgauche)^2+(Yhautdroit-Yhautgauche)^2)+(Zhautdroit-Zhautgauche)^2)) -> 2.2529859 | Y13: =IF(Xinterdroit="","",SQRT(((Xinterdroit-Xintergauche)^2+(Yinterdroit-Yintergauche)^2)+(Zinterdroit-Zintergauche)^2)) -> 5.2746021 | Z13: =IF(T13="","",(T13-T$10)*1000) -> -0.97017878 | AA13: =IF(U13="","",(U13-U$10)*1000) -> -0.29911096 | AB13: =IF(V13="","",(V13-V$10)*1000) -> -0.1755452 | AC13: =IF(W13="","",(W13-W$10)*1000) -> -0.3867218 | AD13: =IF(X13="","",(X13-X$10)*1000) -> 0.071064045 | AE13: =IF(Y13="","",(Y13-Y$10)*1000) -> -0.089940131 | AG13: =IF(E13="","",(E13-E$10)*1000) -> 1.0999999 | AH13: =IF(F13="","",(F13-F$10)*1000) -> -1.4 | AI13: =IF(G13="","",(G13-G$10)*1000) -> -0.85 | AJ13: =IF(H13="","",(H13-H$10)*1000) -> 0.55 | AK13: =IF(I13="","",(I13-I$10)*1000) -> -1.2000001 | AL13: =IF(J13="","",(J13-J$10)*1000) -> -1.55 | AM13: =IF(K13="","",(K13-K$10)*1000) -> 1 | AN13: =IF(L13="","",(L13-L$10)*1000) -> -0.60000014 | ... AU13: =IF(S13="","",(S13-S$10)*1000) -> -0.25 | AW13: 170.1102 | AX13: -2.6275 | AY13: 1.4935 | AZ13: 170.4293 | BA13: -1.1329 | BB13: 2.7594 | BC13: 170.4399 | BD13: 0.385 | BE13: 3.4303 | BF13: 170.6649 | BG13: 1.1077 | BH13: 2.7364 | BI13: 170.3973 | BJ13: 2.6382 | BK13: 1.5927 | BM13: =IF(AW13="","",(AW13-AW$10)*1000) -> 0.5 | BN13: =IF(AX13="","",(AX13-AX$10)*1000) -> 1.8 | BO13: =IF(AY13="","",(AY13-AY$10)*1000) -> -0.8 | BP13: =IF(AZ13="","",(AZ13-AZ$10)*1000) -> 0 | BQ13: =IF(BA13="","",(BA13-BA$10)*1000) -> 1.3 | BR13: =IF(BB13="","",(BB13-BB$10)*1000) -> -1.5 | BS13: =IF(BC13="","",(BC13-BC$10)*1000) -> 0.7 | BT13: =IF(BD13="","",(BD13-BD$10)*1000) -> 0.9 | ... CA13: =IF(BK13="","",(BK13-BK$10)*1000) -> -0.3
A14: 43669 | B14: =A14-$A$10 -> 14 | C14: 189.2 | D14: =C14-PM -> 18.8 | E14: 823220.73 | F14: 1091507.9 | G14: -122.3486 | H14: non-visible (engin) | K14: 823222.3 | L14: 1091505.3 | M14: -120.4088 | N14: 823222.81 | O14: 1091504.7 | P14: -121.1001 | Q14: 823223.22 | R14: 1091503.2 | S14: -122.2468 | T14: =IF(Xhaut="","",SQRT(((Xintergauche-Xhaut)^2+(Yintergauche-Yhaut)^2)+(Zintergauche-Zhaut)^2)) -> 3.5980748 | U14: =IF(Xhaut="","",SQRT(((Xhautgauche-Xhaut)^2+(Yhautgauche-Yhaut)^2)+(Zhautgauche-Zhaut)^2)) -> #VALUE! | V14: =IF(Xhaut="","",SQRT(((Xhautdroit-Xhaut)^2+(Yhautdroit-Yhaut)^2)+(Zhautdroit-Zhaut)^2)) -> 1.0253048 | W14: =IF(Xhaut="","",SQRT(((Xinterdroit-Xhaut)^2+(Yinterdroit-Yhaut)^2)+(Zinterdroit-Zhaut)^2)) -> 2.9068517 | X14: =IF(Xhautdroit="","",SQRT(((Xhautdroit-Xhautgauche)^2+(Yhautdroit-Yhautgauche)^2)+(Zhautdroit-Zhautgauche)^2)) -> #VALUE! | Y14: =IF(Xinterdroit="","",SQRT(((Xinterdroit-Xintergauche)^2+(Yinterdroit-Yintergauche)^2)+(Zinterdroit-Zintergauche)^2)) -> 5.2727842 | Z14: =IF(T14="","",(T14-T$10)*1000) -> -1.2629818 | AA14: =IF(U14="","",(U14-U$10)*1000) -> #VALUE! | AB14: =IF(V14="","",(V14-V$10)*1000) -> -0.13901878 | AC14: =IF(W14="","",(W14-W$10)*1000) -> -1.6449811 | AD14: =IF(X14="","",(X14-X$10)*1000) -> #VALUE! | AE14: =IF(Y14="","",(Y14-Y$10)*1000) -> -1.9078435 | AG14: =IF(E14="","",(E14-E$10)*1000) -> -0.30000007 | AH14: =IF(F14="","",(F14-F$10)*1000) -> -0.69999998 | AI14: =IF(G14="","",(G14-G$10)*1000) -> -1.15 | AJ14: =IF(H14="","",(H14-H$10)*1000) -> #VALUE! | AK14: =IF(I14="","",(I14-I$10)*1000) | AL14: =IF(J14="","",(J14-J$10)*1000) | AM14: =IF(K14="","",(K14-K$10)*1000) -> -0.69999986 | AN14: =IF(L14="","",(L14-L$10)*1000) -> 0.09999983 | ... AU14: =IF(S14="","",(S14-S$10)*1000) -> -0.85 | AW14: 170.1092 | AX14: -2.6288 | AY14: 1.4932 | AZ14: non-visible (engin) | BC14: 170.4386 | BD14: 0.3837 | BE14: 3.4297 | BF14: 170.6644 | BG14: 1.1064 | BH14: 2.7361 | BI14: 170.3953 | BJ14: 2.6353 | BK14: 1.5921 | BM14: =IF(AW14="","",(AW14-AW$10)*1000) -> -0.5 | BN14: =IF(AX14="","",(AX14-AX$10)*1000) -> 0.5 | BO14: =IF(AY14="","",(AY14-AY$10)*1000) -> -1.1 | BP14: =IF(AZ14="","",(AZ14-AZ$10)*1000) -> #VALUE! | BQ14: =IF(BA14="","",(BA14-BA$10)*1000) | BR14: =IF(BB14="","",(BB14-BB$10)*1000) | BS14: =IF(BC14="","",(BC14-BC$10)*1000) -> -0.6 | BT14: =IF(BD14="","",(BD14-BD$10)*1000) -> -0.4 | ... CA14: =IF(BK14="","",(BK14-BK$10)*1000) -> -0.9
A15: 43675 | B15: =A15-$A$10 -> 20 | C15: 191.5 | D15: =C15-PM -> 21.1 | E15: 823220.73 | F15: 1091507.9 | G15: -122.3487 | H15: 823221.65 | I15: 1091506.7 | J15: -121.0802 | K15: 823222.3 | L15: 1091505.3 | M15: -120.4097 | N15: 823222.81 | O15: 1091504.7 | P15: -121.1013 | Q15: 823223.22 | R15: 1091503.2 | S15: -122.2469 | T15: =IF(Xhaut="","",SQRT(((Xintergauche-Xhaut)^2+(Yintergauche-Yhaut)^2)+(Zintergauche-Zhaut)^2)) -> 3.597783 | U15: =IF(Xhaut="","",SQRT(((Xhautgauche-Xhaut)^2+(Yhautgauche-Yhaut)^2)+(Zhautgauche-Zhaut)^2)) -> 1.6593464 | V15: =IF(Xhaut="","",SQRT(((Xhautdroit-Xhaut)^2+(Yhautdroit-Yhaut)^2)+(Zhautdroit-Zhaut)^2)) -> 1.0251291 | W15: =IF(Xhaut="","",SQRT(((Xinterdroit-Xhaut)^2+(Yinterdroit-Yhaut)^2)+(Zinterdroit-Zhaut)^2)) -> 2.9063854 | X15: =IF(Xhautdroit="","",SQRT(((Xhautdroit-Xhautgauche)^2+(Yhautdroit-Yhautgauche)^2)+(Zhautdroit-Zhautgauche)^2)) -> 2.2528015 | Y15: =IF(Xinterdroit="","",SQRT(((Xinterdroit-Xintergauche)^2+(Yinterdroit-Yintergauche)^2)+(Zinterdroit-Zintergauche)^2)) -> 5.2730598 | Z15: =IF(T15="","",(T15-T$10)*1000) -> -1.5547552 | AA15: =IF(U15="","",(U15-U$10)*1000) -> -0.57966459 | AB15: =IF(V15="","",(V15-V$10)*1000) -> -0.31463523 | AC15: =IF(W15="","",(W15-W$10)*1000) -> -2.1113031 | AD15: =IF(X15="","",(X15-X$10)*1000) -> -0.11334755 | AE15: =IF(Y15="","",(Y15-Y$10)*1000) -> -1.632245 | AG15: =IF(E15="","",(E15-E$10)*1000) -> 1.1999999 | AH15: =IF(F15="","",(F15-F$10)*1000) -> -2.4999999 | AI15: =IF(G15="","",(G15-G$10)*1000) -> -1.25 | AJ15: =IF(H15="","",(H15-H$10)*1000) -> -0.44999993 | AK15: =IF(I15="","",(I15-I$10)*1000) -> -3.1000001 | AL15: =IF(J15="","",(J15-J$10)*1000) -> -2.55 | AM15: =IF(K15="","",(K15-K$10)*1000) -> -0.19999989 | AN15: =IF(L15="","",(L15-L$10)*1000) -> -2.5000002 | ... AU15: =IF(S15="","",(S15-S$10)*1000) -> -0.95 | AW15: 170.1098 | AX15: -2.6265 | AY15: 1.4931 | AZ15: 170.4276 | BA15: -1.1316 | BB15: 2.7584 | BC15: 170.438 | BD15: 0.3862 | BE15: 3.4288 | BF15: 170.6625 | BG15: 1.1088 | BH15: 2.735 | BI15: 170.3946 | BJ15: 2.6379 | BK15: 1.592 | BM15: =IF(AW15="","",(AW15-AW$10)*1000) -> 0.1 | BN15: =IF(AX15="","",(AX15-AX$10)*1000) -> 2.8 | BO15: =IF(AY15="","",(AY15-AY$10)*1000) -> -1.2 | BP15: =IF(AZ15="","",(AZ15-AZ$10)*1000) -> -1.7 | BQ15: =IF(BA15="","",(BA15-BA$10)*1000) -> 2.6 | BR15: =IF(BB15="","",(BB15-BB$10)*1000) -> -2.5 | BS15: =IF(BC15="","",(BC15-BC$10)*1000) -> -1.2 | BT15: =IF(BD15="","",(BD15-BD$10)*1000) -> 2.1 | ... CA15: =IF(BK15="","",(BK15-BK$10)*1000) -> -1
A16: 43679 | B16: =A16-$A$10 -> 24 | C16: 192.5 | D16: =C16-PM -> 22.1 | E16: 823220.73 | F16: 1091507.9 | G16: -122.3485 | H16: 823221.65 | I16: 1091506.7 | J16: -121.0798 | K16: 823222.3 | L16: 1091505.3 | M16: -120.4093 | N16: 823222.81 | O16: 1091504.7 | P16: -121.101 | Q16: 823223.22 | R16: 1091503.2 | S16: -122.2463 | T16: =IF(Xhaut="","",SQRT(((Xintergauche-Xhaut)^2+(Yintergauche-Yhaut)^2)+(Zintergauche-Zhaut)^2)) -> 3.5983252 | U16: =IF(Xhaut="","",SQRT(((Xhautgauche-Xhaut)^2+(Yhautgauche-Yhaut)^2)+(Zhautgauche-Zhaut)^2)) -> 1.6599291 | V16: =IF(Xhaut="","",SQRT(((Xhautdroit-Xhaut)^2+(Yhautdroit-Yhaut)^2)+(Zhautdroit-Zhaut)^2)) -> 1.0251966 | W16: =IF(Xhaut="","",SQRT(((Xinterdroit-Xhaut)^2+(Yinterdroit-Yhaut)^2)+(Zinterdroit-Zhaut)^2)) -> 2.9055192 | X16: =IF(Xhautdroit="","",SQRT(((Xhautdroit-Xhautgauche)^2+(Yhautdroit-Yhautgauche)^2)+(Zhautdroit-Zhautgauche)^2)) -> 2.2533854 | Y16: =IF(Xinterdroit="","",SQRT(((Xinterdroit-Xintergauche)^2+(Yinterdroit-Yintergauche)^2)+(Zinterdroit-Zintergauche)^2)) -> 5.2726385 | Z16: =IF(T16="","",(T16-T$10)*1000) -> -1.0125454 | AA16: =IF(U16="","",(U16-U$10)*1000) -> 0.0030650547 | AB16: =IF(V16="","",(V16-V$10)*1000) -> -0.24716796 | AC16: =IF(W16="","",(W16-W$10)*1000) -> -2.9775062 | AD16: =IF(X16="","",(X16-X$10)*1000) -> 0.47049644 | AE16: =IF(Y16="","",(Y16-Y$10)*1000) -> -2.053483 | AG16: =IF(E16="","",(E16-E$10)*1000) -> 0.19999989 | AH16: =IF(F16="","",(F16-F$10)*1000) -> -1.1 | AI16: =IF(G16="","",(G16-G$10)*1000) -> -1.05 | AJ16: =IF(H16="","",(H16-H$10)*1000) -> -0.75000001 | AK16: =IF(I16="","",(I16-I$10)*1000) -> -1.2000001 | AL16: =IF(J16="","",(J16-J$10)*1000) -> -2.15 | AM16: =IF(K16="","",(K16-K$10)*1000) -> -0.69999986 | AN16: =IF(L16="","",(L16-L$10)*1000) -> -1.4000002 | ... AU16: =IF(S16="","",(S16-S$10)*1000) -> -0.35 | AW16: 170.10938 | AX16: -2.6280157 | AY16: 1.4932862 | AZ16: 170.42799 | BA16: -1.1330647 | BB16: 2.7588001 | BC16: 170.43813 | BD16: 0.38475323 | BE16: 3.4291987 | BF16: 170.66262 | BG16: 1.107455 | BH16: 2.7352538 | BI16: 170.3947 | BJ16: 2.6361705 | BK16: 1.5926331 | BM16: =IF(AW16="","",(AW16-AW$10)*1000) -> -0.3227 | BN16: =IF(AX16="","",(AX16-AX$10)*1000) -> 1.28428 | BO16: =IF(AY16="","",(AY16-AY$10)*1000) -> -1.013773 | BP16: =IF(AZ16="","",(AZ16-AZ$10)*1000) -> -1.3102 | BQ16: =IF(BA16="","",(BA16-BA$10)*1000) -> 1.135279 | BR16: =IF(BB16="","",(BB16-BB$10)*1000) -> -2.099898 | BS16: =IF(BC16="","",(BC16-BC$10)*1000) -> -1.0687 | BT16: =IF(BD16="","",(BD16-BD$10)*1000) -> 0.653229 | ... CA16: =IF(BK16="","",(BK16-BK$10)*1000) -> -0.36695
A17: 43682 | B17: =A17-$A$10 -> 27 | C17: 193.04 | D17: =C17-PM -> 22.64 | E17: 823220.73 | F17: 1091507.9 | G17: -122.3489 | H17: 823221.65 | I17: 1091506.7 | J17: -121.0806 | K17: 823222.3 | L17: 1091505.3 | M17: -120.4101 | N17: 823222.81 | O17: 1091504.7 | P17: -121.1015 | T17: =IF(Xhaut="","",SQRT(((Xintergauche-Xhaut)^2+(Yintergauche-Yhaut)^2)+(Zintergauche-Zhaut)^2)) -> 3.5977932 | U17: =IF(Xhaut="","",SQRT(((Xhautgauche-Xhaut)^2+(Yhautgauche-Yhaut)^2)+(Zhautgauche-Zhaut)^2)) -> 1.65946 | V17: =IF(Xhaut="","",SQRT(((Xhautdroit-Xhaut)^2+(Yhautdroit-Yhaut)^2)+(Zhautdroit-Zhaut)^2)) -> 1.0249942 | X17: =IF(Xhautdroit="","",SQRT(((Xhautdroit-Xhautgauche)^2+(Yhautdroit-Yhautgauche)^2)+(Zhautdroit-Zhautgauche)^2)) -> 2.2529714 | Y17: =IF(Xinterdroit="","",SQRT(((Xinterdroit-Xintergauche)^2+(Yinterdroit-Yintergauche)^2)+(Zinterdroit-Zintergauche)^2)) | Z17: =IF(T17="","",(T17-T$10)*1000) -> -1.5445935 | AA17: =IF(U17="","",(U17-U$10)*1000) -> -0.4660937 | AB17: =IF(V17="","",(V17-V$10)*1000) -> -0.44955394 | AD17: =IF(X17="","",(X17-X$10)*1000) -> 0.056527783 | AE17: =IF(Y17="","",(Y17-Y$10)*1000) | AG17: =IF(E17="","",(E17-E$10)*1000) -> -0.20000013 | AH17: =IF(F17="","",(F17-F$10)*1000) -> -2.2 | AI17: =IF(G17="","",(G17-G$10)*1000) -> -1.45 | AJ17: =IF(H17="","",(H17-H$10)*1000) -> -1.7499999 | AK17: =IF(I17="","",(I17-I$10)*1000) -> -2.7000001 | AL17: =IF(J17="","",(J17-J$10)*1000) -> -2.95 | AM17: =IF(K17="","",(K17-K$10)*1000) -> -0.99999993 | AN17: =IF(L17="","",(L17-L$10)*1000) -> -2.0000001 | ... AU17: =IF(S17="","",(S17-S$10)*1000) | AW17: 170.10863 | AX17: -2.6273691 | AY17: 1.4928937 | AZ17: 170.42662 | BA17: -1.1324905 | BB17: 2.7580138 | BC17: 170.43748 | BD17: 0.3854421 | BE17: 3.4284052 | BF17: 170.66201 | BG17: 1.1080533 | BH17: 2.7347599 | BM17: =IF(AW17="","",(AW17-AW$10)*1000) -> -1.0656119 | BN17: =IF(AX17="","",(AX17-AX$10)*1000) -> 1.9308822 | BO17: =IF(AY17="","",(AY17-AY$10)*1000) -> -1.4063439 | BP17: =IF(AZ17="","",(AZ17-AZ$10)*1000) -> -2.6814397 | BQ17: =IF(BA17="","",(BA17-BA$10)*1000) -> 1.7095482 | BR17: =IF(BB17="","",(BB17-BB$10)*1000) -> -2.8861856 | BS17: =IF(BC17="","",(BC17-BC$10)*1000) -> -1.7209699 | BT17: =IF(BD17="","",(BD17-BD$10)*1000) -> 1.3420961 | ... CA17: =IF(BK17="","",(BK17-BK$10)*1000)
A18: 43684 | B18: =A18-$A$10 -> 29 | C18: 193.6 | D18: =C18-PM -> 23.2 | E18: 823220.73 | F18: 1091507.9 | G18: -122.3493 | H18: 823221.65 | I18: 1091506.7 | J18: -121.0811 | K18: 823222.3 | L18: 1091505.3 | M18: -120.4105 | N18: 823222.81 | O18: 1091504.7 | P18: -121.1021 | Q18: 823223.22 | R18: 1091503.2 | S18: -122.2471 | T18: =IF(Xhaut="","",SQRT(((Xintergauche-Xhaut)^2+(Yintergauche-Yhaut)^2)+(Zintergauche-Zhaut)^2)) -> 3.598066 | U18: =IF(Xhaut="","",SQRT(((Xhautgauche-Xhaut)^2+(Yhautgauche-Yhaut)^2)+(Zhautgauche-Zhaut)^2)) -> 1.6593 | V18: =IF(Xhaut="","",SQRT(((Xhautdroit-Xhaut)^2+(Yhautdroit-Yhaut)^2)+(Zhautdroit-Zhaut)^2)) -> 1.0251291 | W18: =IF(Xhaut="","",SQRT(((Xinterdroit-Xhaut)^2+(Yinterdroit-Yhaut)^2)+(Zinterdroit-Zhaut)^2)) -> 2.906069 | X18: =IF(Xhautdroit="","",SQRT(((Xhautdroit-Xhautgauche)^2+(Yhautdroit-Yhautgauche)^2)+(Zhautdroit-Zhautgauche)^2)) -> 2.2527321 | Y18: =IF(Xinterdroit="","",SQRT(((Xinterdroit-Xintergauche)^2+(Yinterdroit-Yintergauche)^2)+(Zinterdroit-Zintergauche)^2)) -> 5.2736147 | Z18: =IF(T18="","",(T18-T$10)*1000) -> -1.2717657 | AA18: =IF(U18="","",(U18-U$10)*1000) -> -0.62604786 | AB18: =IF(V18="","",(V18-V$10)*1000) -> -0.31463523 | AC18: =IF(W18="","",(W18-W$10)*1000) -> -2.4277477 | AD18: =IF(X18="","",(X18-X$10)*1000) -> -0.18274878 | AE18: =IF(Y18="","",(Y18-Y$10)*1000) -> -1.0773601 | AG18: =IF(E18="","",(E18-E$10)*1000) -> 0.69999986 | AH18: =IF(F18="","",(F18-F$10)*1000) -> -1.1 | AI18: =IF(G18="","",(G18-G$10)*1000) -> -1.85 | AJ18: =IF(H18="","",(H18-H$10)*1000) -> -0.75000001 | AK18: =IF(I18="","",(I18-I$10)*1000) -> -2.2 | AL18: =IF(J18="","",(J18-J$10)*1000) -> -3.45 | AM18: =IF(K18="","",(K18-K$10)*1000) -> -0.29999996 | AN18: =IF(L18="","",(L18-L$10)*1000) -> -1.4000002 | ... AU18: =IF(S18="","",(S18-S$10)*1000) -> -1.15 | AW18: 170.1097 | AX18: -2.6275325 | AY18: 1.492483 | AZ18: 170.42761 | BA18: -1.1322491 | BB18: 2.7575039 | BC18: 170.43832 | BD18: 0.38528481 | BE18: 3.4279968 | BF18: 170.66277 | BG18: 1.1080772 | BH18: 2.7341523 | BI18: 170.39524 | BJ18: 2.6366476 | BK18: 1.5918276 | BM18: =IF(AW18="","",(AW18-AW$10)*1000) -> 0.0036 | BN18: =IF(AX18="","",(AX18-AX$10)*1000) -> 1.767494 | BO18: =IF(AY18="","",(AY18-AY$10)*1000) -> -1.817036 | BP18: =IF(AZ18="","",(AZ18-AZ$10)*1000) -> -1.6906 | BQ18: =IF(BA18="","",(BA18-BA$10)*1000) -> 1.950942 | BR18: =IF(BB18="","",(BB18-BB$10)*1000) -> -3.396094 | BS18: =IF(BC18="","",(BC18-BC$10)*1000) -> -0.8752 | BT18: =IF(BD18="","",(BD18-BD$10)*1000) -> 1.184806 | ... CA18: =IF(BK18="","",(BK18-BK$10)*1000) -> -1.172448
A19: 43685 | B19: =A19-$A$10 -> 30 | C19: 193.6 | D19: =C19-PM -> 23.2 | E19: 823220.73 | F19: 1091507.9 | G19: -122.3489 | H19: 823221.65 | I19: 1091506.7 | J19: -121.0807 | K19: 823222.3 | L19: 1091505.3 | M19: -120.4101 | N19: 823222.81 | O19: 1091504.7 | P19: -121.1014 | Q19: 823223.22 | R19: 1091503.2 | S19: -122.2465 | T19: =IF(Xhaut="","",SQRT(((Xintergauche-Xhaut)^2+(Yintergauche-Yhaut)^2)+(Zintergauche-Zhaut)^2)) -> 3.5980223 | U19: =IF(Xhaut="","",SQRT(((Xhautgauche-Xhaut)^2+(Yhautgauche-Yhaut)^2)+(Zhautgauche-Zhaut)^2)) -> 1.6593785 | V19: =IF(Xhaut="","",SQRT(((Xhautdroit-Xhaut)^2+(Yhautdroit-Yhaut)^2)+(Zhautdroit-Zhaut)^2)) -> 1.0249268 | W19: =IF(Xhaut="","",SQRT(((Xinterdroit-Xhaut)^2+(Yinterdroit-Yhaut)^2)+(Zinterdroit-Zhaut)^2)) -> 2.9058798 | X19: =IF(Xhautdroit="","",SQRT(((Xhautdroit-Xhautgauche)^2+(Yhautdroit-Yhautgauche)^2)+(Zhautdroit-Zhautgauche)^2)) -> 2.2528323 | Y19: =IF(Xinterdroit="","",SQRT(((Xinterdroit-Xintergauche)^2+(Yinterdroit-Yintergauche)^2)+(Zinterdroit-Zintergauche)^2)) -> 5.2734773 | Z19: =IF(T19="","",(T19-T$10)*1000) -> -1.3154325 | AA19: =IF(U19="","",(U19-U$10)*1000) -> -0.54755879 | AB19: =IF(V19="","",(V19-V$10)*1000) -> -0.51700532 | AC19: =IF(W19="","",(W19-W$10)*1000) -> -2.6169371 | AD19: =IF(X19="","",(X19-X$10)*1000) -> -0.082532695 | AE19: =IF(Y19="","",(Y19-Y$10)*1000) -> -1.2147637 | AG19: =IF(E19="","",(E19-E$10)*1000) -> 1.1999999 | AH19: =IF(F19="","",(F19-F$10)*1000) -> -2.0999999 | AI19: =IF(G19="","",(G19-G$10)*1000) -> -1.45 | AJ19: =IF(H19="","",(H19-H$10)*1000) -> -0.55 | AK19: =IF(I19="","",(I19-I$10)*1000) -> -3.1999999 | AL19: =IF(J19="","",(J19-J$10)*1000) -> -3.05 | AM19: =IF(K19="","",(K19-K$10)*1000) -> 0.10000006 | AN19: =IF(L19="","",(L19-L$10)*1000) -> -2.4000001 | ... AU19: =IF(S19="","",(S19-S$10)*1000) -> -0.55 | AW19: 170.10978 | AX19: -2.6265055 | AY19: 1.4928822 | AZ19: 170.42741 | BA19: -1.1313489 | BB19: 2.7579059 | BC19: 170.43835 | BD19: 0.3861789 | BE19: 3.4283965 | BF19: 170.66275 | BG19: 1.1090619 | BH19: 2.7348525 | BI19: 170.39505 | BJ19: 2.6375478 | BK19: 1.5924295 | BM19: =IF(AW19="","",(AW19-AW$10)*1000) -> 0.0764 | BN19: =IF(AX19="","",(AX19-AX$10)*1000) -> 2.794483 | BO19: =IF(AY19="","",(AY19-AY$10)*1000) -> -1.417764 | BP19: =IF(AZ19="","",(AZ19-AZ$10)*1000) -> -1.8897 | BQ19: =IF(BA19="","",(BA19-BA$10)*1000) -> 2.851135 | BR19: =IF(BB19="","",(BB19-BB$10)*1000) -> -2.994103 | BS19: =IF(BC19="","",(BC19-BC$10)*1000) -> -0.8508 | BT19: =IF(BD19="","",(BD19-BD$10)*1000) -> 2.078901 | ... CA19: =IF(BK19="","",(BK19-BK$10)*1000) -> -0.570457
A20: 43689 | B20: =A20-$A$10 -> 34 | C20: 194.8 | D20: =C20-PM -> 24.4 | E20: 823220.73 | F20: 1091507.9 | G20: -122.3496 | H20: 823221.65 | I20: 1091506.7 | J20: -121.0818 | K20: 823222.3 | L20: 1091505.3 | M20: -120.4111 | N20: 823222.81 | O20: 1091504.7 | P20: -121.1025 | Q20: 823223.22 | R20: 1091503.2 | S20: -122.247 | T20: =IF(Xhaut="","",SQRT(((Xintergauche-Xhaut)^2+(Yintergauche-Yhaut)^2)+(Zintergauche-Zhaut)^2)) -> 3.5979043 | U20: =IF(Xhaut="","",SQRT(((Xhautgauche-Xhaut)^2+(Yhautgauche-Yhaut)^2)+(Zhautgauche-Zhaut)^2)) -> 1.6594582 | V20: =IF(Xhaut="","",SQRT(((Xhautdroit-Xhaut)^2+(Yhautdroit-Yhaut)^2)+(Zhautdroit-Zhaut)^2)) -> 1.0249446 | W20: =IF(Xhaut="","",SQRT(((Xinterdroit-Xhaut)^2+(Yinterdroit-Yhaut)^2)+(Zinterdroit-Zhaut)^2)) -> 2.9048553 | X20: =IF(Xhautdroit="","",SQRT(((Xhautdroit-Xhautgauche)^2+(Yhautdroit-Yhautgauche)^2)+(Zhautdroit-Zhautgauche)^2)) -> 2.2528323 | Y20: =IF(Xinterdroit="","",SQRT(((Xinterdroit-Xintergauche)^2+(Yinterdroit-Yintergauche)^2)+(Zinterdroit-Zintergauche)^2)) -> 5.2726463 | Z20: =IF(T20="","",(T20-T$10)*1000) -> -1.4334103 | AA20: =IF(U20="","",(U20-U$10)*1000) -> -0.46789234 | AB20: =IF(V20="","",(V20-V$10)*1000) -> -0.49919935 | AC20: =IF(W20="","",(W20-W$10)*1000) -> -3.6414462 | AD20: =IF(X20="","",(X20-X$10)*1000) -> -0.082532755 | AE20: =IF(Y20="","",(Y20-Y$10)*1000) -> -2.0457146 | AG20: =IF(E20="","",(E20-E$10)*1000) -> -0.50000008 | AH20: =IF(F20="","",(F20-F$10)*1000) -> -2.0999999 | AI20: =IF(G20="","",(G20-G$10)*1000) -> -2.15 | AJ20: =IF(H20="","",(H20-H$10)*1000) -> -2.2499999 | AK20: =IF(I20="","",(I20-I$10)*1000) -> -3.1999999 | AL20: =IF(J20="","",(J20-J$10)*1000) -> -4.15 | AM20: =IF(K20="","",(K20-K$10)*1000) -> -1.4999999 | AN20: =IF(L20="","",(L20-L$10)*1000) -> -2.4000001 | ... AU20: =IF(S20="","",(S20-S$10)*1000) -> -1.05 | AW20: 170.10836 | AX20: -2.6274959 | AY20: 1.4921964 | AZ20: 170.42591 | BA20: -1.132158 | BB20: 2.7568209 | BC20: 170.4369 | BD20: 0.38550266 | BE20: 3.427411 | BF20: 170.66121 | BG20: 1.1083434 | BH20: 2.7337679 | BI20: 170.39381 | BJ20: 2.6364184 | BK20: 1.5919419 | BM20: =IF(AW20="","",(AW20-AW$10)*1000) -> -1.3375 | BN20: =IF(AX20="","",(AX20-AX$10)*1000) -> 1.804087 | BO20: =IF(AY20="","",(AY20-AY$10)*1000) -> -2.103625 | BP20: =IF(AZ20="","",(AZ20-AZ$10)*1000) -> -3.3882 | BQ20: =IF(BA20="","",(BA20-BA$10)*1000) -> 2.041997 | BR20: =IF(BB20="","",(BB20-BB$10)*1000) -> -4.079118 | BS20: =IF(BC20="","",(BC20-BC$10)*1000) -> -2.3009 | BT20: =IF(BD20="","",(BD20-BD$10)*1000) -> 1.402658 | ... CA20: =IF(BK20="","",(BK20-BK$10)*1000) -> -1.05807
A21: 43690 | B21: =A21-$A$10 -> 35 | C21: 194.8 | D21: =C21-PM -> 24.4 | E21: 823220.73 | F21: 1091507.9 | G21: -122.3492 | H21: 823221.65 | I21: 1091506.7 | J21: -121.0814 | K21: 823222.3 | L21: 1091505.3 | M21: -120.4105 | N21: 823222.81 | O21: 1091504.7 | P21: -121.1019 | Q21: 823223.22 | R21: 1091503.2 | S21: -122.2466 | T21: =IF(Xhaut="","",SQRT(((Xintergauche-Xhaut)^2+(Yintergauche-Yhaut)^2)+(Zintergauche-Zhaut)^2)) -> 3.5974665 | U21: =IF(Xhaut="","",SQRT(((Xhautgauche-Xhaut)^2+(Yhautgauche-Yhaut)^2)+(Zhautgauche-Zhaut)^2)) -> 1.6590273 | V21: =IF(Xhaut="","",SQRT(((Xhautdroit-Xhaut)^2+(Yhautdroit-Yhaut)^2)+(Zhautdroit-Zhaut)^2)) -> 1.0252433 | W21: =IF(Xhaut="","",SQRT(((Xinterdroit-Xhaut)^2+(Yinterdroit-Yhaut)^2)+(Zinterdroit-Zhaut)^2)) -> 2.9056588 | X21: =IF(Xhautdroit="","",SQRT(((Xhautdroit-Xhautgauche)^2+(Yhautdroit-Yhautgauche)^2)+(Zhautdroit-Zhautgauche)^2)) -> 2.252985 | Y21: =IF(Xinterdroit="","",SQRT(((Xinterdroit-Xintergauche)^2+(Yinterdroit-Yintergauche)^2)+(Zinterdroit-Zintergauche)^2)) -> 5.2727876 | Z21: =IF(T21="","",(T21-T$10)*1000) -> -1.8712529 | AA21: =IF(U21="","",(U21-U$10)*1000) -> -0.89875166 | AB21: =IF(V21="","",(V21-V$10)*1000) -> -0.20047066 | AC21: =IF(W21="","",(W21-W$10)*1000) -> -2.8379113 | AD21: =IF(X21="","",(X21-X$10)*1000) -> 0.070151922 | AE21: =IF(Y21="","",(Y21-Y$10)*1000) -> -1.9044031 | AG21: =IF(E21="","",(E21-E$10)*1000) -> -0.30000007 | AH21: =IF(F21="","",(F21-F$10)*1000) -> -3.0999999 | AI21: =IF(G21="","",(G21-G$10)*1000) -> -1.75 | AJ21: =IF(H21="","",(H21-H$10)*1000) -> -2.4499999 | AK21: =IF(I21="","",(I21-I$10)*1000) -> -4.2000001 | AL21: =IF(J21="","",(J21-J$10)*1000) -> -3.75 | AM21: =IF(K21="","",(K21-K$10)*1000) -> -0.89999987 | AN21: =IF(L21="","",(L21-L$10)*1000) -> -2.4000001 | ... AU21: =IF(S21="","",(S21-S$10)*1000) -> -0.65 | AW21: 170.10825 | AX21: -2.626777 | AY21: 1.4925975 | AZ21: 170.42531 | BA21: -1.1313362 | BB21: 2.7572269 | BC21: 170.43719 | BD21: 0.38630002 | BE21: 3.4280081 | BF21: 170.66092 | BG21: 1.1092014 | BH21: 2.7343708 | BI21: 170.39388 | BJ21: 2.6374454 | BK21: 1.5923412 | BM21: =IF(AW21="","",(AW21-AW$10)*1000) -> -1.4521 | BN21: =IF(AX21="","",(AX21-AX$10)*1000) -> 2.523021 | BO21: =IF(AY21="","",(AY21-AY$10)*1000) -> -1.702479 | BP21: =IF(AZ21="","",(AZ21-AZ$10)*1000) -> -3.9921 | BQ21: =IF(BA21="","",(BA21-BA$10)*1000) -> 2.863759 | BR21: =IF(BB21="","",(BB21-BB$10)*1000) -> -3.673079 | BS21: =IF(BC21="","",(BC21-BC$10)*1000) -> -2.0107 | BT21: =IF(BD21="","",(BD21-BD$10)*1000) -> 2.200024 | ... CA21: =IF(BK21="","",(BK21-BK$10)*1000) -> -0.658797
A22: 43696 | B22: =A22-$A$10 -> 41 | C22: 195.4 | D22: =C22-PM -> 25 | E22: 823220.73 | F22: 1091507.9 | G22: -122.3493 | H22: 823221.65 | I22: 1091506.7 | J22: -121.0818 | K22: 823222.3 | L22: 1091505.3 | M22: -120.4111 | N22: 823222.81 | O22: 1091504.7 | P22: -121.1022 | Q22: 823223.22 | R22: 1091503.2 | S22: -122.2463 | T22: =IF(Xhaut="","",SQRT(((Xintergauche-Xhaut)^2+(Yintergauche-Yhaut)^2)+(Zintergauche-Zhaut)^2)) -> 3.5979634 | U22: =IF(Xhaut="","",SQRT(((Xhautgauche-Xhaut)^2+(Yhautgauche-Yhaut)^2)+(Zhautgauche-Zhaut)^2)) -> 1.6592848 | V22: =IF(Xhaut="","",SQRT(((Xhautdroit-Xhaut)^2+(Yhautdroit-Yhaut)^2)+(Zhautdroit-Zhaut)^2)) -> 1.0251199 | W22: =IF(Xhaut="","",SQRT(((Xinterdroit-Xhaut)^2+(Yinterdroit-Yhaut)^2)+(Zinterdroit-Zhaut)^2)) -> 2.9046409 | X22: =IF(Xhautdroit="","",SQRT(((Xhautdroit-Xhautgauche)^2+(Yhautdroit-Yhautgauche)^2)+(Zhautdroit-Zhautgauche)^2)) -> 2.2532585 | Y22: =IF(Xinterdroit="","",SQRT(((Xinterdroit-Xintergauche)^2+(Yinterdroit-Yintergauche)^2)+(Zinterdroit-Zintergauche)^2)) -> 5.2731844 | Z22: =IF(T22="","",(T22-T$10)*1000) -> -1.3743097 | AA22: =IF(U22="","",(U22-U$10)*1000) -> -0.64125919 | AB22: =IF(V22="","",(V22-V$10)*1000) -> -0.32389757 | AC22: =IF(W22="","",(W22-W$10)*1000) -> -3.8558556 | AD22: =IF(X22="","",(X22-X$10)*1000) -> 0.34368141 | AE22: =IF(Y22="","",(Y22-Y$10)*1000) -> -1.5075846 | AG22: =IF(E22="","",(E22-E$10)*1000) -> -1.3000001 | AH22: =IF(F22="","",(F22-F$10)*1000) -> -1.1 | AI22: =IF(G22="","",(G22-G$10)*1000) -> -1.85 | AJ22: =IF(H22="","",(H22-H$10)*1000) -> -2.4499999 | AK22: =IF(I22="","",(I22-I$10)*1000) -> -2.3000001 | AL22: =IF(J22="","",(J22-J$10)*1000) -> -4.15 | AM22: =IF(K22="","",(K22-K$10)*1000) -> -1.2999999 | AN22: =IF(L22="","",(L22-L$10)*1000) -> -1.1000002 | ... AU22: =IF(S22="","",(S22-S$10)*1000) -> -0.35 | AW22: 170.1081 | AX22: -2.6288 | AY22: 1.4925 | AZ22: 170.4262 | BA22: -1.1331 | BB22: 2.7568 | BC22: 170.4376 | BD22: 0.3845 | BE22: 3.4274 | BF22: 170.6619 | BG22: 1.1077 | BH22: 2.7341 | BI22: 170.395 | BJ22: 2.6355 | BK22: 1.5926 | BM22: =IF(AW22="","",(AW22-AW$10)*1000) -> -1.6 | BN22: =IF(AX22="","",(AX22-AX$10)*1000) -> 0.5 | BO22: =IF(AY22="","",(AY22-AY$10)*1000) -> -1.8 | BP22: =IF(AZ22="","",(AZ22-AZ$10)*1000) -> -3.1 | BQ22: =IF(BA22="","",(BA22-BA$10)*1000) -> 1.1 | BR22: =IF(BB22="","",(BB22-BB$10)*1000) -> -4.1 | BS22: =IF(BC22="","",(BC22-BC$10)*1000) -> -1.6 | BT22: =IF(BD22="","",(BD22-BD$10)*1000) -> 0.4 | ... CA22: =IF(BK22="","",(BK22-BK$10)*1000) -> -0.4
A23: 43699 | B23: =A23-$A$10 -> 44 | C23: 196.35 | D23: =C23-PM -> 25.95 | E23: 823220.73 | F23: 1091507.9 | G23: -122.3498 | H23: 823221.65 | I23: 1091506.7 | J23: -121.0826 | K23: 823222.3 | L23: 1091505.3 | M23: -120.4116 | N23: 823222.81 | O23: 1091504.7 | P23: -121.1029 | Q23: 823223.22 | R23: 1091503.2 | S23: -122.2467 | T23: =IF(Xhaut="","",SQRT(((Xintergauche-Xhaut)^2+(Yintergauche-Yhaut)^2)+(Zintergauche-Zhaut)^2)) -> 3.5980071 | U23: =IF(Xhaut="","",SQRT(((Xhautgauche-Xhaut)^2+(Yhautgauche-Yhaut)^2)+(Zhautgauche-Zhaut)^2)) -> 1.6594021 | V23: =IF(Xhaut="","",SQRT(((Xhautdroit-Xhaut)^2+(Yhautdroit-Yhaut)^2)+(Zhautdroit-Zhaut)^2)) -> 1.0251008 | W23: =IF(Xhaut="","",SQRT(((Xinterdroit-Xhaut)^2+(Yinterdroit-Yhaut)^2)+(Zinterdroit-Zhaut)^2)) -> 2.9044674 | X23: =IF(Xhautdroit="","",SQRT(((Xhautdroit-Xhautgauche)^2+(Yhautdroit-Yhautgauche)^2)+(Zhautdroit-Zhautgauche)^2)) -> 2.2530862 | Y23: =IF(Xinterdroit="","",SQRT(((Xinterdroit-Xintergauche)^2+(Yinterdroit-Yintergauche)^2)+(Zinterdroit-Zintergauche)^2)) -> 5.2731043 | Z23: =IF(T23="","",(T23-T$10)*1000) -> -1.3306116 | AA23: =IF(U23="","",(U23-U$10)*1000) -> -0.52399599 | AB23: =IF(V23="","",(V23-V$10)*1000) -> -0.34299298 | AC23: =IF(W23="","",(W23-W$10)*1000) -> -4.0293174 | AD23: =IF(X23="","",(X23-X$10)*1000) -> 0.17136668 | AE23: =IF(Y23="","",(Y23-Y$10)*1000) -> -1.587729 | AG23: =IF(E23="","",(E23-E$10)*1000) -> -1.5000001 | AH23: =IF(F23="","",(F23-F$10)*1000) -> -1.4999998 | AI23: =IF(G23="","",(G23-G$10)*1000) -> -2.35 | AJ23: =IF(H23="","",(H23-H$10)*1000) -> -2.75 | AK23: =IF(I23="","",(I23-I$10)*1000) -> -2.7999999 | AL23: =IF(J23="","",(J23-J$10)*1000) -> -4.95 | AM23: =IF(K23="","",(K23-K$10)*1000) -> -1.4 | AN23: =IF(L23="","",(L23-L$10)*1000) -> -1.5 | ... AU23: =IF(S23="","",(S23-S$10)*1000) -> -0.75 | AW23: 170.1078 | AX23: -2.6286 | AY23: 1.492 | AZ23: 170.4257 | BA23: -1.1328 | BB23: 2.756 | BC23: 170.4373 | BD23: 0.3848 | BE23: 3.4269 | BF23: 170.6615 | BG23: 1.1078 | BH23: 2.7334 | BI23: 170.3949 | BJ23: 2.6357 | BK23: 1.5922 | BM23: =IF(AW23="","",(AW23-AW$10)*1000) -> -1.9 | BN23: =IF(AX23="","",(AX23-AX$10)*1000) -> 0.7 | BO23: =IF(AY23="","",(AY23-AY$10)*1000) -> -2.3 | BP23: =IF(AZ23="","",(AZ23-AZ$10)*1000) -> -3.6 | BQ23: =IF(BA23="","",(BA23-BA$10)*1000) -> 1.4 | BR23: =IF(BB23="","",(BB23-BB$10)*1000) -> -4.9 | BS23: =IF(BC23="","",(BC23-BC$10)*1000) -> -1.9 | BT23: =IF(BD23="","",(BD23-BD$10)*1000) -> 0.7 | ... CA23: =IF(BK23="","",(BK23-BK$10)*1000) -> -0.8
A24: 43703 | B24: =A24-$A$10 -> 48 | C24: 196.35 | D24: =C24-PM -> 25.95 | E24: 823220.73 | F24: 1091507.9 | G24: -122.3501 | H24: 823221.65 | I24: 1091506.7 | J24: -121.0831 | K24: 823222.3 | L24: 1091505.3 | M24: -120.4122 | N24: 823222.81 | O24: 1091504.7 | P24: -121.1034 | Q24: 823223.22 | R24: 1091503.2 | S24: -122.2468 | T24: =IF(Xhaut="","",SQRT(((Xintergauche-Xhaut)^2+(Yintergauche-Yhaut)^2)+(Zintergauche-Zhaut)^2)) -> 3.5979176 | U24: =IF(Xhaut="","",SQRT(((Xhautgauche-Xhaut)^2+(Yhautgauche-Yhaut)^2)+(Zhautgauche-Zhaut)^2)) -> 1.6592791 | V24: =IF(Xhaut="","",SQRT(((Xhautdroit-Xhaut)^2+(Yhautdroit-Yhaut)^2)+(Zhautdroit-Zhaut)^2)) -> 1.0251033 | W24: =IF(Xhaut="","",SQRT(((Xinterdroit-Xhaut)^2+(Yinterdroit-Yhaut)^2)+(Zinterdroit-Zhaut)^2)) -> 2.9040886 | X24: =IF(Xhautdroit="","",SQRT(((Xhautdroit-Xhautgauche)^2+(Yhautdroit-Yhautgauche)^2)+(Zhautdroit-Zhautgauche)^2)) -> 2.2531888 | Y24: =IF(Xinterdroit="","",SQRT(((Xinterdroit-Xintergauche)^2+(Yinterdroit-Yintergauche)^2)+(Zinterdroit-Zintergauche)^2)) -> 5.2731021 | Z24: =IF(T24="","",(T24-T$10)*1000) -> -1.4201734 | AA24: =IF(U24="","",(U24-U$10)*1000) -> -0.64702063 | AB24: =IF(V24="","",(V24-V$10)*1000) -> -0.3404665 | AC24: =IF(W24="","",(W24-W$10)*1000) -> -4.4080641 | AD24: =IF(X24="","",(X24-X$10)*1000) -> 0.27397026 | AE24: =IF(Y24="","",(Y24-Y$10)*1000) -> -1.5898939 | AG24: =IF(E24="","",(E24-E$10)*1000) -> -2.0000001 | AH24: =IF(F24="","",(F24-F$10)*1000) -> -2.7999999 | AI24: =IF(G24="","",(G24-G$10)*1000) -> -2.65 | AJ24: =IF(H24="","",(H24-H$10)*1000) -> -3.25 | AK24: =IF(I24="","",(I24-I$10)*1000) -> -4.2999999 | AL24: =IF(J24="","",(J24-J$10)*1000) -> -5.45 | AM24: =IF(K24="","",(K24-K$10)*1000) -> -1.8999999 | AN24: =IF(L24="","",(L24-L$10)*1000) -> -2.9000002 | ... AU24: =IF(S24="","",(S24-S$10)*1000) -> -0.85 | AW24: 170.1067 | AX24: -2.6276 | AY24: 1.4917 | AZ24: 170.4246 | BA24: -1.1317 | BB24: 2.7555 | BC24: 170.4363 | BD24: 0.3859 | BE24: 3.4263 | BF24: 170.66 | BG24: 1.1091 | BH24: 2.7329 | BI24: 170.3937 | BJ24: 2.6367 | BK24: 1.5921 | BM24: =IF(AW24="","",(AW24-AW$10)*1000) -> -3 | BN24: =IF(AX24="","",(AX24-AX$10)*1000) -> 1.7 | BO24: =IF(AY24="","",(AY24-AY$10)*1000) -> -2.6 | BP24: =IF(AZ24="","",(AZ24-AZ$10)*1000) -> -4.7 | BQ24: =IF(BA24="","",(BA24-BA$10)*1000) -> 2.5 | BR24: =IF(BB24="","",(BB24-BB$10)*1000) -> -5.4 | BS24: =IF(BC24="","",(BC24-BC$10)*1000) -> -2.9 | BT24: =IF(BD24="","",(BD24-BD$10)*1000) -> 1.8 | ... CA24: =IF(BK24="","",(BK24-BK$10)*1000) -> -0.9
A25: 43706 | B25: =A25-$A$10 -> 51 | C25: 198.3 | D25: =C25-PM -> 27.9 | E25: 823220.73 | F25: 1091507.9 | G25: -122.3505 | H25: 823221.65 | I25: 1091506.7 | J25: -121.0835 | K25: 823222.3 | L25: 1091505.3 | M25: -120.4126 | N25: 823222.81 | O25: 1091504.7 | P25: -121.1037 | Q25: 823223.22 | R25: 1091503.2 | S25: -122.2469 | T25: =IF(Xhaut="","",SQRT(((Xintergauche-Xhaut)^2+(Yintergauche-Yhaut)^2)+(Zintergauche-Zhaut)^2)) -> 3.5980487 | U25: =IF(Xhaut="","",SQRT(((Xhautgauche-Xhaut)^2+(Yhautgauche-Yhaut)^2)+(Zhautgauche-Zhaut)^2)) -> 1.6592358 | V25: =IF(Xhaut="","",SQRT(((Xhautdroit-Xhaut)^2+(Yhautdroit-Yhaut)^2)+(Zhautdroit-Zhaut)^2)) -> 1.02513 | W25: =IF(Xhaut="","",SQRT(((Xinterdroit-Xhaut)^2+(Yinterdroit-Yhaut)^2)+(Zinterdroit-Zhaut)^2)) -> 2.9037888 | X25: =IF(Xhautdroit="","",SQRT(((Xhautdroit-Xhautgauche)^2+(Yhautdroit-Yhautgauche)^2)+(Zhautdroit-Zhautgauche)^2)) -> 2.2532226 | Y25: =IF(Xinterdroit="","",SQRT(((Xinterdroit-Xintergauche)^2+(Yinterdroit-Yintergauche)^2)+(Zinterdroit-Zintergauche)^2)) -> 5.2731202 | Z25: =IF(T25="","",(T25-T$10)*1000) -> -1.2890624 | AA25: =IF(U25="","",(U25-U$10)*1000) -> -0.69031115 | AB25: =IF(V25="","",(V25-V$10)*1000) -> -0.31377191 | AC25: =IF(W25="","",(W25-W$10)*1000) -> -4.7078706 | AD25: =IF(X25="","",(X25-X$10)*1000) -> 0.30768892 | AE25: =IF(Y25="","",(Y25-Y$10)*1000) -> -1.5718409 | AG25: =IF(E25="","",(E25-E$10)*1000) -> -2.3000001 | AH25: =IF(F25="","",(F25-F$10)*1000) -> -2.6999998 | AI25: =IF(G25="","",(G25-G$10)*1000) -> -3.05 | AJ25: =IF(H25="","",(H25-H$10)*1000) -> -3.3499999 | AK25: =IF(I25="","",(I25-I$10)*1000) -> -4.2999999 | AL25: =IF(J25="","",(J25-J$10)*1000) -> -5.85 | AM25: =IF(K25="","",(K25-K$10)*1000) -> -1.8999999 | AN25: =IF(L25="","",(L25-L$10)*1000) -> -2.8000001 | ... AU25: =IF(S25="","",(S25-S$10)*1000) -> -0.95 | AW25: 170.1065 | AX25: -2.6278 | AY25: 1.4913 | AZ25: 170.4245 | BA25: -1.1317 | BB25: 2.7551 | BC25: 170.4363 | BD25: 0.3858 | BE25: 3.4259 | BF25: 170.6603 | BG25: 1.109 | BH25: 2.7326 | BI25: 170.3939 | BJ25: 2.6365 | BK25: 1.592 | BM25: =IF(AW25="","",(AW25-AW$10)*1000) -> -3.2 | BN25: =IF(AX25="","",(AX25-AX$10)*1000) -> 1.5 | BO25: =IF(AY25="","",(AY25-AY$10)*1000) -> -3 | BP25: =IF(AZ25="","",(AZ25-AZ$10)*1000) -> -4.8 | BQ25: =IF(BA25="","",(BA25-BA$10)*1000) -> 2.5 | BR25: =IF(BB25="","",(BB25-BB$10)*1000) -> -5.8 | BS25: =IF(BC25="","",(BC25-BC$10)*1000) -> -2.9 | BT25: =IF(BD25="","",(BD25-BD$10)*1000) -> 1.7 | ... CA25: =IF(BK25="","",(BK25-BK$10)*1000) -> -1
A26: 43710 | B26: =A26-$A$10 -> 55 | C26: 199.4 | D26: =C26-PM -> 29 | E26: 823220.73 | F26: 1091507.9 | G26: -122.3506 | H26: 823221.65 | I26: 1091506.7 | J26: -121.0841 | K26: 823222.3 | L26: 1091505.3 | M26: -120.4131 | N26: 823222.81 | O26: 1091504.7 | P26: -121.1039 | Q26: 823223.22 | R26: 1091503.2 | S26: -122.247 | T26: =IF(Xhaut="","",SQRT(((Xintergauche-Xhaut)^2+(Yintergauche-Yhaut)^2)+(Zintergauche-Zhaut)^2)) -> 3.5979183 | U26: =IF(Xhaut="","",SQRT(((Xhautgauche-Xhaut)^2+(Yhautgauche-Yhaut)^2)+(Zhautgauche-Zhaut)^2)) -> 1.6592409 | V26: =IF(Xhaut="","",SQRT(((Xhautdroit-Xhaut)^2+(Yhautdroit-Yhaut)^2)+(Zhautdroit-Zhaut)^2)) -> 1.0249724 | W26: =IF(Xhaut="","",SQRT(((Xinterdroit-Xhaut)^2+(Yinterdroit-Yhaut)^2)+(Zinterdroit-Zhaut)^2)) -> 2.9033865 | X26: =IF(Xhautdroit="","",SQRT(((Xhautdroit-Xhautgauche)^2+(Yhautdroit-Yhautgauche)^2)+(Zhautdroit-Zhautgauche)^2)) -> 2.2531675 | Y26: =IF(Xinterdroit="","",SQRT(((Xinterdroit-Xintergauche)^2+(Yinterdroit-Yintergauche)^2)+(Zinterdroit-Zintergauche)^2)) -> 5.273073 | Z26: =IF(T26="","",(T26-T$10)*1000) -> -1.4194772 | AA26: =IF(U26="","",(U26-U$10)*1000) -> -0.68516113 | AB26: =IF(V26="","",(V26-V$10)*1000) -> -0.4714226 | AC26: =IF(W26="","",(W26-W$10)*1000) -> -5.1102436 | AD26: =IF(X26="","",(X26-X$10)*1000) -> 0.2526227 | AE26: =IF(Y26="","",(Y26-Y$10)*1000) -> -1.6189738 | AG26: =IF(E26="","",(E26-E$10)*1000) -> -2.4000001 | AH26: =IF(F26="","",(F26-F$10)*1000) -> -2.4999999 | AI26: =IF(G26="","",(G26-G$10)*1000) -> -3.15 | AJ26: =IF(H26="","",(H26-H$10)*1000) -> -3.45 | AK26: =IF(I26="","",(I26-I$10)*1000) -> -4.2999999 | AL26: =IF(J26="","",(J26-J$10)*1000) -> -6.45 | AM26: =IF(K26="","",(K26-K$10)*1000) -> -2.2999999 | AN26: =IF(L26="","",(L26-L$10)*1000) -> -2.9000002 | ... AU26: =IF(S26="","",(S26-S$10)*1000) -> -1.05 | AW26: 170.1065 | AX26: -2.628 | AY26: 1.4912 | AZ26: 170.4244 | BA26: -1.1318 | BB26: 2.7545 | BC26: 170.4359 | BD26: 0.3857 | BE26: 3.4254 | BF26: 170.6602 | BG26: 1.109 | BH26: 2.7324 | BI26: 170.3938 | BJ26: 2.6362 | BK26: 1.5919 | BM26: =IF(AW26="","",(AW26-AW$10)*1000) -> -3.2 | BN26: =IF(AX26="","",(AX26-AX$10)*1000) -> 1.3 | BO26: =IF(AY26="","",(AY26-AY$10)*1000) -> -3.1 | BP26: =IF(AZ26="","",(AZ26-AZ$10)*1000) -> -4.9 | BQ26: =IF(BA26="","",(BA26-BA$10)*1000) -> 2.4 | BR26: =IF(BB26="","",(BB26-BB$10)*1000) -> -6.4 | BS26: =IF(BC26="","",(BC26-BC$10)*1000) -> -3.3 | BT26: =IF(BD26="","",(BD26-BD$10)*1000) -> 1.6 | ... CA26: =IF(BK26="","",(BK26-BK$10)*1000) -> -1.1
A27: 43713 | B27: =A27-$A$10 -> 58 | C27: 200.6 | D27: =C27-PM -> 30.2 | E27: 823220.73 | F27: 1091507.9 | G27: -122.351 | H27: 823221.65 | I27: 1091506.7 | J27: -121.0847 | K27: 823222.3 | L27: 1091505.3 | M27: -120.4136 | N27: 823222.81 | O27: 1091504.7 | P27: -121.1044 | Q27: 823223.22 | R27: 1091503.2 | S27: -122.2473 | T27: =IF(Xhaut="","",SQRT(((Xintergauche-Xhaut)^2+(Yintergauche-Yhaut)^2)+(Zintergauche-Zhaut)^2)) -> 3.5979955 | U27: =IF(Xhaut="","",SQRT(((Xhautgauche-Xhaut)^2+(Yhautgauche-Yhaut)^2)+(Zhautgauche-Zhaut)^2)) -> 1.6593559 | V27: =IF(Xhaut="","",SQRT(((Xhautdroit-Xhaut)^2+(Yhautdroit-Yhaut)^2)+(Zhautdroit-Zhaut)^2)) -> 1.025022 | W27: =IF(Xhaut="","",SQRT(((Xinterdroit-Xhaut)^2+(Yinterdroit-Yhaut)^2)+(Zinterdroit-Zhaut)^2)) -> 2.9032207 | X27: =IF(Xhautdroit="","",SQRT(((Xhautdroit-Xhautgauche)^2+(Yhautdroit-Yhautgauche)^2)+(Zhautdroit-Zhautgauche)^2)) -> 2.2533385 | Y27: =IF(Xinterdroit="","",SQRT(((Xinterdroit-Xintergauche)^2+(Yinterdroit-Yintergauche)^2)+(Zinterdroit-Zintergauche)^2)) -> 5.2731754 | Z27: =IF(T27="","",(T27-T$10)*1000) -> -1.3422138 | AA27: =IF(U27="","",(U27-U$10)*1000) -> -0.57013063 | AB27: =IF(V27="","",(V27-V$10)*1000) -> -0.42176883 | AC27: =IF(W27="","",(W27-W$10)*1000) -> -5.2759823 | AD27: =IF(X27="","",(X27-X$10)*1000) -> 0.42366201 | AE27: =IF(Y27="","",(Y27-Y$10)*1000) -> -1.5166396 | AG27: =IF(E27="","",(E27-E$10)*1000) -> -2.8000001 | AH27: =IF(F27="","",(F27-F$10)*1000) -> -2.6999998 | AI27: =IF(G27="","",(G27-G$10)*1000) -> -3.55 | AJ27: =IF(H27="","",(H27-H$10)*1000) -> -3.9499999 | AK27: =IF(I27="","",(I27-I$10)*1000) -> -4.5999999 | AL27: =IF(J27="","",(J27-J$10)*1000) -> -7.05 | AM27: =IF(K27="","",(K27-K$10)*1000) -> -2.3999999 | AN27: =IF(L27="","",(L27-L$10)*1000) -> -3.1000001 | ... AU27: =IF(S27="","",(S27-S$10)*1000) -> -1.35 | AW27: 170.1061 | AX27: -2.628 | AY27: 1.4908 | AZ27: 170.4238 | BA27: -1.1317 | BB27: 2.7539 | BC27: 170.4357 | BD27: 0.3858 | BE27: 3.4249 | BF27: 170.6601 | BG27: 1.1091 | BH27: 2.7319 | BI27: 170.3938 | BJ27: 2.6363 | BK27: 1.5916 | BM27: =IF(AW27="","",(AW27-AW$10)*1000) -> -3.6 | BN27: =IF(AX27="","",(AX27-AX$10)*1000) -> 1.3 | BO27: =IF(AY27="","",(AY27-AY$10)*1000) -> -3.5 | BP27: =IF(AZ27="","",(AZ27-AZ$10)*1000) -> -5.5 | BQ27: =IF(BA27="","",(BA27-BA$10)*1000) -> 2.5 | BR27: =IF(BB27="","",(BB27-BB$10)*1000) -> -7 | BS27: =IF(BC27="","",(BC27-BC$10)*1000) -> -3.5 | BT27: =IF(BD27="","",(BD27-BD$10)*1000) -> 1.7 | ... CA27: =IF(BK27="","",(BK27-BK$10)*1000) -> -1.4
A28: 43718 | B28: =A28-$A$10 -> 63 | C28: 202.58 | D28: =C28-PM -> 32.18 | E28: 823220.73 | F28: 1091507.9 | G28: -122.3509 | H28: 823221.65 | I28: 1091506.7 | J28: -121.0844 | K28: 823222.3 | L28: 1091505.3 | M28: -120.4133 | N28: 823222.81 | O28: 1091504.7 | P28: -121.1044 | Q28: 823223.22 | R28: 1091503.2 | S28: -122.2467 | T28: =IF(Xhaut="","",SQRT(((Xintergauche-Xhaut)^2+(Yintergauche-Yhaut)^2)+(Zintergauche-Zhaut)^2)) -> 3.5983784 | U28: =IF(Xhaut="","",SQRT(((Xhautgauche-Xhaut)^2+(Yhautgauche-Yhaut)^2)+(Zhautgauche-Zhaut)^2)) -> 1.6594385 | V28: =IF(Xhaut="","",SQRT(((Xhautdroit-Xhaut)^2+(Yhautdroit-Yhaut)^2)+(Zhautdroit-Zhaut)^2)) -> 1.0251898 | W28: =IF(Xhaut="","",SQRT(((Xinterdroit-Xhaut)^2+(Yinterdroit-Yhaut)^2)+(Zinterdroit-Zhaut)^2)) -> 2.9031415 | X28: =IF(Xhautdroit="","",SQRT(((Xhautdroit-Xhautgauche)^2+(Yhautdroit-Yhautgauche)^2)+(Zhautdroit-Zhautgauche)^2)) -> 2.2534779 | Y28: =IF(Xinterdroit="","",SQRT(((Xinterdroit-Xintergauche)^2+(Yinterdroit-Yintergauche)^2)+(Zinterdroit-Zintergauche)^2)) -> 5.2736322 | Z28: =IF(T28="","",(T28-T$10)*1000) -> -0.95930844 | AA28: =IF(U28="","",(U28-U$10)*1000) -> -0.48754938 | AB28: =IF(V28="","",(V28-V$10)*1000) -> -0.25396182 | AC28: =IF(W28="","",(W28-W$10)*1000) -> -5.3551679 | AD28: =IF(X28="","",(X28-X$10)*1000) -> 0.56302203 | AE28: =IF(Y28="","",(Y28-Y$10)*1000) -> -1.0598237 | AG28: =IF(E28="","",(E28-E$10)*1000) -> -2.6000001 | AH28: =IF(F28="","",(F28-F$10)*1000) -> -2.6999998 | AI28: =IF(G28="","",(G28-G$10)*1000) -> -3.45 | AJ28: =IF(H28="","",(H28-H$10)*1000) -> -3.45 | AK28: =IF(I28="","",(I28-I$10)*1000) -> -4.6999999 | AL28: =IF(J28="","",(J28-J$10)*1000) -> -6.75 | AM28: =IF(K28="","",(K28-K$10)*1000) -> -1.8999999 | AN28: =IF(L28="","",(L28-L$10)*1000) -> -3.3000002 | ... AU28: =IF(S28="","",(S28-S$10)*1000) -> -0.75 | AW28: 170.10625 | AX28: -2.6279303 | AY28: 1.4909175 | AZ28: 170.42423 | BA28: -1.1313964 | BB28: 2.7542377 | BC28: 170.43611 | BD28: 0.38623989 | BE28: 3.4252189 | BF28: 170.65995 | BG28: 1.1096305 | BH28: 2.7318805 | BI28: 170.39395 | BJ28: 2.6368171 | BK28: 1.5922405 | BM28: =IF(AW28="","",(AW28-AW$10)*1000) -> -3.4520387 | BN28: =IF(AX28="","",(AX28-AX$10)*1000) -> 1.3696632 | BO28: =IF(AY28="","",(AY28-AY$10)*1000) -> -3.3824796 | BP28: =IF(AZ28="","",(AZ28-AZ$10)*1000) -> -5.0674402 | BQ28: =IF(BA28="","",(BA28-BA$10)*1000) -> 2.8036238 | BR28: =IF(BB28="","",(BB28-BB$10)*1000) -> -6.6623256 | BS28: =IF(BC28="","",(BC28-BC$10)*1000) -> -3.0860804 | BT28: =IF(BD28="","",(BD28-BD$10)*1000) -> 2.1398891 | ... CA28: =IF(BK28="","",(BK28-BK$10)*1000) -> -0.7595205
A29: 43720 | B29: =A29-$A$10 -> 65 | C29: 203.6 | D29: =C29-PM -> 33.2 | E29: 823220.73 | F29: 1091507.9 | G29: -122.3507 | H29: 823221.65 | I29: 1091506.7 | J29: -121.0845 | K29: 823222.3 | L29: 1091505.3 | M29: -120.4132 | N29: 823222.81 | O29: 1091504.7 | P29: -121.1041 | Q29: 823223.22 | R29: 1091503.2 | S29: -122.2464 | T29: =IF(Xhaut="","",SQRT(((Xintergauche-Xhaut)^2+(Yintergauche-Yhaut)^2)+(Zintergauche-Zhaut)^2)) -> 3.5983683 | U29: =IF(Xhaut="","",SQRT(((Xhautgauche-Xhaut)^2+(Yhautgauche-Yhaut)^2)+(Zhautgauche-Zhaut)^2)) -> 1.6593936 | V29: =IF(Xhaut="","",SQRT(((Xhautdroit-Xhaut)^2+(Yhautdroit-Yhaut)^2)+(Zhautdroit-Zhaut)^2)) -> 1.0252535 | W29: =IF(Xhaut="","",SQRT(((Xinterdroit-Xhaut)^2+(Yinterdroit-Yhaut)^2)+(Zinterdroit-Zhaut)^2)) -> 2.9030387 | X29: =IF(Xhautdroit="","",SQRT(((Xhautdroit-Xhautgauche)^2+(Yhautdroit-Yhautgauche)^2)+(Zhautdroit-Zhautgauche)^2)) -> 2.2535606 | Y29: =IF(Xinterdroit="","",SQRT(((Xinterdroit-Xintergauche)^2+(Yinterdroit-Yintergauche)^2)+(Zinterdroit-Zintergauche)^2)) -> 5.2737346 | Z29: =IF(T29="","",(T29-T$10)*1000) -> -0.96944077 | AA29: =IF(U29="","",(U29-U$10)*1000) -> -0.53250202 | AB29: =IF(V29="","",(V29-V$10)*1000) -> -0.19024876 | AC29: =IF(W29="","",(W29-W$10)*1000) -> -5.4579755 | AD29: =IF(X29="","",(X29-X$10)*1000) -> 0.64571263 | AE29: =IF(Y29="","",(Y29-Y$10)*1000) -> -0.95744913 | AG29: =IF(E29="","",(E29-E$10)*1000) -> -3.0000001 | AH29: =IF(F29="","",(F29-F$10)*1000) -> -2.5999998 | AI29: =IF(G29="","",(G29-G$10)*1000) -> -3.25 | AJ29: =IF(H29="","",(H29-H$10)*1000) -> -3.85 | AK29: =IF(I29="","",(I29-I$10)*1000) -> -4.8 | AL29: =IF(J29="","",(J29-J$10)*1000) -> -6.85 | AM29: =IF(K29="","",(K29-K$10)*1000) -> -2.1999999 | AN29: =IF(L29="","",(L29-L$10)*1000) -> -3.2000002 | ... AU29: =IF(S29="","",(S29-S$10)*1000) -> -0.45 | AW29: 170.1059 | AX29: -2.6282 | AY29: 1.4911 | AZ29: 170.4238 | BA29: -1.1315 | BB29: 2.7541 | BC29: 170.4359 | BD29: 0.386 | BE29: 3.4253 | BF29: 170.6601 | BG29: 1.1096 | BH29: 2.7322 | BI29: 170.394 | BJ29: 2.6366 | BK29: 1.5925 | BM29: =IF(AW29="","",(AW29-AW$10)*1000) -> -3.8 | BN29: =IF(AX29="","",(AX29-AX$10)*1000) -> 1.1 | BO29: =IF(AY29="","",(AY29-AY$10)*1000) -> -3.2 | BP29: =IF(AZ29="","",(AZ29-AZ$10)*1000) -> -5.5 | BQ29: =IF(BA29="","",(BA29-BA$10)*1000) -> 2.7 | BR29: =IF(BB29="","",(BB29-BB$10)*1000) -> -6.8 | BS29: =IF(BC29="","",(BC29-BC$10)*1000) -> -3.3 | BT29: =IF(BD29="","",(BD29-BD$10)*1000) -> 1.9 | ... CA29: =IF(BK29="","",(BK29-BK$10)*1000) -> -0.5
... A40: 43762 | B40: =A40-$A$10 -> 107 | C40: 215 | D40: =C40-PM -> 44.6 | E40: 823220.73 | F40: 1091507.9 | G40: -122.3531 | H40: 823221.65 | I40: 1091506.7 | J40: -121.0879 | K40: 823222.3 | L40: 1091505.3 | M40: -120.4166 | N40: 823222.81 | O40: 1091504.7 | P40: -121.107 | Q40: 823223.21 | R40: 1091503.2 | S40: -122.247 | T40: =IF(Xhaut="","",SQRT(((Xintergauche-Xhaut)^2+(Yintergauche-Yhaut)^2)+(Zintergauche-Zhaut)^2)) -> 3.5986404 | U40: =IF(Xhaut="","",SQRT(((Xhautgauche-Xhaut)^2+(Yhautgauche-Yhaut)^2)+(Zhautgauche-Zhaut)^2)) -> 1.659602 | V40: =IF(Xhaut="","",SQRT(((Xhautdroit-Xhaut)^2+(Yhautdroit-Yhaut)^2)+(Zhautdroit-Zhaut)^2)) -> 1.0254044 | W40: =IF(Xhaut="","",SQRT(((Xinterdroit-Xhaut)^2+(Yinterdroit-Yhaut)^2)+(Zinterdroit-Zhaut)^2)) -> 2.9011846 | X40: =IF(Xhautdroit="","",SQRT(((Xhautdroit-Xhautgauche)^2+(Yhautdroit-Yhautgauche)^2)+(Zhautdroit-Zhautgauche)^2)) -> 2.254499 | Y40: =IF(Xinterdroit="","",SQRT(((Xinterdroit-Xintergauche)^2+(Yinterdroit-Yintergauche)^2)+(Zinterdroit-Zintergauche)^2)) -> 5.2746418 | Z40: =IF(T40="","",(T40-T$10)*1000) -> -0.69732775 | AA40: =IF(U40="","",(U40-U$10)*1000) -> -0.32407739 | AB40: =IF(V40="","",(V40-V$10)*1000) -> -0.039370299 | AC40: =IF(W40="","",(W40-W$10)*1000) -> -7.312079 | AD40: =IF(X40="","",(X40-X$10)*1000) -> 1.5841432 | AE40: =IF(Y40="","",(Y40-Y$10)*1000) -> -0.050228127 | AG40: =IF(E40="","",(E40-E$10)*1000) -> -5.4000001 | AH40: =IF(F40="","",(F40-F$10)*1000) -> -1.9999999 | AI40: =IF(G40="","",(G40-G$10)*1000) -> -5.65 | AJ40: =IF(H40="","",(H40-H$10)*1000) -> -5.4499999 | AK40: =IF(I40="","",(I40-I$10)*1000) -> -4.5999999 | AL40: =IF(J40="","",(J40-J$10)*1000) -> -10.25 | AM40: =IF(K40="","",(K40-K$10)*1000) -> -3.8999999 | AN40: =IF(L40="","",(L40-L$10)*1000) -> -3.3000002 | ... AU40: =IF(S40="","",(S40-S$10)*1000) -> -1.05 | AW40: 170.10401 | AX40: -2.6297482 | AY40: 1.4887399 | AZ40: 170.42246 | BA40: -1.1323323 | BB40: 2.7507554 | BC40: 170.4343 | BD40: 0.38539459 | BE40: 3.421937 | BF40: 170.65825 | BG40: 1.1097216 | BH40: 2.7292975 | BI40: 170.39294 | BJ40: 2.6359051 | BK40: 1.5919506 | BM40: =IF(AW40="","",(AW40-AW$10)*1000) -> -5.6938001 | BN40: =IF(AX40="","",(AX40-AX$10)*1000) -> -0.44816683 | BO40: =IF(AY40="","",(AY40-AY$10)*1000) -> -5.560062 | BP40: =IF(AZ40="","",(AZ40-AZ$10)*1000) -> -6.8377591 | BQ40: =IF(BA40="","",(BA40-BA$10)*1000) -> 1.8676905 | BR40: =IF(BB40="","",(BB40-BB$10)*1000) -> -10.144622 | BS40: =IF(BC40="","",(BC40-BC$10)*1000) -> -4.8986645 | BT40: =IF(BD40="","",(BD40-BD$10)*1000) -> 1.294585 | ... CA40: =IF(BK40="","",(BK40-BK$10)*1000) -> -1.0494293
A41: 43766 | B41: =A41-$A$10 -> 111 | C41: 215.55 | D41: =C41-PM -> 45.15 | E41: 823220.73 | F41: 1091507.9 | G41: -122.3526 | H41: - | I41: - | J41: - | K41: 823222.3 | L41: 1091505.3 | M41: -120.4166 | N41: 823222.81 | O41: 1091504.7 | P41: -121.1068 | Q41: 823223.21 | R41: 1091503.2 | S41: -122.2472 | T41: =IF(Xhaut="","",SQRT(((Xintergauche-Xhaut)^2+(Yintergauche-Yhaut)^2)+(Zintergauche-Zhaut)^2)) -> 3.5985285 | V41: =IF(Xhaut="","",SQRT(((Xhautdroit-Xhaut)^2+(Yhautdroit-Yhaut)^2)+(Zhautdroit-Zhaut)^2)) -> 1.02515 | W41: =IF(Xhaut="","",SQRT(((Xinterdroit-Xhaut)^2+(Yinterdroit-Yhaut)^2)+(Zinterdroit-Zhaut)^2)) -> 2.9010193 | Y41: =IF(Xinterdroit="","",SQRT(((Xinterdroit-Xintergauche)^2+(Yinterdroit-Yintergauche)^2)+(Zinterdroit-Zintergauche)^2)) -> 5.2744924 | Z41: =IF(T41="","",(T41-T$10)*1000) -> -0.8092914 | AA41: =IF(U41="","",(U41-U$10)*1000) | AB41: =IF(V41="","",(V41-V$10)*1000) -> -0.29379906 | AC41: =IF(W41="","",(W41-W$10)*1000) -> -7.4773833 | AD41: =IF(X41="","",(X41-X$10)*1000) | AE41: =IF(Y41="","",(Y41-Y$10)*1000) -> -0.19957981 | AG41: =IF(E41="","",(E41-E$10)*1000) -> -5.3000001 | AH41: =IF(F41="","",(F41-F$10)*1000) -> -2.3999999 | AI41: =IF(G41="","",(G41-G$10)*1000) -> -5.15 | AM41: =IF(K41="","",(K41-K$10)*1000) -> -4.0999999 | AN41: =IF(L41="","",(L41-L$10)*1000) -> -4.1 | AO41: =IF(M41="","",(M41-M$10)*1000) -> -9.9 | AP41: =IF(N41="","",(N41-N$10)*1000) -> -4 | AQ41: =IF(O41="","",(O41-O$10)*1000) -> -6.0000001 | AR41: =IF(P41="","",(P41-P$10)*1000) -> -7.85 | AS41: =IF(Q41="","",(Q41-Q$10)*1000) -> -2.0499999 | AT41: =IF(R41="","",(R41-R$10)*1000) -> -0.34999987 | AU41: =IF(S41="","",(S41-S$10)*1000) -> -1.25 | AW41: 170.10393 | AX41: -2.6293434 | AY41: 1.4892407 | BC41: 170.43378 | BD41: 0.38603509 | BE41: 3.4219422 | BF41: 170.65808 | BG41: 1.1100841 | BH41: 2.7294992 | BI41: 170.39282 | BJ41: 2.636177 | BK41: 1.5917518 | BM41: =IF(AW41="","",(AW41-AW$10)*1000) -> -5.7722317 | BN41: =IF(AX41="","",(AX41-AX$10)*1000) -> -0.043384767 | BO41: =IF(AY41="","",(AY41-AY$10)*1000) -> -5.0592777 | BP41: =IF(AZ41="","",(AZ41-AZ$10)*1000) | BQ41: =IF(BA41="","",(BA41-BA$10)*1000) | BR41: =IF(BB41="","",(BB41-BB$10)*1000) | BS41: =IF(BC41="","",(BC41-BC$10)*1000) -> -5.4180444 | BT41: =IF(BD41="","",(BD41-BD$10)*1000) -> 1.9350881 | ... CA41: =IF(BK41="","",(BK41-BK$10)*1000) -> -1.2481614
