Workbook
Name cintre: 'Résultats observations'!$W$4
Name date: 'Résultats observations'!$A:$A
Name DH_BD: 'Résultats observations'!$DD:$DD
Name DH_BG: 'Résultats observations'!$CL:$CL
Name DH_HD: 'Résultats observations'!$CX:$CX
Name DH_HG: 'Résultats observations'!$CR:$CR
Name DH_ID: 'Résultats observations'!$DA:$DA
Name DH_IG: 'Résultats observations'!$CO:$CO
Name DHhaut: 'Résultats observations'!$CU:$CU
Name dist: 'Résultats observations'!$D:$D
Name DPM_BD: 'Résultats observations'!$DC:$DC
Name DPM_BG: 'Résultats observations'!$CK:$CK
Name DPM_HD: 'Résultats observations'!$CW:$CW
Name DPM_HG: 'Résultats observations'!$CQ:$CQ
Name DPM_ID: 'Résultats observations'!$CZ:$CZ
Name DPM_IG: 'Résultats observations'!$CN:$CN
Name DPMhaut: 'Résultats observations'!$CT:$CT
Name DZ_BD: 'Résultats observations'!$BM:$BM
Name DZ_BG: 'Résultats observations'!$AU:$AU
Name DZ_HD: 'Résultats observations'!$BG:$BG
Name DZ_HG: 'Résultats observations'!$BA:$BA
Name DZ_ID: 'Résultats observations'!$BJ:$BJ
Name DZ_IG: 'Résultats observations'!$AX:$AX
Name DZhaut: 'Résultats observations'!$BD:$BD
Name Ecart_BD: 'Résultats observations'!$AN:$AN
Name Ecart_BG: 'Résultats observations'!$AI:$AI
Name Ecart_HD: 'Résultats observations'!$AL:$AL
Name Ecart_HG: 'Résultats observations'!$AK:$AK
Name Ecart_ID: 'Résultats observations'!$AM:$AM
Name Ecart_IG: 'Résultats observations'!$AJ:$AJ
Name Ecart_LB: 'Résultats observations'!$AQ:$AQ
Name Ecart_LH: 'Résultats observations'!$AO:$AO
Name Ecart_LI: 'Résultats observations'!$AP:$AP
Name excav: 'Résultats observations'!$A$7
Name front: 'Résultats observations'!$C:$C
Name galerie: 'Résultats observations'!$G$4
Name jours: 'Résultats observations'!$B:$B
Name PM: 'Résultats observations'!$W$6
Name Xbasdroit: 'Résultats observations'!$W:$W
Name Xbasgauche: 'Résultats observations'!$E:$E
Name Xhaut: 'Résultats observations'!$N:$N
Name Xhautdroit: 'Résultats observations'!$Q:$Q
Name Xhautgauche: 'Résultats observations'!$K:$K
Name Xinterdroit: 'Résultats observations'!$T:$T
Name Xintergauche: 'Résultats observations'!$H:$H
Name Ybasdroit: 'Résultats observations'!$X:$X
Name Ybasgauche: 'Résultats observations'!$F:$F
Name Yhaut: 'Résultats observations'!$O:$O
Name Yhautdroit: 'Résultats observations'!$R:$R
Name Yhautgauche: 'Résultats observations'!$L:$L
Name Yinterdroit: 'Résultats observations'!$U:$U
Name Yintergauche: 'Résultats observations'!$I:$I
Name Zbasdroit: 'Résultats observations'!$Y:$Y
Name Zbasgauche: 'Résultats observations'!$G:$G
Name Zhaut: 'Résultats observations'!$P:$P
Name Zhautdroit: 'Résultats observations'!$S:$S
Name Zhautgauche: 'Résultats observations'!$M:$M
Name Zinterdroit: 'Résultats observations'!$V:$V
Name Zintergauche: 'Résultats observations'!$J:$J

Sheet Résultats observations
F1: ="CONVERGENCE GVA3 - PM" & PM -> CONVERGENCE GVA3 - PM183.9
A6: Date point 0 | V6: PM = | W6: 183.9
A7: =MIN(A10:A42) -> 43658
A8: Date | B8: Jours | C8: Front | D8: Dist | E8: Point bas gauche | H8: Point intermédiaire gauche | K8: Point haut gauche | N8: Point centre haut | Q8: Point haut droit | T8: Point intermédiaire droit | W8: Point bas droit | AI8: Différences | AS8: Point bas gauche | AV8: Point intermédiaire gauche | AY8: Point haut gauche | BB8: Point centre haut | BE8: Point haut droit | BH8: Point intermédiaire droit | BK8: Point bas droit | BO8: Point bas gauche | BR8: Point intermédiaire gauche | BU8: Point haut gauche | BX8: Point centre haut | CA8: Point haut droit | CD8: Point intermédiaire droit | CG8: Point bas droit | CK8: Point bas gauche | CN8: Point intermédiaire gauche | CQ8: Point haut gauche | CT8: Point centre haut | CW8: Point haut droit | CZ8: Point intermédiaire droit | DC8: Point bas droit
E9: X | F9: Y | G9: Z | K9: X | L9: Y | M9: Z | N9: X | O9: Y | P9: Z | Q9: X | R9: Y | S9: Z | W9: X | X9: Y | Y9: Z | Z9: BG | AA9: IG | AB9: HG | AC9: HD | AD9: ID | AE9: BD | AF9: LH | AG9: LI | AH9: LB | AI9: BG | AJ9: IG | AK9: HG | AL9: HD | AM9: ID | AN9: BD | AO9: LH | AP9: LI | AQ9: LB | AS9: DX | AT9: DY | AU9: DZ | AV9: DX | AW9: DY | AX9: DZ | AY9: DX | AZ9: DY | BA9: DZ | BB9: DX | BC9: DY | BD9: DZ | BE9: DX | BF9: DY | BG9: DZ | BH9: DX | BI9: DY | BJ9: DZ | BK9: DX | BL9: DY | BM9: DZ | BO9: PM | BP9: H | BQ9: V | BR9: PM | BS9: H | BT9: V | BU9: PM | BV9: H | BW9: V | BX9: PM | BY9: H | BZ9: V | CA9: PM | CB9: H | CC9: V | CD9: PM | CE9: H | CF9: V | CG9: PM | CH9: H | CI9: V | CK9: DPM | CL9: DH | CM9: DZ | CN9: DPM | CO9: DH | CP9: DZ | CQ9: DPM | CR9: DH | CS9: DZ | CT9: DPM | CU9: DH | CV9: DZ | CW9: DPM | CX9: DH | CY9: DZ | CZ9: DPM | DA9: DH | DB9: DZ | DC9: DPM | DD9: DH | DE9: DZ
A10: 43658 | B10: 0 | C10: 186.15 | D10: =C10-PM -> 2.25 | E10: 823233.32 | F10: 1091513.7 | G10: -124.6653 | H10: 823233.29 | I10: 1091513.7 | J10: -123.49155 | K10: 823233.48 | L10: 1091513.2 | M10: -121.8443 | N10: 823234.27 | O10: 1091511.5 | P10: -121.01705 | Q10: 823234.93 | R10: 1091510.1 | S10: -121.38905 | T10: 823235.53 | U10: 1091508.9 | V10: -123.5458 | W10: 823235.48 | X10: 1091509 | Y10: -124.6596 | Z10: =IF(Xhaut="","",SQRT(((Xbasgauche-Xhaut)^2+(Ybasgauche-Yhaut)^2)+(Zbasgauche-Zhaut)^2)) -> 4.3483666 | AA10: =IF(Xhaut="","",SQRT(((Xintergauche-Xhaut)^2+(Yintergauche-Yhaut)^2)+(Zintergauche-Zhaut)^2)) -> 3.4710529 | AB10: =IF(Xhaut="","",SQRT(((Xhautgauche-Xhaut)^2+(Yhautgauche-Yhaut)^2)+(Zhautgauche-Zhaut)^2)) -> 2.0101673 | AC10: =IF(Xhaut="","",SQRT(((Xhautdroit-Xhaut)^2+(Yhautdroit-Yhaut)^2)+(Zhautdroit-Zhaut)^2)) -> 1.5937504 | AD10: =IF(Xhaut="","",SQRT(((Xinterdroit-Xhaut)^2+(Yinterdroit-Yhaut)^2)+(Zinterdroit-Zhaut)^2)) -> 3.8358234 | AE10: =IF(Xhaut="","",SQRT(((Xbasdroit-Xhaut)^2+(Ybasdroit-Yhaut)^2)+(Zbasdroit-Zhaut)^2)) -> 4.5790216 | AF10: =IF(Xhautdroit="","",SQRT(((Xhautdroit-Xhautgauche)^2+(Yhautdroit-Yhautgauche)^2)+(Zhautdroit-Zhautgauche)^2)) -> 3.412247 | AG10: =IF(Xinterdroit="","",SQRT(((Xinterdroit-Xintergauche)^2+(Yinterdroit-Yintergauche)^2)+(Zinterdroit-Zintergauche)^2)) -> 5.3177807 | AH10: =IF(Xbasdroit="","",SQRT(((Xbasdroit-Xbasgauche)^2+(Ybasdroit-Ybasgauche)^2)+(Zbasdroit-Zbasgauche)^2)) -> 5.1399321 | AI10: 0 | AJ10: 0 | AK10: 0 | AL10: 0 | AM10: 0 | AN10: 0 | AO10: 0 | AP10: 0 | AQ10: 0 | AS10: 0 | AT10: 0 | AU10: 0 | AV10: 0 | AW10: 0 | AX10: 0 | AY10: 0 | AZ10: 0 | BA10: 0 | BB10: 0 | BC10: 0 | BD10: 0 | BE10: 0 | BF10: 0 | BG10: 0 | BH10: 0 | BI10: 0 | BJ10: 0 | BK10: 0 | BL10: 0 | BM10: 0 | BO10: 183.97075 | BP10: -2.5602276 | BQ10: -0.96212747 | BR10: 183.96634 | BS10: -2.6283775 | BT10: 0.21161662 | BU10: 183.89824 | BV10: -2.0266725 | BW10: 1.8595976 | BX10: 183.91548 | BY10: -0.19471889 | BZ10: 2.6866252 | CA10: 183.91459 | CB10: 1.3550298 | CC10: 2.3146341 | CD10: 183.96187 | CE10: 2.6891246 | CF10: 0.15746134 | CG10: 183.95807 | CH10: 2.5796647 | CI10: -0.95630074 | CK10: 0 | CL10: 0 | CM10: 0 | CN10: 0 | CO10: 0 | CP10: 0 | CQ10: 0 | CR10: 0 | CS10: 0 | CT10: 0 | CU10: 0 | CV10: 0 | CW10: 0 | CX10: 0 | CY10: 0 | CZ10: 0 | DA10: 0 | DB10: 0 | DC10: 0 | DD10: 0 | DE10: 0
A11: 43661 | B11: =A11-A$10 -> 3 | C11: 186.15 | D11: =C11-PM -> 2.25 | E11: 823233.33 | F11: 1091513.7 | G11: -124.66473 | H11: 823233.29 | I11: 1091513.7 | J11: -123.4911 | K11: 823233.49 | L11: 1091513.2 | M11: -121.8443 | N11: 823234.27 | O11: 1091511.5 | P11: -121.0207 | Q11: 823234.93 | R11: 1091510.1 | S11: -121.3897 | T11: 823235.54 | U11: 1091508.9 | V11: -123.5458 | W11: 823235.49 | X11: 1091509 | Y11: -124.6593 | Z11: =IF(Xhaut="","",SQRT(((Xbasgauche-Xhaut)^2+(Ybasgauche-Yhaut)^2)+(Zbasgauche-Zhaut)^2)) -> 4.3449805 | AA11: =IF(Xhaut="","",SQRT(((Xintergauche-Xhaut)^2+(Yintergauche-Yhaut)^2)+(Zintergauche-Zhaut)^2)) -> 3.4677648 | AB11: =IF(Xhaut="","",SQRT(((Xhautgauche-Xhaut)^2+(Yhautgauche-Yhaut)^2)+(Zhautgauche-Zhaut)^2)) -> 2.007926 | AC11: =IF(Xhaut="","",SQRT(((Xhautdroit-Xhaut)^2+(Yhautdroit-Yhaut)^2)+(Zhautdroit-Zhaut)^2)) -> 1.5929671 | AD11: =IF(Xhaut="","",SQRT(((Xinterdroit-Xhaut)^2+(Yinterdroit-Yhaut)^2)+(Zinterdroit-Zhaut)^2)) -> 3.8327772 | AE11: =IF(Xhaut="","",SQRT(((Xbasdroit-Xhaut)^2+(Ybasdroit-Yhaut)^2)+(Zbasdroit-Zhaut)^2)) -> 4.5755456 | AF11: =IF(Xhautdroit="","",SQRT(((Xhautdroit-Xhautgauche)^2+(Yhautdroit-Yhautgauche)^2)+(Zhautdroit-Zhautgauche)^2)) -> 3.4112741 | AG11: =IF(Xinterdroit="","",SQRT(((Xinterdroit-Xintergauche)^2+(Yinterdroit-Yintergauche)^2)+(Zinterdroit-Zintergauche)^2)) -> 5.3164021 | AH11: =IF(Xbasdroit="","",SQRT(((Xbasdroit-Xbasgauche)^2+(Ybasdroit-Ybasgauche)^2)+(Zbasdroit-Zbasgauche)^2)) -> 5.1396032 | AI11: =IF(Z11="","",(Z11-Z$10)*1000) -> -3.3861599 | AJ11: =IF(AA11="","",(AA11-AA$10)*1000) -> -3.2880462 | AK11: =IF(AB11="","",(AB11-AB$10)*1000) -> -2.2412708 | AL11: =IF(AC11="","",(AC11-AC$10)*1000) -> -0.78323331 | AM11: =IF(AD11="","",(AD11-AD$10)*1000) -> -3.0461928 | AN11: =IF(AE11="","",(AE11-AE$10)*1000) -> -3.4759716 | AO11: =IF(AF11="","",(AF11-AF$10)*1000) -> -0.97288839 | AP11: =IF(AG11="","",(AG11-AG$10)*1000) -> -1.3786151 | AQ11: =IF(AH11="","",(AH11-AH$10)*1000) -> -0.32889741 | AS11: =IF(E11="","",(E11-E$10)*1000) -> 2.35 | AT11: =IF(F11="","",(F11-F$10)*1000) -> 1.0499998 | AU11: =IF(G11="","",(G11-G$10)*1000) -> 0.56666667 | AV11: =IF(H11="","",(H11-H$10)*1000) -> 1.6000001 | AW11: =IF(I11="","",(I11-I$10)*1000) -> -0.15000021 | AX11: =IF(J11="","",(J11-J$10)*1000) -> 0.45 | AY11: =IF(K11="","",(K11-K$10)*1000) -> 2.1500001 | AZ11: =IF(L11="","",(L11-L$10)*1000) -> -0.20000013 | ... BM11: =IF(Y11="","",(Y11-Y$10)*1000) -> 0.3 | BO11: 183.97325 | BP11: -2.5601618 | BQ11: -0.96158588 | BR11: 183.9677 | BS11: -2.62752 | BT11: 0.21210297 | BU11: 183.90006 | BV11: -2.0256036 | BW11: 1.8595794 | BX11: 183.91656 | BY11: -0.19443523 | BZ11: 2.6830144 | CA11: 183.91639 | CB11: 1.3552045 | CC11: 2.3140161 | CD11: 183.9631 | CE11: 2.6885987 | CF11: 0.15744896 | CG11: 183.96039 | CH11: 2.5794224 | CI11: -0.95602393 | CK11: =IF(BO11="","",(BO11-BO$10)*1000) -> 2.5071236 | CL11: =IF(BP11="","",(BP11-BP$10)*1000) -> 0.065807869 | CM11: =IF(BQ11="","",(BQ11-BQ$10)*1000) -> 0.54159543 | CN11: =IF(BR11="","",(BR11-BR$10)*1000) -> 1.3655368 | CO11: =IF(BS11="","",(BS11-BS$10)*1000) -> 0.85750172 | CP11: =IF(BT11="","",(BT11-BT$10)*1000) -> 0.48634463 | CQ11: =IF(BU11="","",(BU11-BU$10)*1000) -> 1.818683 | CR11: =IF(BV11="","",(BV11-BV$10)*1000) -> 1.0688276 | ... DE11: =IF(CI11="","",(CI11-CI$10)*1000) -> 0.27680233
A12: 43662 | B12: =A12-A$10 -> 4 | C12: 187.2 | D12: =C12-PM -> 3.3 | E12: 823233.33 | F12: 1091513.7 | G12: -124.6642 | H12: 823233.29 | I12: 1091513.7 | J12: -123.4904 | K12: 823233.49 | L12: 1091513.2 | M12: -121.8442 | N12: 823234.27 | O12: 1091511.5 | P12: -121.0236 | Q12: 823234.93 | R12: 1091510.1 | S12: -121.3913 | T12: 823235.54 | U12: 1091508.9 | V12: -123.545 | W12: 823235.49 | X12: 1091509 | Y12: -124.6587 | Z12: =IF(Xhaut="","",SQRT(((Xbasgauche-Xhaut)^2+(Ybasgauche-Yhaut)^2)+(Zbasgauche-Zhaut)^2)) -> 4.3420796 | AA12: =IF(Xhaut="","",SQRT(((Xintergauche-Xhaut)^2+(Yintergauche-Yhaut)^2)+(Zintergauche-Zhaut)^2)) -> 3.4656532 | AB12: =IF(Xhaut="","",SQRT(((Xhautgauche-Xhaut)^2+(Yhautgauche-Yhaut)^2)+(Zhautgauche-Zhaut)^2)) -> 2.0070343 | AC12: =IF(Xhaut="","",SQRT(((Xhautdroit-Xhaut)^2+(Yhautdroit-Yhaut)^2)+(Zhautdroit-Zhaut)^2)) -> 1.5920141 | AD12: =IF(Xhaut="","",SQRT(((Xinterdroit-Xhaut)^2+(Yinterdroit-Yhaut)^2)+(Zinterdroit-Zhaut)^2)) -> 3.8290527 | AE12: =IF(Xhaut="","",SQRT(((Xbasdroit-Xhaut)^2+(Ybasdroit-Yhaut)^2)+(Zbasdroit-Zhaut)^2)) -> 4.5717059 | AF12: =IF(Xhautdroit="","",SQRT(((Xhautdroit-Xhautgauche)^2+(Yhautdroit-Yhautgauche)^2)+(Zhautdroit-Zhautgauche)^2)) -> 3.4107518 | AG12: =IF(Xinterdroit="","",SQRT(((Xinterdroit-Xintergauche)^2+(Yinterdroit-Yintergauche)^2)+(Zinterdroit-Zintergauche)^2)) -> 5.3152898 | AH12: =IF(Xbasdroit="","",SQRT(((Xbasdroit-Xbasgauche)^2+(Ybasdroit-Ybasgauche)^2)+(Zbasdroit-Zbasgauche)^2)) -> 5.1378219 | AI12: =IF(Z12="","",(Z12-Z$10)*1000) -> -6.2870566 | AJ12: =IF(AA12="","",(AA12-AA$10)*1000) -> -5.3996684 | AK12: =IF(AB12="","",(AB12-AB$10)*1000) -> -3.1329559 | AL12: =IF(AC12="","",(AC12-AC$10)*1000) -> -1.7363126 | AM12: =IF(AD12="","",(AD12-AD$10)*1000) -> -6.7706987 | AN12: =IF(AE12="","",(AE12-AE$10)*1000) -> -7.3156899 | AO12: =IF(AF12="","",(AF12-AF$10)*1000) -> -1.4952318 | AP12: =IF(AG12="","",(AG12-AG$10)*1000) -> -2.4908775 | AQ12: =IF(AH12="","",(AH12-AH$10)*1000) -> -2.1102207 | AS12: =IF(E12="","",(E12-E$10)*1000) -> 2.05 | AT12: =IF(F12="","",(F12-F$10)*1000) -> 1.1500001 | AU12: =IF(G12="","",(G12-G$10)*1000) -> 1.1 | AV12: =IF(H12="","",(H12-H$10)*1000) -> 2.1 | AW12: =IF(I12="","",(I12-I$10)*1000) -> 1.0499998 | AX12: =IF(J12="","",(J12-J$10)*1000) -> 1.15 | AY12: =IF(K12="","",(K12-K$10)*1000) -> 2.1500001 | AZ12: =IF(L12="","",(L12-L$10)*1000) -> 0.49999985 | ... BM12: =IF(Y12="","",(Y12-Y$10)*1000) -> 0.9 | BO12: 183.97302 | BP12: -2.5603793 | BQ12: -0.96105025 | BR12: 183.96866 | BS12: -2.6283962 | BT12: 0.21279337 | BU12: 183.90036 | BV12: -2.026238 | BW12: 1.8596764 | BX12: 183.91624 | BY12: -0.19469492 | BZ12: 2.6801176 | CA12: 183.91605 | CB12: 1.3542742 | CC12: 2.3124195 | CD12: 183.96381 | CE12: 2.686611 | CF12: 0.1582419 | CG12: 183.95989 | CH12: 2.5774229 | CI12: -0.95541891 | CK12: =IF(BO12="","",(BO12-BO$10)*1000) -> 2.2775014 | CL12: =IF(BP12="","",(BP12-BP$10)*1000) -> -0.15161719 | CM12: =IF(BQ12="","",(BQ12-BQ$10)*1000) -> 1.077225 | CN12: =IF(BR12="","",(BR12-BR$10)*1000) -> 2.3258652 | CO12: =IF(BS12="","",(BS12-BS$10)*1000) -> -0.018722797 | CP12: =IF(BT12="","",(BT12-BT$10)*1000) -> 1.1767413 | CQ12: =IF(BU12="","",(BU12-BU$10)*1000) -> 2.1145394 | CR12: =IF(BV12="","",(BV12-BV$10)*1000) -> 0.43442314 | ... DE12: =IF(CI12="","",(CI12-CI$10)*1000) -> 0.8818217
A13: 43663 | B13: =A13-A$10 -> 5 | C13: 188.17 | D13: =C13-PM -> 4.27 | E13: 823233.33 | F13: 1091513.7 | G13: -124.6637 | H13: 823233.3 | I13: 1091513.7 | J13: -123.4902 | K13: 823233.49 | L13: 1091513.2 | M13: -121.8442 | N13: 823234.27 | O13: 1091511.5 | P13: -121.0273 | Q13: 823234.93 | R13: 1091510.1 | S13: -121.3932 | T13: 823235.54 | U13: 1091508.9 | V13: -123.5448 | W13: 823235.49 | X13: 1091509 | Y13: -124.6585 | Z13: =IF(Xhaut="","",SQRT(((Xbasgauche-Xhaut)^2+(Ybasgauche-Yhaut)^2)+(Zbasgauche-Zhaut)^2)) -> 4.3384436 | AA13: =IF(Xhaut="","",SQRT(((Xintergauche-Xhaut)^2+(Yintergauche-Yhaut)^2)+(Zintergauche-Zhaut)^2)) -> 3.4625541 | AB13: =IF(Xhaut="","",SQRT(((Xhautgauche-Xhaut)^2+(Yhautgauche-Yhaut)^2)+(Zhautgauche-Zhaut)^2)) -> 2.0051 | AC13: =IF(Xhaut="","",SQRT(((Xhautdroit-Xhaut)^2+(Yhautdroit-Yhaut)^2)+(Zhautdroit-Zhaut)^2)) -> 1.5909289 | AD13: =IF(Xhaut="","",SQRT(((Xinterdroit-Xhaut)^2+(Yinterdroit-Yhaut)^2)+(Zinterdroit-Zhaut)^2)) -> 3.8257338 | AE13: =IF(Xhaut="","",SQRT(((Xbasdroit-Xhaut)^2+(Ybasdroit-Yhaut)^2)+(Zbasdroit-Zhaut)^2)) -> 4.5679194 | AF13: =IF(Xhautdroit="","",SQRT(((Xhautdroit-Xhautgauche)^2+(Yhautdroit-Yhautgauche)^2)+(Zhautdroit-Zhautgauche)^2)) -> 3.4093649 | AG13: =IF(Xinterdroit="","",SQRT(((Xinterdroit-Xintergauche)^2+(Yinterdroit-Yintergauche)^2)+(Zinterdroit-Zintergauche)^2)) -> 5.3137738 | AH13: =IF(Xbasdroit="","",SQRT(((Xbasdroit-Xbasgauche)^2+(Ybasdroit-Ybasgauche)^2)+(Zbasdroit-Zbasgauche)^2)) -> 5.1364166 | AI13: =IF(Z13="","",(Z13-Z$10)*1000) -> -9.9229838 | AJ13: =IF(AA13="","",(AA13-AA$10)*1000) -> -8.4988296 | AK13: =IF(AB13="","",(AB13-AB$10)*1000) -> -5.0672581 | AL13: =IF(AC13="","",(AC13-AC$10)*1000) -> -2.8214405 | AM13: =IF(AD13="","",(AD13-AD$10)*1000) -> -10.089534 | AN13: =IF(AE13="","",(AE13-AE$10)*1000) -> -11.102122 | AO13: =IF(AF13="","",(AF13-AF$10)*1000) -> -2.8821026 | AP13: =IF(AG13="","",(AG13-AG$10)*1000) -> -4.0069347 | AQ13: =IF(AH13="","",(AH13-AH$10)*1000) -> -3.5155551 | AS13: =IF(E13="","",(E13-E$10)*1000) -> 4.45 | AT13: =IF(F13="","",(F13-F$10)*1000) -> -1.1499999 | AU13: =IF(G13="","",(G13-G$10)*1000) -> 1.6 | AV13: =IF(H13="","",(H13-H$10)*1000) -> 4.2000001 | AW13: =IF(I13="","",(I13-I$10)*1000) -> -1.6500002 | AX13: =IF(J13="","",(J13-J$10)*1000) -> 1.35 | AY13: =IF(K13="","",(K13-K$10)*1000) -> 4.1500001 | AZ13: =IF(L13="","",(L13-L$10)*1000) -> -2.2000002 | ... BM13: =IF(Y13="","",(Y13-Y$10)*1000) -> 1.1 | BO13: 183.97423 | BP13: -2.5572804 | BQ13: -0.96056228 | BR13: 183.96943 | BS13: -2.6250617 | BT13: 0.21298575 | BU13: 183.90103 | BV13: -2.0229458 | BW13: 1.8596697 | BX13: 183.91547 | BY13: -0.19185535 | BZ13: 2.6764253 | CA13: 183.91593 | CB13: 1.3564249 | CC13: 2.3105207 | CD13: 183.9644 | CE13: 2.6884292 | CF13: 0.15843603 | CG13: 183.96021 | CH13: 2.5791144 | CI13: -0.95522206 | CK13: =IF(BO13="","",(BO13-BO$10)*1000) -> 3.4805027 | CL13: =IF(BP13="","",(BP13-BP$10)*1000) -> 2.9472194 | CM13: =IF(BQ13="","",(BQ13-BQ$10)*1000) -> 1.565195 | CN13: =IF(BR13="","",(BR13-BR$10)*1000) -> 3.0879181 | CO13: =IF(BS13="","",(BS13-BS$10)*1000) -> 3.315835 | CP13: =IF(BT13="","",(BT13-BT$10)*1000) -> 1.3691208 | CQ13: =IF(BU13="","",(BU13-BU$10)*1000) -> 2.785963 | CR13: =IF(BV13="","",(BV13-BV$10)*1000) -> 3.7267157 | ... DE13: =IF(CI13="","",(CI13-CI$10)*1000) -> 1.0786759
A14: 43669 | B14: =A14-A$10 -> 11 | C14: 189.23 | D14: =C14-PM -> 5.33 | E14: 823233.33 | F14: 1091513.7 | G14: -124.6607 | H14: 823233.29 | I14: 1091513.7 | J14: -123.4875 | K14: 823233.49 | L14: 1091513.2 | M14: -121.8411 | N14: 823234.27 | O14: 1091511.5 | P14: -121.0354 | Q14: 823234.93 | R14: 1091510.1 | S14: -121.3966 | T14: 823235.53 | U14: 1091508.9 | V14: -123.5422 | W14: 823235.5 | X14: 1091509 | Y14: -124.6898 | Z14: =IF(Xhaut="","",SQRT(((Xbasgauche-Xhaut)^2+(Ybasgauche-Yhaut)^2)+(Zbasgauche-Zhaut)^2)) -> 4.3285723 | AA14: =IF(Xhaut="","",SQRT(((Xintergauche-Xhaut)^2+(Yintergauche-Yhaut)^2)+(Zintergauche-Zhaut)^2)) -> 3.4541849 | AB14: =IF(Xhaut="","",SQRT(((Xhautgauche-Xhaut)^2+(Yhautgauche-Yhaut)^2)+(Zhautgauche-Zhaut)^2)) -> 2.0010568 | AC14: =IF(Xhaut="","",SQRT(((Xhautdroit-Xhaut)^2+(Yhautdroit-Yhaut)^2)+(Zhautdroit-Zhaut)^2)) -> 1.5884143 | AD14: =IF(Xhaut="","",SQRT(((Xinterdroit-Xhaut)^2+(Yinterdroit-Yhaut)^2)+(Zinterdroit-Zhaut)^2)) -> 3.8159156 | AE14: =IF(Xhaut="","",SQRT(((Xbasdroit-Xhaut)^2+(Ybasdroit-Yhaut)^2)+(Zbasdroit-Zhaut)^2)) -> 4.5859806 | AF14: =IF(Xhautdroit="","",SQRT(((Xhautdroit-Xhautgauche)^2+(Yhautdroit-Yhautgauche)^2)+(Zhautdroit-Zhautgauche)^2)) -> 3.4075925 | AG14: =IF(Xinterdroit="","",SQRT(((Xinterdroit-Xintergauche)^2+(Yinterdroit-Yintergauche)^2)+(Zinterdroit-Zintergauche)^2)) -> 5.3090075 | AH14: =IF(Xbasdroit="","",SQRT(((Xbasdroit-Xbasgauche)^2+(Ybasdroit-Ybasgauche)^2)+(Zbasdroit-Zbasgauche)^2)) -> 5.1344317 | AI14: =IF(Z14="","",(Z14-Z$10)*1000) -> -19.794294 | AJ14: =IF(AA14="","",(AA14-AA$10)*1000) -> -16.86797 | AK14: =IF(AB14="","",(AB14-AB$10)*1000) -> -9.1104497 | AL14: =IF(AC14="","",(AC14-AC$10)*1000) -> -5.3360982 | AM14: =IF(AD14="","",(AD14-AD$10)*1000) -> -19.907795 | AO14: =IF(AF14="","",(AF14-AF$10)*1000) -> -4.6545208 | AP14: =IF(AG14="","",(AG14-AG$10)*1000) -> -8.7731819 | AQ14: =IF(AH14="","",(AH14-AH$10)*1000) -> -5.5004711 | AS14: =IF(E14="","",(E14-E$10)*1000) -> 3.15 | AT14: =IF(F14="","",(F14-F$10)*1000) -> -3.15 | AU14: =IF(G14="","",(G14-G$10)*1000) -> 4.6 | AV14: =IF(H14="","",(H14-H$10)*1000) -> 3.2000002 | AW14: =IF(I14="","",(I14-I$10)*1000) -> -3.4500002 | AX14: =IF(J14="","",(J14-J$10)*1000) -> 4.05 | AY14: =IF(K14="","",(K14-K$10)*1000) -> 3.0500001 | AZ14: =IF(L14="","",(L14-L$10)*1000) -> -2.3000003 | ... BM14: =IF(Y14="","",(Y14-Y$10)*1000) -> -30.2 | BO14: 183.9722 | BP14: -2.5560173 | BQ14: -0.95754204 | BR14: 183.96776 | BS14: -2.623853 | BT14: 0.21570242 | BU14: 183.89999 | BV14: -2.02332 | BW14: 1.8627801 | BX14: 183.91207 | BY14: -0.19167324 | BZ14: 2.6683593 | CA14: 183.91433 | CB14: 1.3551265 | CC14: 2.3071367 | CD14: 183.96363 | CE14: 2.6848711 | CF14: 0.16104372 | CG14: 183.97249 | CH14: 2.5783319 | CI14: -0.98664488 | CK14: =IF(BO14="","",(BO14-BO$10)*1000) -> 1.4570189 | CL14: =IF(BP14="","",(BP14-BP$10)*1000) -> 4.210356 | CM14: =IF(BQ14="","",(BQ14-BQ$10)*1000) -> 4.5854298 | CN14: =IF(BR14="","",(BR14-BR$10)*1000) -> 1.4208525 | CO14: =IF(BS14="","",(BS14-BS$10)*1000) -> 4.5245087 | CP14: =IF(BT14="","",(BT14-BT$10)*1000) -> 4.0857915 | CQ14: =IF(BU14="","",(BU14-BU$10)*1000) -> 1.7467765 | CR14: =IF(BV14="","",(BV14-BV$10)*1000) -> 3.3524278 | ... DE14: =IF(CI14="","",(CI14-CI$10)*1000) -> -30.34414
A15: 43675 | B15: =A15-A$10 -> 17 | C15: 191.5 | D15: =C15-PM -> 7.6 | E15: 823233.33 | F15: 1091513.7 | G15: -124.6634 | H15: 823233.29 | I15: 1091513.7 | J15: -123.4904 | N15: 823234.27 | O15: 1091511.5 | P15: -121.0494 | Q15: 823234.92 | R15: 1091510.1 | S15: -121.4039 | T15: 823235.53 | U15: 1091508.9 | V15: -123.545 | W15: 823235.49 | X15: 1091509 | Y15: -124.6923 | Z15: =IF(Xhaut="","",SQRT(((Xbasgauche-Xhaut)^2+(Ybasgauche-Yhaut)^2)+(Zbasgauche-Zhaut)^2)) -> 4.3186669 | AA15: =IF(Xhaut="","",SQRT(((Xintergauche-Xhaut)^2+(Yintergauche-Yhaut)^2)+(Zintergauche-Zhaut)^2)) -> 3.4458724 | AC15: =IF(Xhaut="","",SQRT(((Xhautdroit-Xhaut)^2+(Yhautdroit-Yhaut)^2)+(Zhautdroit-Zhaut)^2)) -> 1.5849514 | AD15: =IF(Xhaut="","",SQRT(((Xinterdroit-Xhaut)^2+(Yinterdroit-Yhaut)^2)+(Zinterdroit-Zhaut)^2)) -> 3.8062833 | AE15: =IF(Xhaut="","",SQRT(((Xbasdroit-Xhaut)^2+(Ybasdroit-Yhaut)^2)+(Zbasdroit-Zhaut)^2)) -> 4.5748646 | AG15: =IF(Xinterdroit="","",SQRT(((Xinterdroit-Xintergauche)^2+(Yinterdroit-Yintergauche)^2)+(Zinterdroit-Zintergauche)^2)) -> 5.3052366 | AH15: =IF(Xbasdroit="","",SQRT(((Xbasdroit-Xbasgauche)^2+(Ybasdroit-Ybasgauche)^2)+(Zbasdroit-Zbasgauche)^2)) -> 5.130256 | AI15: =IF(Z15="","",(Z15-Z$10)*1000) -> -29.699712 | AJ15: =IF(AA15="","",(AA15-AA$10)*1000) -> -25.180447 | AK15: =IF(AB15="","",(AB15-AB$10)*1000) | AL15: =IF(AC15="","",(AC15-AC$10)*1000) -> -8.7989674 | AM15: =IF(AD15="","",(AD15-AD$10)*1000) -> -29.540049 | AN15: =IF(AE15="","",(AE15-AE$10)*1000) -> -4.1570055 | AO15: =IF(AF15="","",(AF15-AF$10)*1000) | AP15: =IF(AG15="","",(AG15-AG$10)*1000) -> -12.544164 | AQ15: =IF(AH15="","",(AH15-AH$10)*1000) -> -9.6760964 | AS15: =IF(E15="","",(E15-E$10)*1000) -> 1.65 | AT15: =IF(F15="","",(F15-F$10)*1000) -> -4.0499999 | AU15: =IF(G15="","",(G15-G$10)*1000) -> 1.9 | AV15: =IF(H15="","",(H15-H$10)*1000) -> 1.9000001 | AW15: =IF(I15="","",(I15-I$10)*1000) -> -4.0500001 | AX15: =IF(J15="","",(J15-J$10)*1000) -> 1.15 | AY15: =IF(K15="","",(K15-K$10)*1000) | AZ15: =IF(L15="","",(L15-L$10)*1000) | ... BM15: =IF(Y15="","",(Y15-Y$10)*1000) -> -32.7 | BO15: 183.97046 | BP15: -2.5558356 | BQ15: -0.96022464 | BR15: 183.96633 | BS15: -2.6238587 | BT15: 0.21281673 | BU15: - | BV15: - | BW15: - | BX15: 183.90798 | BY15: -0.19236692 | BZ15: 2.6544002 | CA15: 183.91161 | CB15: 1.3524268 | CC15: 2.2998639 | CD15: 183.96263 | CE15: 2.6810956 | CF15: 0.15825369 | CG15: 183.97126 | CH15: 2.574339 | CI15: -0.9891326 | CK15: =IF(BO15="","",(BO15-BO$10)*1000) -> -0.2828059 | CL15: =IF(BP15="","",(BP15-BP$10)*1000) -> 4.3920407 | CM15: =IF(BQ15="","",(BQ15-BQ$10)*1000) -> 1.9028281 | CN15: =IF(BR15="","",(BR15-BR$10)*1000) -> -0.010918327 | CO15: =IF(BS15="","",(BS15-BS$10)*1000) -> 4.5188363 | CP15: =IF(BT15="","",(BT15-BT$10)*1000) -> 1.2001092 | CT15: =IF(BX15="","",(BX15-BX$10)*1000) -> -7.4965495 | CU15: =IF(BY15="","",(BY15-BY$10)*1000) -> 2.3519663 | CV15: =IF(BZ15="","",(BZ15-BZ$10)*1000) -> -32.225035 | CW15: =IF(CA15="","",(CA15-CA$10)*1000) -> -2.9789926 | CX15: =IF(CB15="","",(CB15-CB$10)*1000) -> -2.6029989 | CY15: =IF(CC15="","",(CC15-CC$10)*1000) -> -14.77021 | CZ15: =IF(CD15="","",(CD15-CD$10)*1000) -> 0.76516664 | DA15: =IF(CE15="","",(CE15-CE$10)*1000) -> -8.0289799 | ... DE15: =IF(CI15="","",(CI15-CI$10)*1000) -> -32.831866
A16: 43679 | B16: =A16-A$10 -> 21 | C16: 193.04 | D16: =C16-PM -> 9.14 | E16: 823233.32 | F16: 1091513.7 | G16: -124.6651 | H16: 823233.29 | I16: 1091513.7 | J16: -123.492 | K16: 823233.48 | L16: 1091513.2 | M16: -121.8505 | N16: 823234.26 | O16: 1091511.5 | P16: -121.0574 | Q16: 823234.92 | R16: 1091510.1 | S16: -121.4074 | T16: 823235.53 | U16: 1091508.9 | V16: -123.5465 | W16: 823235.49 | X16: 1091509 | Y16: -124.6939 | Z16: =IF(Xhaut="","",SQRT(((Xbasgauche-Xhaut)^2+(Ybasgauche-Yhaut)^2)+(Zbasgauche-Zhaut)^2)) -> 4.3145947 | AA16: =IF(Xhaut="","",SQRT(((Xintergauche-Xhaut)^2+(Yintergauche-Yhaut)^2)+(Zintergauche-Zhaut)^2)) -> 3.4428642 | AB16: =IF(Xhaut="","",SQRT(((Xhautgauche-Xhaut)^2+(Yhautgauche-Yhaut)^2)+(Zhautgauche-Zhaut)^2)) -> 1.994524 | AC16: =IF(Xhaut="","",SQRT(((Xhautdroit-Xhaut)^2+(Yhautdroit-Yhaut)^2)+(Zhautdroit-Zhaut)^2)) -> 1.5808616 | AD16: =IF(Xhaut="","",SQRT(((Xinterdroit-Xhaut)^2+(Yinterdroit-Yhaut)^2)+(Zinterdroit-Zhaut)^2)) -> 3.7993756 | AE16: =IF(Xhaut="","",SQRT(((Xbasdroit-Xhaut)^2+(Ybasdroit-Yhaut)^2)+(Zbasdroit-Zhaut)^2)) -> 4.5679237 | AF16: =IF(Xhautdroit="","",SQRT(((Xhautdroit-Xhautgauche)^2+(Yhautdroit-Yhautgauche)^2)+(Zhautdroit-Zhautgauche)^2)) -> 3.400678 | AG16: =IF(Xinterdroit="","",SQRT(((Xinterdroit-Xintergauche)^2+(Yinterdroit-Yintergauche)^2)+(Zinterdroit-Zintergauche)^2)) -> 5.3037976 | AH16: =IF(Xbasdroit="","",SQRT(((Xbasdroit-Xbasgauche)^2+(Ybasdroit-Ybasgauche)^2)+(Zbasdroit-Zbasgauche)^2)) -> 5.129301 | AI16: =IF(Z16="","",(Z16-Z$10)*1000) -> -33.771906 | AJ16: =IF(AA16="","",(AA16-AA$10)*1000) -> -28.188658 | AK16: =IF(AB16="","",(AB16-AB$10)*1000) -> -15.643332 | AL16: =IF(AC16="","",(AC16-AC$10)*1000) -> -12.888754 | AM16: =IF(AD16="","",(AD16-AD$10)*1000) -> -36.447722 | AN16: =IF(AE16="","",(AE16-AE$10)*1000) -> -11.097913 | AO16: =IF(AF16="","",(AF16-AF$10)*1000) -> -11.569012 | AP16: =IF(AG16="","",(AG16-AG$10)*1000) -> -13.983141 | AQ16: =IF(AH16="","",(AH16-AH$10)*1000) -> -10.631183 | AS16: =IF(E16="","",(E16-E$10)*1000) -> -1.35 | AT16: =IF(F16="","",(F16-F$10)*1000) -> 2.1500001 | AU16: =IF(G16="","",(G16-G$10)*1000) -> 0.2 | AV16: =IF(H16="","",(H16-H$10)*1000) -> -0.79999992 | AW16: =IF(I16="","",(I16-I$10)*1000) -> 2.2499999 | AX16: =IF(J16="","",(J16-J$10)*1000) -> -0.45 | AY16: =IF(K16="","",(K16-K$10)*1000) -> -2.55 | AZ16: =IF(L16="","",(L16-L$10)*1000) -> -0.70000021 | ... BM16: =IF(Y16="","",(Y16-Y$10)*1000) -> -34.3 | BO16: 183.97028 | BP16: -2.5625413 | BQ16: -0.96192281 | BR16: 183.96637 | BS16: -2.630347 | BT16: 0.21121627 | BU16: 183.89547 | BV16: -2.0268651 | BW16: 1.8534253 | BX16: 183.90646 | BY16: -0.19738075 | BZ16: 2.6464154 | CA16: 183.91153 | CB16: 1.3443315 | CC16: 2.2963647 | CD16: 183.96286 | CE16: 2.6732601 | CF16: 0.15675136 | CG16: 183.97172 | CH16: 2.5664974 | CI16: -0.99073717 | CK16: =IF(BO16="","",(BO16-BO$10)*1000) -> -0.46577964 | CL16: =IF(BP16="","",(BP16-BP$10)*1000) -> -2.313668 | CM16: =IF(BQ16="","",(BQ16-BQ$10)*1000) -> 0.2046578 | CN16: =IF(BR16="","",(BR16-BR$10)*1000) -> 0.035744102 | CO16: =IF(BS16="","",(BS16-BS$10)*1000) -> -1.9694474 | CP16: =IF(BT16="","",(BT16-BT$10)*1000) -> -0.40035744 | CQ16: =IF(BU16="","",(BU16-BU$10)*1000) -> -2.7789855 | CR16: =IF(BV16="","",(BV16-BV$10)*1000) -> -0.19260301 | ... DE16: =IF(CI16="","",(CI16-CI$10)*1000) -> -34.436437
A17: 43682 | B17: =A17-A$10 -> 24 | C17: 193.04 | D17: =C17-PM -> 9.14 | E17: 823233.32 | F17: 1091513.7 | G17: -124.6643 | H17: 823233.29 | I17: 1091513.7 | J17: -123.4912 | K17: 823233.48 | L17: 1091513.2 | M17: -121.8502 | N17: 823234.26 | O17: 1091511.5 | P17: -121.0605 | Q17: 823234.92 | R17: 1091510.1 | S17: -121.4077 | T17: 823235.53 | U17: 1091508.9 | V17: -123.5456 | W17: 823235.49 | X17: 1091509 | Y17: -124.6929 | Z17: =IF(Xhaut="","",SQRT(((Xbasgauche-Xhaut)^2+(Ybasgauche-Yhaut)^2)+(Zbasgauche-Zhaut)^2)) -> 4.3110722 | AA17: =IF(Xhaut="","",SQRT(((Xintergauche-Xhaut)^2+(Yintergauche-Yhaut)^2)+(Zintergauche-Zhaut)^2)) -> 3.4396582 | AB17: =IF(Xhaut="","",SQRT(((Xhautgauche-Xhaut)^2+(Yhautgauche-Yhaut)^2)+(Zhautgauche-Zhaut)^2)) -> 1.9927817 | AC17: =IF(Xhaut="","",SQRT(((Xhautdroit-Xhaut)^2+(Yhautdroit-Yhaut)^2)+(Zhautdroit-Zhaut)^2)) -> 1.5785052 | AD17: =IF(Xhaut="","",SQRT(((Xinterdroit-Xhaut)^2+(Yinterdroit-Yhaut)^2)+(Zinterdroit-Zhaut)^2)) -> 3.7961406 | AE17: =IF(Xhaut="","",SQRT(((Xbasdroit-Xhaut)^2+(Ybasdroit-Yhaut)^2)+(Zbasdroit-Zhaut)^2)) -> 4.5639264 | AF17: =IF(Xhautdroit="","",SQRT(((Xhautdroit-Xhautgauche)^2+(Yhautdroit-Yhautgauche)^2)+(Zhautdroit-Zhautgauche)^2)) -> 3.3984108 | AG17: =IF(Xinterdroit="","",SQRT(((Xinterdroit-Xintergauche)^2+(Yinterdroit-Yintergauche)^2)+(Zinterdroit-Zintergauche)^2)) -> 5.302304 | AH17: =IF(Xbasdroit="","",SQRT(((Xbasdroit-Xbasgauche)^2+(Ybasdroit-Ybasgauche)^2)+(Zbasdroit-Zbasgauche)^2)) -> 5.1275479 | AI17: =IF(Z17="","",(Z17-Z$10)*1000) -> -37.294385 | AJ17: =IF(AA17="","",(AA17-AA$10)*1000) -> -31.394687 | AK17: =IF(AB17="","",(AB17-AB$10)*1000) -> -17.385591 | AL17: =IF(AC17="","",(AC17-AC$10)*1000) -> -15.245144 | AM17: =IF(AD17="","",(AD17-AD$10)*1000) -> -39.682739 | AN17: =IF(AE17="","",(AE17-AE$10)*1000) -> -15.095207 | AO17: =IF(AF17="","",(AF17-AF$10)*1000) -> -13.836231 | AP17: =IF(AG17="","",(AG17-AG$10)*1000) -> -15.476772 | AQ17: =IF(AH17="","",(AH17-AH$10)*1000) -> -12.384221 | AS17: =IF(E17="","",(E17-E$10)*1000) -> -1.55 | AT17: =IF(F17="","",(F17-F$10)*1000) -> 1.1500001 | AU17: =IF(G17="","",(G17-G$10)*1000) -> 1 | AV17: =IF(H17="","",(H17-H$10)*1000) -> -1.2999999 | AW17: =IF(I17="","",(I17-I$10)*1000) -> 0.94999978 | AX17: =IF(J17="","",(J17-J$10)*1000) -> 0.35 | AY17: =IF(K17="","",(K17-K$10)*1000) -> -2.95 | AZ17: =IF(L17="","",(L17-L$10)*1000) -> -1.7000001 | ... BM17: =IF(Y17="","",(Y17-Y$10)*1000) -> -33.3 | BO17: 183.96976 | BP17: -2.5619008 | BQ17: -0.96111762 | BR17: 183.96554 | BS17: -2.6297426 | BT17: 0.2120246 | BU17: 183.89481 | BV17: -2.0263997 | BW17: 1.8537319 | BX17: 183.90464 | BY17: -0.19679428 | BZ17: 2.6433336 | CA17: 183.91136 | CB17: 1.3430388 | CC17: 2.2960664 | CD17: 183.96266 | CE17: 2.6722815 | CF17: 0.15765341 | CG17: 183.97138 | CH17: 2.5655671 | CI17: -0.98973379 | CK17: =IF(BO17="","",(BO17-BO$10)*1000) -> -0.98515003 | CL17: =IF(BP17="","",(BP17-BP$10)*1000) -> -1.6731644 | CM17: =IF(BQ17="","",(BQ17-BQ$10)*1000) -> 1.0098515 | CN17: =IF(BR17="","",(BR17-BR$10)*1000) -> -0.79779291 | CO17: =IF(BS17="","",(BS17-BS$10)*1000) -> -1.3651103 | CP17: =IF(BT17="","",(BT17-BT$10)*1000) -> 0.40797793 | CQ17: =IF(BU17="","",(BU17-BU$10)*1000) -> -3.4373845 | CR17: =IF(BV17="","",(BV17-BV$10)*1000) -> 0.27274036 | ... DE17: =IF(CI17="","",(CI17-CI$10)*1000) -> -33.433052
A18: 43684 | B18: =A18-A$10 -> 26 | C18: 193.66 | D18: =C18-PM -> 9.76 | E18: 823233.32 | F18: 1091513.7 | G18: -124.6642 | H18: 823233.29 | I18: 1091513.7 | J18: -123.491 | K18: 823233.48 | L18: 1091513.2 | M18: -121.8501 | N18: 823234.26 | O18: 1091511.5 | P18: -121.0623 | Q18: 823234.92 | R18: 1091510.1 | S18: -121.4068 | T18: 823235.53 | U18: 1091508.9 | V18: -123.5456 | W18: 823235.49 | X18: 1091509 | Y18: -124.6927 | Z18: =IF(Xhaut="","",SQRT(((Xbasgauche-Xhaut)^2+(Ybasgauche-Yhaut)^2)+(Zbasgauche-Zhaut)^2)) -> 4.3093313 | AA18: =IF(Xhaut="","",SQRT(((Xintergauche-Xhaut)^2+(Yintergauche-Yhaut)^2)+(Zintergauche-Zhaut)^2)) -> 3.4381852 | AB18: =IF(Xhaut="","",SQRT(((Xhautgauche-Xhaut)^2+(Yhautgauche-Yhaut)^2)+(Zhautgauche-Zhaut)^2)) -> 1.9904929 | AC18: =IF(Xhaut="","",SQRT(((Xhautdroit-Xhaut)^2+(Yhautdroit-Yhaut)^2)+(Zhautdroit-Zhaut)^2)) -> 1.5759552 | AD18: =IF(Xhaut="","",SQRT(((Xinterdroit-Xhaut)^2+(Yinterdroit-Yhaut)^2)+(Zinterdroit-Zhaut)^2)) -> 3.7950995 | AE18: =IF(Xhaut="","",SQRT(((Xbasdroit-Xhaut)^2+(Ybasdroit-Yhaut)^2)+(Zbasdroit-Zhaut)^2)) -> 4.5620105 | AF18: =IF(Xhautdroit="","",SQRT(((Xhautdroit-Xhautgauche)^2+(Yhautdroit-Yhautgauche)^2)+(Zhautdroit-Zhautgauche)^2)) -> 3.3948669 | AG18: =IF(Xinterdroit="","",SQRT(((Xinterdroit-Xintergauche)^2+(Yinterdroit-Yintergauche)^2)+(Zinterdroit-Zintergauche)^2)) -> 5.3023857 | AH18: =IF(Xbasdroit="","",SQRT(((Xbasdroit-Xbasgauche)^2+(Ybasdroit-Ybasgauche)^2)+(Zbasdroit-Zbasgauche)^2)) -> 5.1267258 | AI18: =IF(Z18="","",(Z18-Z$10)*1000) -> -39.035276 | AJ18: =IF(AA18="","",(AA18-AA$10)*1000) -> -32.867687 | AK18: =IF(AB18="","",(AB18-AB$10)*1000) -> -19.674394 | AL18: =IF(AC18="","",(AC18-AC$10)*1000) -> -17.795136 | AM18: =IF(AD18="","",(AD18-AD$10)*1000) -> -40.723893 | AN18: =IF(AE18="","",(AE18-AE$10)*1000) -> -17.011058 | AO18: =IF(AF18="","",(AF18-AF$10)*1000) -> -17.38012 | AP18: =IF(AG18="","",(AG18-AG$10)*1000) -> -15.395035 | AQ18: =IF(AH18="","",(AH18-AH$10)*1000) -> -13.206324 | AS18: =IF(E18="","",(E18-E$10)*1000) -> -0.75000001 | AT18: =IF(F18="","",(F18-F$10)*1000) -> 0.14999998 | AU18: =IF(G18="","",(G18-G$10)*1000) -> 1.1 | AV18: =IF(H18="","",(H18-H$10)*1000) -> -0.29999996 | AW18: =IF(I18="","",(I18-I$10)*1000) -> 0.24999981 | AX18: =IF(J18="","",(J18-J$10)*1000) -> 0.55 | AY18: =IF(K18="","",(K18-K$10)*1000) -> -1.05 | AZ18: =IF(L18="","",(L18-L$10)*1000) -> -3.7000002 | ... BM18: =IF(Y18="","",(Y18-Y$10)*1000) -> -33.1 | BO18: 183.9699 | BP18: -2.5604 | BQ18: -0.961 | BR18: 183.966 | BS18: -2.6284 | BT18: 0.2122 | BU18: 183.8959 | BV18: -2.0241 | BW18: 1.8538 | BX18: 183.9043 | BY18: -0.1958 | BZ18: 2.6415 | CA18: 183.9105 | CB18: 1.3424 | CC18: 2.297 | CD18: 183.9622 | CE18: 2.6731 | CF18: 0.1577 | CG18: 183.9705 | CH18: 2.5663 | CI18: -0.9895 | CK18: =IF(BO18="","",(BO18-BO$10)*1000) -> -0.84707964 | CL18: =IF(BP18="","",(BP18-BP$10)*1000) -> -0.17236603 | CM18: =IF(BQ18="","",(BQ18-BQ$10)*1000) -> 1.1274708 | CN18: =IF(BR18="","",(BR18-BR$10)*1000) -> -0.3375559 | CO18: =IF(BS18="","",(BS18-BS$10)*1000) -> -0.022486393 | CP18: =IF(BT18="","",(BT18-BT$10)*1000) -> 0.58337556 | CQ18: =IF(BU18="","",(BU18-BU$10)*1000) -> -2.3448855 | CR18: =IF(BV18="","",(BV18-BV$10)*1000) -> 2.572471 | ... DE18: =IF(CI18="","",(CI18-CI$10)*1000) -> -33.199263
A19: CHANGEMENT DE SYSTÈME DE CIBLES | E19: CHANGEMENT DE SYSTÈME DE CIBLES
A20: 43684 | B20: =A20-A$10 -> 26 | C20: 193.66 | D20: =C20-PM -> 9.76 | E20: 823233.38 | F20: 1091513.6 | G20: -124.5821 | H20: 823233.25 | I20: 1091513.8 | J20: -123.4123 | K20: 823233.45 | L20: 1091513.3 | M20: -121.9659 | N20: 823234.11 | O20: 1091511.6 | P20: -121.0358 | Q20: 823234.86 | R20: 1091510.1 | S20: -121.3609 | T20: 823235.48 | U20: 1091508.9 | V20: -123.4488 | W20: 823235.41 | X20: 1091509 | Y20: -124.6252 | Z20: =IF(Xhaut="","",SQRT(((Xbasgauche-Xhaut)^2+(Ybasgauche-Yhaut)^2)+(Zbasgauche-Zhaut)^2)) -> 4.1413096 | AA20: =IF(Xhaut="","",SQRT(((Xintergauche-Xhaut)^2+(Yintergauche-Yhaut)^2)+(Zintergauche-Zhaut)^2)) -> 3.3586749 | AB20: =IF(Xhaut="","",SQRT(((Xhautgauche-Xhaut)^2+(Yhautgauche-Yhaut)^2)+(Zhautgauche-Zhaut)^2)) -> 2.0790032 | AC20: =IF(Xhaut="","",SQRT(((Xhautdroit-Xhaut)^2+(Yhautdroit-Yhaut)^2)+(Zhautdroit-Zhaut)^2)) -> 1.632602 | AD20: =IF(Xhaut="","",SQRT(((Xinterdroit-Xhaut)^2+(Yinterdroit-Yhaut)^2)+(Zinterdroit-Zhaut)^2)) -> 3.8459325 | AE20: =IF(Xhaut="","",SQRT(((Xbasdroit-Xhaut)^2+(Ybasdroit-Yhaut)^2)+(Zbasdroit-Zhaut)^2)) -> 4.5740696 | AF20: =IF(Xhautdroit="","",SQRT(((Xhautdroit-Xhautgauche)^2+(Yhautdroit-Yhautgauche)^2)+(Zhautdroit-Zhautgauche)^2)) -> 3.5050098 | AG20: =IF(Xinterdroit="","",SQRT(((Xinterdroit-Xintergauche)^2+(Yinterdroit-Yintergauche)^2)+(Zinterdroit-Zintergauche)^2)) -> 5.3611372 | AH20: =IF(Xbasdroit="","",SQRT(((Xbasdroit-Xbasgauche)^2+(Ybasdroit-Ybasgauche)^2)+(Zbasdroit-Zbasgauche)^2)) -> 4.9646653 | BO20: 183.97 | BP20: -2.435 | BQ20: -0.8789 | BR20: 183.9409 | BS20: -2.672 | BT20: 0.2912 | BU20: 183.9242 | BV20: -2.158 | BW20: 1.7377 | BX20: 183.7884 | BY20: -0.3037 | BZ20: 2.6692 | CA20: 183.8737 | CB20: 1.2934 | CC20: 2.3432 | CD20: 183.907 | CE20: 2.6883 | CF20: 0.255 | CG20: 183.9008 | CH20: 2.5293 | CI20: -0.9213
A21: 43685 | B21: =A21-A$10 -> 27 | C21: 193.66 | D21: =C21-PM -> 9.76 | E21: 823233.38 | F21: 1091513.6 | G21: -124.5819 | H21: 823233.25 | I21: 1091513.8 | J21: -123.4123 | K21: 823233.45 | L21: 1091513.3 | M21: -121.9658 | N21: 823234.11 | O21: 1091511.6 | P21: -121.036 | Q21: 823234.86 | R21: 1091510.1 | S21: -121.3609 | T21: 823235.48 | U21: 1091508.9 | V21: -123.4488 | W21: 823235.41 | X21: 1091509 | Y21: -124.6251 | Z21: =IF(Xhaut="","",SQRT(((Xbasgauche-Xhaut)^2+(Ybasgauche-Yhaut)^2)+(Zbasgauche-Zhaut)^2)) -> 4.1415232 | AA21: =IF(Xhaut="","",SQRT(((Xintergauche-Xhaut)^2+(Yintergauche-Yhaut)^2)+(Zintergauche-Zhaut)^2)) -> 3.3586105 | AB21: =IF(Xhaut="","",SQRT(((Xhautgauche-Xhaut)^2+(Yhautgauche-Yhaut)^2)+(Zhautgauche-Zhaut)^2)) -> 2.0789326 | AC21: =IF(Xhaut="","",SQRT(((Xhautdroit-Xhaut)^2+(Yhautdroit-Yhaut)^2)+(Zhautdroit-Zhaut)^2)) -> 1.6314669 | AD21: =IF(Xhaut="","",SQRT(((Xinterdroit-Xhaut)^2+(Yinterdroit-Yhaut)^2)+(Zinterdroit-Zhaut)^2)) -> 3.8450079 | AE21: =IF(Xhaut="","",SQRT(((Xbasdroit-Xhaut)^2+(Ybasdroit-Yhaut)^2)+(Zbasdroit-Zhaut)^2)) -> 4.5736922 | AF21: =IF(Xhautdroit="","",SQRT(((Xhautdroit-Xhautgauche)^2+(Yhautdroit-Yhautgauche)^2)+(Zhautdroit-Zhautgauche)^2)) -> 3.5039729 | AG21: =IF(Xinterdroit="","",SQRT(((Xinterdroit-Xintergauche)^2+(Yinterdroit-Yintergauche)^2)+(Zinterdroit-Zintergauche)^2)) -> 5.3602283 | AH21: =IF(Xbasdroit="","",SQRT(((Xbasdroit-Xbasgauche)^2+(Ybasdroit-Ybasgauche)^2)+(Zbasdroit-Zbasgauche)^2)) -> 4.9655373 | AI21: =IF(Z21="","",(Z21-Z$20)*1000)+AI$18 -> -38.821663 | AJ21: =IF(AA21="","",(AA21-AA$20)*1000)+AJ$18 -> -32.932116 | AK21: =IF(AB21="","",(AB21-AB$20)*1000)+AK$18 -> -19.745018 | AL21: =IF(AC21="","",(AC21-AC$20)*1000)+AL$18 -> -18.930238 | AM21: =IF(AD21="","",(AD21-AD$20)*1000)+AM$18 -> -41.648523 | AN21: =IF(AE21="","",(AE21-AE$20)*1000)+AN$18 -> -17.388472 | AO21: =IF(AF21="","",(AF21-AF$20)*1000)+AO$18 -> -18.417032 | AP21: =IF(AG21="","",(AG21-AG$20)*1000)+AP$18 -> -16.303968 | AQ21: =IF(AH21="","",(AH21-AH$20)*1000)+AQ$18 -> -12.334384 | AS21: =IF(E21="","",(E21-E$20)*1000)+AS$18 -> -0.25000004 | AT21: =IF(F21="","",(F21-F$20)*1000)+AT$18 -> 0.14999998 | AU21: =IF(G21="","",(G21-G$20)*1000)+AU$18 -> 1.3 | AV21: =IF(H21="","",(H21-H$20)*1000)+AV$18 -> 0.30000007 | AW21: =IF(I21="","",(I21-I$20)*1000)+AW$18 -> -0.75000036 | AX21: =IF(J21="","",(J21-J$20)*1000)+AX$18 -> 0.55 | AY21: =IF(K21="","",(K21-K$20)*1000)+AY$18 -> -0.34999987 | AZ21: =IF(L21="","",(L21-L$20)*1000)+AZ$18 -> -4.7000004 | ... BM21: =IF(Y21="","",(Y21-Y$20)*1000)+BM$18 -> -33 | BO21: 183.9702 | BP21: -2.4343 | BQ21: -0.8787 | BR21: 183.9411 | BS21: -2.6711 | BT21: 0.2912 | BU21: 183.9246 | BV21: -2.1573 | BW21: 1.7378 | BX21: 183.7891 | BY21: -0.3029 | BZ21: 2.669 | CA21: 183.8738 | CB21: 1.2941 | CC21: 2.3432 | CD21: 183.9073 | CE21: 2.689 | CF21: 0.255 | CG21: 183.9008 | CH21: 2.5303 | CI21: -0.9212 | CK21: =IF(BO21="","",(BO21-BO$20)*1000)+CK$18 -> -0.64707964 | CL21: =IF(BP21="","",(BP21-BP$20)*1000)+CL$18 -> 0.52763397 | CM21: =IF(BQ21="","",(BQ21-BQ$20)*1000)+CM$18 -> 1.3274708 | CN21: =IF(BR21="","",(BR21-BR$20)*1000)+CN$18 -> -0.1375559 | CO21: =IF(BS21="","",(BS21-BS$20)*1000)+CO$18 -> 0.87751361 | CP21: =IF(BT21="","",(BT21-BT$20)*1000)+CP$18 -> 0.58337556 | CQ21: =IF(BU21="","",(BU21-BU$20)*1000)+CQ$18 -> -1.9448855 | CR21: =IF(BV21="","",(BV21-BV$20)*1000)+CR$18 -> 3.272471 | ... DE21: =IF(CI21="","",(CI21-CI$20)*1000)+DE$18 -> -33.099263
A22: 43689 | B22: =A22-A$10 -> 31 | C22: 194.8 | D22: =C22-PM -> 10.9 | E22: 823233.37 | F22: 1091513.6 | G22: -124.5819 | H22: 823233.25 | I22: 1091513.8 | J22: -123.4123 | K22: 823233.45 | L22: 1091513.3 | M22: -121.9662 | N22: 823234.11 | O22: 1091511.6 | P22: -121.0396 | Q22: 823234.86 | R22: 1091510.1 | S22: -121.3618 | T22: 823235.48 | U22: 1091508.9 | V22: -123.4487 | W22: 823235.41 | X22: 1091509 | Y22: -124.6249 | Z22: =IF(Xhaut="","",SQRT(((Xbasgauche-Xhaut)^2+(Ybasgauche-Yhaut)^2)+(Zbasgauche-Zhaut)^2)) -> 4.1377959 | AA22: =IF(Xhaut="","",SQRT(((Xintergauche-Xhaut)^2+(Yintergauche-Yhaut)^2)+(Zintergauche-Zhaut)^2)) -> 3.3553718 | AB22: =IF(Xhaut="","",SQRT(((Xhautgauche-Xhaut)^2+(Yhautgauche-Yhaut)^2)+(Zhautgauche-Zhaut)^2)) -> 2.0767153 | AC22: =IF(Xhaut="","",SQRT(((Xhautdroit-Xhaut)^2+(Yhautdroit-Yhaut)^2)+(Zhautdroit-Zhaut)^2)) -> 1.6310005 | AD22: =IF(Xhaut="","",SQRT(((Xinterdroit-Xhaut)^2+(Yinterdroit-Yhaut)^2)+(Zinterdroit-Zhaut)^2)) -> 3.8430129 | AE22: =IF(Xhaut="","",SQRT(((Xbasdroit-Xhaut)^2+(Ybasdroit-Yhaut)^2)+(Zbasdroit-Zhaut)^2)) -> 4.5707799 | AF22: =IF(Xhautdroit="","",SQRT(((Xhautdroit-Xhautgauche)^2+(Yhautdroit-Yhautgauche)^2)+(Zhautdroit-Zhautgauche)^2)) -> 3.502988 | AG22: =IF(Xinterdroit="","",SQRT(((Xinterdroit-Xintergauche)^2+(Yinterdroit-Yintergauche)^2)+(Zinterdroit-Zintergauche)^2)) -> 5.3595764 | AH22: =IF(Xbasdroit="","",SQRT(((Xbasdroit-Xbasgauche)^2+(Ybasdroit-Ybasgauche)^2)+(Zbasdroit-Zbasgauche)^2)) -> 4.9642721 | AI22: =IF(Z22="","",(Z22-Z$20)*1000)+AI$18 -> -42.548995 | AJ22: =IF(AA22="","",(AA22-AA$20)*1000)+AJ$18 -> -36.170743 | AK22: =IF(AB22="","",(AB22-AB$20)*1000)+AK$18 -> -21.962369 | AL22: =IF(AC22="","",(AC22-AC$20)*1000)+AL$18 -> -19.396682 | AM22: =IF(AD22="","",(AD22-AD$20)*1000)+AM$18 -> -43.643481 | AN22: =IF(AE22="","",(AE22-AE$20)*1000)+AN$18 -> -20.300814 | AO22: =IF(AF22="","",(AF22-AF$20)*1000)+AO$18 -> -19.402003 | AP22: =IF(AG22="","",(AG22-AG$20)*1000)+AP$18 -> -16.955853 | AQ22: =IF(AH22="","",(AH22-AH$20)*1000)+AQ$18 -> -13.599555 | AS22: =IF(E22="","",(E22-E$20)*1000)+AS$18 -> -1.85 | AT22: =IF(F22="","",(F22-F$20)*1000)+AT$18 -> 0.34999987 | AU22: =IF(G22="","",(G22-G$20)*1000)+AU$18 -> 1.3 | AV22: =IF(H22="","",(H22-H$20)*1000)+AV$18 -> -1.2999999 | AW22: =IF(I22="","",(I22-I$20)*1000)+AW$18 -> -0.25000027 | AX22: =IF(J22="","",(J22-J$20)*1000)+AX$18 -> 0.55 | AY22: =IF(K22="","",(K22-K$20)*1000)+AY$18 -> -1.9499999 | AZ22: =IF(L22="","",(L22-L$20)*1000)+AZ$18 -> -4.1000003 | ... BM22: =IF(Y22="","",(Y22-Y$20)*1000)+BM$18 -> -32.8 | BO22: 183.969 | BP22: -2.4355847 | BQ22: -0.87871003 | BR22: 183.93995 | BS22: -2.6723508 | BT22: 0.2911805 | BU22: 183.92333 | BV22: -2.1583051 | BW22: 1.7374467 | BX22: 183.78717 | BY22: -0.30476293 | BZ22: 2.6654083 | CA22: 183.87314 | CB22: 1.2917828 | CC22: 2.3423486 | CD22: 183.90691 | CE22: 2.6870002 | CF22: 0.25511086 | CG22: 183.90083 | CH22: 2.528033 | CI22: -0.92102832 | CK22: =IF(BO22="","",(BO22-BO$20)*1000)+CK$18 -> -1.8440098 | CL22: =IF(BP22="","",(BP22-BP$20)*1000)+CL$18 -> -0.75707618 | CM22: =IF(BQ22="","",(BQ22-BQ$20)*1000)+CM$18 -> 1.3174401 | CN22: =IF(BR22="","",(BR22-BR$20)*1000)+CN$18 -> -1.2872994 | CO22: =IF(BS22="","",(BS22-BS$20)*1000)+CO$18 -> -0.37329215 | CP22: =IF(BT22="","",(BT22-BT$20)*1000)+CP$18 -> 0.56387299 | CQ22: =IF(BU22="","",(BU22-BU$20)*1000)+CQ$18 -> -3.2145123 | CR22: =IF(BV22="","",(BV22-BV$20)*1000)+CR$18 -> 2.2674116 | ... DE22: =IF(CI22="","",(CI22-CI$20)*1000)+DE$18 -> -32.927582
A23: 43690 | B23: =A23-A$10 -> 32 | C23: 194.8 | D23: =C23-PM -> 10.9 | E23: 823233.38 | F23: 1091513.6 | G23: -124.5812 | H23: 823233.25 | I23: 1091513.8 | J23: -123.4117 | K23: 823233.45 | L23: 1091513.3 | M23: -121.9656 | N23: 823234.11 | O23: 1091511.6 | P23: -121.0393 | Q23: 823234.86 | R23: 1091510.1 | S23: -121.3614 | T23: 823235.48 | U23: 1091508.9 | V23: -123.4482 | W23: 823235.41 | X23: 1091509 | Y23: -124.6241 | Z23: =IF(Xhaut="","",SQRT(((Xbasgauche-Xhaut)^2+(Ybasgauche-Yhaut)^2)+(Zbasgauche-Zhaut)^2)) -> 4.1375068 | AA23: =IF(Xhaut="","",SQRT(((Xintergauche-Xhaut)^2+(Yintergauche-Yhaut)^2)+(Zintergauche-Zhaut)^2)) -> 3.3550906 | AB23: =IF(Xhaut="","",SQRT(((Xhautgauche-Xhaut)^2+(Yhautgauche-Yhaut)^2)+(Zhautgauche-Zhaut)^2)) -> 2.0763104 | AC23: =IF(Xhaut="","",SQRT(((Xhautdroit-Xhaut)^2+(Yhautdroit-Yhaut)^2)+(Zhautdroit-Zhaut)^2)) -> 1.6311421 | AD23: =IF(Xhaut="","",SQRT(((Xinterdroit-Xhaut)^2+(Yinterdroit-Yhaut)^2)+(Zinterdroit-Zhaut)^2)) -> 3.8429189 | AE23: =IF(Xhaut="","",SQRT(((Xbasdroit-Xhaut)^2+(Ybasdroit-Yhaut)^2)+(Zbasdroit-Zhaut)^2)) -> 4.5700232 | AF23: =IF(Xhautdroit="","",SQRT(((Xhautdroit-Xhautgauche)^2+(Yhautdroit-Yhautgauche)^2)+(Zhautdroit-Zhautgauche)^2)) -> 3.5028728 | AG23: =IF(Xinterdroit="","",SQRT(((Xinterdroit-Xintergauche)^2+(Yinterdroit-Yintergauche)^2)+(Zinterdroit-Zintergauche)^2)) -> 5.3595696 | AH23: =IF(Xbasdroit="","",SQRT(((Xbasdroit-Xbasgauche)^2+(Ybasdroit-Ybasgauche)^2)+(Zbasdroit-Zbasgauche)^2)) -> 4.9638336 | AI23: =IF(Z23="","",(Z23-Z$20)*1000)+AI$18 -> -42.838061 | AJ23: =IF(AA23="","",(AA23-AA$20)*1000)+AJ$18 -> -36.45197 | AK23: =IF(AB23="","",(AB23-AB$20)*1000)+AK$18 -> -22.367277 | AL23: =IF(AC23="","",(AC23-AC$20)*1000)+AL$18 -> -19.254993 | AM23: =IF(AD23="","",(AD23-AD$20)*1000)+AM$18 -> -43.737542 | AN23: =IF(AE23="","",(AE23-AE$20)*1000)+AN$18 -> -21.057473 | AO23: =IF(AF23="","",(AF23-AF$20)*1000)+AO$18 -> -19.517158 | AP23: =IF(AG23="","",(AG23-AG$20)*1000)+AP$18 -> -16.962645 | AQ23: =IF(AH23="","",(AH23-AH$20)*1000)+AQ$18 -> -14.038067 | AS23: =IF(E23="","",(E23-E$20)*1000)+AS$18 -> -1.55 | AT23: =IF(F23="","",(F23-F$20)*1000)+AT$18 -> 1.1499999 | AU23: =IF(G23="","",(G23-G$20)*1000)+AU$18 -> 2 | AV23: =IF(H23="","",(H23-H$20)*1000)+AV$18 -> -1.1999999 | AW23: =IF(I23="","",(I23-I$20)*1000)+AW$18 -> 0.24999981 | AX23: =IF(J23="","",(J23-J$20)*1000)+AX$18 -> 1.15 | AY23: =IF(K23="","",(K23-K$20)*1000)+AY$18 -> -1.5499999 | AZ23: =IF(L23="","",(L23-L$20)*1000)+AZ$18 -> -3.7000002 | ... BM23: =IF(Y23="","",(Y23-Y$20)*1000)+BM$18 -> -32 | BO23: 183.96944 | BP23: -2.4358204 | BQ23: -0.87801444 | BR23: 183.94021 | BS23: -2.6726711 | BT23: 0.2917779 | BU23: 183.9239 | BV23: -2.1585891 | BW23: 1.738041 | BX23: 183.78792 | BY23: -0.30496248 | BZ23: 2.6657008 | CA23: 183.87353 | CB23: 1.2914142 | CC23: 2.3427447 | CD23: 183.90748 | CE23: 2.6864926 | CF23: 0.25560518 | CG23: 183.90104 | CH23: 2.5273564 | CI23: -0.92023037 | CK23: =IF(BO23="","",(BO23-BO$20)*1000)+CK$18 -> -1.4030796 | CL23: =IF(BP23="","",(BP23-BP$20)*1000)+CL$18 -> -0.99279703 | CM23: =IF(BQ23="","",(BQ23-BQ$20)*1000)+CM$18 -> 2.0130308 | CN23: =IF(BR23="","",(BR23-BR$20)*1000)+CN$18 -> -1.0276559 | CO23: =IF(BS23="","",(BS23-BS$20)*1000)+CO$18 -> -0.69354339 | CP23: =IF(BT23="","",(BT23-BT$20)*1000)+CP$18 -> 1.1612766 | CQ23: =IF(BU23="","",(BU23-BU$20)*1000)+CQ$18 -> -2.6406855 | CR23: =IF(BV23="","",(BV23-BV$20)*1000)+CR$18 -> 1.983327 | ... DE23: =IF(CI23="","",(CI23-CI$20)*1000)+DE$18 -> -32.129634
A24: 43696 | B24: =A24-A$10 -> 38 | C24: 195.4 | D24: =C24-PM -> 11.5 | E24: 823233.38 | F24: 1091513.6 | G24: -124.5809 | H24: 823233.25 | I24: 1091513.8 | J24: -123.4116 | K24: 823233.45 | L24: 1091513.3 | M24: -121.966 | N24: 823234.11 | O24: 1091511.6 | P24: -121.0421 | Q24: 823234.86 | R24: 1091510.1 | S24: -121.3621 | T24: 823235.48 | U24: 1091508.9 | V24: -123.4479 | W24: 823235.41 | X24: 1091509 | Y24: -124.624 | Z24: =IF(Xhaut="","",SQRT(((Xbasgauche-Xhaut)^2+(Ybasgauche-Yhaut)^2)+(Zbasgauche-Zhaut)^2)) -> 4.1345819 | AA24: =IF(Xhaut="","",SQRT(((Xintergauche-Xhaut)^2+(Yintergauche-Yhaut)^2)+(Zintergauche-Zhaut)^2)) -> 3.3527757 | AB24: =IF(Xhaut="","",SQRT(((Xhautgauche-Xhaut)^2+(Yhautgauche-Yhaut)^2)+(Zhautgauche-Zhaut)^2)) -> 2.0746168 | AC24: =IF(Xhaut="","",SQRT(((Xhautdroit-Xhaut)^2+(Yhautdroit-Yhaut)^2)+(Zhautdroit-Zhaut)^2)) -> 1.6303313 | AD24: =IF(Xhaut="","",SQRT(((Xinterdroit-Xhaut)^2+(Yinterdroit-Yhaut)^2)+(Zinterdroit-Zhaut)^2)) -> 3.8406055 | AE24: =IF(Xhaut="","",SQRT(((Xbasdroit-Xhaut)^2+(Ybasdroit-Yhaut)^2)+(Zbasdroit-Zhaut)^2)) -> 4.5678128 | AF24: =IF(Xhautdroit="","",SQRT(((Xhautdroit-Xhautgauche)^2+(Yhautdroit-Yhautgauche)^2)+(Zhautdroit-Zhautgauche)^2)) -> 3.501541 | AG24: =IF(Xinterdroit="","",SQRT(((Xinterdroit-Xintergauche)^2+(Yinterdroit-Yintergauche)^2)+(Zinterdroit-Zintergauche)^2)) -> 5.3585567 | AH24: =IF(Xbasdroit="","",SQRT(((Xbasdroit-Xbasgauche)^2+(Ybasdroit-Ybasgauche)^2)+(Zbasdroit-Zbasgauche)^2)) -> 4.9632337 | AI24: =IF(Z24="","",(Z24-Z$20)*1000)+AI$18 -> -45.762991 | AJ24: =IF(AA24="","",(AA24-AA$20)*1000)+AJ$18 -> -38.76685 | AK24: =IF(AB24="","",(AB24-AB$20)*1000)+AK$18 -> -24.060792 | AL24: =IF(AC24="","",(AC24-AC$20)*1000)+AL$18 -> -20.065805 | AM24: =IF(AD24="","",(AD24-AD$20)*1000)+AM$18 -> -46.050921 | AN24: =IF(AE24="","",(AE24-AE$20)*1000)+AN$18 -> -23.267873 | AO24: =IF(AF24="","",(AF24-AF$20)*1000)+AO$18 -> -20.848952 | AP24: =IF(AG24="","",(AG24-AG$20)*1000)+AP$18 -> -17.975544 | AQ24: =IF(AH24="","",(AH24-AH$20)*1000)+AQ$18 -> -14.637982 | AS24: =IF(E24="","",(E24-E$20)*1000)+AS$18 -> -0.44999993 | AT24: =IF(F24="","",(F24-F$20)*1000)+AT$18 -> 0.34999987 | AU24: =IF(G24="","",(G24-G$20)*1000)+AU$18 -> 2.3 | AV24: =IF(H24="","",(H24-H$20)*1000)+AV$18 -> -0.099999947 | AW24: =IF(I24="","",(I24-I$20)*1000)+AW$18 -> -0.35000034 | AX24: =IF(J24="","",(J24-J$20)*1000)+AX$18 -> 1.25 | AY24: =IF(K24="","",(K24-K$20)*1000)+AY$18 -> -0.54999988 | AZ24: =IF(L24="","",(L24-L$20)*1000)+AZ$18 -> -4.7000004 | ... BM24: =IF(Y24="","",(Y24-Y$20)*1000)+BM$18 -> -31.9 | BO24: 183.9703 | BP24: -2.435 | BQ24: -0.8777 | BR24: 183.941 | BS24: -2.6718 | BT24: 0.2919 | BU24: 183.9243 | BV24: -2.1572 | BW24: 1.7376 | BX24: 183.787 | BY24: -0.3047 | BZ24: 2.6629 | CA24: 183.874 | CB24: 1.2915 | CC24: 2.342 | CD24: 183.9077 | CE24: 2.6866 | CF24: 0.2559 | CG24: 183.9013 | CH24: 2.5276 | CI24: -0.9201 | CK24: =IF(BO24="","",(BO24-BO$20)*1000)+CK$18 -> -0.54707964 | CL24: =IF(BP24="","",(BP24-BP$20)*1000)+CL$18 -> -0.17236603 | CM24: =IF(BQ24="","",(BQ24-BQ$20)*1000)+CM$18 -> 2.3274708 | CN24: =IF(BR24="","",(BR24-BR$20)*1000)+CN$18 -> -0.2375559 | CO24: =IF(BS24="","",(BS24-BS$20)*1000)+CO$18 -> 0.17751361 | CP24: =IF(BT24="","",(BT24-BT$20)*1000)+CP$18 -> 1.2833756 | CQ24: =IF(BU24="","",(BU24-BU$20)*1000)+CQ$18 -> -2.2448855 | CR24: =IF(BV24="","",(BV24-BV$20)*1000)+CR$18 -> 3.372471 | ... DE24: =IF(CI24="","",(CI24-CI$20)*1000)+DE$18 -> -31.999263
A25: 43699 | B25: =A25-A$10 -> 41 | C25: 196.35 | D25: =C25-PM -> 12.45 | E25: 823233.38 | F25: 1091513.6 | G25: -124.5815 | H25: 823233.25 | I25: 1091513.8 | J25: -123.4122 | K25: 823233.45 | L25: 1091513.3 | M25: -121.9668 | N25: 823234.11 | O25: 1091511.6 | P25: -121.0444 | Q25: 823234.86 | R25: 1091510.1 | S25: -121.3634 | T25: 823235.48 | U25: 1091508.9 | V25: -123.4486 | W25: 823235.41 | X25: 1091509 | Y25: -124.6244 | Z25: =IF(Xhaut="","",SQRT(((Xbasgauche-Xhaut)^2+(Ybasgauche-Yhaut)^2)+(Zbasgauche-Zhaut)^2)) -> 4.1325916 | AA25: =IF(Xhaut="","",SQRT(((Xintergauche-Xhaut)^2+(Yintergauche-Yhaut)^2)+(Zintergauche-Zhaut)^2)) -> 3.3508964 | AB25: =IF(Xhaut="","",SQRT(((Xhautgauche-Xhaut)^2+(Yhautgauche-Yhaut)^2)+(Zhautgauche-Zhaut)^2)) -> 2.0735596 | AC25: =IF(Xhaut="","",SQRT(((Xhautdroit-Xhaut)^2+(Yhautdroit-Yhaut)^2)+(Zhautdroit-Zhaut)^2)) -> 1.6297492 | AD25: =IF(Xhaut="","",SQRT(((Xinterdroit-Xhaut)^2+(Yinterdroit-Yhaut)^2)+(Zinterdroit-Zhaut)^2)) -> 3.839541 | AE25: =IF(Xhaut="","",SQRT(((Xbasdroit-Xhaut)^2+(Ybasdroit-Yhaut)^2)+(Zbasdroit-Zhaut)^2)) -> 4.5661879 | AF25: =IF(Xhautdroit="","",SQRT(((Xhautdroit-Xhautgauche)^2+(Yhautdroit-Yhautgauche)^2)+(Zhautdroit-Zhautgauche)^2)) -> 3.5005838 | AG25: =IF(Xinterdroit="","",SQRT(((Xinterdroit-Xintergauche)^2+(Yinterdroit-Yintergauche)^2)+(Zinterdroit-Zintergauche)^2)) -> 5.35744 | AH25: =IF(Xbasdroit="","",SQRT(((Xbasdroit-Xbasgauche)^2+(Ybasdroit-Ybasgauche)^2)+(Zbasdroit-Zbasgauche)^2)) -> 4.9619007 | AI25: =IF(Z25="","",(Z25-Z$20)*1000)+AI$18 -> -47.753288 | AJ25: =IF(AA25="","",(AA25-AA$20)*1000)+AJ$18 -> -40.646145 | AK25: =IF(AB25="","",(AB25-AB$20)*1000)+AK$18 -> -25.118023 | AL25: =IF(AC25="","",(AC25-AC$20)*1000)+AL$18 -> -20.647981 | AM25: =IF(AD25="","",(AD25-AD$20)*1000)+AM$18 -> -47.115374 | AN25: =IF(AE25="","",(AE25-AE$20)*1000)+AN$18 -> -24.892778 | AO25: =IF(AF25="","",(AF25-AF$20)*1000)+AO$18 -> -21.806193 | AP25: =IF(AG25="","",(AG25-AG$20)*1000)+AP$18 -> -19.092246 | AQ25: =IF(AH25="","",(AH25-AH$20)*1000)+AQ$18 -> -15.970954 | AS25: =IF(E25="","",(E25-E$20)*1000)+AS$18 -> -0.44999993 | AT25: =IF(F25="","",(F25-F$20)*1000)+AT$18 -> -0.050000148 | AU25: =IF(G25="","",(G25-G$20)*1000)+AU$18 -> 1.7 | AV25: =IF(H25="","",(H25-H$20)*1000)+AV$18 -> -0.099999947 | AW25: =IF(I25="","",(I25-I$20)*1000)+AW$18 -> -0.65000029 | AX25: =IF(J25="","",(J25-J$20)*1000)+AX$18 -> 0.65 | AY25: =IF(K25="","",(K25-K$20)*1000)+AY$18 -> -0.9499999 | AZ25: =IF(L25="","",(L25-L$20)*1000)+AZ$18 -> -4.6000003 | ... BM25: =IF(Y25="","",(Y25-Y$20)*1000)+BM$18 -> -32.3 | BO25: 183.9701 | BP25: -2.4346 | BQ25: -0.8783 | BR25: 183.9409 | BS25: -2.6715 | BT25: 0.2913 | BU25: 183.924 | BV25: -2.1574 | BW25: 1.7368 | BX25: 183.7862 | BY25: -0.3055 | BZ25: 2.6606 | CA25: 183.8735 | CB25: 1.2904 | CC25: 2.3407 | CD25: 183.9075 | CE25: 2.6857 | CF25: 0.2552 | CG25: 183.9008 | CH25: 2.5266 | CI25: -0.9205 | CK25: =IF(BO25="","",(BO25-BO$20)*1000)+CK$18 -> -0.74707964 | CL25: =IF(BP25="","",(BP25-BP$20)*1000)+CL$18 -> 0.22763397 | CM25: =IF(BQ25="","",(BQ25-BQ$20)*1000)+CM$18 -> 1.7274708 | CN25: =IF(BR25="","",(BR25-BR$20)*1000)+CN$18 -> -0.3375559 | CO25: =IF(BS25="","",(BS25-BS$20)*1000)+CO$18 -> 0.47751361 | CP25: =IF(BT25="","",(BT25-BT$20)*1000)+CP$18 -> 0.68337556 | CQ25: =IF(BU25="","",(BU25-BU$20)*1000)+CQ$18 -> -2.5448855 | CR25: =IF(BV25="","",(BV25-BV$20)*1000)+CR$18 -> 3.172471 | ... DE25: =IF(CI25="","",(CI25-CI$20)*1000)+DE$18 -> -32.399263
A26: 43704 | B26: =A26-A$10 -> 46 | C26: 197.2 | D26: =C26-PM -> 13.3 | E26: 823233.38 | F26: 1091513.6 | G26: -124.5816 | H26: 823233.25 | I26: 1091513.8 | J26: -123.4122 | K26: 823233.45 | L26: 1091513.3 | M26: -121.967 | N26: 823234.11 | O26: 1091511.6 | P26: -121.0462 | Q26: 823234.88 | R26: 1091510.1 | S26: -121.3719 | T26: 823235.48 | U26: 1091508.9 | V26: -123.4485 | W26: 823235.41 | X26: 1091509 | Y26: -124.6244 | Z26: =IF(Xhaut="","",SQRT(((Xbasgauche-Xhaut)^2+(Ybasgauche-Yhaut)^2)+(Zbasgauche-Zhaut)^2)) -> 4.13149 | AA26: =IF(Xhaut="","",SQRT(((Xintergauche-Xhaut)^2+(Yintergauche-Yhaut)^2)+(Zintergauche-Zhaut)^2)) -> 3.3501123 | AB26: =IF(Xhaut="","",SQRT(((Xhautgauche-Xhaut)^2+(Yhautgauche-Yhaut)^2)+(Zhautgauche-Zhaut)^2)) -> 2.072889 | AC26: =IF(Xhaut="","",SQRT(((Xhautdroit-Xhaut)^2+(Yhautdroit-Yhaut)^2)+(Zhautdroit-Zhaut)^2)) -> 1.6369789 | AD26: =IF(Xhaut="","",SQRT(((Xinterdroit-Xhaut)^2+(Yinterdroit-Yhaut)^2)+(Zinterdroit-Zhaut)^2)) -> 3.8378597 | AE26: =IF(Xhaut="","",SQRT(((Xbasdroit-Xhaut)^2+(Ybasdroit-Yhaut)^2)+(Zbasdroit-Zhaut)^2)) -> 4.5644992 | AF26: =IF(Xhautdroit="","",SQRT(((Xhautdroit-Xhautgauche)^2+(Yhautdroit-Yhautgauche)^2)+(Zhautdroit-Zhautgauche)^2)) -> 3.5041388 | AG26: =IF(Xinterdroit="","",SQRT(((Xinterdroit-Xintergauche)^2+(Yinterdroit-Yintergauche)^2)+(Zinterdroit-Zintergauche)^2)) -> 5.3575035 | AH26: =IF(Xbasdroit="","",SQRT(((Xbasdroit-Xbasgauche)^2+(Ybasdroit-Ybasgauche)^2)+(Zbasdroit-Zbasgauche)^2)) -> 4.9621007 | AI26: =IF(Z26="","",(Z26-Z$20)*1000)+AI$18 -> -48.854924 | AJ26: =IF(AA26="","",(AA26-AA$20)*1000)+AJ$18 -> -41.430325 | AK26: =IF(AB26="","",(AB26-AB$20)*1000)+AK$18 -> -25.788592 | AL26: =IF(AC26="","",(AC26-AC$20)*1000)+AL$18 -> -13.418221 | AM26: =IF(AD26="","",(AD26-AD$20)*1000)+AM$18 -> -48.796744 | AN26: =IF(AE26="","",(AE26-AE$20)*1000)+AN$18 -> -26.581531 | AO26: =IF(AF26="","",(AF26-AF$20)*1000)+AO$18 -> -18.251149 | AP26: =IF(AG26="","",(AG26-AG$20)*1000)+AP$18 -> -19.028723 | AQ26: =IF(AH26="","",(AH26-AH$20)*1000)+AQ$18 -> -15.770939 | AS26: =IF(E26="","",(E26-E$20)*1000)+AS$18 -> 0.45000005 | AT26: =IF(F26="","",(F26-F$20)*1000)+AT$18 -> -1.1500001 | AU26: =IF(G26="","",(G26-G$20)*1000)+AU$18 -> 1.6 | AV26: =IF(H26="","",(H26-H$20)*1000)+AV$18 -> 0.50000008 | AW26: =IF(I26="","",(I26-I$20)*1000)+AW$18 -> -1.8500003 | AX26: =IF(J26="","",(J26-J$20)*1000)+AX$18 -> 0.65 | AY26: =IF(K26="","",(K26-K$20)*1000)+AY$18 -> 0.15000009 | AZ26: =IF(L26="","",(L26-L$20)*1000)+AZ$18 -> -6.3000002 | ... BM26: =IF(Y26="","",(Y26-Y$20)*1000)+BM$18 -> -32.3 | BO26: 183.97045 | BP26: -2.4332532 | BQ26: -0.87842454 | BR26: 183.94091 | BS26: -2.67014 | BT26: 0.29127095 | BU26: 183.9243 | BV26: -2.1554236 | BW26: 1.736637 | BX26: 183.786 | BY26: -0.30343356 | BZ26: 2.65882 | CA26: 183.8873 | CB26: 1.297615 | CC26: 2.332107 | CD26: 183.90696 | CE26: 2.6871331 | CF26: 0.25531038 | CG26: 183.90066 | CH26: 2.528172 | CI26: -0.92052657 | CK26: =IF(BO26="","",(BO26-BO$20)*1000)+CK$18 -> -0.3935161 | CL26: =IF(BP26="","",(BP26-BP$20)*1000)+CL$18 -> 1.5744615 | CM26: =IF(BQ26="","",(BQ26-BQ$20)*1000)+CM$18 -> 1.6029352 | CN26: =IF(BR26="","",(BR26-BR$20)*1000)+CN$18 -> -0.33221701 | CO26: =IF(BS26="","",(BS26-BS$20)*1000)+CO$18 -> 1.8375488 | CP26: =IF(BT26="","",(BT26-BT$20)*1000)+CP$18 -> 0.65432217 | CQ26: =IF(BU26="","",(BU26-BU$20)*1000)+CQ$18 -> -2.2411333 | CR26: =IF(BV26="","",(BV26-BV$20)*1000)+CR$18 -> 5.1488234 | ... DE26: =IF(CI26="","",(CI26-CI$20)*1000)+DE$18 -> -32.425831
A27: 43706 | B27: =A27-A$10 -> 48 | C27: 198.3 | D27: =C27-PM -> 14.4 | E27: 823233.38 | F27: 1091513.6 | G27: -124.5808 | H27: 823233.25 | I27: 1091513.8 | J27: -123.4114 | K27: 823233.45 | L27: 1091513.3 | M27: -121.9662 | N27: 823234.11 | O27: 1091511.6 | P27: -121.0457 | Q27: 823234.88 | R27: 1091510.1 | S27: -121.3709 | T27: 823235.48 | U27: 1091508.9 | V27: -123.4478 | W27: 823235.41 | X27: 1091509 | Y27: -124.6238 | Z27: =IF(Xhaut="","",SQRT(((Xbasgauche-Xhaut)^2+(Ybasgauche-Yhaut)^2)+(Zbasgauche-Zhaut)^2)) -> 4.1313529 | AA27: =IF(Xhaut="","",SQRT(((Xintergauche-Xhaut)^2+(Yintergauche-Yhaut)^2)+(Zintergauche-Zhaut)^2)) -> 3.3501754 | AB27: =IF(Xhaut="","",SQRT(((Xhautgauche-Xhaut)^2+(Yhautgauche-Yhaut)^2)+(Zhautgauche-Zhaut)^2)) -> 2.073082 | AC27: =IF(Xhaut="","",SQRT(((Xhautdroit-Xhaut)^2+(Yhautdroit-Yhaut)^2)+(Zhautdroit-Zhaut)^2)) -> 1.6368483 | AD27: =IF(Xhaut="","",SQRT(((Xinterdroit-Xhaut)^2+(Yinterdroit-Yhaut)^2)+(Zinterdroit-Zhaut)^2)) -> 3.8375289 | AE27: =IF(Xhaut="","",SQRT(((Xbasdroit-Xhaut)^2+(Ybasdroit-Yhaut)^2)+(Zbasdroit-Zhaut)^2)) -> 4.5641183 | AF27: =IF(Xhautdroit="","",SQRT(((Xhautdroit-Xhautgauche)^2+(Yhautdroit-Yhautgauche)^2)+(Zhautdroit-Zhautgauche)^2)) -> 3.5044984 | AG27: =IF(Xinterdroit="","",SQRT(((Xinterdroit-Xintergauche)^2+(Yinterdroit-Yintergauche)^2)+(Zinterdroit-Zintergauche)^2)) -> 5.3576218 | AH27: =IF(Xbasdroit="","",SQRT(((Xbasdroit-Xbasgauche)^2+(Ybasdroit-Ybasgauche)^2)+(Zbasdroit-Zbasgauche)^2)) -> 4.9618514 | AI27: =IF(Z27="","",(Z27-Z$20)*1000)+AI$18 -> -48.992037 | AJ27: =IF(AA27="","",(AA27-AA$20)*1000)+AJ$18 -> -41.367216 | AK27: =IF(AB27="","",(AB27-AB$20)*1000)+AK$18 -> -25.595619 | AL27: =IF(AC27="","",(AC27-AC$20)*1000)+AL$18 -> -13.548802 | AM27: =IF(AD27="","",(AD27-AD$20)*1000)+AM$18 -> -49.12749 | AN27: =IF(AE27="","",(AE27-AE$20)*1000)+AN$18 -> -26.962364 | AO27: =IF(AF27="","",(AF27-AF$20)*1000)+AO$18 -> -17.89157 | AP27: =IF(AG27="","",(AG27-AG$20)*1000)+AP$18 -> -18.910468 | AQ27: =IF(AH27="","",(AH27-AH$20)*1000)+AQ$18 -> -16.020299 | AS27: =IF(E27="","",(E27-E$20)*1000)+AS$18 -> 1.05 | AT27: =IF(F27="","",(F27-F$20)*1000)+AT$18 -> 0.34999987 | AU27: =IF(G27="","",(G27-G$20)*1000)+AU$18 -> 2.4 | AV27: =IF(H27="","",(H27-H$20)*1000)+AV$18 -> 1.2000001 | AW27: =IF(I27="","",(I27-I$20)*1000)+AW$18 -> -0.15000021 | AX27: =IF(J27="","",(J27-J$20)*1000)+AX$18 -> 1.45 | AY27: =IF(K27="","",(K27-K$20)*1000)+AY$18 -> 0.65000006 | AZ27: =IF(L27="","",(L27-L$20)*1000)+AZ$18 -> -4.7000004 | ... BM27: =IF(Y27="","",(Y27-Y$20)*1000)+BM$18 -> -31.7 | BO27: 183.972 | BP27: -2.434 | BQ27: -0.878 | BR27: 183.942 | BS27: -2.671 | BT27: 0.292 | BU27: 183.925 | BV27: -2.157 | BW27: 1.737 | BX27: 183.787 | BY27: -0.304 | BZ27: 2.659 | CA27: 183.889 | CB27: 1.297 | CC27: 2.333 | CD27: 183.909 | CE27: 2.686 | CF27: 0.256 | CG27: 183.902 | CH27: 2.527 | CI27: -0.92 | CK27: =IF(BO27="","",(BO27-BO$20)*1000)+CK$18 -> 1.1529204 | CL27: =IF(BP27="","",(BP27-BP$20)*1000)+CL$18 -> 0.82763397 | CM27: =IF(BQ27="","",(BQ27-BQ$20)*1000)+CM$18 -> 2.0274708 | CN27: =IF(BR27="","",(BR27-BR$20)*1000)+CN$18 -> 0.7624441 | CO27: =IF(BS27="","",(BS27-BS$20)*1000)+CO$18 -> 0.97751361 | CP27: =IF(BT27="","",(BT27-BT$20)*1000)+CP$18 -> 1.3833756 | CQ27: =IF(BU27="","",(BU27-BU$20)*1000)+CQ$18 -> -1.5448855 | CR27: =IF(BV27="","",(BV27-BV$20)*1000)+CR$18 -> 3.572471 | ... DE27: =IF(CI27="","",(CI27-CI$20)*1000)+DE$18 -> -31.899263
