Workbook
Name cintre: 'Résultats observations'!$W$4
Name date: 'Résultats observations'!$A:$A
Name DH_BD: 'Résultats observations'!$DD:$DD
Name DH_BG: 'Résultats observations'!$CL:$CL
Name DH_HD: 'Résultats observations'!$CX:$CX
Name DH_HG: 'Résultats observations'!$CR:$CR
Name DH_ID: 'Résultats observations'!$DA:$DA
Name DH_IG: 'Résultats observations'!$CO:$CO
Name DHhaut: 'Résultats observations'!$CU:$CU
Name dist: 'Résultats observations'!$D:$D
Name DPM_BD: 'Résultats observations'!$DC:$DC
Name DPM_BG: 'Résultats observations'!$CK:$CK
Name DPM_HD: 'Résultats observations'!$CW:$CW
Name DPM_HG: 'Résultats observations'!$CQ:$CQ
Name DPM_ID: 'Résultats observations'!$CZ:$CZ
Name DPM_IG: 'Résultats observations'!$CN:$CN
Name DPMhaut: 'Résultats observations'!$CT:$CT
Name DZ_BD: 'Résultats observations'!$BM:$BM
Name DZ_BG: 'Résultats observations'!$AU:$AU
Name DZ_HD: 'Résultats observations'!$BG:$BG
Name DZ_HG: 'Résultats observations'!$BA:$BA
Name DZ_ID: 'Résultats observations'!$BJ:$BJ
Name DZ_IG: 'Résultats observations'!$AX:$AX
Name DZhaut: 'Résultats observations'!$BD:$BD
Name Ecart_BD: 'Résultats observations'!$AN:$AN
Name Ecart_BG: 'Résultats observations'!$AI:$AI
Name Ecart_HD: 'Résultats observations'!$AL:$AL
Name Ecart_HG: 'Résultats observations'!$AK:$AK
Name Ecart_ID: 'Résultats observations'!$AM:$AM
Name Ecart_IG: 'Résultats observations'!$AJ:$AJ
Name Ecart_LB: 'Résultats observations'!$AQ:$AQ
Name Ecart_LH: 'Résultats observations'!$AO:$AO
Name Ecart_LI: 'Résultats observations'!$AP:$AP
Name excav: 'Résultats observations'!$A$7
Name front: 'Résultats observations'!$C:$C
Name galerie: 'Résultats observations'!$G$4
Name jours: 'Résultats observations'!$B:$B
Name N_DEST: #REF!
Name N_SOURCE: #REF!
Name PM: 'Résultats observations'!$W$6
Name Xbasdroit: 'Résultats observations'!$W:$W
Name Xbasgauche: 'Résultats observations'!$E:$E
Name Xhaut: 'Résultats observations'!$N:$N
Name Xhautdroit: 'Résultats observations'!$Q:$Q
Name Xhautgauche: 'Résultats observations'!$K:$K
Name Xinterdroit: 'Résultats observations'!$T:$T
Name Xintergauche: 'Résultats observations'!$H:$H
Name Ybasdroit: 'Résultats observations'!$X:$X
Name Ybasgauche: 'Résultats observations'!$F:$F
Name Yhaut: 'Résultats observations'!$O:$O
Name Yhautdroit: 'Résultats observations'!$R:$R
Name Yhautgauche: 'Résultats observations'!$L:$L
Name Yinterdroit: 'Résultats observations'!$U:$U
Name Yintergauche: 'Résultats observations'!$I:$I
Name Zbasdroit: 'Résultats observations'!$Y:$Y
Name Zbasgauche: 'Résultats observations'!$G:$G
Name Zhaut: 'Résultats observations'!$P:$P
Name Zhautdroit: 'Résultats observations'!$S:$S
Name Zhautgauche: 'Résultats observations'!$M:$M
Name Zinterdroit: 'Résultats observations'!$V:$V

Sheet Résultats observations
F1: CONVERGENCE T12T13 - PM158
A6: Date point 0 | V6: PM = | W6: 158
A7: 44140
A8: Date | B8: Jours | C8: Front | D8: Dist | E8: Point bas gauche | H8: Point intermédiaire gauche | K8: Point haut gauche | N8: Point centre haut | Q8: Point haut droit | T8: Point intermédiaire droit | W8: Point bas droit | AI8: Différences | AS8: Point bas gauche | AV8: Point intermédiaire gauche | AY8: Point haut gauche | BB8: Point centre haut | BE8: Point haut droit | BH8: Point intermédiaire droit | BK8: Point bas droit | BO8: Point bas gauche | BR8: Point intermédiaire gauche | BU8: Point haut gauche | BX8: Point centre haut | CA8: Point haut droit | CD8: Point intermédiaire droit | CG8: Point bas droit | CK8: Point bas gauche | CN8: Point intermédiaire gauche | CQ8: Point haut gauche | CT8: Point centre haut | CW8: Point haut droit | CZ8: Point intermédiaire droit | DC8: Point bas droit
E9: X | F9: Y | G9: Z | K9: X | L9: Y | M9: Z | N9: X | O9: Y | P9: Z | Q9: X | R9: Y | S9: Z | W9: X | X9: Y | Y9: Z | Z9: BG | AA9: IG | AB9: HG | AC9: HD | AD9: ID | AE9: BD | AF9: LH | AG9: LI | AH9: LB | AI9: BG | AJ9: IG | AK9: HG | AL9: HD | AM9: ID | AN9: BD | AO9: LH | AP9: LI | AQ9: LB | AS9: DX | AT9: DY | AU9: DZ | AV9: DX | AW9: DY | AX9: DZ | AY9: DX | AZ9: DY | BA9: DZ | BB9: DX | BC9: DY | BD9: DZ | BE9: DX | BF9: DY | BG9: DZ | BH9: DX | BI9: DY | BJ9: DZ | BK9: DX | BL9: DY | BM9: DZ | BO9: PM | BP9: H | BQ9: V | BR9: PM | BS9: H | BT9: V | BU9: PM | BV9: H | BW9: V | BX9: PM | BY9: H | BZ9: V | CA9: PM | CB9: H | CC9: V | CD9: PM | CE9: H | CF9: V | CG9: PM | CH9: H | CI9: V | CK9: DPM | CL9: DH | CM9: DZ | CN9: DPM | CO9: DH | CP9: DZ | CQ9: DPM | CR9: DH | CS9: DZ | CT9: DPM | CU9: DH | CV9: DZ | CW9: DPM | CX9: DH | CY9: DZ | CZ9: DPM | DA9: DH | DB9: DZ | DC9: DPM | DD9: DH | DE9: DZ
A10: 44140 | B10: 0 | C10: 222.9 | D10: =C10-PM -> 64.9 | E10: 823209.97 | F10: 1091504.2 | G10: -125.007 | H10: 823209.74 | I10: 1091504.3 | J10: -123.6355 | K10: 823210.19 | L10: 1091503.4 | M10: -121.1001 | N10: 823211.71 | O10: 1091500.2 | P10: -119.6079 | Q10: 823212.8 | R10: 1091497.7 | S10: -121.0721 | T10: 823213.21 | U10: 1091497 | V10: -123.6497 | W10: 823213.18 | X10: 1091497.2 | Y10: -125.0366 | Z10: =IF(Xhaut="","",SQRT(((Xbasgauche-Xhaut)^2+(Ybasgauche-Yhaut)^2)+(Zbasgauche-Zhaut)^2)) -> 6.9349477 | AA10: =IF(Xhaut="","",SQRT(((Xintergauche-Xhaut)^2+(Yintergauche-Yhaut)^2)+(Zintergauche-Zhaut)^2)) -> 6.1128028 | AB10: =IF(Xhaut="","",SQRT(((Xhautgauche-Xhaut)^2+(Yhautgauche-Yhaut)^2)+(Zhautgauche-Zhaut)^2)) -> 3.8935811 | AC10: =IF(Xhaut="","",SQRT(((Xhautdroit-Xhaut)^2+(Yhautdroit-Yhaut)^2)+(Zhautdroit-Zhaut)^2)) -> 3.0347242 | AD10: =IF(Xhaut="","",SQRT(((Xinterdroit-Xhaut)^2+(Yinterdroit-Yhaut)^2)+(Zinterdroit-Zhaut)^2)) -> 5.355996 | AE10: =IF(Xhaut="","",SQRT(((Xbasdroit-Xhaut)^2+(Ybasdroit-Yhaut)^2)+(Zbasdroit-Zhaut)^2)) -> 6.3502229 | AF10: =IF(Xhautdroit="","",SQRT(((Xhautdroit-Xhautgauche)^2+(Yhautdroit-Yhautgauche)^2)+(Zhautdroit-Zhautgauche)^2)) -> 6.2543918 | AG10: =IF(Xinterdroit="","",SQRT(((Xinterdroit-Xintergauche)^2+(Yinterdroit-Yintergauche)^2)+(Zinterdroit-Zintergauche)^2)) -> 8.1126935 | AH10: =IF(Xbasdroit="","",SQRT(((Xbasdroit-Xbasgauche)^2+(Ybasdroit-Ybasgauche)^2)+(Zbasdroit-Zbasgauche)^2)) -> 7.6445688 | AI10: 0 | AJ10: 0 | AK10: 0 | AL10: 0 | AM10: 0 | AN10: 0 | AO10: 0 | AP10: 0 | AQ10: 0 | AS10: 0 | AT10: 0 | AU10: 0 | AV10: 0 | AW10: 0 | AX10: 0 | AY10: 0 | AZ10: 0 | BA10: 0 | BB10: 0 | BC10: 0 | BD10: 0 | BE10: 0 | BF10: 0 | BG10: 0 | BH10: 0 | BI10: 0 | BJ10: 0 | BK10: 0 | BL10: 0 | BM10: 0 | BO10: 158.78103 | BP10: -3.8091466 | BQ10: -1.0519303 | BR10: 158.64123 | BS10: -4.0564019 | BT10: 0.32096769 | BU10: 158.67998 | BV10: -3.0544331 | BW10: 2.8559802 | BX10: 158.67118 | BY10: 0.54184773 | BZ10: 4.3482682 | CA10: 158.63503 | CB10: 3.1997346 | CC10: 2.8844297 | CD10: 158.69633 | CE10: 4.0560921 | CF10: 0.30621667 | CG10: 158.75791 | CH10: 3.83533 | CI10: -1.0812991 | CK10: 0 | CL10: 0 | CM10: 0 | CN10: 0 | CO10: 0 | CP10: 0 | CQ10: 0 | CR10: 0 | CS10: 0 | CT10: 0 | CU10: 0 | CV10: 0 | CW10: 0 | CX10: 0 | CY10: 0 | CZ10: 0 | DA10: 0 | DB10: 0 | DC10: 0 | DD10: 0 | DE10: 0
A11: 44172 | B11: =A11-$A$10 -> 32 | C11: 222.9 | D11: =C11-PM -> 64.9 | E11: 823209.97 | F11: 1091504.2 | G11: -125.0064 | H11: 823209.73 | I11: 1091504.3 | J11: -123.6349 | K11: 823210.19 | L11: 1091503.4 | M11: -121.0997 | N11: 823211.71 | O11: 1091500.2 | P11: -119.6076 | Q11: 823212.8 | R11: 1091497.7 | S11: -121.0722 | T11: 823213.21 | U11: 1091497 | V11: -123.6493 | W11: 823213.18 | X11: 1091497.2 | Y11: -125.0359 | Z11: =IF(Xhaut="","",SQRT(((Xbasgauche-Xhaut)^2+(Ybasgauche-Yhaut)^2)+(Zbasgauche-Zhaut)^2)) -> 6.9342601 | AA11: =IF(Xhaut="","",SQRT(((Xintergauche-Xhaut)^2+(Yintergauche-Yhaut)^2)+(Zintergauche-Zhaut)^2)) -> 6.1120764 | AB11: =IF(Xhaut="","",SQRT(((Xhautgauche-Xhaut)^2+(Yhautgauche-Yhaut)^2)+(Zhautgauche-Zhaut)^2)) -> 3.8936228 | AC11: =IF(Xhaut="","",SQRT(((Xhautdroit-Xhaut)^2+(Yhautdroit-Yhaut)^2)+(Zhautdroit-Zhaut)^2)) -> 3.0343704 | AD11: =IF(Xhaut="","",SQRT(((Xinterdroit-Xhaut)^2+(Yinterdroit-Yhaut)^2)+(Zinterdroit-Zhaut)^2)) -> 5.3556139 | AE11: =IF(Xhaut="","",SQRT(((Xbasdroit-Xhaut)^2+(Ybasdroit-Yhaut)^2)+(Zbasdroit-Zhaut)^2)) -> 6.3496726 | AF11: =IF(Xhautdroit="","",SQRT(((Xhautdroit-Xhautgauche)^2+(Yhautdroit-Yhautgauche)^2)+(Zhautdroit-Zhautgauche)^2)) -> 6.2538363 | AG11: =IF(Xinterdroit="","",SQRT(((Xinterdroit-Xintergauche)^2+(Yinterdroit-Yintergauche)^2)+(Zinterdroit-Zintergauche)^2)) -> 8.1115241 | AH11: =IF(Xbasdroit="","",SQRT(((Xbasdroit-Xbasgauche)^2+(Ybasdroit-Ybasgauche)^2)+(Zbasdroit-Zbasgauche)^2)) -> 7.6435079 | AI11: =(Z11-Z$10)*1000 -> -0.6875872 | AJ11: =(AA11-AA$10)*1000 -> -0.72642608 | AK11: =(AB11-AB$10)*1000 -> 0.041681278 | AL11: =(AC11-AC$10)*1000 -> -0.35378594 | AM11: =(AD11-AD$10)*1000 -> -0.38209469 | AN11: =(AE11-AE$10)*1000 -> -0.550325 | AO11: =(AF11-AF$10)*1000 -> -0.55548392 | AP11: =(AG11-AG$10)*1000 -> -1.1694789 | AQ11: =(AH11-AH$10)*1000 -> -1.0609457 | AS11: =(E11-E$10)*1000 -> -1.1 | AT11: =(F11-F$10)*1000 -> -1.4 | AU11: =(G11-G$10)*1000 -> 0.6 | AV11: =(H11-H$10)*1000 -> -0.80000004 | AW11: =(I11-I$10)*1000 -> -1.3000001 | AX11: =(J11-J$10)*1000 -> 0.6 | AY11: =(K11-K$10)*1000 -> -1.2000001 | AZ11: =(L11-L$10)*1000 -> -0.59999991 | ... BM11: =(Y11-Y$10)*1000 -> 0.7 | BO11: 158.77944 | BP11: -3.8083427 | BQ11: -1.0513144 | BR11: 158.63996 | BS11: -4.0555618 | BT11: 0.32158043 | BU11: 158.67864 | BV11: -3.0543965 | BW11: 2.8563936 | BX11: 158.67145 | BY11: 0.54197452 | BZ11: 4.3485655 | CA11: 158.63417 | CB11: 3.1992213 | CC11: 2.8843383 | CD11: 158.69538 | CE11: 4.0557601 | CF11: 0.30662616 | CG11: 158.75736 | CH11: 3.8350764 | CI11: -1.0805936 | CK11: =(BO11-BO$10)*1000 -> -1.588634 | CL11: =(BP11-BP$10)*1000 -> 0.80389162 | CM11: =(BQ11-BQ$10)*1000 -> 0.61588634 | CN11: =(BR11-BR$10)*1000 -> -1.2744813 | CO11: =(BS11-BS$10)*1000 -> 0.84005815 | CP11: =(BT11-BT$10)*1000 -> 0.61274481 | CQ11: =(BU11-BU$10)*1000 -> -1.3411417 | CR11: =(BV11-BV$10)*1000 -> 0.036592714 | ... DE11: =(CI11-CI$10)*1000 -> 0.70543775
A12: 44229 | B12: =A12-$A$10 -> 89 | C12: 222.9 | D12: =C12-PM -> 64.9 | E12: 823209.96 | F12: 1091504.2 | G12: -125.008 | H12: 823209.73 | I12: 1091504.3 | J12: -123.636 | K12: 823210.19 | L12: 1091503.4 | M12: -121.101 | N12: 823211.71 | O12: 1091500.2 | P12: -119.609 | Q12: 823212.8 | R12: 1091497.7 | S12: -121.073 | T12: 823213.21 | U12: 1091497 | V12: -123.65 | Z12: =IF(Xhaut="","",SQRT(((Xbasgauche-Xhaut)^2+(Ybasgauche-Yhaut)^2)+(Zbasgauche-Zhaut)^2)) -> 6.935371 | AA12: =IF(Xhaut="","",SQRT(((Xintergauche-Xhaut)^2+(Yintergauche-Yhaut)^2)+(Zintergauche-Zhaut)^2)) -> 6.1130288 | AB12: =IF(Xhaut="","",SQRT(((Xhautgauche-Xhaut)^2+(Yhautgauche-Yhaut)^2)+(Zhautgauche-Zhaut)^2)) -> 3.8946705 | AC12: =IF(Xhaut="","",SQRT(((Xhautdroit-Xhaut)^2+(Yhautdroit-Yhaut)^2)+(Zhautdroit-Zhaut)^2)) -> 3.0352127 | AD12: =IF(Xhaut="","",SQRT(((Xinterdroit-Xhaut)^2+(Yinterdroit-Yhaut)^2)+(Zinterdroit-Zhaut)^2)) -> 5.3552163 | AF12: =IF(Xhautdroit="","",SQRT(((Xhautdroit-Xhautgauche)^2+(Yhautdroit-Yhautgauche)^2)+(Zhautdroit-Zhautgauche)^2)) -> 6.256286 | AG12: =IF(Xinterdroit="","",SQRT(((Xinterdroit-Xintergauche)^2+(Yinterdroit-Yintergauche)^2)+(Zinterdroit-Zintergauche)^2)) -> 8.1132507 | AH12: =IF(Xbasdroit="","",SQRT(((Xbasdroit-Xbasgauche)^2+(Ybasdroit-Ybasgauche)^2)+(Zbasdroit-Zbasgauche)^2)) | AI12: =(Z12-Z$10)*1000 -> 0.42333119 | AJ12: =(AA12-AA$10)*1000 -> 0.22597956 | AK12: =(AB12-AB$10)*1000 -> 1.0893534 | AL12: =(AC12-AC$10)*1000 -> 0.48850447 | AM12: =(AD12-AD$10)*1000 -> -0.77968191 | AO12: =(AF12-AF$10)*1000 -> 1.8941284 | AP12: =(AG12-AG$10)*1000 -> 0.55717374 | AS12: =(E12-E$10)*1000 -> -1.6000001 | AT12: =(F12-F$10)*1000 -> 0.69999998 | AU12: =(G12-G$10)*1000 -> -1 | AV12: =(H12-H$10)*1000 -> -1.4 | AW12: =(I12-I$10)*1000 -> 0.69999998 | AX12: =(J12-J$10)*1000 -> -0.5 | AY12: =(K12-K$10)*1000 -> -1 | AZ12: =(L12-L$10)*1000 -> 1.4 | ... BJ12: =(V12-V$10)*1000 -> -0.3 | BO12: 158.77988 | BP12: -3.8102337 | BQ12: -1.0526188 | BR12: 158.64071 | BS12: -4.0576402 | BT12: 0.32077295 | BU12: 158.67972 | BV12: -3.0555446 | BW12: 2.8552828 | BX12: 158.67358 | BY12: 0.5412007 | BZ12: 4.3469442 | CA12: 158.63444 | CB12: 3.1995716 | CC12: 2.8840356 | CD12: 158.69657 | CE12: 4.0551013 | CF12: 0.30571426 | CK12: =(BO12-BO$10)*1000 -> -1.148112 | CL12: =(BP12-BP$10)*1000 -> -1.0871241 | CM12: =(BQ12-BQ$10)*1000 -> -0.68851888 | CN12: =(BR12-BR$10)*1000 -> -0.52590524 | CO12: =(BS12-BS$10)*1000 -> -1.238315 | CP12: =(BT12-BT$10)*1000 -> -0.19474095 | CQ12: =(BU12-BU$10)*1000 -> -0.25401756 | CR12: =(BV12-BV$10)*1000 -> -1.1115193 | ... DB12: =(CF12-CF$10)*1000 -> -0.50241394
A13: 44273 | B13: =A13-$A$10 -> 133 | C13: 222.9 | D13: =C13-PM -> 64.9 | E13: 823209.97 | F13: 1091504.2 | G13: -125.0073 | H13: 823209.73 | I13: 1091504.3 | J13: -123.6356 | K13: 823210.19 | L13: 1091503.4 | M13: -121.101 | N13: 823211.71 | O13: 1091500.2 | P13: -119.6102 | Q13: 823212.8 | R13: 1091497.7 | S13: -121.0731 | T13: 823213.21 | U13: 1091497 | V13: -123.6498 | W13: 823213.18 | X13: 1091497.2 | Y13: -125.0365 | Z13: =IF(Xhaut="","",SQRT(((Xbasgauche-Xhaut)^2+(Ybasgauche-Yhaut)^2)+(Zbasgauche-Zhaut)^2)) -> 6.9327633 | AA13: =IF(Xhaut="","",SQRT(((Xintergauche-Xhaut)^2+(Yintergauche-Yhaut)^2)+(Zintergauche-Zhaut)^2)) -> 6.1102928 | AB13: =IF(Xhaut="","",SQRT(((Xhautgauche-Xhaut)^2+(Yhautgauche-Yhaut)^2)+(Zhautgauche-Zhaut)^2)) -> 3.8921731 | AC13: =IF(Xhaut="","",SQRT(((Xhautdroit-Xhaut)^2+(Yhautdroit-Yhaut)^2)+(Zhautdroit-Zhaut)^2)) -> 3.0341586 | AD13: =IF(Xhaut="","",SQRT(((Xinterdroit-Xhaut)^2+(Yinterdroit-Yhaut)^2)+(Zinterdroit-Zhaut)^2)) -> 5.3540567 | AE13: =IF(Xhaut="","",SQRT(((Xbasdroit-Xhaut)^2+(Ybasdroit-Yhaut)^2)+(Zbasdroit-Zhaut)^2)) -> 6.3476391 | AF13: =IF(Xhautdroit="","",SQRT(((Xhautdroit-Xhautgauche)^2+(Yhautdroit-Yhautgauche)^2)+(Zhautdroit-Zhautgauche)^2)) -> 6.2534821 | AG13: =IF(Xinterdroit="","",SQRT(((Xinterdroit-Xintergauche)^2+(Yinterdroit-Yintergauche)^2)+(Zinterdroit-Zintergauche)^2)) -> 8.1108576 | AH13: =IF(Xbasdroit="","",SQRT(((Xbasdroit-Xbasgauche)^2+(Ybasdroit-Ybasgauche)^2)+(Zbasdroit-Zbasgauche)^2)) -> 7.64269 | AI13: =(Z13-Z$10)*1000 -> -2.1843402 | AJ13: =(AA13-AA$10)*1000 -> -2.5100066 | AK13: =(AB13-AB$10)*1000 -> -1.4079959 | AL13: =(AC13-AC$10)*1000 -> -0.56562303 | AM13: =(AD13-AD$10)*1000 -> -1.9393078 | AN13: =(AE13-AE$10)*1000 -> -2.5838288 | AO13: =(AF13-AF$10)*1000 -> -0.90973009 | AP13: =(AG13-AG$10)*1000 -> -1.8359358 | AQ13: =(AH13-AH$10)*1000 -> -1.8788405 | AS13: =(E13-E$10)*1000 -> -1.5 | AT13: =(F13-F$10)*1000 -> -0.19999989 | AU13: =(G13-G$10)*1000 -> -0.3 | AV13: =(H13-H$10)*1000 -> -0.89999998 | AW13: =(I13-I$10)*1000 -> -0.50000008 | AX13: =(J13-J$10)*1000 -> -0.1 | AY13: =(K13-K$10)*1000 -> -1 | AZ13: =(L13-L$10)*1000 -> 0 | ... BM13: =(Y13-Y$10)*1000 -> 0.1 | BO13: 158.77958 | BP13: -3.8095993 | BQ13: -1.0522158 | BR13: 158.6402 | BS13: -4.0563291 | BT13: 0.32087796 | BU13: 158.67907 | BV13: -3.0548557 | BW13: 2.8550893 | BX13: 158.67347 | BY13: 0.54048786 | BZ13: 4.3459453 | CA13: 158.63455 | CB13: 3.1984056 | CC13: 2.8834345 | CD13: 158.69539 | CE13: 4.0543283 | CF13: 0.3061261 | CG13: 158.75789 | CH13: 3.8330041 | CI13: -1.0811989 | CK13: =(BO13-BO$10)*1000 -> -1.4439684 | CL13: =(BP13-BP$10)*1000 -> -0.45271971 | CM13: =(BQ13-BQ$10)*1000 -> -0.28556032 | CN13: =(BR13-BR$10)*1000 -> -1.0269889 | CO13: =(BS13-BS$10)*1000 -> 0.072759296 | CP13: =(BT13-BT$10)*1000 -> -0.089730111 | CQ13: =(BU13-BU$10)*1000 -> -0.90629209 | CR13: =(BV13-BV$10)*1000 -> -0.42265203 | ... DE13: =(CI13-CI$10)*1000 -> 0.10018723
A14: 44287 | B14: =A14-$A$10 -> 147 | C14: 222.9 | D14: =C14-PM -> 64.9 | H14: 823209.73 | I14: 1091504.3 | J14: -123.6346 | K14: 823210.19 | L14: 1091503.4 | M14: -121.0997 | N14: 823211.71 | O14: 1091500.2 | P14: -119.6097 | Q14: 823212.8 | R14: 1091497.7 | S14: -121.0721 | T14: 823213.21 | U14: 1091497 | V14: -123.6489 | W14: 823213.18 | X14: 1091497.2 | Y14: -125.0357 | AA14: =IF(Xhaut="","",SQRT(((Xintergauche-Xhaut)^2+(Yintergauche-Yhaut)^2)+(Zintergauche-Zhaut)^2)) -> 6.1107621 | AB14: =IF(Xhaut="","",SQRT(((Xhautgauche-Xhaut)^2+(Yhautgauche-Yhaut)^2)+(Zhautgauche-Zhaut)^2)) -> 3.8927917 | AC14: =IF(Xhaut="","",SQRT(((Xhautdroit-Xhaut)^2+(Yhautdroit-Yhaut)^2)+(Zhautdroit-Zhaut)^2)) -> 3.0338571 | AD14: =IF(Xhaut="","",SQRT(((Xinterdroit-Xhaut)^2+(Yinterdroit-Yhaut)^2)+(Zinterdroit-Zhaut)^2)) -> 5.3527029 | AE14: =IF(Xhaut="","",SQRT(((Xbasdroit-Xhaut)^2+(Ybasdroit-Yhaut)^2)+(Zbasdroit-Zhaut)^2)) -> 6.3469659 | AF14: =IF(Xhautdroit="","",SQRT(((Xhautdroit-Xhautgauche)^2+(Yhautdroit-Yhautgauche)^2)+(Zhautdroit-Zhautgauche)^2)) -> 6.2544119 | AG14: =IF(Xinterdroit="","",SQRT(((Xinterdroit-Xintergauche)^2+(Yinterdroit-Yintergauche)^2)+(Zinterdroit-Zintergauche)^2)) -> 8.1103157 | AJ14: =(AA14-AA$10)*1000 -> -2.0407231 | AK14: =(AB14-AB$10)*1000 -> -0.78939337 | AL14: =(AC14-AC$10)*1000 -> -0.86710374 | AM14: =(AD14-AD$10)*1000 -> -3.2930889 | AN14: =(AE14-AE$10)*1000 -> -3.2570737 | AO14: =(AF14-AF$10)*1000 -> 0.020116984 | AP14: =(AG14-AG$10)*1000 -> -2.3777923 | AV14: =(H14-H$10)*1000 -> -0.49999997 | AW14: =(I14-I$10)*1000 -> -3.1999999 | AX14: =(J14-J$10)*1000 -> 0.9 | AY14: =(K14-K$10)*1000 -> -0.89999998 | AZ14: =(L14-L$10)*1000 -> -2.9 | BA14: =(M14-M$10)*1000 -> 0.4 | BB14: =(N14-N$10)*1000 -> 2.9 | BC14: =(O14-O$10)*1000 -> -1.1999998 | ... BM14: =(Y14-Y$10)*1000 -> 0.9 | BR14: 158.63943 | BS14: -4.0537131 | BT14: 0.32188575 | BU14: 158.67794 | BV14: -3.0521852 | BW14: 2.8564006 | BX14: 158.6733 | BY14: 0.54416097 | BZ14: 4.346447 | CA14: 158.63496 | CB14: 3.2020182 | CC14: 2.8844304 | CD14: 158.69486 | CE14: 4.0564006 | CF14: 0.30703135 | CG14: 158.75676 | CH14: 3.8358982 | CI14: -1.0803876 | CN14: =(BR14-BR$10)*1000 -> -1.8056324 | CO14: =(BS14-BS$10)*1000 -> 2.6888085 | CP14: =(BT14-BT$10)*1000 -> 0.91805632 | CQ14: =(BU14-BU$10)*1000 -> -2.0413536 | CR14: =(BV14-BV$10)*1000 -> 2.2478601 | CS14: =(BW14-BW$10)*1000 -> 0.42041354 | CT14: =(BX14-BX$10)*1000 -> 2.1210646 | CU14: =(BY14-BY$10)*1000 -> 2.3132411 | ... DE14: =(CI14-CI$10)*1000 -> 0.91147686
A15: 44308 | B15: =A15-$A$10 -> 168 | C15: 222.9 | D15: =C15-PM -> 64.9 | E15: 823209.97 | F15: 1091504.2 | G15: -125.007 | H15: 823209.73 | I15: 1091504.3 | J15: -123.6354 | K15: 823210.19 | L15: 1091503.4 | M15: -121.1005 | N15: 823211.71 | O15: 1091500.2 | P15: -119.6101 | Q15: 823212.8 | R15: 1091497.7 | S15: -121.0727 | T15: 823213.21 | U15: 1091497 | V15: -123.6496 | W15: 823213.18 | X15: 1091497.2 | Y15: -125.0364 | Z15: =IF(Xhaut="","",SQRT(((Xbasgauche-Xhaut)^2+(Ybasgauche-Yhaut)^2)+(Zbasgauche-Zhaut)^2)) -> 6.9330427 | AA15: =IF(Xhaut="","",SQRT(((Xintergauche-Xhaut)^2+(Yintergauche-Yhaut)^2)+(Zintergauche-Zhaut)^2)) -> 6.1111427 | AB15: =IF(Xhaut="","",SQRT(((Xhautgauche-Xhaut)^2+(Yhautgauche-Yhaut)^2)+(Zhautgauche-Zhaut)^2)) -> 3.8929027 | AC15: =IF(Xhaut="","",SQRT(((Xhautdroit-Xhaut)^2+(Yhautdroit-Yhaut)^2)+(Zhautdroit-Zhaut)^2)) -> 3.0342537 | AD15: =IF(Xhaut="","",SQRT(((Xinterdroit-Xhaut)^2+(Yinterdroit-Yhaut)^2)+(Zinterdroit-Zhaut)^2)) -> 5.3540534 | AE15: =IF(Xhaut="","",SQRT(((Xbasdroit-Xhaut)^2+(Ybasdroit-Yhaut)^2)+(Zbasdroit-Zhaut)^2)) -> 6.3480797 | AF15: =IF(Xhautdroit="","",SQRT(((Xhautdroit-Xhautgauche)^2+(Yhautdroit-Yhautgauche)^2)+(Zhautdroit-Zhautgauche)^2)) -> 6.2547131 | AG15: =IF(Xinterdroit="","",SQRT(((Xinterdroit-Xintergauche)^2+(Yinterdroit-Yintergauche)^2)+(Zinterdroit-Zintergauche)^2)) -> 8.1121852 | AH15: =IF(Xbasdroit="","",SQRT(((Xbasdroit-Xbasgauche)^2+(Ybasdroit-Ybasgauche)^2)+(Zbasdroit-Zbasgauche)^2)) -> 7.6442133 | AI15: =(Z15-Z$10)*1000 -> -1.9050165 | AJ15: =(AA15-AA$10)*1000 -> -1.660153 | AK15: =(AB15-AB$10)*1000 -> -0.67844615 | AL15: =(AC15-AC$10)*1000 -> -0.47043837 | AM15: =(AD15-AD$10)*1000 -> -1.9426492 | AN15: =(AE15-AE$10)*1000 -> -2.1431959 | AO15: =(AF15-AF$10)*1000 -> 0.32121962 | AP15: =(AG15-AG$10)*1000 -> -0.50828155 | AQ15: =(AH15-AH$10)*1000 -> -0.3555549 | AS15: =(E15-E$10)*1000 -> -1.2000001 | AT15: =(F15-F$10)*1000 -> 0.29999996 | AU15: =(G15-G$10)*1000 -> 0 | AV15: =(H15-H$10)*1000 -> -0.80000004 | AW15: =(I15-I$10)*1000 -> 0.50000008 | AX15: =(J15-J$10)*1000 -> 0.1 | AY15: =(K15-K$10)*1000 -> -0.69999998 | AZ15: =(L15-L$10)*1000 -> 0.80000004 | ... BM15: =(Y15-Y$10)*1000 -> 0.2 | BO15: 158.78007 | BP15: -3.8099256 | BQ15: -1.0519207 | BR15: 158.64072 | BS15: -4.0571932 | BT15: 0.32107283 | BU15: 158.67968 | BV15: -3.055454 | BW15: 2.8555832 | BX15: 158.67352 | BY15: 0.54084428 | BZ15: 4.3460448 | CA15: 158.63447 | CB15: 3.1990339 | CC15: 2.8838353 | CD15: 158.69661 | CE15: 4.0547871 | CF15: 0.3063139 | CG15: 158.75832 | CH15: 3.8342002 | CI15: -1.0811032 | CK15: =(BO15-BO$10)*1000 -> -0.96075493 | CL15: =(BP15-BP$10)*1000 -> -0.77907001 | CM15: =(BQ15-BQ$10)*1000 -> 0.0096075493 | CN15: =(BR15-BR$10)*1000 -> -0.51370763 | CO15: =(BS15-BS$10)*1000 -> -0.79126772 | CP15: =(BT15-BT$10)*1000 -> 0.10513708 | CQ15: =(BU15-BU$10)*1000 -> -0.29628279 | CR15: =(BV15-BV$10)*1000 -> -1.0208901 | ... DE15: =(CI15-CI$10)*1000 -> 0.19583447
A16: 44322 | B16: =A16-$A$10 -> 182 | C16: 222.9 | D16: =C16-PM -> 64.9 | H16: 823209.73 | I16: 1091504.3 | J16: -123.6356 | K16: 823210.19 | L16: 1091503.4 | M16: -121.1008 | N16: 823211.71 | O16: 1091500.2 | P16: -119.6104 | Q16: 823212.8 | R16: 1091497.7 | S16: -121.0733 | T16: 823213.21 | U16: 1091497 | V16: -123.6501 | W16: 823213.18 | X16: 1091497.2 | Y16: -125.0366 | AA16: =IF(Xhaut="","",SQRT(((Xintergauche-Xhaut)^2+(Yintergauche-Yhaut)^2)+(Zintergauche-Zhaut)^2)) -> 6.1114388 | AB16: =IF(Xhaut="","",SQRT(((Xhautgauche-Xhaut)^2+(Yhautgauche-Yhaut)^2)+(Zhautgauche-Zhaut)^2)) -> 3.8930254 | AC16: =IF(Xhaut="","",SQRT(((Xhautdroit-Xhaut)^2+(Yhautdroit-Yhaut)^2)+(Zhautdroit-Zhaut)^2)) -> 3.0341862 | AD16: =IF(Xhaut="","",SQRT(((Xinterdroit-Xhaut)^2+(Yinterdroit-Yhaut)^2)+(Zinterdroit-Zhaut)^2)) -> 5.353939 | AE16: =IF(Xhaut="","",SQRT(((Xbasdroit-Xhaut)^2+(Ybasdroit-Yhaut)^2)+(Zbasdroit-Zhaut)^2)) -> 6.3478782 | AF16: =IF(Xhautdroit="","",SQRT(((Xhautdroit-Xhautgauche)^2+(Yhautdroit-Yhautgauche)^2)+(Zhautdroit-Zhautgauche)^2)) -> 6.2546054 | AG16: =IF(Xinterdroit="","",SQRT(((Xinterdroit-Xintergauche)^2+(Yinterdroit-Yintergauche)^2)+(Zinterdroit-Zintergauche)^2)) -> 8.1122625 | AJ16: =(AA16-AA$10)*1000 -> -1.3640503 | AK16: =(AB16-AB$10)*1000 -> -0.55575293 | AL16: =(AC16-AC$10)*1000 -> -0.53795493 | AM16: =(AD16-AD$10)*1000 -> -2.0570619 | AN16: =(AE16-AE$10)*1000 -> -2.3447184 | AO16: =(AF16-AF$10)*1000 -> 0.21355273 | AP16: =(AG16-AG$10)*1000 -> -0.43106675 | AV16: =(H16-H$10)*1000 -> -0.89999998 | AW16: =(I16-I$10)*1000 -> -0.10000006 | AX16: =(J16-J$10)*1000 -> -0.1 | AY16: =(K16-K$10)*1000 -> -0.20000001 | AZ16: =(L16-L$10)*1000 -> 0.10000006 | BA16: =(M16-M$10)*1000 -> -0.7 | BB16: =(N16-N$10)*1000 -> 2.3000001 | BC16: =(O16-O$10)*1000 -> 1.1 | ... BM16: =(Y16-Y$10)*1000 -> 0 | BR16: 158.64037 | BS16: -4.0566917 | BT16: 0.32087627 | BU16: 158.67984 | BV16: -3.0546082 | BW16: 2.8552816 | BX16: 158.67373 | BY16: 0.54182291 | BZ16: 4.3457427 | CA16: 158.63512 | CB16: 3.1997768 | CC16: 2.8832288 | CD16: 158.69689 | CE16: 4.0553609 | CF16: 0.30581106 | CG16: 158.75852 | CH16: 3.8349553 | CI16: -1.0813052 | CN16: =(BR16-BR$10)*1000 -> -0.85792806 | CO16: =(BS16-BS$10)*1000 -> -0.28975754 | CP16: =(BT16-BT$10)*1000 -> -0.091420719 | CQ16: =(BU16-BU$10)*1000 -> -0.13899319 | CR16: =(BV16-BV$10)*1000 -> -0.17515967 | CS16: =(BW16-BW$10)*1000 -> -0.69861007 | CT16: =(BX16-BX$10)*1000 -> 2.549389 | CU16: =(BY16-BY$10)*1000 -> -0.024821604 | ... DE16: =(CI16-CI$10)*1000 -> -0.006161081
A17: 44337 | B17: =A17-$A$10 -> 197 | C17: 222.9 | D17: =C17-PM -> 64.9 | H17: 823209.74 | I17: 1091504.3 | J17: -123.6359 | K17: 823210.19 | L17: 1091503.4 | M17: -121.1008 | N17: 823211.71 | O17: 1091500.2 | P17: -119.6106 | Q17: 823212.8 | R17: 1091497.7 | S17: -121.073 | T17: 823213.21 | U17: 1091497 | V17: -123.65 | W17: 823213.18 | X17: 1091497.2 | Y17: -125.0366 | AA17: =IF(Xhaut="","",SQRT(((Xintergauche-Xhaut)^2+(Yintergauche-Yhaut)^2)+(Zintergauche-Zhaut)^2)) -> 6.110881 | AB17: =IF(Xhaut="","",SQRT(((Xhautgauche-Xhaut)^2+(Yhautgauche-Yhaut)^2)+(Zhautgauche-Zhaut)^2)) -> 3.8930326 | AC17: =IF(Xhaut="","",SQRT(((Xhautdroit-Xhaut)^2+(Yhautdroit-Yhaut)^2)+(Zhautdroit-Zhaut)^2)) -> 3.0339452 | AD17: =IF(Xhaut="","",SQRT(((Xinterdroit-Xhaut)^2+(Yinterdroit-Yhaut)^2)+(Zinterdroit-Zhaut)^2)) -> 5.3536814 | AE17: =IF(Xhaut="","",SQRT(((Xbasdroit-Xhaut)^2+(Ybasdroit-Yhaut)^2)+(Zbasdroit-Zhaut)^2)) -> 6.3476606 | AF17: =IF(Xhautdroit="","",SQRT(((Xhautdroit-Xhautgauche)^2+(Yhautdroit-Yhautgauche)^2)+(Zhautdroit-Zhautgauche)^2)) -> 6.2546976 | AG17: =IF(Xinterdroit="","",SQRT(((Xinterdroit-Xintergauche)^2+(Yinterdroit-Yintergauche)^2)+(Zinterdroit-Zintergauche)^2)) -> 8.1113857 | AJ17: =(AA17-AA$10)*1000 -> -1.9218127 | AK17: =(AB17-AB$10)*1000 -> -0.54852353 | AL17: =(AC17-AC$10)*1000 -> -0.77899284 | AM17: =(AD17-AD$10)*1000 -> -2.3145804 | AN17: =(AE17-AE$10)*1000 -> -2.5623034 | AO17: =(AF17-AF$10)*1000 -> 0.30580711 | AP17: =(AG17-AG$10)*1000 -> -1.3077968 | AV17: =(H17-H$10)*1000 -> 0.80000004 | AW17: =(I17-I$10)*1000 -> 0.10000006 | AX17: =(J17-J$10)*1000 -> -0.4 | AY17: =(K17-K$10)*1000 -> 0.20000001 | AZ17: =(L17-L$10)*1000 -> 0.69999998 | BA17: =(M17-M$10)*1000 -> -0.7 | BB17: =(N17-N$10)*1000 -> 2.7 | BC17: =(O17-O$10)*1000 -> 1.6000001 | ... BM17: =(Y17-Y$10)*1000 -> 0 | BR17: 158.642 | BS17: -4.0561544 | BT17: 0.32056002 | BU17: 158.68045 | BV17: -3.0549829 | BW17: 2.8552755 | BX17: 158.6743 | BY17: 0.54153882 | BZ17: 4.345537 | CA17: 158.63569 | CB17: 3.1994927 | CC17: 2.8835231 | CD17: 158.6976 | CE17: 4.0550285 | CF17: 0.30590399 | CG17: 158.75936 | CH17: 3.8345745 | CI17: -1.0813136 | CN17: =(BR17-BR$10)*1000 -> 0.7672989 | CO17: =(BS17-BS$10)*1000 -> 0.24749236 | CP17: =(BT17-BT$10)*1000 -> -0.40767299 | CQ17: =(BU17-BU$10)*1000 -> 0.47711481 | CR17: =(BV17-BV$10)*1000 -> -0.54987401 | CS17: =(BW17-BW$10)*1000 -> -0.70477115 | CT17: =(BX17-BX$10)*1000 -> 3.1232317 | CU17: =(BY17-BY$10)*1000 -> -0.30890694 | ... DE17: =(CI17-CI$10)*1000 -> -0.014557398
A18: 44351 | B18: =A18-$A$10 -> 211 | C18: 222.9 | D18: =C18-PM -> 64.9 | E18: 823209.97 | F18: 1091504.2 | G18: -125.0086 | H18: 823209.73 | I18: 1091504.3 | J18: -123.6367 | K18: 823210.19 | L18: 1091503.4 | M18: -121.1019 | N18: 823211.71 | O18: 1091500.2 | P18: -119.6112 | Q18: 823212.8 | R18: 1091497.8 | S18: -121.0743 | T18: 823213.21 | U18: 1091497 | V18: -123.6509 | W18: 823213.18 | X18: 1091497.2 | Y18: -125.0377 | Z18: =IF(Xhaut="","",SQRT(((Xbasgauche-Xhaut)^2+(Ybasgauche-Yhaut)^2)+(Zbasgauche-Zhaut)^2)) -> 6.933662 | AA18: =IF(Xhaut="","",SQRT(((Xintergauche-Xhaut)^2+(Yintergauche-Yhaut)^2)+(Zintergauche-Zhaut)^2)) -> 6.1115106 | AB18: =IF(Xhaut="","",SQRT(((Xhautgauche-Xhaut)^2+(Yhautgauche-Yhaut)^2)+(Zhautgauche-Zhaut)^2)) -> 3.8930295 | AC18: =IF(Xhaut="","",SQRT(((Xhautdroit-Xhaut)^2+(Yhautdroit-Yhaut)^2)+(Zhautdroit-Zhaut)^2)) -> 3.0342745 | AD18: =IF(Xhaut="","",SQRT(((Xinterdroit-Xhaut)^2+(Yinterdroit-Yhaut)^2)+(Zinterdroit-Zhaut)^2)) -> 5.3537862 | AE18: =IF(Xhaut="","",SQRT(((Xbasdroit-Xhaut)^2+(Ybasdroit-Yhaut)^2)+(Zbasdroit-Zhaut)^2)) -> 6.3481575 | AF18: =IF(Xhautdroit="","",SQRT(((Xhautdroit-Xhautgauche)^2+(Yhautdroit-Yhautgauche)^2)+(Zhautdroit-Zhautgauche)^2)) -> 6.254481 | AG18: =IF(Xinterdroit="","",SQRT(((Xinterdroit-Xintergauche)^2+(Yinterdroit-Yintergauche)^2)+(Zinterdroit-Zintergauche)^2)) -> 8.1118623 | AH18: =IF(Xbasdroit="","",SQRT(((Xbasdroit-Xbasgauche)^2+(Ybasdroit-Ybasgauche)^2)+(Zbasdroit-Zbasgauche)^2)) -> 7.6443802 | AI18: =(Z18-Z$10)*1000 -> -1.2857064 | AJ18: =(AA18-AA$10)*1000 -> -1.2922412 | AK18: =(AB18-AB$10)*1000 -> -0.55158026 | AL18: =(AC18-AC$10)*1000 -> -0.44970008 | AM18: =(AD18-AD$10)*1000 -> -2.2098253 | AN18: =(AE18-AE$10)*1000 -> -2.065472 | AO18: =(AF18-AF$10)*1000 -> 0.089151975 | AP18: =(AG18-AG$10)*1000 -> -0.83127996 | AQ18: =(AH18-AH$10)*1000 -> -0.18866621 | AS18: =(E18-E$10)*1000 -> -1.1 | AT18: =(F18-F$10)*1000 -> 1.3000001 | AU18: =(G18-G$10)*1000 -> -1.6 | AV18: =(H18-H$10)*1000 -> -0.80000004 | AW18: =(I18-I$10)*1000 -> 1.4 | AX18: =(J18-J$10)*1000 -> -1.2 | AY18: =(K18-K$10)*1000 -> -0.20000001 | AZ18: =(L18-L$10)*1000 -> 1.6000001 | ... BM18: =(Y18-Y$10)*1000 -> -1.1 | BO18: 158.78058 | BP18: -3.8107897 | BQ18: -1.0535258 | BR18: 158.6411 | BS18: -4.0580088 | BT18: 0.31976902 | BU18: 158.68047 | BV18: -3.0559677 | BW18: 2.8541753 | BX18: 158.67387 | BY18: 0.54034277 | BZ18: 4.3449413 | CA18: 158.63548 | CB18: 3.1982906 | CC18: 2.8822252 | CD18: 158.69747 | CE18: 4.0536451 | CF18: 0.30500526 | CG18: 158.7592 | CH18: 3.8335052 | CI18: -1.082412 | CK18: =(BO18-BO$10)*1000 -> -0.44747358 | CL18: =(BP18-BP$10)*1000 -> -1.643097 | CM18: =(BQ18-BQ$10)*1000 -> -1.5955253 | CN18: =(BR18-BR$10)*1000 -> -0.13332088 | CO18: =(BS18-BS$10)*1000 -> -1.6069304 | CP18: =(BT18-BT$10)*1000 -> -1.1986668 | CQ18: =(BU18-BU$10)*1000 -> 0.49498483 | CR18: =(BV18-BV$10)*1000 -> -1.5345978 | ... DE18: =(CI18-CI$10)*1000 -> -1.1129235
A19: 44357 | B19: =A19-$A$10 -> 217 | C19: 222.9 | D19: =C19-PM -> 64.9 | E19: 823209.97 | F19: 1091504.2 | G19: -125.0071 | H19: 823209.73 | I19: 1091504.3 | J19: -123.6353 | K19: 823210.19 | L19: 1091503.4 | M19: -121.1003 | N19: 823211.71 | O19: 1091500.2 | P19: -119.6096 | Q19: 823212.8 | R19: 1091497.7 | S19: -121.0729 | T19: 823213.21 | U19: 1091497 | V19: -123.6495 | W19: 823213.18 | X19: 1091497.2 | Y19: -125.0362 | Z19: =IF(Xhaut="","",SQRT(((Xbasgauche-Xhaut)^2+(Ybasgauche-Yhaut)^2)+(Zbasgauche-Zhaut)^2)) -> 6.9334991 | AA19: =IF(Xhaut="","",SQRT(((Xintergauche-Xhaut)^2+(Yintergauche-Yhaut)^2)+(Zintergauche-Zhaut)^2)) -> 6.1115166 | AB19: =IF(Xhaut="","",SQRT(((Xhautgauche-Xhaut)^2+(Yhautgauche-Yhaut)^2)+(Zhautgauche-Zhaut)^2)) -> 3.8931851 | AC19: =IF(Xhaut="","",SQRT(((Xhautdroit-Xhaut)^2+(Yhautdroit-Yhaut)^2)+(Zhautdroit-Zhaut)^2)) -> 3.034459 | AD19: =IF(Xhaut="","",SQRT(((Xinterdroit-Xhaut)^2+(Yinterdroit-Yhaut)^2)+(Zinterdroit-Zhaut)^2)) -> 5.354324 | AE19: =IF(Xhaut="","",SQRT(((Xbasdroit-Xhaut)^2+(Ybasdroit-Yhaut)^2)+(Zbasdroit-Zhaut)^2)) -> 6.3478944 | AF19: =IF(Xhautdroit="","",SQRT(((Xhautdroit-Xhautgauche)^2+(Yhautdroit-Yhautgauche)^2)+(Zhautdroit-Zhautgauche)^2)) -> 6.2547452 | AG19: =IF(Xinterdroit="","",SQRT(((Xinterdroit-Xintergauche)^2+(Yinterdroit-Yintergauche)^2)+(Zinterdroit-Zintergauche)^2)) -> 8.1122847 | AH19: =IF(Xbasdroit="","",SQRT(((Xbasdroit-Xbasgauche)^2+(Ybasdroit-Ybasgauche)^2)+(Zbasdroit-Zbasgauche)^2)) -> 7.6432979 | AI19: =(Z19-Z$10)*1000 -> -1.4485313 | AJ19: =(AA19-AA$10)*1000 -> -1.2862286 | AK19: =(AB19-AB$10)*1000 -> -0.39600253 | AL19: =(AC19-AC$10)*1000 -> -0.26515425 | AM19: =(AD19-AD$10)*1000 -> -1.6720181 | AN19: =(AE19-AE$10)*1000 -> -2.3285122 | AO19: =(AF19-AF$10)*1000 -> 0.35335709 | AP19: =(AG19-AG$10)*1000 -> -0.40881394 | AQ19: =(AH19-AH$10)*1000 -> -1.2708942 | AS19: =(E19-E$10)*1000 -> -0.80000004 | AT19: =(F19-F$10)*1000 -> -1.8 | AU19: =(G19-G$10)*1000 -> -0.1 | AV19: =(H19-H$10)*1000 -> -0.40000002 | AW19: =(I19-I$10)*1000 -> -1.4 | AX19: =(J19-J$10)*1000 -> 0.2 | AY19: =(K19-K$10)*1000 -> -0.80000004 | AZ19: =(L19-L$10)*1000 -> -1.2999999 | ... BM19: =(Y19-Y$10)*1000 -> 0.4 | BO19: 158.77954 | BP19: -3.8078534 | BQ19: -1.0520154 | BR19: 158.64028 | BS19: -4.0553022 | BT19: 0.32117723 | BU19: 158.6787 | BV19: -3.053593 | BW19: 2.855793 | BX19: 158.67246 | BY19: 0.54288649 | BZ19: 4.3465554 | CA19: 158.63381 | CB19: 3.200931 | CC19: 2.8836419 | CD19: 158.69568 | CE19: 4.0567809 | CF19: 0.3064232 | CG19: 158.75845 | CH19: 3.8353601 | CI19: -1.0809045 | CK19: =(BO19-BO$10)*1000 -> -1.4858073 | CL19: =(BP19-BP$10)*1000 -> 1.293204 | CM19: =(BQ19-BQ$10)*1000 -> -0.085141927 | CN19: =(BR19-BR$10)*1000 -> -0.95422963 | CO19: =(BS19-BS$10)*1000 -> 1.099748 | CP19: =(BT19-BT$10)*1000 -> 0.2095423 | CQ19: =(BU19-BU$10)*1000 -> -1.2744812 | CR19: =(BV19-BV$10)*1000 -> 0.84005794 | ... DE19: =(CI19-CI$10)*1000 -> 0.39462324
A20: 44364 | B20: =A20-$A$10 -> 224 | C20: 222.9 | D20: =C20-PM -> 64.9 | E20: 823209.97 | F20: 1091504.2 | G20: -125.0085 | H20: 823209.74 | I20: 1091504.3 | J20: -123.6367 | K20: 823210.19 | L20: 1091503.4 | M20: -121.1016 | N20: 823211.71 | O20: 1091500.2 | P20: -119.6107 | Q20: 823212.8 | R20: 1091497.7 | S20: -121.0739 | T20: 823213.21 | U20: 1091497 | V20: -123.6508 | Z20: =IF(Xhaut="","",SQRT(((Xbasgauche-Xhaut)^2+(Ybasgauche-Yhaut)^2)+(Zbasgauche-Zhaut)^2)) -> 6.9339628 | AA20: =IF(Xhaut="","",SQRT(((Xintergauche-Xhaut)^2+(Yintergauche-Yhaut)^2)+(Zintergauche-Zhaut)^2)) -> 6.1115494 | AB20: =IF(Xhaut="","",SQRT(((Xhautgauche-Xhaut)^2+(Yhautgauche-Yhaut)^2)+(Zhautgauche-Zhaut)^2)) -> 3.8929834 | AC20: =IF(Xhaut="","",SQRT(((Xhautdroit-Xhaut)^2+(Yhautdroit-Yhaut)^2)+(Zhautdroit-Zhaut)^2)) -> 3.0341987 | AD20: =IF(Xhaut="","",SQRT(((Xinterdroit-Xhaut)^2+(Yinterdroit-Yhaut)^2)+(Zinterdroit-Zhaut)^2)) -> 5.3540287 | AF20: =IF(Xhautdroit="","",SQRT(((Xhautdroit-Xhautgauche)^2+(Yhautdroit-Yhautgauche)^2)+(Zhautdroit-Zhautgauche)^2)) -> 6.2542086 | AG20: =IF(Xinterdroit="","",SQRT(((Xinterdroit-Xintergauche)^2+(Yinterdroit-Yintergauche)^2)+(Zinterdroit-Zintergauche)^2)) -> 8.1113857 | AH20: =IF(Xbasdroit="","",SQRT(((Xbasdroit-Xbasgauche)^2+(Ybasdroit-Ybasgauche)^2)+(Zbasdroit-Zbasgauche)^2)) | AI20: =(Z20-Z$10)*1000 -> -0.98490007 | AJ20: =(AA20-AA$10)*1000 -> -1.2533966 | AK20: =(AB20-AB$10)*1000 -> -0.5976732 | AL20: =(AC20-AC$10)*1000 -> -0.52544248 | AM20: =(AD20-AD$10)*1000 -> -1.9672819 | AO20: =(AF20-AF$10)*1000 -> -0.18319487 | AP20: =(AG20-AG$10)*1000 -> -1.3077968 | AS20: =(E20-E$10)*1000 -> -0.9000001 | AT20: =(F20-F$10)*1000 -> -1.9 | AU20: =(G20-G$10)*1000 -> -1.5 | AV20: =(H20-H$10)*1000 -> -0.20000001 | AW20: =(I20-I$10)*1000 -> -2.0000001 | AX20: =(J20-J$10)*1000 -> -1.2 | AY20: =(K20-K$10)*1000 -> -0.40000002 | AZ20: =(L20-L$10)*1000 -> -1.9 | ... BJ20: =(V20-V$10)*1000 -> -1.1 | BO20: 158.77941 | BP20: -3.807805 | BQ20: -1.0534141 | BR20: 158.6402 | BS20: -4.0546738 | BT20: 0.31977795 | BU20: 158.67881 | BV20: -3.0528802 | BW20: 2.8544919 | BX20: 158.67216 | BY20: 0.54329737 | BZ20: 4.3454584 | CA20: 158.63395 | CB20: 3.2011062 | CC20: 2.8826405 | CD20: 158.69581 | CE20: 4.0565091 | CF20: 0.30512193 | CK20: =(BO20-BO$10)*1000 -> -1.6187018 | CL20: =(BP20-BP$10)*1000 -> 1.3415681 | CM20: =(BQ20-BQ$10)*1000 -> -1.483813 | CN20: =(BR20-BR$10)*1000 -> -1.0265625 | CO20: =(BS20-BS$10)*1000 -> 1.7280538 | CP20: =(BT20-BT$10)*1000 -> -1.1897344 | CQ20: =(BU20-BU$10)*1000 -> -1.1655557 | CR20: =(BV20-BV$10)*1000 -> 1.5528941 | ... DB20: =(CF20-CF$10)*1000 -> -1.0947452
A21: 44378 | B21: =A21-$A$10 -> 238 | C21: 222.9 | D21: =C21-PM -> 64.9 | E21: 823209.97 | F21: 1091504.2 | G21: -125.0074 | H21: 823209.74 | I21: 1091504.3 | J21: -123.6357 | K21: 823210.19 | L21: 1091503.4 | M21: -121.1012 | N21: 823211.71 | O21: 1091500.2 | P21: -119.6101 | Q21: 823212.8 | R21: 1091497.7 | S21: -121.0732 | T21: 823213.21 | U21: 1091497 | V21: -123.65 | Z21: =IF(Xhaut="","",SQRT(((Xbasgauche-Xhaut)^2+(Ybasgauche-Yhaut)^2)+(Zbasgauche-Zhaut)^2)) -> 6.9331385 | AA21: =IF(Xhaut="","",SQRT(((Xintergauche-Xhaut)^2+(Yintergauche-Yhaut)^2)+(Zintergauche-Zhaut)^2)) -> 6.1112043 | AB21: =IF(Xhaut="","",SQRT(((Xhautgauche-Xhaut)^2+(Yhautgauche-Yhaut)^2)+(Zhautgauche-Zhaut)^2)) -> 3.8928925 | AC21: =IF(Xhaut="","",SQRT(((Xhautdroit-Xhaut)^2+(Yhautdroit-Yhaut)^2)+(Zhautdroit-Zhaut)^2)) -> 3.0339353 | AD21: =IF(Xhaut="","",SQRT(((Xinterdroit-Xhaut)^2+(Yinterdroit-Yhaut)^2)+(Zinterdroit-Zhaut)^2)) -> 5.3541803 | AF21: =IF(Xhautdroit="","",SQRT(((Xhautdroit-Xhautgauche)^2+(Yhautdroit-Yhautgauche)^2)+(Zhautdroit-Zhautgauche)^2)) -> 6.2537784 | AG21: =IF(Xinterdroit="","",SQRT(((Xinterdroit-Xintergauche)^2+(Yinterdroit-Yintergauche)^2)+(Zinterdroit-Zintergauche)^2)) -> 8.1117383 | AH21: =IF(Xbasdroit="","",SQRT(((Xbasdroit-Xbasgauche)^2+(Ybasdroit-Ybasgauche)^2)+(Zbasdroit-Zbasgauche)^2)) | AI21: =(Z21-Z$10)*1000 -> -1.8091862 | AJ21: =(AA21-AA$10)*1000 -> -1.5984636 | AK21: =(AB21-AB$10)*1000 -> -0.68865324 | AL21: =(AC21-AC$10)*1000 -> -0.78890239 | AM21: =(AD21-AD$10)*1000 -> -1.8156964 | AO21: =(AF21-AF$10)*1000 -> -0.61338151 | AP21: =(AG21-AG$10)*1000 -> -0.95522586 | AS21: =(E21-E$10)*1000 -> -0.20000001 | AT21: =(F21-F$10)*1000 -> -2.0999999 | AU21: =(G21-G$10)*1000 -> -0.4 | AV21: =(H21-H$10)*1000 -> -0.20000001 | AW21: =(I21-I$10)*1000 -> -1.9 | AX21: =(J21-J$10)*1000 -> -0.2 | AY21: =(K21-K$10)*1000 -> 0.40000002 | AZ21: =(L21-L$10)*1000 -> -1.5 | ... BJ21: =(V21-V$10)*1000 -> -0.3 | BO21: 158.77996 | BP21: -3.8073279 | BQ21: -1.0523196 | BR21: 158.64025 | BS21: -4.0547645 | BT21: 0.32077753 | BU21: 158.67971 | BV21: -3.0529046 | BW21: 2.8548829 | BX21: 158.67314 | BY21: 0.54309171 | BZ21: 4.3460486 | CA21: 158.63438 | CB21: 3.200647 | CC21: 2.8833362 | CD21: 158.69613 | CE21: 4.0567687 | CF21: 0.30591873 | CK21: =(BO21-BO$10)*1000 -> -1.0688276 | CL21: =(BP21-BP$10)*1000 -> 1.8186828 | CM21: =(BQ21-BQ$10)*1000 -> -0.38931172 | CN21: =(BR21-BR$10)*1000 -> -0.98429725 | CO21: =(BS21-BS$10)*1000 -> 1.6374245 | CP21: =(BT21-BT$10)*1000 -> -0.19015703 | CQ21: =(BU21-BU$10)*1000 -> -0.27146118 | CR21: =(BV21-BV$10)*1000 -> 1.5284989 | ... DB21: =(CF21-CF$10)*1000 -> -0.29794773
A22: 44392 | B22: =A22-$A$10 -> 252 | C22: 222.9 | D22: =C22-PM -> 64.9 | E22: 823209.97 | F22: 1091504.2 | G22: -125.0076 | H22: 823209.74 | I22: 1091504.3 | J22: -123.6358 | K22: 823210.19 | L22: 1091503.4 | M22: -121.1008 | N22: 823211.71 | O22: 1091500.2 | P22: -119.6105 | Q22: 823212.8 | R22: 1091497.7 | S22: -121.0735 | T22: 823213.21 | U22: 1091497 | V22: -123.6501 | Z22: =IF(Xhaut="","",SQRT(((Xbasgauche-Xhaut)^2+(Ybasgauche-Yhaut)^2)+(Zbasgauche-Zhaut)^2)) -> 6.933166 | AA22: =IF(Xhaut="","",SQRT(((Xintergauche-Xhaut)^2+(Yintergauche-Yhaut)^2)+(Zintergauche-Zhaut)^2)) -> 6.1110713 | AB22: =IF(Xhaut="","",SQRT(((Xhautgauche-Xhaut)^2+(Yhautgauche-Yhaut)^2)+(Zhautgauche-Zhaut)^2)) -> 3.892607 | AC22: =IF(Xhaut="","",SQRT(((Xhautdroit-Xhaut)^2+(Yhautdroit-Yhaut)^2)+(Zhautdroit-Zhaut)^2)) -> 3.0338789 | AD22: =IF(Xhaut="","",SQRT(((Xinterdroit-Xhaut)^2+(Yinterdroit-Yhaut)^2)+(Zinterdroit-Zhaut)^2)) -> 5.3536575 | AF22: =IF(Xhautdroit="","",SQRT(((Xhautdroit-Xhautgauche)^2+(Yhautdroit-Yhautgauche)^2)+(Zhautdroit-Zhautgauche)^2)) -> 6.2537862 | AG22: =IF(Xinterdroit="","",SQRT(((Xinterdroit-Xintergauche)^2+(Yinterdroit-Yintergauche)^2)+(Zinterdroit-Zintergauche)^2)) -> 8.1113724 | AH22: =IF(Xbasdroit="","",SQRT(((Xbasdroit-Xbasgauche)^2+(Ybasdroit-Ybasgauche)^2)+(Zbasdroit-Zbasgauche)^2)) | AI22: =(Z22-Z$10)*1000 -> -1.7817197 | AJ22: =(AA22-AA$10)*1000 -> -1.7314986 | AK22: =(AB22-AB$10)*1000 -> -0.97407633 | AL22: =(AC22-AC$10)*1000 -> -0.84531466 | AM22: =(AD22-AD$10)*1000 -> -2.3385191 | AO22: =(AF22-AF$10)*1000 -> -0.6056662 | AP22: =(AG22-AG$10)*1000 -> -1.3211182 | AS22: =(E22-E$10)*1000 -> -0.60000003 | AT22: =(F22-F$10)*1000 -> -1.8 | AU22: =(G22-G$10)*1000 -> -0.6 | AV22: =(H22-H$10)*1000 -> -0.29999996 | AW22: =(I22-I$10)*1000 -> -1.6999999 | AX22: =(J22-J$10)*1000 -> -0.3 | AY22: =(K22-K$10)*1000 -> -0.20000001 | AZ22: =(L22-L$10)*1000 -> -1.6000001 | ... BJ22: =(V22-V$10)*1000 -> -0.4 | BO22: 158.77972 | BP22: -3.8077688 | BQ22: -1.0525172 | BR22: 158.64024 | BS22: -4.054988 | BT22: 0.32067759 | BU22: 158.67912 | BV22: -3.0530675 | BW22: 2.8552888 | BX22: 158.67331 | BY22: 0.54295272 | BZ22: 4.3456469 | CA22: 158.63478 | CB22: 3.2005019 | CC22: 2.8830322 | CD22: 158.69651 | CE22: 4.0561766 | CF22: 0.30581486 | CK22: =(BO22-BO$10)*1000 -> -1.3045489 | CL22: =(BP22-BP$10)*1000 -> 1.3777344 | CM22: =(BQ22-BQ$10)*1000 -> -0.58695451 | CN22: =(BR22-BR$10)*1000 -> -0.99039595 | CO22: =(BS22-BS$10)*1000 -> 1.4139008 | CP22: =(BT22-BT$10)*1000 -> -0.29009604 | CQ22: =(BU22-BU$10)*1000 -> -0.85750167 | CR22: =(BV22-BV$10)*1000 -> 1.3655369 | ... DB22: =(CF22-CF$10)*1000 -> -0.40181258
A23: 44410 | B23: =A23-$A$10 -> 270 | C23: 222.9 | D23: =C23-PM -> 64.9 | E23: 823209.97 | F23: 1091504.2 | G23: -125.0077 | H23: 823209.74 | I23: 1091504.3 | J23: -123.6359 | K23: 823210.19 | L23: 1091503.4 | M23: -121.1011 | N23: 823211.71 | O23: 1091500.2 | P23: -119.6106 | Q23: 823212.8 | R23: 1091497.7 | S23: -121.0736 | T23: 823213.21 | U23: 1091497 | V23: -123.6502 | Z23: =IF(Xhaut="","",SQRT(((Xbasgauche-Xhaut)^2+(Ybasgauche-Yhaut)^2)+(Zbasgauche-Zhaut)^2)) -> 6.9331554 | AA23: =IF(Xhaut="","",SQRT(((Xintergauche-Xhaut)^2+(Yintergauche-Yhaut)^2)+(Zintergauche-Zhaut)^2)) -> 6.1109524 | AB23: =IF(Xhaut="","",SQRT(((Xhautgauche-Xhaut)^2+(Yhautgauche-Yhaut)^2)+(Zhautgauche-Zhaut)^2)) -> 3.8926687 | AC23: =IF(Xhaut="","",SQRT(((Xhautdroit-Xhaut)^2+(Yhautdroit-Yhaut)^2)+(Zhautdroit-Zhaut)^2)) -> 3.0339147 | AD23: =IF(Xhaut="","",SQRT(((Xinterdroit-Xhaut)^2+(Yinterdroit-Yhaut)^2)+(Zinterdroit-Zhaut)^2)) -> 5.3535389 | AE23: =IF(Xbasdroit="","",SQRT(((Xbasdroit-Xbasgauche)^2+(Ybasdroit-Ybasgauche)^2)+(Zbasdroit-Zbasgauche)^2)) | AF23: =IF(Xhautdroit="","",SQRT(((Xhautdroit-Xhautgauche)^2+(Yhautdroit-Yhautgauche)^2)+(Zhautdroit-Zhautgauche)^2)) -> 6.2538178 | AG23: =IF(Xinterdroit="","",SQRT(((Xinterdroit-Xintergauche)^2+(Yinterdroit-Yintergauche)^2)+(Zinterdroit-Zintergauche)^2)) -> 8.1110339 | AH23: =IF(Xbasdroit="","",SQRT(((Xbasdroit-Xbasgauche)^2+(Ybasdroit-Ybasgauche)^2)+(Zbasdroit-Zbasgauche)^2)) | AI23: =(Z23-Z$10)*1000 -> -1.7923143 | AJ23: =(AA23-AA$10)*1000 -> -1.8504354 | AK23: =(AB23-AB$10)*1000 -> -0.91241484 | AL23: =(AC23-AC$10)*1000 -> -0.80944182 | AM23: =(AD23-AD$10)*1000 -> -2.4570973 | AO23: =(AF23-AF$10)*1000 -> -0.57399262 | AP23: =(AG23-AG$10)*1000 -> -1.6596579 | AS23: =(E23-E$10)*1000 -> -0.50000008 | AT23: =(F23-F$10)*1000 -> -1.9 | AU23: =(G23-G$10)*1000 -> -0.7 | AV23: =(H23-H$10)*1000 -> 0.29999996 | AW23: =(I23-I$10)*1000 -> -1.6999999 | AX23: =(J23-J$10)*1000 -> -0.4 | AY23: =(K23-K$10)*1000 -> 0.29999996 | AZ23: =(L23-L$10)*1000 -> -1.5 | ... BJ23: =(V23-V$10)*1000 -> -0.5 | BO23: 158.77977 | BP23: -3.8076359 | BQ23: -1.0526177 | BR23: 158.64078 | BS23: -4.0547344 | BT23: 0.32057216 | BU23: 158.67962 | BV23: -3.0529468 | BW23: 2.8549838 | BX23: 158.67282 | BY23: 0.54305555 | BZ23: 4.3455518 | CA23: 158.63438 | CB23: 3.200647 | CC23: 2.8829362 | CD23: 158.69611 | CE23: 4.0560982 | CF23: 0.30571891 | CK23: =(BO23-BO$10)*1000 -> -1.2561849 | CL23: =(BP23-BP$10)*1000 -> 1.5106289 | CM23: =(BQ23-BQ$10)*1000 -> -0.68743815 | CN23: =(BR23-BR$10)*1000 -> -0.4466208 | CO23: =(BS23-BS$10)*1000 -> 1.667492 | CP23: =(BT23-BT$10)*1000 -> -0.39553379 | CQ23: =(BU23-BU$10)*1000 -> -0.36209045 | CR23: =(BV23-BV$10)*1000 -> 1.4862337 | ... DB23: =(CF23-CF$10)*1000 -> -0.49776476
A24: 44453 | B24: =A24-$A$10 -> 313 | C24: 222.9 | D24: =C24-PM -> 64.9 | E24: 823209.97 | F24: 1091504.2 | G24: -125.0074 | H24: 823209.73 | I24: 1091504.3 | J24: -123.6358 | K24: 823210.19 | L24: 1091503.4 | M24: -121.1012 | N24: 823211.71 | O24: 1091500.2 | P24: -119.6121 | Q24: 823212.8 | R24: 1091497.7 | S24: -121.0738 | T24: 823213.21 | U24: 1091497 | V24: -123.6499 | W24: 823213.18 | X24: 1091497.2 | Y24: -125.0366 | Z24: =IF(Xhaut="","",SQRT(((Xbasgauche-Xhaut)^2+(Ybasgauche-Yhaut)^2)+(Zbasgauche-Zhaut)^2)) -> 6.9310136 | AA24: =IF(Xhaut="","",SQRT(((Xintergauche-Xhaut)^2+(Yintergauche-Yhaut)^2)+(Zintergauche-Zhaut)^2)) -> 6.1095485 | AB24: =IF(Xhaut="","",SQRT(((Xhautgauche-Xhaut)^2+(Yhautgauche-Yhaut)^2)+(Zhautgauche-Zhaut)^2)) -> 3.8915731 | AC24: =IF(Xhaut="","",SQRT(((Xhautdroit-Xhaut)^2+(Yhautdroit-Yhaut)^2)+(Zhautdroit-Zhaut)^2)) -> 3.0333485 | AD24: =IF(Xhaut="","",SQRT(((Xinterdroit-Xhaut)^2+(Yinterdroit-Yhaut)^2)+(Zinterdroit-Zhaut)^2)) -> 5.3521557 | AE24: =IF(Xhaut="","",SQRT(((Xbasdroit-Xhaut)^2+(Ybasdroit-Yhaut)^2)+(Zbasdroit-Zhaut)^2)) -> 6.3463559 | AF24: =IF(Xhautdroit="","",SQRT(((Xhautdroit-Xhautgauche)^2+(Yhautdroit-Yhautgauche)^2)+(Zhautdroit-Zhautgauche)^2)) -> 6.2532718 | AG24: =IF(Xinterdroit="","",SQRT(((Xinterdroit-Xintergauche)^2+(Yinterdroit-Yintergauche)^2)+(Zinterdroit-Zintergauche)^2)) -> 8.1105298 | AH24: =IF(Xbasdroit="","",SQRT(((Xbasdroit-Xbasgauche)^2+(Ybasdroit-Ybasgauche)^2)+(Zbasdroit-Zbasgauche)^2)) -> 7.6426195 | AI24: =(Z24-Z$10)*1000 -> -3.9340424 | AJ24: =(AA24-AA$10)*1000 -> -3.2543125 | AK24: =(AB24-AB$10)*1000 -> -2.0079744 | AL24: =(AC24-AC$10)*1000 -> -1.3756426 | AM24: =(AD24-AD$10)*1000 -> -3.8402827 | AN24: =(AE24-AE$10)*1000 -> -3.8670543 | AO24: =(AF24-AF$10)*1000 -> -1.1200165 | AP24: =(AG24-AG$10)*1000 -> -2.1637119 | AQ24: =(AH24-AH$10)*1000 -> -1.949363 | AS24: =(E24-E$10)*1000 -> -0.60000003 | AT24: =(F24-F$10)*1000 -> -2.9 | AU24: =(G24-G$10)*1000 -> -0.4 | AV24: =(H24-H$10)*1000 -> -0.60000003 | AW24: =(I24-I$10)*1000 -> -2.3000001 | AX24: =(J24-J$10)*1000 -> -0.3 | AY24: =(K24-K$10)*1000 -> -0.49999997 | AZ24: =(L24-L$10)*1000 -> -2.2 | ... BM24: =(Y24-Y$10)*1000 -> 0 | BO24: 158.77926 | BP24: -3.8067719 | BQ24: -1.0523126 | BR24: 158.63972 | BS24: -4.054571 | BT24: 0.32068285 | BU24: 158.67859 | BV24: -3.0526506 | BW24: 2.8548941 | BX24: 158.67263 | BY24: 0.54274749 | BZ24: 4.3440537 | CA24: 158.63362 | CB24: 3.2003995 | CC24: 2.8827438 | CD24: 158.69561 | CE24: 4.055754 | CF24: 0.30602392 | CG24: 158.75694 | CH24: 3.8357592 | CI24: -1.0812894 | CK24: =(BO24-BO$10)*1000 -> -1.7694661 | CL24: =(BP24-BP$10)*1000 -> 2.3746557 | CM24: =(BQ24-BQ$10)*1000 -> -0.38230534 | CN24: =(BR24-BR$10)*1000 -> -1.5158749 | CO24: =(BS24-BS$10)*1000 -> 1.8308805 | CP24: =(BT24-BT$10)*1000 -> -0.28484125 | CQ24: =(BU24-BU$10)*1000 -> -1.3829804 | CR24: =(BV24-BV$10)*1000 -> 1.7825165 | ... DE24: =(CI24-CI$10)*1000 -> 0.0097252604
A25: 44470 | B25: =A25-$A$10 -> 330 | C25: 222.9 | D25: =C25-PM -> 64.9 | E25: 823209.97 | F25: 1091504.2 | G25: -125.0077 | H25: 823209.74 | I25: 1091504.3 | J25: -123.636 | K25: 823210.19 | L25: 1091503.4 | M25: -121.1017 | N25: 823211.71 | O25: 1091500.2 | P25: -119.6112 | Q25: 823212.8 | R25: 1091497.7 | S25: -121.074 | T25: 823213.21 | U25: 1091497 | V25: -123.65 | W25: 823213.18 | X25: 1091497.2 | Y25: -125.0367 | Z25: =IF(Xhaut="","",SQRT(((Xbasgauche-Xhaut)^2+(Ybasgauche-Yhaut)^2)+(Zbasgauche-Zhaut)^2)) -> 6.9323504 | AA25: =IF(Xhaut="","",SQRT(((Xintergauche-Xhaut)^2+(Yintergauche-Yhaut)^2)+(Zintergauche-Zhaut)^2)) -> 6.1100861 | AB25: =IF(Xhaut="","",SQRT(((Xhautgauche-Xhaut)^2+(Yhautgauche-Yhaut)^2)+(Zhautgauche-Zhaut)^2)) -> 3.8922618 | AC25: =IF(Xhaut="","",SQRT(((Xhautdroit-Xhaut)^2+(Yhautdroit-Yhaut)^2)+(Zhautdroit-Zhaut)^2)) -> 3.0336666 | AD25: =IF(Xhaut="","",SQRT(((Xinterdroit-Xhaut)^2+(Yinterdroit-Yhaut)^2)+(Zinterdroit-Zhaut)^2)) -> 5.352664 | AE25: =IF(Xhaut="","",SQRT(((Xbasdroit-Xhaut)^2+(Ybasdroit-Yhaut)^2)+(Zbasdroit-Zhaut)^2)) -> 6.3467453 | AF25: =IF(Xhautdroit="","",SQRT(((Xhautdroit-Xhautgauche)^2+(Yhautdroit-Yhautgauche)^2)+(Zhautdroit-Zhautgauche)^2)) -> 6.2532054 | AG25: =IF(Xinterdroit="","",SQRT(((Xinterdroit-Xintergauche)^2+(Yinterdroit-Yintergauche)^2)+(Zinterdroit-Zintergauche)^2)) -> 8.1099064 | AH25: =IF(Xbasdroit="","",SQRT(((Xbasdroit-Xbasgauche)^2+(Ybasdroit-Ybasgauche)^2)+(Zbasdroit-Zbasgauche)^2)) -> 7.6423128 | AI25: =(Z25-Z$10)*1000 -> -2.5972493 | AJ25: =(AA25-AA$10)*1000 -> -2.7166835 | AK25: =(AB25-AB$10)*1000 -> -1.3193356 | AL25: =(AC25-AC$10)*1000 -> -1.0575521 | AM25: =(AD25-AD$10)*1000 -> -3.3320602 | AN25: =(AE25-AE$10)*1000 -> -3.4776104 | AO25: =(AF25-AF$10)*1000 -> -1.1864739 | AP25: =(AG25-AG$10)*1000 -> -2.7871167 | AQ25: =(AH25-AH$10)*1000 -> -2.2560363 | AS25: =(E25-E$10)*1000 -> -1 | AT25: =(F25-F$10)*1000 -> -3 | AU25: =(G25-G$10)*1000 -> -0.7 | AV25: =(H25-H$10)*1000 -> 0 | AW25: =(I25-I$10)*1000 -> -2.9 | AX25: =(J25-J$10)*1000 -> -0.5 | AY25: =(K25-K$10)*1000 -> 0 | AZ25: =(L25-L$10)*1000 -> -2.3999999 | ... BM25: =(Y25-Y$10)*1000 -> -0.1 | BO25: 158.77885 | BP25: -3.8068503 | BQ25: -1.0526085 | BR25: 158.64001 | BS25: -4.0537737 | BT25: 0.32047995 | BU25: 158.67896 | BV25: -3.052258 | BW25: 2.8543904 | BX25: 158.67193 | BY25: 0.54330347 | BZ25: 4.3449607 | CA25: 158.63336 | CB25: 3.2007197 | CC25: 2.8825464 | CD25: 158.69575 | CE25: 4.0559291 | CF25: 0.30592253 | CG25: 158.75778 | CH25: 3.8353784 | CI25: -1.0813978 | CK25: =(BO25-BO$10)*1000 -> -2.1742481 | CL25: =(BP25-BP$10)*1000 -> 2.2962241 | CM25: =(BQ25-BQ$10)*1000 -> -0.67825752 | CN25: =(BR25-BR$10)*1000 -> -1.2256908 | CO25: =(BS25-BS$10)*1000 -> 2.6282469 | CP25: =(BT25-BT$10)*1000 -> -0.48774309 | CQ25: =(BU25-BU$10)*1000 -> -1.0143648 | CR25: =(BV25-BV$10)*1000 -> 2.1751008 | ... DE25: =(CI25-CI$10)*1000 -> -0.098671055
A26: 44489 | B26: =A26-$A$10 -> 349 | C26: 222.9 | D26: =C26-PM -> 64.9 | E26: 823209.97 | F26: 1091504.2 | G26: -125.0079 | H26: 823209.73 | I26: 1091504.3 | J26: -123.6364 | K26: 823210.19 | L26: 1091503.4 | M26: -121.1017 | N26: 823211.71 | O26: 1091500.2 | P26: -119.6124 | Q26: 823212.8 | R26: 1091497.7 | S26: -121.0744 | T26: 823213.21 | U26: 1091497 | V26: -123.6503 | W26: 823213.18 | X26: 1091497.2 | Y26: -125.0372 | Z26: =IF(Xhaut="","",SQRT(((Xbasgauche-Xhaut)^2+(Ybasgauche-Yhaut)^2)+(Zbasgauche-Zhaut)^2)) -> 6.9314352 | AA26: =IF(Xhaut="","",SQRT(((Xintergauche-Xhaut)^2+(Yintergauche-Yhaut)^2)+(Zintergauche-Zhaut)^2)) -> 6.1096747 | AB26: =IF(Xhaut="","",SQRT(((Xhautgauche-Xhaut)^2+(Yhautgauche-Yhaut)^2)+(Zhautgauche-Zhaut)^2)) -> 3.8916886 | AC26: =IF(Xhaut="","",SQRT(((Xhautdroit-Xhaut)^2+(Yhautdroit-Yhaut)^2)+(Zhautdroit-Zhaut)^2)) -> 3.0333938 | AD26: =IF(Xhaut="","",SQRT(((Xinterdroit-Xhaut)^2+(Yinterdroit-Yhaut)^2)+(Zinterdroit-Zhaut)^2)) -> 5.3525057 | AE26: =IF(Xhaut="","",SQRT(((Xbasdroit-Xhaut)^2+(Ybasdroit-Yhaut)^2)+(Zbasdroit-Zhaut)^2)) -> 6.3465892 | AF26: =IF(Xhautdroit="","",SQRT(((Xhautdroit-Xhautgauche)^2+(Yhautdroit-Yhautgauche)^2)+(Zhautdroit-Zhautgauche)^2)) -> 6.2531959 | AG26: =IF(Xinterdroit="","",SQRT(((Xinterdroit-Xintergauche)^2+(Yinterdroit-Yintergauche)^2)+(Zinterdroit-Zintergauche)^2)) -> 8.1108525 | AH26: =IF(Xbasdroit="","",SQRT(((Xbasdroit-Xbasgauche)^2+(Ybasdroit-Ybasgauche)^2)+(Zbasdroit-Zbasgauche)^2)) -> 7.6430114 | AI26: =(Z26-Z$10)*1000 -> -3.5125152 | AJ26: =(AA26-AA$10)*1000 -> -3.1280761 | AK26: =(AB26-AB$10)*1000 -> -1.8925305 | AL26: =(AC26-AC$10)*1000 -> -1.3303977 | AM26: =(AD26-AD$10)*1000 -> -3.4902995 | AN26: =(AE26-AE$10)*1000 -> -3.6337625 | AO26: =(AF26-AF$10)*1000 -> -1.1959581 | AP26: =(AG26-AG$10)*1000 -> -1.8410301 | AQ26: =(AH26-AH$10)*1000 -> -1.5574682 | AS26: =(E26-E$10)*1000 -> -1 | AT26: =(F26-F$10)*1000 -> -2.7000001 | AU26: =(G26-G$10)*1000 -> -0.9 | AV26: =(H26-H$10)*1000 -> -0.60000003 | AW26: =(I26-I$10)*1000 -> -2.4999999 | AX26: =(J26-J$10)*1000 -> -0.9 | AY26: =(K26-K$10)*1000 -> -0.40000002 | AZ26: =(L26-L$10)*1000 -> -2.2 | ... BM26: =(Y26-Y$10)*1000 -> -0.6 | BO26: 158.77898 | BP26: -3.8071222 | BQ26: -1.0528098 | BR26: 158.63963 | BS26: -4.0543898 | BT26: 0.32008369 | BU26: 158.67869 | BV26: -3.0526083 | BW26: 2.8543931 | BX26: 158.67282 | BY26: 0.54283202 | BZ26: 4.3437518 | CA26: 158.6333 | CB26: 3.2003633 | CC26: 2.882147 | CD26: 158.69504 | CE26: 4.0562616 | CF26: 0.3056296 | CG26: 158.75703 | CH26: 3.8358014 | CI26: -1.0818903 | CK26: =(BO26-BO$10)*1000 -> -2.0474525 | CL26: =(BP26-BP$10)*1000 -> 2.0243366 | CM26: =(BQ26-BQ$10)*1000 -> -0.87952547 | CN26: =(BR26-BR$10)*1000 -> -1.6004053 | CO26: =(BS26-BS$10)*1000 -> 2.0121389 | CP26: =(BT26-BT$10)*1000 -> -0.88399595 | CQ26: =(BU26-BU$10)*1000 -> -1.2923513 | CR26: =(BV26-BV$10)*1000 -> 1.8247817 | ... DE26: =(CI26-CI$10)*1000 -> -0.59118103
A27: 44502 | B27: =A27-$A$10 -> 362 | C27: 222.9 | D27: =C27-PM -> 64.9 | E27: 823209.97 | F27: 1091504.2 | G27: -125.0068 | H27: 823209.74 | I27: 1091504.3 | J27: -123.6354 | K27: 823210.19 | L27: 1091503.4 | M27: -121.101 | N27: 823211.71 | O27: 1091500.2 | P27: -119.612 | Q27: 823212.8 | R27: 1091497.7 | S27: -121.0736 | T27: 823213.21 | U27: 1091497 | V27: -123.6494 | W27: 823213.18 | X27: 1091497.2 | Y27: -125.036 | Z27: =IF(Xhaut="","",SQRT(((Xbasgauche-Xhaut)^2+(Ybasgauche-Yhaut)^2)+(Zbasgauche-Zhaut)^2)) -> 6.930797 | AA27: =IF(Xhaut="","",SQRT(((Xintergauche-Xhaut)^2+(Yintergauche-Yhaut)^2)+(Zintergauche-Zhaut)^2)) -> 6.1091895 | AB27: =IF(Xhaut="","",SQRT(((Xhautgauche-Xhaut)^2+(Yhautgauche-Yhaut)^2)+(Zhautgauche-Zhaut)^2)) -> 3.8916247 | AC27: =IF(Xhaut="","",SQRT(((Xhautdroit-Xhaut)^2+(Yhautdroit-Yhaut)^2)+(Zhautdroit-Zhaut)^2)) -> 3.0332645 | AD27: =IF(Xhaut="","",SQRT(((Xinterdroit-Xhaut)^2+(Yinterdroit-Yhaut)^2)+(Zinterdroit-Zhaut)^2)) -> 5.3519695 | AE27: =IF(Xhaut="","",SQRT(((Xbasdroit-Xhaut)^2+(Ybasdroit-Yhaut)^2)+(Zbasdroit-Zhaut)^2)) -> 6.3458817 | AF27: =IF(Xhautdroit="","",SQRT(((Xhautdroit-Xhautgauche)^2+(Yhautdroit-Yhautgauche)^2)+(Zhautdroit-Zhautgauche)^2)) -> 6.2533288 | AG27: =IF(Xinterdroit="","",SQRT(((Xinterdroit-Xintergauche)^2+(Yinterdroit-Yintergauche)^2)+(Zinterdroit-Zintergauche)^2)) -> 8.1104913 | AH27: =IF(Xbasdroit="","",SQRT(((Xbasdroit-Xbasgauche)^2+(Ybasdroit-Ybasgauche)^2)+(Zbasdroit-Zbasgauche)^2)) -> 7.6427875 | AI27: =(Z27-Z$10)*1000 -> -4.1506635 | AJ27: =(AA27-AA$10)*1000 -> -3.6133332 | AK27: =(AB27-AB$10)*1000 -> -1.9564543 | AL27: =(AC27-AC$10)*1000 -> -1.4596928 | AM27: =(AD27-AD$10)*1000 -> -4.0264697 | AN27: =(AE27-AE$10)*1000 -> -4.3412591 | AO27: =(AF27-AF$10)*1000 -> -1.0629816 | AP27: =(AG27-AG$10)*1000 -> -2.2022094 | AQ27: =(AH27-AH$10)*1000 -> -1.7813546 | AS27: =(E27-E$10)*1000 -> -0.60000003 | AT27: =(F27-F$10)*1000 -> -3 | AU27: =(G27-G$10)*1000 -> 0.2 | AV27: =(H27-H$10)*1000 -> -0.10000006 | AW27: =(I27-I$10)*1000 -> -2.7000001 | AX27: =(J27-J$10)*1000 -> 0.1 | AY27: =(K27-K$10)*1000 -> -0.30000007 | AZ27: =(L27-L$10)*1000 -> -2.3999999 | ... BM27: =(Y27-Y$10)*1000 -> 0.6 | BO27: 158.77922 | BP27: -3.8066813 | BQ27: -1.0517122 | BR27: 158.64 | BS27: -4.0539972 | BT27: 0.32108001 | BU27: 158.67869 | BV27: -3.0523848 | BW27: 2.8550931 | BX27: 158.67247 | BY27: 0.54311001 | BZ27: 4.3441553 | CA27: 158.63336 | CB27: 3.2007197 | CC27: 2.8829464 | CD27: 158.69558 | CE27: 4.0562916 | CF27: 0.30652422 | CG27: 158.75726 | CH27: 3.8360189 | CI27: -1.0806926 | CK27: =(BO27-BO$10)*1000 -> -1.8117313 | CL27: =(BP27-BP$10)*1000 -> 2.465285 | CM27: =(BQ27-BQ$10)*1000 -> 0.21811731 | CN27: =(BR27-BR$10)*1000 -> -1.2317897 | CO27: =(BS27-BS$10)*1000 -> 2.4047234 | CP27: =(BT27-BT$10)*1000 -> 0.1123179 | CQ27: =(BU27-BU$10)*1000 -> -1.2862525 | CR27: =(BV27-BV$10)*1000 -> 2.0483052 | ... DE27: =(CI27-CI$10)*1000 -> 0.60652274
A28: 44915 | B28: =A28-$A$10 -> 775 | C28: 222.9 | D28: =C28-PM -> 64.9 | E28: 823209.97 | F28: 1091504.2 | G28: -125.0066 | H28: 823209.73 | I28: 1091504.3 | J28: -123.6361 | K28: 823210.19 | L28: 1091503.4 | M28: -121.1034 | N28: 823211.71 | O28: 1091500.2 | P28: -119.6173 | Q28: 823212.79 | R28: 1091497.8 | S28: -121.0772 | T28: 823213.21 | U28: 1091497 | V28: -123.6501 | W28: 823213.18 | X28: 1091497.2 | Y28: -125.0359 | Z28: =IF(Xhaut="","",SQRT(((Xbasgauche-Xhaut)^2+(Ybasgauche-Yhaut)^2)+(Zbasgauche-Zhaut)^2)) -> 6.9248695 | AA28: =IF(Xhaut="","",SQRT(((Xintergauche-Xhaut)^2+(Yintergauche-Yhaut)^2)+(Zintergauche-Zhaut)^2)) -> 6.1051666 | AB28: =IF(Xhaut="","",SQRT(((Xhautgauche-Xhaut)^2+(Yhautgauche-Yhaut)^2)+(Zhautgauche-Zhaut)^2)) -> 3.8888337 | AC28: =IF(Xhaut="","",SQRT(((Xhautdroit-Xhaut)^2+(Yhautdroit-Yhaut)^2)+(Zhautdroit-Zhaut)^2)) -> 3.0303802 | AD28: =IF(Xhaut="","",SQRT(((Xinterdroit-Xhaut)^2+(Yinterdroit-Yhaut)^2)+(Zinterdroit-Zhaut)^2)) -> 5.3473098 | AE28: =IF(Xhaut="","",SQRT(((Xbasdroit-Xhaut)^2+(Ybasdroit-Yhaut)^2)+(Zbasdroit-Zhaut)^2)) -> 6.3401057 | AF28: =IF(Xhautdroit="","",SQRT(((Xhautdroit-Xhautgauche)^2+(Yhautdroit-Yhautgauche)^2)+(Zhautdroit-Zhautgauche)^2)) -> 6.2491378 | AG28: =IF(Xinterdroit="","",SQRT(((Xinterdroit-Xintergauche)^2+(Yinterdroit-Yintergauche)^2)+(Zinterdroit-Zintergauche)^2)) -> 8.1073569 | AH28: =IF(Xbasdroit="","",SQRT(((Xbasdroit-Xbasgauche)^2+(Ybasdroit-Ybasgauche)^2)+(Zbasdroit-Zbasgauche)^2)) -> 7.6379481 | AI28: =(Z28-Z$10)*1000 -> -10.078161 | AJ28: =(AA28-AA$10)*1000 -> -7.6362567 | AK28: =(AB28-AB$10)*1000 -> -4.7473929 | AL28: =(AC28-AC$10)*1000 -> -4.3440209 | AM28: =(AD28-AD$10)*1000 -> -8.6862591 | AN28: =(AE28-AE$10)*1000 -> -10.117233 | AO28: =(AF28-AF$10)*1000 -> -5.2539884 | AP28: =(AG28-AG$10)*1000 -> -5.336612 | AQ28: =(AH28-AH$10)*1000 -> -6.6207772 | AS28: =(E28-E$10)*1000 -> 0.20000001 | AT28: =(F28-F$10)*1000 -> -4 | AU28: =(G28-G$10)*1000 -> 0.4 | AV28: =(H28-H$10)*1000 -> -0.40000002 | AW28: =(I28-I$10)*1000 -> -2.7999999 | AX28: =(J28-J$10)*1000 -> -0.6 | AY28: =(K28-K$10)*1000 -> -0.30000007 | AZ28: =(L28-L$10)*1000 -> -2.9 | ... BM28: =(Y28-Y$10)*1000 -> 0.7 | BO28: 158.77952 | BP28: -3.8054369 | BQ28: -1.0515152 | BR28: 158.63969 | BS28: -4.0540333 | BT28: 0.32038315 | BU28: 158.67848 | BV28: -3.0519316 | BW28: 2.8526952 | BX28: 158.67332 | BY28: 0.54174447 | BZ28: 4.3388468 | CA28: 158.63388 | CB28: 3.1969921 | CC28: 2.8793412 | CD28: 158.6954 | CE28: 4.05312 | CF28: 0.30582598 | CG28: 158.75783 | CH28: 3.8324242 | CI28: -1.0805983 | CK28: =(BO28-BO$10)*1000 -> -1.5093496 | CL28: =(BP28-BP$10)*1000 -> 3.7096986 | CM28: =(BQ28-BQ$10)*1000 -> 0.4150935 | CN28: =(BR28-BR$10)*1000 -> -1.5459424 | CO28: =(BS28-BS$10)*1000 -> 2.3685568 | CP28: =(BT28-BT$10)*1000 -> -0.58454058 | CQ28: =(BU28-BU$10)*1000 -> -1.4975785 | CR28: =(BV28-BV$10)*1000 -> 2.5014513 | ... DE28: =(CI28-CI$10)*1000 -> 0.70079284

Sheet Convergences
U1: Laboratoire ANDRA - Bure
U2: Chantier 4
A5: CARREFOUR GCR2 - GVA2 - GVA3 - CONVERGENCE T12-T13 ( PM158 )
D8: Ecarts ( en mm ) | R8: Vitesse de convergence ( en mm/j )
A9: Temps (j) | B9: Date | C9: Distance au front | D9: BG | E9: IG | F9: HG | G9: HD | H9: ID | I9: BD | J9: LH | K9: LI | L9: LB | R9: BG | S9: IG | T9: HG | U9: HD | V9: ID | W9: BD | X9: LH | Y9: LI | Z9: LB
A10: =jours -> 0 | B10: =date -> 44140 | C10: ='Résultats observations'!C10 -> 222.9 | D10: =Ecart_BG -> 0 | E10: =Ecart_IG -> 0 | F10: =Ecart_HG -> 0 | G10: =Ecart_HD -> 0 | H10: =Ecart_ID -> 0 | I10: =Ecart_BD -> 0 | J10: =Ecart_LH -> 0 | K10: =Ecart_LI -> 0 | L10: =Ecart_LB -> 0
A11: =jours -> 32 | B11: =date -> 44172 | C11: ='Résultats observations'!C11 -> 222.9 | D11: =Ecart_BG -> -0.6875872 | E11: =Ecart_IG -> -0.72642608 | F11: =Ecart_HG -> 0.041681278 | G11: =Ecart_HD -> -0.35378594 | H11: =Ecart_ID -> -0.38209469 | I11: =Ecart_BD -> -0.550325 | J11: =Ecart_LH -> -0.55548392 | K11: =Ecart_LI -> -1.1694789 | L11: =Ecart_LB -> -1.0609457 | R11: =IF(AND(D11<>"",D10<>""),(D11-D10)/($B11-$B10),"") -> -0.0214871 | S11: =IF(AND(E11<>"",E10<>""),(E11-E10)/($B11-$B10),"") -> -0.022700815 | T11: =IF(AND(F11<>"",F10<>""),(F11-F10)/($B11-$B10),"") -> 0.0013025399 | U11: =IF(AND(G11<>"",G10<>""),(G11-G10)/($B11-$B10),"") -> -0.011055811 | V11: =IF(AND(H11<>"",H10<>""),(H11-H10)/($B11-$B10),"") -> -0.011940459 | W11: =IF(AND(I11<>"",I10<>""),(I11-I10)/($B11-$B10),"") -> -0.017197656 | X11: =IF(AND(J11<>"",J10<>""),(J11-J10)/($B11-$B10),"") -> -0.017358873 | Y11: =IF(AND(K11<>"",K10<>""),(K11-K10)/($B11-$B10),"") -> -0.036546216 | Z11: =IF(AND(L11<>"",L10<>""),(L11-L10)/($B11-$B10),"") -> -0.033154554
A12: =jours -> 89 | B12: =date -> 44229 | C12: ='Résultats observations'!C12 -> 222.9 | D12: =Ecart_BG -> 0.42333119 | E12: =Ecart_IG -> 0.22597956 | F12: =Ecart_HG -> 1.0893534 | G12: =Ecart_HD -> 0.48850447 | H12: =Ecart_ID -> -0.77968191 | J12: =Ecart_LH -> 1.8941284 | K12: =Ecart_LI -> 0.55717374 | R12: =IF(AND(D12<>"",D11<>""),(D12-D11)/($B12-$B11),"") -> 0.019489796 | S12: =IF(AND(E12<>"",E11<>""),(E12-E11)/($B12-$B11),"") -> 0.016708871 | T12: =IF(AND(F12<>"",F11<>""),(F12-F11)/($B12-$B11),"") -> 0.018380213 | U12: =IF(AND(G12<>"",G11<>""),(G12-G11)/($B12-$B11),"") -> 0.014777025 | V12: =IF(AND(H12<>"",H11<>""),(H12-H11)/($B12-$B11),"") -> -0.0069752143 | W12: =IF(AND(I12<>"",I11<>""),(I12-I11)/($B12-$B11),"") | X12: =IF(AND(J12<>"",J11<>""),(J12-J11)/($B12-$B11),"") -> 0.042975655 | Y12: =IF(AND(K12<>"",K11<>""),(K12-K11)/($B12-$B11),"") -> 0.030292152 | Z12: =IF(AND(L12<>"",L11<>""),(L12-L11)/($B12-$B11),"")
