Workbook
Name cintre: 'Résultats observations'!$W$4
Name date: 'Résultats observations'!$A:$A
Name DH_BD: 'Résultats observations'!$DD:$DD
Name DH_BG: 'Résultats observations'!$CL:$CL
Name DH_HD: 'Résultats observations'!$CX:$CX
Name DH_HG: 'Résultats observations'!$CR:$CR
Name DH_ID: 'Résultats observations'!$DA:$DA
Name DH_IG: 'Résultats observations'!$CO:$CO
Name DHhaut: 'Résultats observations'!$CU:$CU
Name dist: 'Résultats observations'!$D:$D
Name DPM_BD: 'Résultats observations'!$DC:$DC
Name DPM_BG: 'Résultats observations'!$CK:$CK
Name DPM_HD: 'Résultats observations'!$CW:$CW
Name DPM_HG: 'Résultats observations'!$CQ:$CQ
Name DPM_ID: 'Résultats observations'!$CZ:$CZ
Name DPM_IG: 'Résultats observations'!$CN:$CN
Name DPMhaut: 'Résultats observations'!$CT:$CT
Name DZ_BD: 'Résultats observations'!$BM:$BM
Name DZ_BG: 'Résultats observations'!$AU:$AU
Name DZ_HD: 'Résultats observations'!$BG:$BG
Name DZ_HG: 'Résultats observations'!$BA:$BA
Name DZ_ID: 'Résultats observations'!$BJ:$BJ
Name DZ_IG: 'Résultats observations'!$AX:$AX
Name DZhaut: 'Résultats observations'!$BD:$BD
Name Ecart_BD: 'Résultats observations'!$AN:$AN
Name Ecart_BG: 'Résultats observations'!$AI:$AI
Name Ecart_HD: 'Résultats observations'!$AL:$AL
Name Ecart_HG: 'Résultats observations'!$AK:$AK
Name Ecart_ID: 'Résultats observations'!$AM:$AM
Name Ecart_IG: 'Résultats observations'!$AJ:$AJ
Name Ecart_LB: 'Résultats observations'!$AQ:$AQ
Name Ecart_LH: 'Résultats observations'!$AO:$AO
Name Ecart_LI: 'Résultats observations'!$AP:$AP
Name excav: 'Résultats observations'!$A$7
Name front: 'Résultats observations'!$C:$C
Name galerie: 'Résultats observations'!$G$4
Name jours: 'Résultats observations'!$B:$B
Name PM: 'Résultats observations'!$W$6
Name Xbasdroit: 'Résultats observations'!$W:$W
Name Xbasgauche: 'Résultats observations'!$E:$E
Name Xhaut: 'Résultats observations'!$N:$N
Name Xhautdroit: 'Résultats observations'!$Q:$Q
Name Xhautgauche: 'Résultats observations'!$K:$K
Name Xinterdroit: 'Résultats observations'!$T:$T
Name Xintergauche: 'Résultats observations'!$H:$H
Name Ybasdroit: 'Résultats observations'!$X:$X
Name Ybasgauche: 'Résultats observations'!$F:$F
Name Yhaut: 'Résultats observations'!$O:$O
Name Yhautdroit: 'Résultats observations'!$R:$R
Name Yhautgauche: 'Résultats observations'!$L:$L
Name Yinterdroit: 'Résultats observations'!$U:$U
Name Yintergauche: 'Résultats observations'!$I:$I
Name Zbasdroit: 'Résultats observations'!$Y:$Y
Name Zbasgauche: 'Résultats observations'!$G:$G
Name Zhaut: 'Résultats observations'!$P:$P
Name Zhautdroit: 'Résultats observations'!$S:$S
Name Zhautgauche: 'Résultats observations'!$M:$M
Name Zinterdroit: 'Résultats observations'!$V:$V
Name Zintergauche: 'Résultats observations'!$J:$J

Sheet Résultats observations
F1: ="CONVERGENCE GVA3 - PM" & PM -> CONVERGENCE GVA3 - PM196.1
A6: Date point 0 | V6: PM = | W6: 196.1
A7: =MIN(A10:A19) -> 43705
A8: Date | B8: Jours | C8: Front | D8: Dist | E8: Point bas gauche | H8: Point intermédiaire gauche | K8: Point haut gauche | N8: Point centre haut | Q8: Point haut droit | T8: Point intermédiaire droit | W8: Point bas droit | AI8: Différences | AS8: Point bas gauche | AV8: Point intermédiaire gauche | AY8: Point haut gauche | BB8: Point centre haut | BE8: Point haut droit | BH8: Point intermédiaire droit | BK8: Point bas droit | BO8: Point bas gauche | BR8: Point intermédiaire gauche | BU8: Point haut gauche | BX8: Point centre haut | CA8: Point haut droit | CD8: Point intermédiaire droit | CG8: Point bas droit | CK8: Point bas gauche | CN8: Point intermédiaire gauche | CQ8: Point haut gauche | CT8: Point centre haut | CW8: Point haut droit | CZ8: Point intermédiaire droit | DC8: Point bas droit
E9: X | F9: Y | G9: Z | K9: X | L9: Y | M9: Z | N9: X | O9: Y | P9: Z | Q9: X | R9: Y | S9: Z | W9: X | X9: Y | Y9: Z | Z9: BG | AA9: IG | AB9: HG | AC9: HD | AD9: ID | AE9: BD | AF9: LH | AG9: LI | AH9: LB | AI9: BG | AJ9: IG | AK9: HG | AL9: HD | AM9: ID | AN9: BD | AO9: LH | AP9: LI | AQ9: LB | AS9: DX | AT9: DY | AU9: DZ | AV9: DX | AW9: DY | AX9: DZ | AY9: DX | AZ9: DY | BA9: DZ | BB9: DX | BC9: DY | BD9: DZ | BE9: DX | BF9: DY | BG9: DZ | BH9: DX | BI9: DY | BJ9: DZ | BK9: DX | BL9: DY | BM9: DZ | BO9: PM | BP9: H | BQ9: V | BR9: PM | BS9: H | BT9: V | BU9: PM | BV9: H | BW9: V | BX9: PM | BY9: H | BZ9: V | CA9: PM | CB9: H | CC9: V | CD9: PM | CE9: H | CF9: V | CG9: PM | CH9: H | CI9: V | CK9: DPM | CL9: DH | CM9: DZ | CN9: DPM | CO9: DH | CP9: DZ | CQ9: DPM | CR9: DH | CS9: DZ | CT9: DPM | CU9: DH | CV9: DZ | CW9: DPM | CX9: DH | CY9: DZ | CZ9: DPM | DA9: DH | DB9: DZ | DC9: DPM | DD9: DH | DE9: DZ
A10: 43705 | B10: 0 | C10: 197.2 | D10: =C10-PM -> 1.1 | E10: 823244.33 | F10: 1091518.8 | G10: -124.5515 | H10: 823244.24 | I10: 1091519 | J10: -123.1822 | K10: 823244.51 | L10: 1091518.5 | M10: -121.8104 | N10: 823245.31 | O10: 1091516.7 | P10: -120.8554 | Q10: 823245.97 | R10: 1091515.2 | S10: -121.2536 | T10: 823246.56 | U10: 1091514.1 | V10: -123.4431 | W10: 823246.48 | X10: 1091514.2 | Y10: -124.5718 | Z10: =IF(Xhaut="","",SQRT(((Xbasgauche-Xhaut)^2+(Ybasgauche-Yhaut)^2)+(Zbasgauche-Zhaut)^2)) -> 4.374139 | AA10: =IF(Xhaut="","",SQRT(((Xintergauche-Xhaut)^2+(Yintergauche-Yhaut)^2)+(Zintergauche-Zhaut)^2)) -> 3.4411644 | AB10: =IF(Xhaut="","",SQRT(((Xhautgauche-Xhaut)^2+(Yhautgauche-Yhaut)^2)+(Zhautgauche-Zhaut)^2)) -> 2.2058669 | AC10: =IF(Xhaut="","",SQRT(((Xhautdroit-Xhaut)^2+(Yhautdroit-Yhaut)^2)+(Zhautdroit-Zhaut)^2)) -> 1.6703112 | AD10: =IF(Xhaut="","",SQRT(((Xinterdroit-Xhaut)^2+(Yinterdroit-Yhaut)^2)+(Zinterdroit-Zhaut)^2)) -> 3.8485205 | AE10: =IF(Xhaut="","",SQRT(((Xbasdroit-Xhaut)^2+(Ybasdroit-Yhaut)^2)+(Zbasdroit-Zhaut)^2)) -> 4.6226019 | AF10: =IF(Xhautdroit="","",SQRT(((Xhautdroit-Xhautgauche)^2+(Yhautdroit-Yhautgauche)^2)+(Zhautdroit-Zhautgauche)^2)) -> 3.6531821 | AG10: =IF(Xinterdroit="","",SQRT(((Xinterdroit-Xintergauche)^2+(Yinterdroit-Yintergauche)^2)+(Zinterdroit-Zintergauche)^2)) -> 5.3899122 | AH10: =IF(Xbasdroit="","",SQRT(((Xbasdroit-Xbasgauche)^2+(Ybasdroit-Ybasgauche)^2)+(Zbasdroit-Zbasgauche)^2)) -> 5.0881672 | AI10: 0 | AJ10: 0 | AK10: 0 | AL10: 0 | AM10: 0 | AN10: 0 | AO10: 0 | AP10: 0 | AQ10: 0 | AS10: 0 | AT10: 0 | AU10: 0 | AV10: 0 | AW10: 0 | AX10: 0 | AY10: 0 | AZ10: 0 | BA10: 0 | BB10: 0 | BC10: 0 | BD10: 0 | BE10: 0 | BF10: 0 | BG10: 0 | BH10: 0 | BI10: 0 | BJ10: 0 | BK10: 0 | BL10: 0 | BM10: 0 | BO10: 196.10477 | BP10: -2.537201 | BQ10: -0.96966769 | BR10: 196.09978 | BS10: -2.7332857 | BT10: 0.39968223 | BU10: 196.13865 | BV10: -2.1858584 | BW10: 1.7710935 | BX10: 196.09003 | BY10: -0.19803036 | BZ10: 2.7265797 | CA10: 196.07121 | CB10: 1.4240122 | CC10: 2.3285679 | CD10: 196.14412 | CE10: 2.6501257 | CF10: 0.13833877 | CG10: 196.09892 | CH10: 2.5509223 | CI10: -0.98990915 | CK10: 0 | CL10: 0 | CM10: 0 | CN10: 0 | CO10: 0 | CP10: 0 | CQ10: 0 | CR10: 0 | CS10: 0 | CT10: 0 | CU10: 0 | CV10: 0 | CW10: 0 | CX10: 0 | CY10: 0 | CZ10: 0 | DA10: 0 | DB10: 0 | DC10: 0 | DD10: 0 | DE10: 0
A11: 43706 | B11: =A11-A$10 -> 1 | C11: 198.3 | D11: =C11-PM -> 2.2 | E11: 823244.33 | F11: 1091518.8 | G11: -124.5515 | H11: 823244.23 | I11: 1091519 | J11: -123.1861 | K11: 823244.51 | L11: 1091518.5 | M11: -121.8106 | N11: 823245.31 | O11: 1091516.7 | P11: -120.8565 | Q11: 823245.97 | R11: 1091515.2 | S11: -121.2543 | T11: 823246.56 | U11: 1091514.1 | V11: -123.4432 | W11: 823246.47 | X11: 1091514.2 | Y11: -124.5717 | Z11: =IF(Xhaut="","",SQRT(((Xbasgauche-Xhaut)^2+(Ybasgauche-Yhaut)^2)+(Zbasgauche-Zhaut)^2)) -> 4.3729036 | AA11: =IF(Xhaut="","",SQRT(((Xintergauche-Xhaut)^2+(Yintergauche-Yhaut)^2)+(Zintergauche-Zhaut)^2)) -> 3.4443375 | AB11: =IF(Xhaut="","",SQRT(((Xhautgauche-Xhaut)^2+(Yhautgauche-Yhaut)^2)+(Zhautgauche-Zhaut)^2)) -> 2.2051317 | AC11: =IF(Xhaut="","",SQRT(((Xhautdroit-Xhaut)^2+(Yhautdroit-Yhaut)^2)+(Zhautdroit-Zhaut)^2)) -> 1.6703528 | AD11: =IF(Xhaut="","",SQRT(((Xinterdroit-Xhaut)^2+(Yinterdroit-Yhaut)^2)+(Zinterdroit-Zhaut)^2)) -> 3.847916 | AE11: =IF(Xhaut="","",SQRT(((Xbasdroit-Xhaut)^2+(Ybasdroit-Yhaut)^2)+(Zbasdroit-Zhaut)^2)) -> 4.6214095 | AF11: =IF(Xhautdroit="","",SQRT(((Xhautdroit-Xhautgauche)^2+(Yhautdroit-Yhautgauche)^2)+(Zhautdroit-Zhautgauche)^2)) -> 3.6528654 | AG11: =IF(Xinterdroit="","",SQRT(((Xinterdroit-Xintergauche)^2+(Yinterdroit-Yintergauche)^2)+(Zinterdroit-Zintergauche)^2)) -> 5.391663 | AH11: =IF(Xbasdroit="","",SQRT(((Xbasdroit-Xbasgauche)^2+(Ybasdroit-Ybasgauche)^2)+(Zbasdroit-Zbasgauche)^2)) -> 5.087214 | AI11: =IF(Z11="","",(Z11-Z$10)*1000) -> -1.2353959 | AJ11: =IF(AA11="","",(AA11-AA$10)*1000) -> 3.1730077 | AK11: =IF(AB11="","",(AB11-AB$10)*1000) -> -0.73517134 | AL11: =IF(AC11="","",(AC11-AC$10)*1000) -> 0.041653275 | AM11: =IF(AD11="","",(AD11-AD$10)*1000) -> -0.60444604 | AN11: =IF(AE11="","",(AE11-AE$10)*1000) -> -1.1924402 | AO11: =IF(AF11="","",(AF11-AF$10)*1000) -> -0.31668428 | AP11: =IF(AG11="","",(AG11-AG$10)*1000) -> 1.7508082 | AQ11: =IF(AH11="","",(AH11-AH$10)*1000) -> -0.95323531 | AS11: =IF(E11="","",(E11-E$10)*1000) -> 0.80000004 | AT11: =IF(F11="","",(F11-F$10)*1000) -> -1.3000001 | AU11: =IF(G11="","",(G11-G$10)*1000) -> 0 | AV11: =IF(H11="","",(H11-H$10)*1000) -> -9 | AW11: =IF(I11="","",(I11-I$10)*1000) -> -3.3 | AX11: =IF(J11="","",(J11-J$10)*1000) -> -3.9 | AY11: =IF(K11="","",(K11-K$10)*1000) -> 0.80000004 | AZ11: =IF(L11="","",(L11-L$10)*1000) -> -1.1 | ... BM11: =IF(Y11="","",(Y11-Y$10)*1000) -> 0.1 | BO11: 196.10494 | BP11: -2.5356847 | BQ11: -0.96966945 | BR11: 196.09023 | BS11: -2.7340988 | BT11: 0.39587774 | BU11: 196.13891 | BV11: -2.1845233 | BW11: 1.7708909 | BX11: 196.08992 | BY11: -0.19708791 | BZ11: 2.7254808 | CA11: 196.07093 | CB11: 1.4250936 | CC11: 2.3278707 | CD11: 196.14375 | CE11: 2.6511648 | CF11: 0.13824251 | CG11: 196.09799 | CH11: 2.5514844 | CI11: -0.98979991 | CK11: =IF(BO11="","",(BO11-BO$10)*1000) -> 0.17558601 | CL11: =IF(BP11="","",(BP11-BP$10)*1000) -> 1.5163014 | CM11: =IF(BQ11="","",(BQ11-BQ$10)*1000) -> -0.0017558601 | CN11: =IF(BR11="","",(BR11-BR$10)*1000) -> -9.55138 | CO11: =IF(BS11="","",(BS11-BS$10)*1000) -> -0.81310433 | CP11: =IF(BT11="","",(BT11-BT$10)*1000) -> -3.8044862 | CQ11: =IF(BU11="","",(BU11-BU$10)*1000) -> 0.26011647 | CR11: =IF(BV11="","",(BV11-BV$10)*1000) -> 1.3350429 | ... DE11: =IF(CI11="","",(CI11-CI$10)*1000) -> 0.10924162
A12: 43707 | B12: =A12-A$10 -> 2 | C12: 199 | D12: =C12-PM -> 2.9 | E12: 823244.33 | F12: 1091518.8 | G12: -124.5505 | H12: 823244.23 | I12: 1091519 | J12: -123.1862 | K12: 823244.51 | L12: 1091518.5 | M12: -121.8112 | N12: 823245.31 | O12: 1091516.7 | P12: -120.8596 | Q12: 823245.97 | R12: 1091515.2 | S12: -121.2562 | T12: 823246.56 | U12: 1091514.1 | V12: -123.443 | W12: 823246.47 | X12: 1091514.2 | Y12: -124.5715 | Z12: =IF(Xhaut="","",SQRT(((Xbasgauche-Xhaut)^2+(Ybasgauche-Yhaut)^2)+(Zbasgauche-Zhaut)^2)) -> 4.368858 | AA12: =IF(Xhaut="","",SQRT(((Xintergauche-Xhaut)^2+(Yintergauche-Yhaut)^2)+(Zintergauche-Zhaut)^2)) -> 3.4412813 | AB12: =IF(Xhaut="","",SQRT(((Xhautgauche-Xhaut)^2+(Yhautgauche-Yhaut)^2)+(Zhautgauche-Zhaut)^2)) -> 2.2030247 | AC12: =IF(Xhaut="","",SQRT(((Xhautdroit-Xhaut)^2+(Yhautdroit-Yhaut)^2)+(Zhautdroit-Zhaut)^2)) -> 1.6696482 | AD12: =IF(Xhaut="","",SQRT(((Xinterdroit-Xhaut)^2+(Yinterdroit-Yhaut)^2)+(Zinterdroit-Zhaut)^2)) -> 3.8444658 | AE12: =IF(Xhaut="","",SQRT(((Xbasdroit-Xhaut)^2+(Ybasdroit-Yhaut)^2)+(Zbasdroit-Zhaut)^2)) -> 4.6177593 | AF12: =IF(Xhautdroit="","",SQRT(((Xhautdroit-Xhautgauche)^2+(Yhautdroit-Yhautgauche)^2)+(Zhautdroit-Zhautgauche)^2)) -> 3.6511026 | AG12: =IF(Xinterdroit="","",SQRT(((Xinterdroit-Xintergauche)^2+(Yinterdroit-Yintergauche)^2)+(Zinterdroit-Zintergauche)^2)) -> 5.3885692 | AH12: =IF(Xbasdroit="","",SQRT(((Xbasdroit-Xbasgauche)^2+(Ybasdroit-Ybasgauche)^2)+(Zbasdroit-Zbasgauche)^2)) -> 5.0844444 | AI12: =IF(Z12="","",(Z12-Z$10)*1000) -> -5.2809856 | AJ12: =IF(AA12="","",(AA12-AA$10)*1000) -> 0.11689442 | AK12: =IF(AB12="","",(AB12-AB$10)*1000) -> -2.8421863 | AL12: =IF(AC12="","",(AC12-AC$10)*1000) -> -0.6630231 | AM12: =IF(AD12="","",(AD12-AD$10)*1000) -> -4.0546231 | AN12: =IF(AE12="","",(AE12-AE$10)*1000) -> -4.8426483 | AO12: =IF(AF12="","",(AF12-AF$10)*1000) -> -2.079514 | AP12: =IF(AG12="","",(AG12-AG$10)*1000) -> -1.3429685 | AQ12: =IF(AH12="","",(AH12-AH$10)*1000) -> -3.7228397 | AS12: =IF(E12="","",(E12-E$10)*1000) -> 1.3 | AT12: =IF(F12="","",(F12-F$10)*1000) -> -2.7000001 | AU12: =IF(G12="","",(G12-G$10)*1000) -> 1 | AV12: =IF(H12="","",(H12-H$10)*1000) -> -8 | AW12: =IF(I12="","",(I12-I$10)*1000) -> -4.8 | AX12: =IF(J12="","",(J12-J$10)*1000) -> -4 | AY12: =IF(K12="","",(K12-K$10)*1000) -> 1.7 | AZ12: =IF(L12="","",(L12-L$10)*1000) -> -2.4000001 | ... BM12: =IF(Y12="","",(Y12-Y$10)*1000) -> 0.3 | BO12: 196.10481 | BP12: -2.5342046 | BQ12: -0.96866806 | BR12: 196.0905 | BS12: -2.7323167 | BT12: 0.39577502 | BU12: 196.13917 | BV12: -2.1829648 | BW12: 1.7702883 | BX12: 196.08886 | BY12: -0.19670099 | BZ12: 2.7223914 | CA12: 196.07061 | CB12: 1.4250574 | CC12: 2.3259739 | CD12: 196.1438 | CE12: 2.649866 | CF12: 0.13844197 | CG12: 196.09782 | CH12: 2.5501916 | CI12: -0.98959821 | CK12: =IF(BO12="","",(BO12-BO$10)*1000) -> 0.03701921 | CL12: =IF(BP12="","",(BP12-BP$10)*1000) -> 2.9964362 | CM12: =IF(BQ12="","",(BQ12-BQ$10)*1000) -> 0.99962981 | CN12: =IF(BR12="","",(BR12-BR$10)*1000) -> -9.2790661 | CO12: =IF(BS12="","",(BS12-BS$10)*1000) -> 0.96898574 | CP12: =IF(BT12="","",(BT12-BT$10)*1000) -> -3.9072093 | CQ12: =IF(BU12="","",(BU12-BU$10)*1000) -> 0.52633163 | CR12: =IF(BV12="","",(BV12-BV$10)*1000) -> 2.8936094 | ... DE12: =IF(CI12="","",(CI12-CI$10)*1000) -> 0.31093649
A13: 43710 | B13: =A13-A$10 -> 5 | C13: 199.4 | D13: =C13-PM -> 3.3 | E13: 823244.33 | F13: 1091518.8 | G13: -124.5503 | H13: 823244.23 | I13: 1091519 | J13: -123.1866 | K13: 823244.51 | L13: 1091518.5 | M13: -121.8112 | N13: 823245.3 | O13: 1091516.7 | P13: -120.8626 | Q13: 823245.97 | R13: 1091515.2 | S13: -121.2579 | T13: 823246.56 | U13: 1091514.1 | V13: -123.4429 | W13: 823246.47 | X13: 1091514.2 | Y13: -124.5715 | Z13: =IF(Xhaut="","",SQRT(((Xbasgauche-Xhaut)^2+(Ybasgauche-Yhaut)^2)+(Zbasgauche-Zhaut)^2)) -> 4.365932 | AA13: =IF(Xhaut="","",SQRT(((Xintergauche-Xhaut)^2+(Yintergauche-Yhaut)^2)+(Zintergauche-Zhaut)^2)) -> 3.4390747 | AB13: =IF(Xhaut="","",SQRT(((Xhautgauche-Xhaut)^2+(Yhautgauche-Yhaut)^2)+(Zhautgauche-Zhaut)^2)) -> 2.2001292 | AC13: =IF(Xhaut="","",SQRT(((Xhautdroit-Xhaut)^2+(Yhautdroit-Yhaut)^2)+(Zhautdroit-Zhaut)^2)) -> 1.6695556 | AD13: =IF(Xhaut="","",SQRT(((Xinterdroit-Xhaut)^2+(Yinterdroit-Yhaut)^2)+(Zinterdroit-Zhaut)^2)) -> 3.8421774 | AE13: =IF(Xhaut="","",SQRT(((Xbasdroit-Xhaut)^2+(Ybasdroit-Yhaut)^2)+(Zbasdroit-Zhaut)^2)) -> 4.6148255 | AF13: =IF(Xhautdroit="","",SQRT(((Xhautdroit-Xhautgauche)^2+(Yhautdroit-Yhautgauche)^2)+(Zhautdroit-Zhautgauche)^2)) -> 3.6492983 | AG13: =IF(Xinterdroit="","",SQRT(((Xinterdroit-Xintergauche)^2+(Yinterdroit-Yintergauche)^2)+(Zinterdroit-Zintergauche)^2)) -> 5.3876405 | AH13: =IF(Xbasdroit="","",SQRT(((Xbasdroit-Xbasgauche)^2+(Ybasdroit-Ybasgauche)^2)+(Zbasdroit-Zbasgauche)^2)) -> 5.0831399 | AI13: =IF(Z13="","",(Z13-Z$10)*1000) -> -8.2069311 | AJ13: =IF(AA13="","",(AA13-AA$10)*1000) -> -2.0897312 | AK13: =IF(AB13="","",(AB13-AB$10)*1000) -> -5.7376901 | AL13: =IF(AC13="","",(AC13-AC$10)*1000) -> -0.75558407 | AM13: =IF(AD13="","",(AD13-AD$10)*1000) -> -6.343085 | AN13: =IF(AE13="","",(AE13-AE$10)*1000) -> -7.7764205 | AO13: =IF(AF13="","",(AF13-AF$10)*1000) -> -3.883764 | AP13: =IF(AG13="","",(AG13-AG$10)*1000) -> -2.2716549 | AQ13: =IF(AH13="","",(AH13-AH$10)*1000) -> -5.0273463 | AS13: =IF(E13="","",(E13-E$10)*1000) -> 0.89999998 | AT13: =IF(F13="","",(F13-F$10)*1000) -> -2.5000002 | AU13: =IF(G13="","",(G13-G$10)*1000) -> 1.2 | AV13: =IF(H13="","",(H13-H$10)*1000) -> -8.6000001 | AW13: =IF(I13="","",(I13-I$10)*1000) -> -4.9000001 | AX13: =IF(J13="","",(J13-J$10)*1000) -> -4.4 | AY13: =IF(K13="","",(K13-K$10)*1000) -> 1.3 | AZ13: =IF(L13="","",(L13-L$10)*1000) -> -3.7 | ... BM13: =IF(Y13="","",(Y13-Y$10)*1000) -> 0.3 | BO13: 196.10453 | BP13: -2.5345549 | BQ13: -0.96846528 | BR13: 196.08991 | BS13: -2.7324797 | BT13: 0.39538088 | BU13: 196.13826 | BV13: -2.1819556 | BW13: 1.7702974 | BX13: 196.08768 | BY13: -0.19747397 | BZ13: 2.7194032 | CA13: 196.07064 | CB13: 1.4245198 | CC13: 2.3242736 | CD13: 196.14386 | CE13: 2.6487906 | CF13: 0.13854137 | CG13: 196.09782 | CH13: 2.5485363 | CI13: -0.98959821 | CK13: =IF(BO13="","",(BO13-BO$10)*1000) -> -0.24096727 | CL13: =IF(BP13="","",(BP13-BP$10)*1000) -> 2.6461171 | CM13: =IF(BQ13="","",(BQ13-BQ$10)*1000) -> 1.2024097 | CN13: =IF(BR13="","",(BR13-BR$10)*1000) -> -9.8651066 | CO13: =IF(BS13="","",(BS13-BS$10)*1000) -> 0.80602378 | CP13: =IF(BT13="","",(BT13-BT$10)*1000) -> -4.3013489 | CQ13: =IF(BU13="","",(BU13-BU$10)*1000) -> -0.38563277 | CR13: =IF(BV13="","",(BV13-BV$10)*1000) -> 3.9027282 | ... DE13: =IF(CI13="","",(CI13-CI$10)*1000) -> 0.31094076
A14: 43711 | B14: =A14-A$10 -> 6 | C14: 200.6 | D14: =C14-PM -> 4.5 | E14: 823244.33 | F14: 1091518.8 | G14: -124.5501 | H14: 823244.23 | I14: 1091519 | J14: -123.1865 | K14: 823244.51 | L14: 1091518.5 | M14: -121.8111 | N14: 823245.3 | O14: 1091516.7 | P14: -120.8642 | Q14: 823245.97 | R14: 1091515.2 | S14: -121.2588 | T14: 823246.56 | U14: 1091514.1 | V14: -123.4426 | W14: 823246.47 | X14: 1091514.2 | Y14: -124.5718 | Z14: =IF(Xhaut="","",SQRT(((Xbasgauche-Xhaut)^2+(Ybasgauche-Yhaut)^2)+(Zbasgauche-Zhaut)^2)) -> 4.3641 | AA14: =IF(Xhaut="","",SQRT(((Xintergauche-Xhaut)^2+(Yintergauche-Yhaut)^2)+(Zintergauche-Zhaut)^2)) -> 3.4375484 | AB14: =IF(Xhaut="","",SQRT(((Xhautgauche-Xhaut)^2+(Yhautgauche-Yhaut)^2)+(Zhautgauche-Zhaut)^2)) -> 2.1989897 | AC14: =IF(Xhaut="","",SQRT(((Xhautdroit-Xhaut)^2+(Yhautdroit-Yhaut)^2)+(Zhautdroit-Zhaut)^2)) -> 1.6694621 | AD14: =IF(Xhaut="","",SQRT(((Xinterdroit-Xhaut)^2+(Yinterdroit-Yhaut)^2)+(Zinterdroit-Zhaut)^2)) -> 3.8408302 | AE14: =IF(Xhaut="","",SQRT(((Xbasdroit-Xhaut)^2+(Ybasdroit-Yhaut)^2)+(Zbasdroit-Zhaut)^2)) -> 4.6136545 | AF14: =IF(Xhautdroit="","",SQRT(((Xhautdroit-Xhautgauche)^2+(Yhautdroit-Yhautgauche)^2)+(Zhautdroit-Zhautgauche)^2)) -> 3.6487657 | AG14: =IF(Xinterdroit="","",SQRT(((Xinterdroit-Xintergauche)^2+(Yinterdroit-Yintergauche)^2)+(Zinterdroit-Zintergauche)^2)) -> 5.3870042 | AH14: =IF(Xbasdroit="","",SQRT(((Xbasdroit-Xbasgauche)^2+(Ybasdroit-Ybasgauche)^2)+(Zbasdroit-Zbasgauche)^2)) -> 5.0823322 | AI14: =IF(Z14="","",(Z14-Z$10)*1000) -> -10.038943 | AJ14: =IF(AA14="","",(AA14-AA$10)*1000) -> -3.616088 | AK14: =IF(AB14="","",(AB14-AB$10)*1000) -> -6.8771752 | AL14: =IF(AC14="","",(AC14-AC$10)*1000) -> -0.84906071 | AM14: =IF(AD14="","",(AD14-AD$10)*1000) -> -7.6902397 | AN14: =IF(AE14="","",(AE14-AE$10)*1000) -> -8.9474573 | AO14: =IF(AF14="","",(AF14-AF$10)*1000) -> -4.4163916 | AP14: =IF(AG14="","",(AG14-AG$10)*1000) -> -2.9080044 | AQ14: =IF(AH14="","",(AH14-AH$10)*1000) -> -5.8349967 | AS14: =IF(E14="","",(E14-E$10)*1000) -> 1.8 | AT14: =IF(F14="","",(F14-F$10)*1000) -> -2.0000001 | AU14: =IF(G14="","",(G14-G$10)*1000) -> 1.4 | AV14: =IF(H14="","",(H14-H$10)*1000) -> -8.1 | AW14: =IF(I14="","",(I14-I$10)*1000) -> -4.5 | AX14: =IF(J14="","",(J14-J$10)*1000) -> -4.3 | AY14: =IF(K14="","",(K14-K$10)*1000) -> 1.7 | AZ14: =IF(L14="","",(L14-L$10)*1000) -> -3.3 | ... BM14: =IF(Y14="","",(Y14-Y$10)*1000) -> 0 | BO14: 196.1056 | BP14: -2.5346 | BQ14: -0.9683 | BR14: 196.091 | BS14: -2.733 | BT14: 0.395 | BU14: 196.139 | BV14: -2.182 | BW14: 1.77 | BX14: 196.087 | BY14: -0.198 | BZ14: 2.718 | CA14: 196.071 | CB14: 1.424 | CC14: 2.323 | CD14: 196.145 | CE14: 2.648 | CF14: 0.139 | CG14: 196.099 | CH14: 2.548 | CI14: -0.99 | CK14: =IF(BO14="","",(BO14-BO$10)*1000) -> 0.83081613 | CL14: =IF(BP14="","",(BP14-BP$10)*1000) -> 2.6010247 | CM14: =IF(BQ14="","",(BQ14-BQ$10)*1000) -> 1.3676918 | CN14: =IF(BR14="","",(BR14-BR$10)*1000) -> -8.7769518 | CO14: =IF(BS14="","",(BS14-BS$10)*1000) -> 0.28569421 | CP14: =IF(BT14="","",(BT14-BT$10)*1000) -> -4.6822305 | CQ14: =IF(BU14="","",(BU14-BU$10)*1000) -> 0.35175721 | CR14: =IF(BV14="","",(BV14-BV$10)*1000) -> 3.8583723 | ... DE14: =IF(CI14="","",(CI14-CI$10)*1000) -> -0.090849565
A15: 43712 | B15: =A15-A$10 -> 7 | C15: 200.6 | D15: =C15-PM -> 4.5 | E15: 823244.33 | F15: 1091518.8 | G15: -124.5499 | H15: 823244.23 | I15: 1091519 | J15: -123.1868 | K15: 823244.51 | L15: 1091518.5 | M15: -121.8116 | N15: 823245.3 | O15: 1091516.7 | P15: -120.866 | Q15: 823245.97 | R15: 1091515.2 | S15: -121.2602 | T15: 823246.56 | U15: 1091514.1 | V15: -123.4429 | W15: 823246.47 | X15: 1091514.2 | Y15: -124.5715 | Z15: =IF(Xhaut="","",SQRT(((Xbasgauche-Xhaut)^2+(Ybasgauche-Yhaut)^2)+(Zbasgauche-Zhaut)^2)) -> 4.3620617 | AA15: =IF(Xhaut="","",SQRT(((Xintergauche-Xhaut)^2+(Yintergauche-Yhaut)^2)+(Zintergauche-Zhaut)^2)) -> 3.4360407 | AB15: =IF(Xhaut="","",SQRT(((Xhautgauche-Xhaut)^2+(Yhautgauche-Yhaut)^2)+(Zhautgauche-Zhaut)^2)) -> 2.1979083 | AC15: =IF(Xhaut="","",SQRT(((Xhautdroit-Xhaut)^2+(Yhautdroit-Yhaut)^2)+(Zhautdroit-Zhaut)^2)) -> 1.6689573 | AD15: =IF(Xhaut="","",SQRT(((Xinterdroit-Xhaut)^2+(Yinterdroit-Yhaut)^2)+(Zinterdroit-Zhaut)^2)) -> 3.8391592 | AE15: =IF(Xhaut="","",SQRT(((Xbasdroit-Xhaut)^2+(Ybasdroit-Yhaut)^2)+(Zbasdroit-Zhaut)^2)) -> 4.6113555 | AF15: =IF(Xhautdroit="","",SQRT(((Xhautdroit-Xhautgauche)^2+(Yhautdroit-Yhautgauche)^2)+(Zhautdroit-Zhautgauche)^2)) -> 3.6476357 | AG15: =IF(Xinterdroit="","",SQRT(((Xinterdroit-Xintergauche)^2+(Yinterdroit-Yintergauche)^2)+(Zinterdroit-Zintergauche)^2)) -> 5.3854371 | AH15: =IF(Xbasdroit="","",SQRT(((Xbasdroit-Xbasgauche)^2+(Ybasdroit-Ybasgauche)^2)+(Zbasdroit-Zbasgauche)^2)) -> 5.0806574 | AI15: =IF(Z15="","",(Z15-Z$10)*1000) -> -12.077309 | AJ15: =IF(AA15="","",(AA15-AA$10)*1000) -> -5.1237719 | AK15: =IF(AB15="","",(AB15-AB$10)*1000) -> -7.9585991 | AL15: =IF(AC15="","",(AC15-AC$10)*1000) -> -1.3538774 | AM15: =IF(AD15="","",(AD15-AD$10)*1000) -> -9.3612732 | AN15: =IF(AE15="","",(AE15-AE$10)*1000) -> -11.246417 | AO15: =IF(AF15="","",(AF15-AF$10)*1000) -> -5.5464419 | AP15: =IF(AG15="","",(AG15-AG$10)*1000) -> -4.4750958 | AQ15: =IF(AH15="","",(AH15-AH$10)*1000) -> -7.5098171 | AS15: =IF(E15="","",(E15-E$10)*1000) -> 0.80000004 | AT15: =IF(F15="","",(F15-F$10)*1000) -> -2.5000002 | AU15: =IF(G15="","",(G15-G$10)*1000) -> 1.6 | AV15: =IF(H15="","",(H15-H$10)*1000) -> -8.4 | AW15: =IF(I15="","",(I15-I$10)*1000) -> -4.6999999 | AX15: =IF(J15="","",(J15-J$10)*1000) -> -4.6 | AY15: =IF(K15="","",(K15-K$10)*1000) -> 1.4000001 | AZ15: =IF(L15="","",(L15-L$10)*1000) -> -3.4 | ... BM15: =IF(Y15="","",(Y15-Y$10)*1000) -> 0.3 | BO15: 196.10444 | BP15: -2.5345972 | BQ15: -0.96806438 | BR15: 196.09018 | BS15: -2.7325764 | BT15: 0.39517822 | BU15: 196.13848 | BV15: -2.1821853 | BW15: 1.7698952 | BX15: 196.08706 | BY15: -0.19875455 | BZ15: 2.7160094 | CA15: 196.07096 | CB15: 1.4229006 | CC15: 2.3219704 | CD15: 196.14438 | CE15: 2.6464948 | CF15: 0.13853618 | CG15: 196.09856 | CH15: 2.5460109 | CI15: -0.98960557 | CK15: =IF(BO15="","",(BO15-BO$10)*1000) -> -0.33159643 | CL15: =IF(BP15="","",(BP15-BP$10)*1000) -> 2.6038519 | CM15: =IF(BQ15="","",(BQ15-BQ$10)*1000) -> 1.603316 | CN15: =IF(BR15="","",(BR15-BR$10)*1000) -> -9.5993177 | CO15: =IF(BS15="","",(BS15-BS$10)*1000) -> 0.70929566 | CP15: =IF(BT15="","",(BT15-BT$10)*1000) -> -4.5040068 | CQ15: =IF(BU15="","",(BU15-BU$10)*1000) -> -0.16820792 | CR15: =IF(BV15="","",(BV15-BV$10)*1000) -> 3.6731059 | ... DE15: =IF(CI15="","",(CI15-CI$10)*1000) -> 0.30357697
A16: 43713 | B16: =A16-A$10 -> 8 | C16: 200.6 | D16: =C16-PM -> 4.5 | E16: 823244.33 | F16: 1091518.8 | G16: -124.5496 | H16: 823244.24 | I16: 1091519 | J16: -123.1864 | K16: 823244.51 | L16: 1091518.5 | M16: -121.8109 | N16: 823245.3 | O16: 1091516.7 | P16: -120.8659 | Q16: 823245.97 | R16: 1091515.2 | S16: -121.2599 | T16: 823246.56 | U16: 1091514.1 | V16: -123.4425 | W16: 823246.47 | X16: 1091514.2 | Y16: -124.5713 | Z16: =IF(Xhaut="","",SQRT(((Xbasgauche-Xhaut)^2+(Ybasgauche-Yhaut)^2)+(Zbasgauche-Zhaut)^2)) -> 4.3620472 | AA16: =IF(Xhaut="","",SQRT(((Xintergauche-Xhaut)^2+(Yintergauche-Yhaut)^2)+(Zintergauche-Zhaut)^2)) -> 3.4358428 | AB16: =IF(Xhaut="","",SQRT(((Xhautgauche-Xhaut)^2+(Yhautgauche-Yhaut)^2)+(Zhautgauche-Zhaut)^2)) -> 2.1977077 | AC16: =IF(Xhaut="","",SQRT(((Xhautdroit-Xhaut)^2+(Yhautdroit-Yhaut)^2)+(Zhautdroit-Zhaut)^2)) -> 1.669264 | AD16: =IF(Xhaut="","",SQRT(((Xinterdroit-Xhaut)^2+(Yinterdroit-Yhaut)^2)+(Zinterdroit-Zhaut)^2)) -> 3.8390921 | AE16: =IF(Xhaut="","",SQRT(((Xbasdroit-Xhaut)^2+(Ybasdroit-Yhaut)^2)+(Zbasdroit-Zhaut)^2)) -> 4.6113575 | AF16: =IF(Xhautdroit="","",SQRT(((Xhautdroit-Xhautgauche)^2+(Yhautdroit-Yhautgauche)^2)+(Zhautdroit-Zhautgauche)^2)) -> 3.6479971 | AG16: =IF(Xinterdroit="","",SQRT(((Xinterdroit-Xintergauche)^2+(Yinterdroit-Yintergauche)^2)+(Zinterdroit-Zintergauche)^2)) -> 5.385625 | AH16: =IF(Xbasdroit="","",SQRT(((Xbasdroit-Xbasgauche)^2+(Ybasdroit-Ybasgauche)^2)+(Zbasdroit-Zbasgauche)^2)) -> 5.0810818 | AI16: =IF(Z16="","",(Z16-Z$10)*1000) -> -12.091752 | AJ16: =IF(AA16="","",(AA16-AA$10)*1000) -> -5.3216855 | AK16: =IF(AB16="","",(AB16-AB$10)*1000) -> -8.1591465 | AL16: =IF(AC16="","",(AC16-AC$10)*1000) -> -1.0472111 | AM16: =IF(AD16="","",(AD16-AD$10)*1000) -> -9.4283563 | AN16: =IF(AE16="","",(AE16-AE$10)*1000) -> -11.244472 | AO16: =IF(AF16="","",(AF16-AF$10)*1000) -> -5.1849995 | AP16: =IF(AG16="","",(AG16-AG$10)*1000) -> -4.2871923 | AQ16: =IF(AH16="","",(AH16-AH$10)*1000) -> -7.0853948 | AS16: =IF(E16="","",(E16-E$10)*1000) -> 1.6000001 | AT16: =IF(F16="","",(F16-F$10)*1000) -> -2.5000002 | AU16: =IF(G16="","",(G16-G$10)*1000) -> 1.9 | AV16: =IF(H16="","",(H16-H$10)*1000) -> -7.8 | AW16: =IF(I16="","",(I16-I$10)*1000) -> -5.1 | AX16: =IF(J16="","",(J16-J$10)*1000) -> -4.2 | AY16: =IF(K16="","",(K16-K$10)*1000) -> 2.1 | AZ16: =IF(L16="","",(L16-L$10)*1000) -> -3.7 | ... BM16: =IF(Y16="","",(Y16-Y$10)*1000) -> 0.5 | BO16: 196.1052 | BP16: -2.5343 | BQ16: -0.9678 | BR16: 196.0906 | BS16: -2.732 | BT16: 0.3956 | BU16: 196.139 | BV16: -2.1816 | BW16: 1.7706 | BX16: 196.0872 | BY16: -0.1981 | BZ16: 2.7161 | CA16: 196.0709 | CB16: 1.4239 | CC16: 2.3223 | CD16: 196.1442 | CE16: 2.6473 | CF16: 0.1389 | CG16: 196.0985 | CH16: 2.5468 | CI16: -0.9894 | CK16: =IF(BO16="","",(BO16-BO$10)*1000) -> 0.43081613 | CL16: =IF(BP16="","",(BP16-BP$10)*1000) -> 2.9010247 | CM16: =IF(BQ16="","",(BQ16-BQ$10)*1000) -> 1.8676918 | CN16: =IF(BR16="","",(BR16-BR$10)*1000) -> -9.1769518 | CO16: =IF(BS16="","",(BS16-BS$10)*1000) -> 1.2856942 | CP16: =IF(BT16="","",(BT16-BT$10)*1000) -> -4.0822305 | CQ16: =IF(BU16="","",(BU16-BU$10)*1000) -> 0.35175721 | CR16: =IF(BV16="","",(BV16-BV$10)*1000) -> 4.2583723 | ... DE16: =IF(CI16="","",(CI16-CI$10)*1000) -> 0.50915044
A17: 43718 | B17: =A17-A$10 -> 13 | C17: 202.58 | D17: =C17-PM -> 6.48 | E17: 823244.33 | F17: 1091518.8 | G17: -124.5488 | H17: 823244.24 | I17: 1091519 | J17: -123.1865 | K17: 823244.51 | L17: 1091518.5 | M17: -121.8119 | N17: 823245.3 | O17: 1091516.7 | P17: -120.871 | Q17: 823245.97 | R17: 1091515.2 | S17: -121.2634 | T17: 823246.56 | U17: 1091514.1 | V17: -123.4422 | W17: 823246.47 | X17: 1091514.2 | Y17: -124.5707 | Z17: =IF(Xhaut="","",SQRT(((Xbasgauche-Xhaut)^2+(Ybasgauche-Yhaut)^2)+(Zbasgauche-Zhaut)^2)) -> 4.3563905 | AA17: =IF(Xhaut="","",SQRT(((Xintergauche-Xhaut)^2+(Yintergauche-Yhaut)^2)+(Zintergauche-Zhaut)^2)) -> 3.4316453 | AB17: =IF(Xhaut="","",SQRT(((Xhautgauche-Xhaut)^2+(Yhautgauche-Yhaut)^2)+(Zhautgauche-Zhaut)^2)) -> 2.1946619 | AC17: =IF(Xhaut="","",SQRT(((Xhautdroit-Xhaut)^2+(Yhautdroit-Yhaut)^2)+(Zhautdroit-Zhaut)^2)) -> 1.6681716 | AD17: =IF(Xhaut="","",SQRT(((Xinterdroit-Xhaut)^2+(Yinterdroit-Yhaut)^2)+(Zinterdroit-Zhaut)^2)) -> 3.8340061 | AE17: =IF(Xhaut="","",SQRT(((Xbasdroit-Xhaut)^2+(Ybasdroit-Yhaut)^2)+(Zbasdroit-Zhaut)^2)) -> 4.6054032 | AF17: =IF(Xhautdroit="","",SQRT(((Xhautdroit-Xhautgauche)^2+(Yhautdroit-Yhautgauche)^2)+(Zhautdroit-Zhautgauche)^2)) -> 3.6454617 | AG17: =IF(Xinterdroit="","",SQRT(((Xinterdroit-Xintergauche)^2+(Yinterdroit-Yintergauche)^2)+(Zinterdroit-Zintergauche)^2)) -> 5.382495 | AH17: =IF(Xbasdroit="","",SQRT(((Xbasdroit-Xbasgauche)^2+(Ybasdroit-Ybasgauche)^2)+(Zbasdroit-Zbasgauche)^2)) -> 5.0775001 | AI17: =IF(Z17="","",(Z17-Z$10)*1000) -> -17.748515 | AJ17: =IF(AA17="","",(AA17-AA$10)*1000) -> -9.5191724 | AK17: =IF(AB17="","",(AB17-AB$10)*1000) -> -11.204981 | AL17: =IF(AC17="","",(AC17-AC$10)*1000) -> -2.1396156 | AM17: =IF(AD17="","",(AD17-AD$10)*1000) -> -14.514324 | AN17: =IF(AE17="","",(AE17-AE$10)*1000) -> -17.198766 | AO17: =IF(AF17="","",(AF17-AF$10)*1000) -> -7.7203864 | AP17: =IF(AG17="","",(AG17-AG$10)*1000) -> -7.4171538 | AQ17: =IF(AH17="","",(AH17-AH$10)*1000) -> -10.66714 | AS17: =IF(E17="","",(E17-E$10)*1000) -> 2.5000001 | AT17: =IF(F17="","",(F17-F$10)*1000) -> -5.7000001 | AU17: =IF(G17="","",(G17-G$10)*1000) -> 2.7 | AV17: =IF(H17="","",(H17-H$10)*1000) -> -6.4000001 | AW17: =IF(I17="","",(I17-I$10)*1000) -> -7.9000001 | AX17: =IF(J17="","",(J17-J$10)*1000) -> -4.3 | AY17: =IF(K17="","",(K17-K$10)*1000) -> 3 | AZ17: =IF(L17="","",(L17-L$10)*1000) -> -7.1 | ... BM17: =IF(Y17="","",(Y17-Y$10)*1000) -> 1.1 | BO17: 196.10463 | BP17: -2.5309785 | BQ17: -0.96696626 | BR17: 196.09064 | BS17: -2.728831 | BT17: 0.39547362 | BU17: 196.13837 | BV17: -2.1781557 | BW17: 1.7695963 | BX17: 196.08561 | BY17: -0.1961202 | BZ17: 2.7110239 | CA17: 196.07111 | CB17: 1.4251781 | CC17: 2.3187689 | CD17: 196.14333 | CE17: 2.6473288 | CF17: 0.13924669 | CG17: 196.09812 | CH17: 2.5464701 | CI17: -0.98880122 | CK17: =IF(BO17="","",(BO17-BO$10)*1000) -> -0.14338632 | CL17: =IF(BP17="","",(BP17-BP$10)*1000) -> 6.2224948 | CM17: =IF(BQ17="","",(BQ17-BQ$10)*1000) -> 2.7014339 | CN17: =IF(BR17="","",(BR17-BR$10)*1000) -> -9.1392201 | CO17: =IF(BS17="","",(BS17-BS$10)*1000) -> 4.4547344 | CP17: =IF(BT17="","",(BT17-BT$10)*1000) -> -4.2086078 | CQ17: =IF(BU17="","",(BU17-BU$10)*1000) -> -0.28195312 | CR17: =IF(BV17="","",(BV17-BV$10)*1000) -> 7.7026296 | ... DE17: =IF(CI17="","",(CI17-CI$10)*1000) -> 1.1079255
A18: 43720 | B18: =A18-A$10 -> 15 | C18: 203.6 | D18: =C18-PM -> 7.5 | E18: 823244.33 | F18: 1091518.8 | G18: -124.5487 | H18: 823244.24 | I18: 1091519 | J18: -123.1866 | K18: 823244.51 | L18: 1091518.5 | M18: -121.8138 | N18: 823245.3 | O18: 1091516.7 | P18: -120.8741 | Q18: 823245.98 | R18: 1091515.2 | S18: -121.2658 | T18: 823246.56 | U18: 1091514.1 | V18: -123.4422 | W18: 823246.47 | X18: 1091514.2 | Y18: -124.5704 | Z18: =IF(Xhaut="","",SQRT(((Xbasgauche-Xhaut)^2+(Ybasgauche-Yhaut)^2)+(Zbasgauche-Zhaut)^2)) -> 4.3533425 | AA18: =IF(Xhaut="","",SQRT(((Xintergauche-Xhaut)^2+(Yintergauche-Yhaut)^2)+(Zintergauche-Zhaut)^2)) -> 3.4290693 | AB18: =IF(Xhaut="","",SQRT(((Xhautgauche-Xhaut)^2+(Yhautgauche-Yhaut)^2)+(Zhautgauche-Zhaut)^2)) -> 2.1921161 | AC18: =IF(Xhaut="","",SQRT(((Xhautdroit-Xhaut)^2+(Yhautdroit-Yhaut)^2)+(Zhautdroit-Zhaut)^2)) -> 1.6677586 | AD18: =IF(Xhaut="","",SQRT(((Xinterdroit-Xhaut)^2+(Yinterdroit-Yhaut)^2)+(Zinterdroit-Zhaut)^2)) -> 3.8314943 | AE18: =IF(Xhaut="","",SQRT(((Xbasdroit-Xhaut)^2+(Ybasdroit-Yhaut)^2)+(Zbasdroit-Zhaut)^2)) -> 4.6020572 | AF18: =IF(Xhautdroit="","",SQRT(((Xhautdroit-Xhautgauche)^2+(Yhautdroit-Yhautgauche)^2)+(Zhautdroit-Zhautgauche)^2)) -> 3.642897 | AG18: =IF(Xinterdroit="","",SQRT(((Xinterdroit-Xintergauche)^2+(Yinterdroit-Yintergauche)^2)+(Zinterdroit-Zintergauche)^2)) -> 5.3811503 | AH18: =IF(Xbasdroit="","",SQRT(((Xbasdroit-Xbasgauche)^2+(Ybasdroit-Ybasgauche)^2)+(Zbasdroit-Zbasgauche)^2)) -> 5.0758146 | AI18: =IF(Z18="","",(Z18-Z$10)*1000) -> -20.796429 | AJ18: =IF(AA18="","",(AA18-AA$10)*1000) -> -12.095146 | AK18: =IF(AB18="","",(AB18-AB$10)*1000) -> -13.750788 | AL18: =IF(AC18="","",(AC18-AC$10)*1000) -> -2.552598 | AM18: =IF(AD18="","",(AD18-AD$10)*1000) -> -17.026117 | AN18: =IF(AE18="","",(AE18-AE$10)*1000) -> -20.544771 | AO18: =IF(AF18="","",(AF18-AF$10)*1000) -> -10.285124 | AP18: =IF(AG18="","",(AG18-AG$10)*1000) -> -8.7618254 | AQ18: =IF(AH18="","",(AH18-AH$10)*1000) -> -12.352626 | AS18: =IF(E18="","",(E18-E$10)*1000) -> 3.3 | AT18: =IF(F18="","",(F18-F$10)*1000) -> -5.4000001 | AU18: =IF(G18="","",(G18-G$10)*1000) -> 2.8 | AV18: =IF(H18="","",(H18-H$10)*1000) -> -5.8 | AW18: =IF(I18="","",(I18-I$10)*1000) -> -7.8 | AX18: =IF(J18="","",(J18-J$10)*1000) -> -4.4 | AY18: =IF(K18="","",(K18-K$10)*1000) -> 4.4 | AZ18: =IF(L18="","",(L18-L$10)*1000) -> -8.3000001 | ... BM18: =IF(Y18="","",(Y18-Y$10)*1000) -> 1.4 | BO18: 196.1055 | BP18: -2.5309 | BQ18: -0.9669 | BR18: 196.0912 | BS18: -2.7287 | BT18: 0.3954 | BU18: 196.1391 | BV18: -2.1765 | BW18: 1.7677 | BX18: 196.0858 | BY18: -0.1967 | BZ18: 2.7079 | CA18: 196.0722 | CB18: 1.4243 | CC18: 2.3164 | CD18: 196.1439 | CE18: 2.6462 | CF18: 0.1392 | CG18: 196.0984 | CH18: 2.5449 | CI18: -0.9885 | CK18: =IF(BO18="","",(BO18-BO$10)*1000) -> 0.73081613 | CL18: =IF(BP18="","",(BP18-BP$10)*1000) -> 6.3010247 | CM18: =IF(BQ18="","",(BQ18-BQ$10)*1000) -> 2.7676918 | CN18: =IF(BR18="","",(BR18-BR$10)*1000) -> -8.5769518 | CO18: =IF(BS18="","",(BS18-BS$10)*1000) -> 4.5856942 | CP18: =IF(BT18="","",(BT18-BT$10)*1000) -> -4.2822305 | CQ18: =IF(BU18="","",(BU18-BU$10)*1000) -> 0.45175721 | CR18: =IF(BV18="","",(BV18-BV$10)*1000) -> 9.3583723 | ... DE18: =IF(CI18="","",(CI18-CI$10)*1000) -> 1.4091504
A19: 43724 | B19: =A19-A$10 -> 19 | C19: 203.6 | D19: =C19-PM -> 7.5 | E19: 823244.33 | F19: 1091518.8 | G19: -124.5483 | H19: 823244.24 | I19: 1091519 | J19: -123.1866 | K19: 823244.51 | L19: 1091518.5 | M19: -121.8144 | N19: 823245.3 | O19: 1091516.7 | P19: -120.8781 | Q19: 823245.97 | R19: 1091515.2 | S19: -121.2682 | T19: 823246.56 | U19: 1091514.1 | V19: -123.4423 | W19: 823246.47 | X19: 1091514.2 | Y19: -124.5702 | Z19: =IF(Xhaut="","",SQRT(((Xbasgauche-Xhaut)^2+(Ybasgauche-Yhaut)^2)+(Zbasgauche-Zhaut)^2)) -> 4.3490785 | AA19: =IF(Xhaut="","",SQRT(((Xintergauche-Xhaut)^2+(Yintergauche-Yhaut)^2)+(Zintergauche-Zhaut)^2)) -> 3.4257222 | AB19: =IF(Xhaut="","",SQRT(((Xhautgauche-Xhaut)^2+(Yhautgauche-Yhaut)^2)+(Zhautgauche-Zhaut)^2)) -> 2.1891289 | AC19: =IF(Xhaut="","",SQRT(((Xhautdroit-Xhaut)^2+(Yhautdroit-Yhaut)^2)+(Zhautdroit-Zhaut)^2)) -> 1.6676181 | AD19: =IF(Xhaut="","",SQRT(((Xinterdroit-Xhaut)^2+(Yinterdroit-Yhaut)^2)+(Zinterdroit-Zhaut)^2)) -> 3.828215 | AE19: =IF(Xhaut="","",SQRT(((Xbasdroit-Xhaut)^2+(Ybasdroit-Yhaut)^2)+(Zbasdroit-Zhaut)^2)) -> 4.5979583 | AF19: =IF(Xhautdroit="","",SQRT(((Xhautdroit-Xhautgauche)^2+(Yhautdroit-Yhautgauche)^2)+(Zhautdroit-Zhautgauche)^2)) -> 3.6411808 | AG19: =IF(Xinterdroit="","",SQRT(((Xinterdroit-Xintergauche)^2+(Yinterdroit-Yintergauche)^2)+(Zinterdroit-Zintergauche)^2)) -> 5.3793685 | AH19: =IF(Xbasdroit="","",SQRT(((Xbasdroit-Xbasgauche)^2+(Ybasdroit-Ybasgauche)^2)+(Zbasdroit-Zbasgauche)^2)) -> 5.0735675 | AI19: =IF(Z19="","",(Z19-Z$10)*1000) -> -25.060484 | AJ19: =IF(AA19="","",(AA19-AA$10)*1000) -> -15.442253 | AK19: =IF(AB19="","",(AB19-AB$10)*1000) -> -16.737918 | AL19: =IF(AC19="","",(AC19-AC$10)*1000) -> -2.6931309 | AM19: =IF(AD19="","",(AD19-AD$10)*1000) -> -20.305454 | AN19: =IF(AE19="","",(AE19-AE$10)*1000) -> -24.643656 | AO19: =IF(AF19="","",(AF19-AF$10)*1000) -> -12.001257 | AP19: =IF(AG19="","",(AG19-AG$10)*1000) -> -10.543635 | AQ19: =IF(AH19="","",(AH19-AH$10)*1000) -> -14.599698 | AS19: =IF(E19="","",(E19-E$10)*1000) -> 2.3000001 | AT19: =IF(F19="","",(F19-F$10)*1000) -> -6.2000002 | AU19: =IF(G19="","",(G19-G$10)*1000) -> 3.2 | AV19: =IF(H19="","",(H19-H$10)*1000) -> -6.5 | AW19: =IF(I19="","",(I19-I$10)*1000) -> -8.3000001 | AX19: =IF(J19="","",(J19-J$10)*1000) -> -4.4 | AY19: =IF(K19="","",(K19-K$10)*1000) -> 3.7 | AZ19: =IF(L19="","",(L19-L$10)*1000) -> -9.7000001 | ... BM19: =IF(Y19="","",(Y19-Y$10)*1000) -> 1.6 | BO19: 196.1042 | BP19: -2.5306 | BQ19: -0.9665 | BR19: 196.0904 | BS19: -2.7285 | BT19: 0.3954 | BU19: 196.1379 | BV19: -2.1755 | BW19: 1.7671 | BX19: 196.0845 | BY19: -0.1974 | BZ19: 2.7039 | CA19: 196.0716 | CB19: 1.4239 | CC19: 2.314 | CD19: 196.143 | CE19: 2.6445 | CF19: 0.1392 | CG19: 196.0976 | CH19: 2.5429 | CI19: -0.9883 | CK19: =IF(BO19="","",(BO19-BO$10)*1000) -> -0.56918387 | CL19: =IF(BP19="","",(BP19-BP$10)*1000) -> 6.6010247 | CM19: =IF(BQ19="","",(BQ19-BQ$10)*1000) -> 3.1676918 | CN19: =IF(BR19="","",(BR19-BR$10)*1000) -> -9.3769518 | CO19: =IF(BS19="","",(BS19-BS$10)*1000) -> 4.7856942 | CP19: =IF(BT19="","",(BT19-BT$10)*1000) -> -4.2822305 | CQ19: =IF(BU19="","",(BU19-BU$10)*1000) -> -0.74824279 | CR19: =IF(BV19="","",(BV19-BV$10)*1000) -> 10.358372 | ... DE19: =IF(CI19="","",(CI19-CI$10)*1000) -> 1.6091504
A20: 43727 | B20: =A20-A$10 -> 22 | C20: 206.32 | D20: =C20-PM -> 10.22 | E20: 823244.33 | F20: 1091518.8 | G20: -124.548 | H20: 823244.24 | I20: 1091519 | J20: -123.1865 | K20: 823244.51 | L20: 1091518.5 | M20: -121.815 | N20: 823245.3 | O20: 1091516.7 | P20: -120.881 | Q20: 823245.97 | R20: 1091515.2 | S20: -121.2703 | T20: 823246.55 | U20: 1091514.1 | V20: -123.4422 | W20: 823246.47 | X20: 1091514.2 | Y20: -124.5697 | Z20: =IF(Xhaut="","",SQRT(((Xbasgauche-Xhaut)^2+(Ybasgauche-Yhaut)^2)+(Zbasgauche-Zhaut)^2)) -> 4.3462225 | AA20: =IF(Xhaut="","",SQRT(((Xintergauche-Xhaut)^2+(Yintergauche-Yhaut)^2)+(Zintergauche-Zhaut)^2)) -> 3.4233807 | AB20: =IF(Xhaut="","",SQRT(((Xhautgauche-Xhaut)^2+(Yhautgauche-Yhaut)^2)+(Zhautgauche-Zhaut)^2)) -> 2.1876565 | AC20: =IF(Xhaut="","",SQRT(((Xhautdroit-Xhaut)^2+(Yhautdroit-Yhaut)^2)+(Zhautdroit-Zhaut)^2)) -> 1.667047 | AD20: =IF(Xhaut="","",SQRT(((Xinterdroit-Xhaut)^2+(Yinterdroit-Yhaut)^2)+(Zinterdroit-Zhaut)^2)) -> 3.8254052 | AE20: =IF(Xhaut="","",SQRT(((Xbasdroit-Xhaut)^2+(Ybasdroit-Yhaut)^2)+(Zbasdroit-Zhaut)^2)) -> 4.5946041 | AF20: =IF(Xhautdroit="","",SQRT(((Xhautdroit-Xhautgauche)^2+(Yhautdroit-Yhautgauche)^2)+(Zhautdroit-Zhautgauche)^2)) -> 3.6400124 | AG20: =IF(Xinterdroit="","",SQRT(((Xinterdroit-Xintergauche)^2+(Yinterdroit-Yintergauche)^2)+(Zinterdroit-Zintergauche)^2)) -> 5.3778445 | AH20: =IF(Xbasdroit="","",SQRT(((Xbasdroit-Xbasgauche)^2+(Ybasdroit-Ybasgauche)^2)+(Zbasdroit-Zbasgauche)^2)) -> 5.0722192 | AI20: =IF(Z20="","",(Z20-Z$10)*1000) -> -27.916513 | AJ20: =IF(AA20="","",(AA20-AA$10)*1000) -> -17.783792 | AK20: =IF(AB20="","",(AB20-AB$10)*1000) -> -18.210378 | AL20: =IF(AC20="","",(AC20-AC$10)*1000) -> -3.2641506 | AM20: =IF(AD20="","",(AD20-AD$10)*1000) -> -23.115253 | AN20: =IF(AE20="","",(AE20-AE$10)*1000) -> -27.997854 | AO20: =IF(AF20="","",(AF20-AF$10)*1000) -> -13.169716 | AP20: =IF(AG20="","",(AG20-AG$10)*1000) -> -12.06767 | AQ20: =IF(AH20="","",(AH20-AH$10)*1000) -> -15.948027 | AS20: =IF(E20="","",(E20-E$10)*1000) -> 2.4 | AT20: =IF(F20="","",(F20-F$10)*1000) -> -6.2000002 | AU20: =IF(G20="","",(G20-G$10)*1000) -> 3.5 | AV20: =IF(H20="","",(H20-H$10)*1000) -> -6.5 | AW20: =IF(I20="","",(I20-I$10)*1000) -> -8.5 | AX20: =IF(J20="","",(J20-J$10)*1000) -> -4.3 | AY20: =IF(K20="","",(K20-K$10)*1000) -> 4 | AZ20: =IF(L20="","",(L20-L$10)*1000) -> -9.8999999 | ... BM20: =IF(Y20="","",(Y20-Y$10)*1000) -> 2.1 | BO20: 196.1043 | BP20: -2.5306 | BQ20: -0.9662 | BR20: 196.0903 | BS20: -2.7283 | BT20: 0.3955 | BU20: 196.1381 | BV20: -2.1752 | BW20: 1.7665 | BX20: 196.0839 | BY20: -0.1977 | BZ20: 2.701 | CA20: 196.0721 | CB20: 1.4232 | CC20: 2.3119 | CD20: 196.1432 | CE20: 2.6432 | CF20: 0.1392 | CG20: 196.0979 | CH20: 2.5416 | CI20: -0.9878 | CK20: =IF(BO20="","",(BO20-BO$10)*1000) -> -0.46918387 | CL20: =IF(BP20="","",(BP20-BP$10)*1000) -> 6.6010247 | CM20: =IF(BQ20="","",(BQ20-BQ$10)*1000) -> 3.4676918 | CN20: =IF(BR20="","",(BR20-BR$10)*1000) -> -9.4769518 | CO20: =IF(BS20="","",(BS20-BS$10)*1000) -> 4.9856942 | CP20: =IF(BT20="","",(BT20-BT$10)*1000) -> -4.1822305 | CQ20: =IF(BU20="","",(BU20-BU$10)*1000) -> -0.54824279 | CR20: =IF(BV20="","",(BV20-BV$10)*1000) -> 10.658372 | ... DE20: =IF(CI20="","",(CI20-CI$10)*1000) -> 2.1091504
A21: 43731 | B21: =A21-A$10 -> 26 | C21: 206.32 | D21: =C21-PM -> 10.22 | E21: 823244.33 | F21: 1091518.8 | G21: -124.5478 | H21: 823244.24 | I21: 1091519 | J21: -123.1865 | K21: 823244.51 | L21: 1091518.5 | M21: -121.8153 | N21: 823245.3 | O21: 1091516.7 | P21: -120.8836 | Q21: 823245.98 | R21: 1091515.2 | S21: -121.2722 | T21: 823246.55 | U21: 1091514.1 | V21: -123.4421 | W21: 823246.47 | X21: 1091514.2 | Y21: -124.5698 | Z21: =IF(Xhaut="","",SQRT(((Xbasgauche-Xhaut)^2+(Ybasgauche-Yhaut)^2)+(Zbasgauche-Zhaut)^2)) -> 4.3439314 | AA21: =IF(Xhaut="","",SQRT(((Xintergauche-Xhaut)^2+(Yintergauche-Yhaut)^2)+(Zintergauche-Zhaut)^2)) -> 3.4216041 | AB21: =IF(Xhaut="","",SQRT(((Xhautgauche-Xhaut)^2+(Yhautgauche-Yhaut)^2)+(Zhautgauche-Zhaut)^2)) -> 2.1862826 | AC21: =IF(Xhaut="","",SQRT(((Xhautdroit-Xhaut)^2+(Yhautdroit-Yhaut)^2)+(Zhautdroit-Zhaut)^2)) -> 1.6669572 | AD21: =IF(Xhaut="","",SQRT(((Xinterdroit-Xhaut)^2+(Yinterdroit-Yhaut)^2)+(Zinterdroit-Zhaut)^2)) -> 3.8232646 | AE21: =IF(Xhaut="","",SQRT(((Xbasdroit-Xhaut)^2+(Ybasdroit-Yhaut)^2)+(Zbasdroit-Zhaut)^2)) -> 4.5922963 | AF21: =IF(Xhautdroit="","",SQRT(((Xhautdroit-Xhautgauche)^2+(Yhautdroit-Yhautgauche)^2)+(Zhautdroit-Zhautgauche)^2)) -> 3.6394118 | AG21: =IF(Xinterdroit="","",SQRT(((Xinterdroit-Xintergauche)^2+(Yinterdroit-Yintergauche)^2)+(Zinterdroit-Zintergauche)^2)) -> 5.37735 | AH21: =IF(Xbasdroit="","",SQRT(((Xbasdroit-Xbasgauche)^2+(Ybasdroit-Ybasgauche)^2)+(Zbasdroit-Zbasgauche)^2)) -> 5.071845 | AI21: =IF(Z21="","",(Z21-Z$10)*1000) -> -30.207526 | AJ21: =IF(AA21="","",(AA21-AA$10)*1000) -> -19.560389 | AK21: =IF(AB21="","",(AB21-AB$10)*1000) -> -19.584261 | AL21: =IF(AC21="","",(AC21-AC$10)*1000) -> -3.3540246 | AM21: =IF(AD21="","",(AD21-AD$10)*1000) -> -25.255826 | AN21: =IF(AE21="","",(AE21-AE$10)*1000) -> -30.305685 | AO21: =IF(AF21="","",(AF21-AF$10)*1000) -> -13.770258 | AP21: =IF(AG21="","",(AG21-AG$10)*1000) -> -12.562169 | AQ21: =IF(AH21="","",(AH21-AH$10)*1000) -> -16.322193 | AS21: =IF(E21="","",(E21-E$10)*1000) -> 2.4 | AT21: =IF(F21="","",(F21-F$10)*1000) -> -3.6000002 | AU21: =IF(G21="","",(G21-G$10)*1000) -> 3.7 | AV21: =IF(H21="","",(H21-H$10)*1000) -> -6.1 | AW21: =IF(I21="","",(I21-I$10)*1000) -> -5.9 | AX21: =IF(J21="","",(J21-J$10)*1000) -> -4.3 | AY21: =IF(K21="","",(K21-K$10)*1000) -> 4.5 | AZ21: =IF(L21="","",(L21-L$10)*1000) -> -7.7 | ... BM21: =IF(Y21="","",(Y21-Y$10)*1000) -> 2 | BO21: 196.1054 | BP21: -2.5329 | BQ21: -0.966 | BR21: 196.0918 | BS21: -2.7305 | BT21: 0.3955 | BU21: 196.1395 | BV21: -2.177 | BW21: 1.7662 | BX21: 196.0851 | BY21: -0.1999 | BZ21: 2.6984 | CA21: 196.0737 | CB21: 1.4211 | CC21: 2.3099 | CD21: 196.1445 | CE21: 2.6405 | CF21: 0.1393 | CG21: 196.0996 | CH21: 2.5389 | CI21: -0.9879 | CK21: =IF(BO21="","",(BO21-BO$10)*1000) -> 0.63081613 | CL21: =IF(BP21="","",(BP21-BP$10)*1000) -> 4.3010247 | CM21: =IF(BQ21="","",(BQ21-BQ$10)*1000) -> 3.6676918 | CN21: =IF(BR21="","",(BR21-BR$10)*1000) -> -7.9769518 | CO21: =IF(BS21="","",(BS21-BS$10)*1000) -> 2.7856942 | CP21: =IF(BT21="","",(BT21-BT$10)*1000) -> -4.1822305 | CQ21: =IF(BU21="","",(BU21-BU$10)*1000) -> 0.85175721 | CR21: =IF(BV21="","",(BV21-BV$10)*1000) -> 8.8583723 | ... DE21: =IF(CI21="","",(CI21-CI$10)*1000) -> 2.0091504
A22: 43734 | B22: =A22-A$10 -> 29 | C22: 206.32 | D22: =C22-PM -> 10.22 | E22: 823244.33 | F22: 1091518.8 | G22: -124.5478 | H22: 823244.24 | I22: 1091519 | J22: -123.1866 | K22: 823244.51 | L22: 1091518.5 | M22: -121.8158 | N22: 823245.3 | O22: 1091516.7 | P22: -120.885 | Q22: 823245.97 | R22: 1091515.2 | S22: -121.2734 | T22: 823246.55 | U22: 1091514.1 | V22: -123.4421 | W22: 823246.47 | X22: 1091514.2 | Y22: -124.5697 | Z22: =IF(Xhaut="","",SQRT(((Xbasgauche-Xhaut)^2+(Ybasgauche-Yhaut)^2)+(Zbasgauche-Zhaut)^2)) -> 4.3426349 | AA22: =IF(Xhaut="","",SQRT(((Xintergauche-Xhaut)^2+(Yintergauche-Yhaut)^2)+(Zintergauche-Zhaut)^2)) -> 3.4205999 | AB22: =IF(Xhaut="","",SQRT(((Xhautgauche-Xhaut)^2+(Yhautgauche-Yhaut)^2)+(Zhautgauche-Zhaut)^2)) -> 2.1857802 | AC22: =IF(Xhaut="","",SQRT(((Xhautdroit-Xhaut)^2+(Yhautdroit-Yhaut)^2)+(Zhautdroit-Zhaut)^2)) -> 1.6668221 | AD22: =IF(Xhaut="","",SQRT(((Xinterdroit-Xhaut)^2+(Yinterdroit-Yhaut)^2)+(Zinterdroit-Zhaut)^2)) -> 3.8220591 | AE22: =IF(Xhaut="","",SQRT(((Xbasdroit-Xhaut)^2+(Ybasdroit-Yhaut)^2)+(Zbasdroit-Zhaut)^2)) -> 4.5908169 | AF22: =IF(Xhautdroit="","",SQRT(((Xhautdroit-Xhautgauche)^2+(Yhautdroit-Yhautgauche)^2)+(Zhautdroit-Zhautgauche)^2)) -> 3.6390866 | AG22: =IF(Xinterdroit="","",SQRT(((Xinterdroit-Xintergauche)^2+(Yinterdroit-Yintergauche)^2)+(Zinterdroit-Zintergauche)^2)) -> 5.3768007 | AH22: =IF(Xbasdroit="","",SQRT(((Xbasdroit-Xbasgauche)^2+(Ybasdroit-Ybasgauche)^2)+(Zbasdroit-Zbasgauche)^2)) -> 5.0711613 | AI22: =IF(Z22="","",(Z22-Z$10)*1000) -> -31.50411 | AJ22: =IF(AA22="","",(AA22-AA$10)*1000) -> -20.564518 | AK22: =IF(AB22="","",(AB22-AB$10)*1000) -> -20.086644 | AL22: =IF(AC22="","",(AC22-AC$10)*1000) -> -3.4890575 | AM22: =IF(AD22="","",(AD22-AD$10)*1000) -> -26.461363 | AN22: =IF(AE22="","",(AE22-AE$10)*1000) -> -31.785089 | AO22: =IF(AF22="","",(AF22-AF$10)*1000) -> -14.095531 | AP22: =IF(AG22="","",(AG22-AG$10)*1000) -> -13.111444 | AQ22: =IF(AH22="","",(AH22-AH$10)*1000) -> -17.005864 | AS22: =IF(E22="","",(E22-E$10)*1000) -> 1.3 | AT22: =IF(F22="","",(F22-F$10)*1000) -> -4.3000001 | AU22: =IF(G22="","",(G22-G$10)*1000) -> 3.7 | AV22: =IF(H22="","",(H22-H$10)*1000) -> -7.3000001 | AW22: =IF(I22="","",(I22-I$10)*1000) -> -6.6 | AX22: =IF(J22="","",(J22-J$10)*1000) -> -4.4 | AY22: =IF(K22="","",(K22-K$10)*1000) -> 3.2 | AZ22: =IF(L22="","",(L22-L$10)*1000) -> -8.3999999 | ... BM22: =IF(Y22="","",(Y22-Y$10)*1000) -> 2.1 | BO22: 196.1041 | BP22: -2.5328 | BQ22: -0.966 | BR22: 196.0904 | BS22: -2.7304 | BT22: 0.3954 | BU22: 196.138 | BV22: -2.1769 | BW22: 1.7657 | BX22: 196.0835 | BY22: -0.2 | BZ22: 2.697 | CA22: 196.0722 | CB22: 1.4209 | CC22: 2.3088 | CD22: 196.1436 | CE22: 2.6401 | CF22: 0.1393 | CG22: 196.0987 | CH22: 2.5384 | CI22: -0.9878 | CK22: =IF(BO22="","",(BO22-BO$10)*1000) -> -0.66918387 | CL22: =IF(BP22="","",(BP22-BP$10)*1000) -> 4.4010247 | CM22: =IF(BQ22="","",(BQ22-BQ$10)*1000) -> 3.6676918 | CN22: =IF(BR22="","",(BR22-BR$10)*1000) -> -9.3769518 | CO22: =IF(BS22="","",(BS22-BS$10)*1000) -> 2.8856942 | CP22: =IF(BT22="","",(BT22-BT$10)*1000) -> -4.2822305 | CQ22: =IF(BU22="","",(BU22-BU$10)*1000) -> -0.64824279 | CR22: =IF(BV22="","",(BV22-BV$10)*1000) -> 8.9583723 | ... DE22: =IF(CI22="","",(CI22-CI$10)*1000) -> 2.1091504
... A34: 43782 | B34: =A34-A$10 -> 77 | C34: 219.45 | D34: =C34-PM -> 23.35 | E34: 823244.33 | F34: 1091518.8 | G34: -124.5461 | H34: 823244.24 | I34: 1091519 | J34: -123.1861 | K34: 823244.51 | L34: 1091518.5 | M34: -121.8181 | N34: 823245.3 | O34: 1091516.7 | P34: -120.9029 | Q34: 823245.97 | R34: 1091515.2 | S34: -121.2872 | T34: 823246.55 | U34: 1091514.1 | V34: -123.4413 | W34: 823246.47 | X34: 1091514.2 | Y34: -124.5682 | Z34: =IF(Xhaut="","",SQRT(((Xbasgauche-Xhaut)^2+(Ybasgauche-Yhaut)^2)+(Zbasgauche-Zhaut)^2)) -> 4.3254552 | AA34: =IF(Xhaut="","",SQRT(((Xintergauche-Xhaut)^2+(Yintergauche-Yhaut)^2)+(Zintergauche-Zhaut)^2)) -> 3.4071198 | AB34: =IF(Xhaut="","",SQRT(((Xhautgauche-Xhaut)^2+(Yhautgauche-Yhaut)^2)+(Zhautgauche-Zhaut)^2)) -> 2.1767088 | AC34: =IF(Xhaut="","",SQRT(((Xhautdroit-Xhaut)^2+(Yhautdroit-Yhaut)^2)+(Zhautdroit-Zhaut)^2)) -> 1.6656481 | AD34: =IF(Xhaut="","",SQRT(((Xinterdroit-Xhaut)^2+(Yinterdroit-Yhaut)^2)+(Zinterdroit-Zhaut)^2)) -> 3.8062938 | AE34: =IF(Xhaut="","",SQRT(((Xbasdroit-Xhaut)^2+(Ybasdroit-Yhaut)^2)+(Zbasdroit-Zhaut)^2)) -> 4.5725976 | AF34: =IF(Xhautdroit="","",SQRT(((Xhautdroit-Xhautgauche)^2+(Yhautdroit-Yhautgauche)^2)+(Zhautdroit-Zhautgauche)^2)) -> 3.634407 | AG34: =IF(Xinterdroit="","",SQRT(((Xinterdroit-Xintergauche)^2+(Yinterdroit-Yintergauche)^2)+(Zinterdroit-Zintergauche)^2)) -> 5.3707999 | AH34: =IF(Xbasdroit="","",SQRT(((Xbasdroit-Xbasgauche)^2+(Ybasdroit-Ybasgauche)^2)+(Zbasdroit-Zbasgauche)^2)) -> 5.0654352 | AI34: =IF(Z34="","",(Z34-Z$10)*1000) -> -48.683728 | AJ34: =IF(AA34="","",(AA34-AA$10)*1000) -> -34.044631 | AK34: =IF(AB34="","",(AB34-AB$10)*1000) -> -29.158082 | AL34: =IF(AC34="","",(AC34-AC$10)*1000) -> -4.6631117 | AM34: =IF(AD34="","",(AD34-AD$10)*1000) -> -42.226698 | AN34: =IF(AE34="","",(AE34-AE$10)*1000) -> -50.004377 | AO34: =IF(AF34="","",(AF34-AF$10)*1000) -> -18.775102 | AP34: =IF(AG34="","",(AG34-AG$10)*1000) -> -19.112241 | AQ34: =IF(AH34="","",(AH34-AH$10)*1000) -> -22.732047 | AS34: =IF(E34="","",(E34-E$10)*1000) -> 1.8 | AT34: =IF(F34="","",(F34-F$10)*1000) -> -5.8000002 | AU34: =IF(G34="","",(G34-G$10)*1000) -> 5.4 | AV34: =IF(H34="","",(H34-H$10)*1000) -> -6.8 | AW34: =IF(I34="","",(I34-I$10)*1000) -> -8.3999999 | AX34: =IF(J34="","",(J34-J$10)*1000) -> -3.9 | AY34: =IF(K34="","",(K34-K$10)*1000) -> 3.7 | AZ34: =IF(L34="","",(L34-L$10)*1000) -> -11.6 | ... BM34: =IF(Y34="","",(Y34-Y$10)*1000) -> 3.6 | BO34: 196.10395 | BP34: -2.5311838 | BQ34: -0.96425949 | BR34: 196.09006 | BS34: -2.7285469 | BT34: 0.39587936 | BU34: 196.1371 | BV34: -2.1737816 | BW34: 1.763409 | BX34: 196.08019 | BY34: -0.19964084 | BZ34: 2.6791781 | CA34: 196.07171 | CB34: 1.4210458 | CC34: 2.2949629 | CD34: 196.14324 | CE34: 2.635923 | CF34: 0.14014757 | CG34: 196.09855 | CH34: 2.5342003 | CI34: -0.98630548 | CK34: =IF(BO34="","",(BO34-BO$10)*1000) -> -0.82005607 | CL34: =IF(BP34="","",(BP34-BP$10)*1000) -> 6.0172676 | CM34: =IF(BQ34="","",(BQ34-BQ$10)*1000) -> 5.4082006 | CN34: =IF(BR34="","",(BR34-BR$10)*1000) -> -9.7130628 | CO34: =IF(BS34="","",(BS34-BS$10)*1000) -> 4.7388195 | CP34: =IF(BT34="","",(BT34-BT$10)*1000) -> -3.8028694 | CQ34: =IF(BU34="","",(BU34-BU$10)*1000) -> -1.5494828 | CR34: =IF(BV34="","",(BV34-BV$10)*1000) -> 12.0768 | ... DE34: =IF(CI34="","",(CI34-CI$10)*1000) -> 3.6036678
A35: 43783 | B35: =IF(A35="","",A35-excav) -> 78 | C35: 220.5 | D35: =IF(C35="","",+C35-$W$6) -> 24.4 | E35: 823244.33 | F35: 1091518.8 | G35: -124.545 | H35: 823244.24 | I35: 1091519 | J35: -123.185 | K35: 823244.51 | L35: 1091518.5 | M35: -121.8169 | N35: 823245.3 | O35: 1091516.7 | P35: -120.9021 | Q35: 823245.97 | R35: 1091515.2 | S35: -121.2863 | T35: 823246.55 | U35: 1091514.1 | V35: -123.4401 | W35: 823246.47 | X35: 1091514.2 | Y35: -124.5671 | Z35: =IF(Xhaut="","",SQRT(((Xbasgauche-Xhaut)^2+(Ybasgauche-Yhaut)^2)+(Zbasgauche-Zhaut)^2)) -> 4.3249662 | AA35: =IF(Xhaut="","",SQRT(((Xintergauche-Xhaut)^2+(Yintergauche-Yhaut)^2)+(Zintergauche-Zhaut)^2)) -> 3.4065922 | AB35: =IF(Xhaut="","",SQRT(((Xhautgauche-Xhaut)^2+(Yhautgauche-Yhaut)^2)+(Zhautgauche-Zhaut)^2)) -> 2.1763021 | AC35: =IF(Xhaut="","",SQRT(((Xhautdroit-Xhaut)^2+(Yhautdroit-Yhaut)^2)+(Zhautdroit-Zhaut)^2)) -> 1.6657947 | AD35: =IF(Xhaut="","",SQRT(((Xinterdroit-Xhaut)^2+(Yinterdroit-Yhaut)^2)+(Zinterdroit-Zhaut)^2)) -> 3.8060279 | AE35: =IF(Xhaut="","",SQRT(((Xbasdroit-Xhaut)^2+(Ybasdroit-Yhaut)^2)+(Zbasdroit-Zhaut)^2)) -> 4.5723571 | AF35: =IF(Xhautdroit="","",SQRT(((Xhautdroit-Xhautgauche)^2+(Yhautdroit-Yhautgauche)^2)+(Zhautdroit-Zhautgauche)^2)) -> 3.6342728 | AG35: =IF(Xinterdroit="","",SQRT(((Xinterdroit-Xintergauche)^2+(Yinterdroit-Yintergauche)^2)+(Zinterdroit-Zintergauche)^2)) -> 5.3703563 | AH35: =IF(Xbasdroit="","",SQRT(((Xbasdroit-Xbasgauche)^2+(Ybasdroit-Ybasgauche)^2)+(Zbasdroit-Zbasgauche)^2)) -> 5.0649945 | AI35: =IF(Z35="","",(Z35-Z$10)*1000) -> -49.172786 | AJ35: =IF(AA35="","",(AA35-AA$10)*1000) -> -34.572267 | AK35: =IF(AB35="","",(AB35-AB$10)*1000) -> -29.564771 | AL35: =IF(AC35="","",(AC35-AC$10)*1000) -> -4.5164485 | AM35: =IF(AD35="","",(AD35-AD$10)*1000) -> -42.492597 | AN35: =IF(AE35="","",(AE35-AE$10)*1000) -> -50.244847 | AO35: =IF(AF35="","",(AF35-AF$10)*1000) -> -18.909317 | AP35: =IF(AG35="","",(AG35-AG$10)*1000) -> -19.555857 | AQ35: =IF(AH35="","",(AH35-AH$10)*1000) -> -23.172734 | AS35: =IF(E35="","",(E35-E$10)*1000) -> 2.4 | AT35: =IF(F35="","",(F35-F$10)*1000) -> -4.6000001 | AU35: =IF(G35="","",(G35-G$10)*1000) -> 6.5 | AV35: =IF(H35="","",(H35-H$10)*1000) -> -6.2000001 | AW35: =IF(I35="","",(I35-I$10)*1000) -> -7.2000001 | AX35: =IF(J35="","",(J35-J$10)*1000) -> -2.8 | AY35: =IF(K35="","",(K35-K$10)*1000) -> 4.1 | AZ35: =IF(L35="","",(L35-L$10)*1000) -> -10.3 | ... BM35: =IF(Y35="","",(Y35-Y$10)*1000) -> 4.7 | BO35: 196.105 | BP35: -2.532 | BQ35: -0.9632 | BR35: 196.0911 | BS35: -2.7294 | BT35: 0.397 | BU35: 196.138 | BV35: -2.1748 | BW35: 1.7646 | BX35: 196.081 | BY35: -0.2009 | BZ35: 2.68 | CA35: 196.0727 | CB35: 1.4199 | CC35: 2.2959 | CD35: 196.1438 | CE35: 2.6347 | CF35: 0.1413 | CG35: 196.0994 | CH35: 2.5329 | CI35: -0.9852 | CK35: =IF(BO35="","",(BO35-BO$10)*1000) -> 0.23081613 | CL35: =IF(BP35="","",(BP35-BP$10)*1000) -> 5.2010247 | CM35: =IF(BQ35="","",(BQ35-BQ$10)*1000) -> 6.4676918 | CN35: =IF(BR35="","",(BR35-BR$10)*1000) -> -8.6769518 | CO35: =IF(BS35="","",(BS35-BS$10)*1000) -> 3.8856942 | CP35: =IF(BT35="","",(BT35-BT$10)*1000) -> -2.6822305 | CQ35: =IF(BU35="","",(BU35-BU$10)*1000) -> -0.64824279 | CR35: =IF(BV35="","",(BV35-BV$10)*1000) -> 11.058372 | ... DE35: =IF(CI35="","",(CI35-CI$10)*1000) -> 4.7091504
A36: 43787 | B36: =IF(A36="","",A36-excav) -> 82 | C36: 221.7 | D36: =IF(C36="","",+C36-$W$6) -> 25.6 | E36: 823244.33 | F36: 1091518.8 | G36: -124.5448 | H36: 823244.24 | I36: 1091519 | J36: -123.1849 | K36: 823244.51 | L36: 1091518.5 | M36: -121.8169 | N36: 823245.3 | O36: 1091516.7 | P36: -120.903 | Q36: 823245.97 | R36: 1091515.2 | S36: -121.2868 | T36: 823246.55 | U36: 1091514.1 | V36: -123.4401 | W36: 823246.47 | X36: 1091514.2 | Y36: -124.5668 | Z36: =IF(Xhaut="","",SQRT(((Xbasgauche-Xhaut)^2+(Ybasgauche-Yhaut)^2)+(Zbasgauche-Zhaut)^2)) -> 4.3241247 | AA36: =IF(Xhaut="","",SQRT(((Xintergauche-Xhaut)^2+(Yintergauche-Yhaut)^2)+(Zintergauche-Zhaut)^2)) -> 3.4061037 | AB36: =IF(Xhaut="","",SQRT(((Xhautgauche-Xhaut)^2+(Yhautgauche-Yhaut)^2)+(Zhautgauche-Zhaut)^2)) -> 2.1760056 | AC36: =IF(Xhaut="","",SQRT(((Xhautdroit-Xhaut)^2+(Yhautdroit-Yhaut)^2)+(Zhautdroit-Zhaut)^2)) -> 1.6657362 | AD36: =IF(Xhaut="","",SQRT(((Xinterdroit-Xhaut)^2+(Yinterdroit-Yhaut)^2)+(Zinterdroit-Zhaut)^2)) -> 3.8055259 | AE36: =IF(Xhaut="","",SQRT(((Xbasdroit-Xhaut)^2+(Ybasdroit-Yhaut)^2)+(Zbasdroit-Zhaut)^2)) -> 4.5713129 | AF36: =IF(Xhautdroit="","",SQRT(((Xhautdroit-Xhautgauche)^2+(Yhautdroit-Yhautgauche)^2)+(Zhautdroit-Zhautgauche)^2)) -> 3.6343104 | AG36: =IF(Xinterdroit="","",SQRT(((Xinterdroit-Xintergauche)^2+(Yinterdroit-Yintergauche)^2)+(Zinterdroit-Zintergauche)^2)) -> 5.3707215 | AH36: =IF(Xbasdroit="","",SQRT(((Xbasdroit-Xbasgauche)^2+(Ybasdroit-Ybasgauche)^2)+(Zbasdroit-Zbasgauche)^2)) -> 5.0650068 | AI36: =IF(Z36="","",(Z36-Z$10)*1000) -> -50.014265 | AJ36: =IF(AA36="","",(AA36-AA$10)*1000) -> -35.060767 | AK36: =IF(AB36="","",(AB36-AB$10)*1000) -> -29.861262 | AL36: =IF(AC36="","",(AC36-AC$10)*1000) -> -4.57501 | AM36: =IF(AD36="","",(AD36-AD$10)*1000) -> -42.994543 | AN36: =IF(AE36="","",(AE36-AE$10)*1000) -> -51.289072 | AO36: =IF(AF36="","",(AF36-AF$10)*1000) -> -18.871741 | AP36: =IF(AG36="","",(AG36-AG$10)*1000) -> -19.190673 | AQ36: =IF(AH36="","",(AH36-AH$10)*1000) -> -23.160455 | AS36: =IF(E36="","",(E36-E$10)*1000) -> 2.9000001 | AT36: =IF(F36="","",(F36-F$10)*1000) -> -5.8000002 | AU36: =IF(G36="","",(G36-G$10)*1000) -> 6.7 | AV36: =IF(H36="","",(H36-H$10)*1000) -> -5.7 | AW36: =IF(I36="","",(I36-I$10)*1000) -> -8.3000001 | AX36: =IF(J36="","",(J36-J$10)*1000) -> -2.7 | AY36: =IF(K36="","",(K36-K$10)*1000) -> 4.8 | AZ36: =IF(L36="","",(L36-L$10)*1000) -> -11.5 | ... BM36: =IF(Y36="","",(Y36-Y$10)*1000) -> 5 | BO36: 196.1049 | BP36: -2.5307 | BQ36: -0.963 | BR36: 196.0911 | BS36: -2.7282 | BT36: 0.3971 | BU36: 196.1381 | BV36: -2.1734 | BW36: 1.7646 | BX36: 196.0803 | BY36: -0.1995 | BZ36: 2.6791 | CA36: 196.0723 | CB36: 1.4214 | CC36: 2.2954 | CD36: 196.1437 | CE36: 2.6362 | CF36: 0.1413 | CG36: 196.0989 | CH36: 2.5342 | CI36: -0.9849 | CK36: =IF(BO36="","",(BO36-BO$10)*1000) -> 0.13081613 | CL36: =IF(BP36="","",(BP36-BP$10)*1000) -> 6.5010247 | CM36: =IF(BQ36="","",(BQ36-BQ$10)*1000) -> 6.6676918 | CN36: =IF(BR36="","",(BR36-BR$10)*1000) -> -8.6769518 | CO36: =IF(BS36="","",(BS36-BS$10)*1000) -> 5.0856942 | CP36: =IF(BT36="","",(BT36-BT$10)*1000) -> -2.5822305 | CQ36: =IF(BU36="","",(BU36-BU$10)*1000) -> -0.54824279 | CR36: =IF(BV36="","",(BV36-BV$10)*1000) -> 12.458372 | ... DE36: =IF(CI36="","",(CI36-CI$10)*1000) -> 5.0091504
A37: 43790 | B37: =IF(A37="","",A37-excav) -> 85 | C37: 222.9 | D37: =IF(C37="","",+C37-$W$6) -> 26.8 | E37: 823244.33 | F37: 1091518.8 | G37: -124.5446 | H37: 823244.24 | I37: 1091519 | J37: -123.1848 | K37: 823244.51 | L37: 1091518.5 | M37: -121.817 | N37: 823245.3 | O37: 1091516.7 | P37: -120.9035 | Q37: 823245.97 | R37: 1091515.2 | S37: -121.2872 | T37: 823246.55 | U37: 1091514.1 | V37: -123.4399 | W37: 823246.47 | X37: 1091514.2 | Y37: -124.5667 | Z37: =IF(Xhaut="","",SQRT(((Xbasgauche-Xhaut)^2+(Ybasgauche-Yhaut)^2)+(Zbasgauche-Zhaut)^2)) -> 4.3234279 | AA37: =IF(Xhaut="","",SQRT(((Xintergauche-Xhaut)^2+(Yintergauche-Yhaut)^2)+(Zintergauche-Zhaut)^2)) -> 3.4055358 | AB37: =IF(Xhaut="","",SQRT(((Xhautgauche-Xhaut)^2+(Yhautgauche-Yhaut)^2)+(Zhautgauche-Zhaut)^2)) -> 2.1756595 | AC37: =IF(Xhaut="","",SQRT(((Xhautdroit-Xhaut)^2+(Yhautdroit-Yhaut)^2)+(Zhautdroit-Zhaut)^2)) -> 1.6656725 | AD37: =IF(Xhaut="","",SQRT(((Xinterdroit-Xhaut)^2+(Yinterdroit-Yhaut)^2)+(Zinterdroit-Zhaut)^2)) -> 3.8047589 | AE37: =IF(Xhaut="","",SQRT(((Xbasdroit-Xhaut)^2+(Ybasdroit-Yhaut)^2)+(Zbasdroit-Zhaut)^2)) -> 4.5705902 | AF37: =IF(Xhautdroit="","",SQRT(((Xhautdroit-Xhautgauche)^2+(Yhautdroit-Yhautgauche)^2)+(Zhautdroit-Zhautgauche)^2)) -> 3.6340355 | AG37: =IF(Xinterdroit="","",SQRT(((Xinterdroit-Xintergauche)^2+(Yinterdroit-Yintergauche)^2)+(Zinterdroit-Zintergauche)^2)) -> 5.3700899 | AH37: =IF(Xbasdroit="","",SQRT(((Xbasdroit-Xbasgauche)^2+(Ybasdroit-Ybasgauche)^2)+(Zbasdroit-Zbasgauche)^2)) -> 5.0644083 | AI37: =IF(Z37="","",(Z37-Z$10)*1000) -> -50.711094 | AJ37: =IF(AA37="","",(AA37-AA$10)*1000) -> -35.628646 | AK37: =IF(AB37="","",(AB37-AB$10)*1000) -> -30.207361 | AL37: =IF(AC37="","",(AC37-AC$10)*1000) -> -4.638737 | AM37: =IF(AD37="","",(AD37-AD$10)*1000) -> -43.761535 | AN37: =IF(AE37="","",(AE37-AE$10)*1000) -> -52.011704 | AO37: =IF(AF37="","",(AF37-AF$10)*1000) -> -19.146551 | AP37: =IF(AG37="","",(AG37-AG$10)*1000) -> -19.822281 | AQ37: =IF(AH37="","",(AH37-AH$10)*1000) -> -23.758947 | AS37: =IF(E37="","",(E37-E$10)*1000) -> 1.8 | AT37: =IF(F37="","",(F37-F$10)*1000) -> -5.7000001 | AU37: =IF(G37="","",(G37-G$10)*1000) -> 6.9 | AV37: =IF(H37="","",(H37-H$10)*1000) -> -6.3 | AW37: =IF(I37="","",(I37-I$10)*1000) -> -7.9999999 | AX37: =IF(J37="","",(J37-J$10)*1000) -> -2.6 | AY37: =IF(K37="","",(K37-K$10)*1000) -> 3.9 | AZ37: =IF(L37="","",(L37-L$10)*1000) -> -11.3 | ... BM37: =IF(Y37="","",(Y37-Y$10)*1000) -> 5.1 | BO37: 196.104 | BP37: -2.5313 | BQ37: -0.9628 | BR37: 196.0907 | BS37: -2.7287 | BT37: 0.3972 | BU37: 196.1374 | BV37: -2.174 | BW37: 1.7645 | BX37: 196.0799 | BY37: -0.2002 | BZ37: 2.6786 | CA37: 196.0718 | CB37: 1.4206 | CC37: 2.295 | CD37: 196.1433 | CE37: 2.6351 | CF37: 0.1415 | CG37: 196.0985 | CH37: 2.5331 | CI37: -0.9848 | CK37: =IF(BO37="","",(BO37-BO$10)*1000) -> -0.76918387 | CL37: =IF(BP37="","",(BP37-BP$10)*1000) -> 5.9010247 | CM37: =IF(BQ37="","",(BQ37-BQ$10)*1000) -> 6.8676918 | CN37: =IF(BR37="","",(BR37-BR$10)*1000) -> -9.0769518 | CO37: =IF(BS37="","",(BS37-BS$10)*1000) -> 4.5856942 | CP37: =IF(BT37="","",(BT37-BT$10)*1000) -> -2.4822305 | CQ37: =IF(BU37="","",(BU37-BU$10)*1000) -> -1.2482428 | CR37: =IF(BV37="","",(BV37-BV$10)*1000) -> 11.858372 | ... DE37: =IF(CI37="","",(CI37-CI$10)*1000) -> 5.1091504
