Workbook
Name cintre: 'Résultats observations'!#REF!
Name date: 'Résultats observations'!$A:$A
Name DH_BD: 'Résultats observations'!#REF!
Name DH_BG: 'Résultats observations'!#REF!
Name DH_HD: 'Résultats observations'!#REF!
Name DH_HG: 'Résultats observations'!#REF!
Name DH_ID: 'Résultats observations'!#REF!
Name DH_IG: 'Résultats observations'!#REF!
Name DHhaut: 'Résultats observations'!#REF!
Name dist: 'Résultats observations'!#REF!
Name DPM_BD: 'Résultats observations'!#REF!
Name DPM_BG: 'Résultats observations'!#REF!
Name DPM_HD: 'Résultats observations'!#REF!
Name DPM_HG: 'Résultats observations'!#REF!
Name DPM_ID: 'Résultats observations'!#REF!
Name DPM_IG: 'Résultats observations'!#REF!
Name DPMhaut: 'Résultats observations'!#REF!
Name DZ_BD: 'Résultats observations'!#REF!
Name DZ_BG: 'Résultats observations'!#REF!
Name DZ_HD: 'Résultats observations'!#REF!
Name DZ_HG: 'Résultats observations'!#REF!
Name DZ_ID: 'Résultats observations'!#REF!
Name DZ_IG: 'Résultats observations'!#REF!
Name DZhaut: 'Résultats observations'!#REF!
Name Ecart_BD: 'Résultats observations'!#REF!
Name Ecart_BG: 'Résultats observations'!#REF!
Name Ecart_HD: 'Résultats observations'!#REF!
Name Ecart_HG: 'Résultats observations'!#REF!
Name Ecart_ID: 'Résultats observations'!#REF!
Name Ecart_IG: 'Résultats observations'!#REF!
Name Ecart_LB: 'Résultats observations'!#REF!
Name Ecart_LH: 'Résultats observations'!#REF!
Name Ecart_LI: 'Résultats observations'!#REF!
Name excav: 'Résultats observations'!$A$7
Name front: 'Résultats observations'!#REF!
Name galerie: 'Résultats observations'!$E$4
Name jours: 'Résultats observations'!$B:$B
Name PM: 'Résultats observations'!#REF!
Name Xbasdroit: 'Résultats observations'!#REF!
Name Xbasgauche: 'Résultats observations'!$C:$C
Name Xhaut: 'Résultats observations'!$L:$L
Name Xhautdroit: 'Résultats observations'!#REF!
Name Xhautgauche: 'Résultats observations'!$I:$I
Name Xinterdroit: 'Résultats observations'!#REF!
Name Xintergauche: 'Résultats observations'!$F:$F
Name Ybasdroit: 'Résultats observations'!#REF!
Name Ybasgauche: 'Résultats observations'!$D:$D
Name Yhaut: 'Résultats observations'!$M:$M
Name Yhautdroit: 'Résultats observations'!#REF!
Name Yhautgauche: 'Résultats observations'!$J:$J
Name Yinterdroit: 'Résultats observations'!#REF!
Name Yintergauche: 'Résultats observations'!$G:$G
Name Zbasdroit: 'Résultats observations'!#REF!
Name Zbasgauche: 'Résultats observations'!$E:$E
Name Zhaut: 'Résultats observations'!$N:$N
Name Zhautdroit: 'Résultats observations'!#REF!
Name Zhautgauche: 'Résultats observations'!$K:$K
Name Zinterdroit: 'Résultats observations'!#REF!
Name Zintergauche: 'Résultats observations'!$H:$H
Name cintre: 'Résultats Projection'!#REF!

Sheet Résultats observations
D1: AUSCULTATION CARREFOUR - MESURES XYZ
C4: V1 | D4: V1 | E4: V1 | F4: V2 | G4: V2 | H4: V2 | I4: V3 | J4: V3 | K4: V3 | L4: H1 | M4: H1 | N4: H1 | O4: H2 | P4: H2 | Q4: H2 | R4: H3 | S4: H3 | T4: H3 | U4: H4 | V4: H4 | W4: H4 | X4: H5 | Y4: H5 | Z4: H5 | AA4: B1 | AB4: B1 | AC4: B1 | AD4: B2 | AE4: B2 | AF4: B2 | AG4: B3 | AH4: B3 | AI4: B3 | AJ4: B4 | AK4: B4 | AL4: B4 | AM4: B5 | AN4: B5 | AO4: B5 | AP4: M1 | AQ4: M1 | AR4: M1 | AS4: M2 | AT4: M2 | AU4: M2 | AV4: M3 | AW4: M3 | AX4: M3 | AY4: M4 | AZ4: M4 | BA4: M4 | BB4: M5 | BC4: M5 | BD4: M5 | BE4: C530 | BF4: C530 | BG4: C530 | BH4: C540 | BI4: C540 | BJ4: C540
C5: 3 | D5: 4 | E5: 5 | F5: 3 | G5: 4 | H5: 5 | I5: 3 | J5: 4 | K5: 5 | L5: 3 | M5: 4 | N5: 5 | BB5: *
A6: Date point 0
A7: =A10 | C7: BG | F7: IG | I7: HG | L7: CH
A8: Date | B8: Jours | C8: =D4 | F8: =G4 | I8: =J4 | L8: =M4 | O8: =P4 | R8: =S4 | U8: =V4 | X8: =Y4 | AA8: =AB4 | AD8: =AE4 | AG8: =AH4 | AJ8: =AK4 | AM8: =AN4 | AP8: =AQ4 | AS8: =AT4 | AV8: =AW4 | AY8: =AZ4 | BB8: =BC4 | BE8: =BF4 | BH8: =BI4
C9: V1_X | D9: V1_Y | E9: V1_Z | F9: V2_X | G9: V2_Y | H9: V2_Z | I9: V3_X | J9: V3_Y | K9: V3_Z | L9: H1_X | M9: H1_Y | N9: H1_Z | O9: H2_X | P9: H2_Y | Q9: H2_Z | R9: H3_X | S9: H3_Y | T9: H3_Z | U9: H4_X | V9: H4_Y | W9: H4_Z | X9: H5_X | Y9: H5_Y | Z9: H5_Z | AA9: B1_X | AB9: B1_Y | AC9: B1_Z | AD9: B2_X | AE9: B2_Y | AF9: B2_Z | AG9: B3_X | AH9: B3_Y | AI9: B3_Z | AJ9: B4_X | AK9: B4_Y | AL9: B4_Z | AM9: B5_X | AN9: B5_Y | AO9: B5_Z | AP9: M1_X | AQ9: M1_Y | AR9: M1_Z | AS9: M2_X | AT9: M2_Y | AU9: M2_Z | AV9: M3_X | AW9: M3_Y | AX9: M3_Z | AY9: M4_X | AZ9: M4_Y | BA9: M4_Z | BB9: M5_X | BC9: M5_Y | BD9: M5_Z | BE9: REF1_X | BF9: REF1_Y | BG9: REF1_Z | BH9: REF2_X | BI9: REF2_Y | BJ9: REF2_Z
A10: 45532 | B10: 0 | C10: {=IFERROR(_xlfn.SINGLE(INDEX(DATABASE!$AV$14:$BC$968,SUMPRODUCT((ROW(DATABASE!$AV$14:$AV$968)) * (DATABASE!AV$14:$AV$968='Résultats observations'!$A10 ) * (DATABASE!$AW$14:$AW$968= C$4))-ROW(DATABASE!$AV$14)+1,C$5)),"")} | D10: {=IFERROR(_xlfn.SINGLE(INDEX(DATABASE!$AV$14:$BC$968,SUMPRODUCT((ROW(DATABASE!$AV$14:$AV$968)) * (DATABASE!$AV$14:AW$968='Résultats observations'!$A10 ) * (DATABASE!$AW$14:$AW$968= D$4))-ROW(DATABASE!$AV$14)+1,D$5)),"")} | E10: {=IFERROR(_xlfn.SINGLE(INDEX(DATABASE!$AV$14:$BC$968,SUMPRODUCT((ROW(DATABASE!$AV$14:$AV$968)) * (DATABASE!$AV$14:AX$968='Résultats observations'!$A10 ) * (DATABASE!$AW$14:$AW$968= E$4))-ROW(DATABASE!$AV$14)+1,E$5)),"")} | F10: {=IFERROR(_xlfn.SINGLE(INDEX(DATABASE!$AV$14:$BC$968,SUMPRODUCT((ROW(DATABASE!$AV$14:$AV$968)) * (DATABASE!$AV$14:AY$968='Résultats observations'!$A10 ) * (DATABASE!$AW$14:$AW$968= F$4))-ROW(DATABASE!$AV$14)+1,F$5)),"")} | G10: {=IFERROR(_xlfn.SINGLE(INDEX(DATABASE!$AV$14:$BC$968,SUMPRODUCT((ROW(DATABASE!$AV$14:$AV$968)) * (DATABASE!$AV$14:AZ$968='Résultats observations'!$A10 ) * (DATABASE!$AW$14:$AW$968= G$4))-ROW(DATABASE!$AV$14)+1,G$5)),"")} | H10: {=IFERROR(_xlfn.SINGLE(INDEX(DATABASE!$AV$14:$BC$968,SUMPRODUCT((ROW(DATABASE!$AV$14:$AV$968)) * (DATABASE!$AV$14:BA$968='Résultats observations'!$A10 ) * (DATABASE!$AW$14:$AW$968= H$4))-ROW(DATABASE!$AV$14)+1,H$5)),"")} | I10: {=IFERROR(_xlfn.SINGLE(INDEX(DATABASE!$AV$14:$BC$968,SUMPRODUCT((ROW(DATABASE!$AV$14:$AV$968)) * (DATABASE!$AV$14:BB$968='Résultats observations'!$A10 ) * (DATABASE!$AW$14:$AW$968= I$4))-ROW(DATABASE!$AV$14)+1,I$5)),"")} | J10: {=IFERROR(_xlfn.SINGLE(INDEX(DATABASE!$AV$14:$BC$968,SUMPRODUCT((ROW(DATABASE!$AV$14:$AV$968)) * (DATABASE!$AV$14:BC$968='Résultats observations'!$A10 ) * (DATABASE!$AW$14:$AW$968= J$4))-ROW(DATABASE!$AV$14)+1,J$5)),"")} | K10: {=IFERROR(_xlfn.SINGLE(INDEX(DATABASE!$AV$14:$BC$968,SUMPRODUCT((ROW(DATABASE!$AV$14:$AV$968)) * (DATABASE!$AV$14:BD$968='Résultats observations'!$A10 ) * (DATABASE!$AW$14:$AW$968= K$4))-ROW(DATABASE!$AV$14)+1,K$5)),"")} | ... N10: {=IFERROR(_xlfn.SINGLE(INDEX(DATABASE!$AV$14:$BC$968,SUMPRODUCT((ROW(DATABASE!$AV$14:$AV$968)) * (DATABASE!$AV$14:BG$968='Résultats observations'!$A10 ) * (DATABASE!$AW$14:$AW$968= N$4))-ROW(DATABASE!$AV$14)+1,N$5)),"")}
A11: 45540 | B11: =A11-A$10 | C11: {=IFERROR(_xlfn.SINGLE(INDEX(DATABASE!$AV$14:$BC$968,SUMPRODUCT((ROW(DATABASE!$AV$14:$AV$968)) * (DATABASE!AV$14:$AV$968='Résultats observations'!$A11 ) * (DATABASE!$AW$14:$AW$968= C$4))-ROW(DATABASE!$AV$14)+1,C$5)),"")} | D11: {=IFERROR(_xlfn.SINGLE(INDEX(DATABASE!$AV$14:$BC$968,SUMPRODUCT((ROW(DATABASE!$AV$14:$AV$968)) * (DATABASE!$AV$14:AW$968='Résultats observations'!$A11 ) * (DATABASE!$AW$14:$AW$968= D$4))-ROW(DATABASE!$AV$14)+1,D$5)),"")} | E11: {=IFERROR(_xlfn.SINGLE(INDEX(DATABASE!$AV$14:$BC$968,SUMPRODUCT((ROW(DATABASE!$AV$14:$AV$968)) * (DATABASE!$AV$14:AX$968='Résultats observations'!$A11 ) * (DATABASE!$AW$14:$AW$968= E$4))-ROW(DATABASE!$AV$14)+1,E$5)),"")} | F11: {=IFERROR(_xlfn.SINGLE(INDEX(DATABASE!$AV$14:$BC$968,SUMPRODUCT((ROW(DATABASE!$AV$14:$AV$968)) * (DATABASE!$AV$14:AY$968='Résultats observations'!$A11 ) * (DATABASE!$AW$14:$AW$968= F$4))-ROW(DATABASE!$AV$14)+1,F$5)),"")} | G11: {=IFERROR(_xlfn.SINGLE(INDEX(DATABASE!$AV$14:$BC$968,SUMPRODUCT((ROW(DATABASE!$AV$14:$AV$968)) * (DATABASE!$AV$14:AZ$968='Résultats observations'!$A11 ) * (DATABASE!$AW$14:$AW$968= G$4))-ROW(DATABASE!$AV$14)+1,G$5)),"")} | H11: {=IFERROR(_xlfn.SINGLE(INDEX(DATABASE!$AV$14:$BC$968,SUMPRODUCT((ROW(DATABASE!$AV$14:$AV$968)) * (DATABASE!$AV$14:BA$968='Résultats observations'!$A11 ) * (DATABASE!$AW$14:$AW$968= H$4))-ROW(DATABASE!$AV$14)+1,H$5)),"")} | I11: {=IFERROR(_xlfn.SINGLE(INDEX(DATABASE!$AV$14:$BC$968,SUMPRODUCT((ROW(DATABASE!$AV$14:$AV$968)) * (DATABASE!$AV$14:BB$968='Résultats observations'!$A11 ) * (DATABASE!$AW$14:$AW$968= I$4))-ROW(DATABASE!$AV$14)+1,I$5)),"")} | J11: {=IFERROR(_xlfn.SINGLE(INDEX(DATABASE!$AV$14:$BC$968,SUMPRODUCT((ROW(DATABASE!$AV$14:$AV$968)) * (DATABASE!$AV$14:BC$968='Résultats observations'!$A11 ) * (DATABASE!$AW$14:$AW$968= J$4))-ROW(DATABASE!$AV$14)+1,J$5)),"")} | K11: {=IFERROR(_xlfn.SINGLE(INDEX(DATABASE!$AV$14:$BC$968,SUMPRODUCT((ROW(DATABASE!$AV$14:$AV$968)) * (DATABASE!$AV$14:BD$968='Résultats observations'!$A11 ) * (DATABASE!$AW$14:$AW$968= K$4))-ROW(DATABASE!$AV$14)+1,K$5)),"")} | ... N11: {=IFERROR(_xlfn.SINGLE(INDEX(DATABASE!$AV$14:$BC$968,SUMPRODUCT((ROW(DATABASE!$AV$14:$AV$968)) * (DATABASE!$AV$14:BG$968='Résultats observations'!$A11 ) * (DATABASE!$AW$14:$AW$968= N$4))-ROW(DATABASE!$AV$14)+1,N$5)),"")}
A12: 45544 | B12: =A12-A$10 | C12: {=IFERROR(_xlfn.SINGLE(INDEX(DATABASE!$AV$14:$BC$968,SUMPRODUCT((ROW(DATABASE!$AV$14:$AV$968)) * (DATABASE!AV$14:$AV$968='Résultats observations'!$A12 ) * (DATABASE!$AW$14:$AW$968= C$4))-ROW(DATABASE!$AV$14)+1,C$5)),"")} | D12: {=IFERROR(_xlfn.SINGLE(INDEX(DATABASE!$AV$14:$BC$968,SUMPRODUCT((ROW(DATABASE!$AV$14:$AV$968)) * (DATABASE!$AV$14:AW$968='Résultats observations'!$A12 ) * (DATABASE!$AW$14:$AW$968= D$4))-ROW(DATABASE!$AV$14)+1,D$5)),"")} | E12: {=IFERROR(_xlfn.SINGLE(INDEX(DATABASE!$AV$14:$BC$968,SUMPRODUCT((ROW(DATABASE!$AV$14:$AV$968)) * (DATABASE!$AV$14:AX$968='Résultats observations'!$A12 ) * (DATABASE!$AW$14:$AW$968= E$4))-ROW(DATABASE!$AV$14)+1,E$5)),"")} | F12: {=IFERROR(_xlfn.SINGLE(INDEX(DATABASE!$AV$14:$BC$968,SUMPRODUCT((ROW(DATABASE!$AV$14:$AV$968)) * (DATABASE!$AV$14:AY$968='Résultats observations'!$A12 ) * (DATABASE!$AW$14:$AW$968= F$4))-ROW(DATABASE!$AV$14)+1,F$5)),"")} | G12: {=IFERROR(_xlfn.SINGLE(INDEX(DATABASE!$AV$14:$BC$968,SUMPRODUCT((ROW(DATABASE!$AV$14:$AV$968)) * (DATABASE!$AV$14:AZ$968='Résultats observations'!$A12 ) * (DATABASE!$AW$14:$AW$968= G$4))-ROW(DATABASE!$AV$14)+1,G$5)),"")} | H12: {=IFERROR(_xlfn.SINGLE(INDEX(DATABASE!$AV$14:$BC$968,SUMPRODUCT((ROW(DATABASE!$AV$14:$AV$968)) * (DATABASE!$AV$14:BA$968='Résultats observations'!$A12 ) * (DATABASE!$AW$14:$AW$968= H$4))-ROW(DATABASE!$AV$14)+1,H$5)),"")} | I12: {=IFERROR(_xlfn.SINGLE(INDEX(DATABASE!$AV$14:$BC$968,SUMPRODUCT((ROW(DATABASE!$AV$14:$AV$968)) * (DATABASE!$AV$14:BB$968='Résultats observations'!$A12 ) * (DATABASE!$AW$14:$AW$968= I$4))-ROW(DATABASE!$AV$14)+1,I$5)),"")} | J12: {=IFERROR(_xlfn.SINGLE(INDEX(DATABASE!$AV$14:$BC$968,SUMPRODUCT((ROW(DATABASE!$AV$14:$AV$968)) * (DATABASE!$AV$14:BC$968='Résultats observations'!$A12 ) * (DATABASE!$AW$14:$AW$968= J$4))-ROW(DATABASE!$AV$14)+1,J$5)),"")} | K12: {=IFERROR(_xlfn.SINGLE(INDEX(DATABASE!$AV$14:$BC$968,SUMPRODUCT((ROW(DATABASE!$AV$14:$AV$968)) * (DATABASE!$AV$14:BD$968='Résultats observations'!$A12 ) * (DATABASE!$AW$14:$AW$968= K$4))-ROW(DATABASE!$AV$14)+1,K$5)),"")} | ... N12: {=IFERROR(_xlfn.SINGLE(INDEX(DATABASE!$AV$14:$BC$968,SUMPRODUCT((ROW(DATABASE!$AV$14:$AV$968)) * (DATABASE!$AV$14:BG$968='Résultats observations'!$A12 ) * (DATABASE!$AW$14:$AW$968= N$4))-ROW(DATABASE!$AV$14)+1,N$5)),"")}
A13: 45548 | B13: =A13-A$10 | C13: {=IFERROR(_xlfn.SINGLE(INDEX(DATABASE!$AV$14:$BC$968,SUMPRODUCT((ROW(DATABASE!$AV$14:$AV$968)) * (DATABASE!AV$14:$AV$968='Résultats observations'!$A13 ) * (DATABASE!$AW$14:$AW$968= C$4))-ROW(DATABASE!$AV$14)+1,C$5)),"")} | D13: {=IFERROR(_xlfn.SINGLE(INDEX(DATABASE!$AV$14:$BC$968,SUMPRODUCT((ROW(DATABASE!$AV$14:$AV$968)) * (DATABASE!$AV$14:AW$968='Résultats observations'!$A13 ) * (DATABASE!$AW$14:$AW$968= D$4))-ROW(DATABASE!$AV$14)+1,D$5)),"")} | E13: {=IFERROR(_xlfn.SINGLE(INDEX(DATABASE!$AV$14:$BC$968,SUMPRODUCT((ROW(DATABASE!$AV$14:$AV$968)) * (DATABASE!$AV$14:AX$968='Résultats observations'!$A13 ) * (DATABASE!$AW$14:$AW$968= E$4))-ROW(DATABASE!$AV$14)+1,E$5)),"")} | F13: {=IFERROR(_xlfn.SINGLE(INDEX(DATABASE!$AV$14:$BC$968,SUMPRODUCT((ROW(DATABASE!$AV$14:$AV$968)) * (DATABASE!$AV$14:AY$968='Résultats observations'!$A13 ) * (DATABASE!$AW$14:$AW$968= F$4))-ROW(DATABASE!$AV$14)+1,F$5)),"")} | G13: {=IFERROR(_xlfn.SINGLE(INDEX(DATABASE!$AV$14:$BC$968,SUMPRODUCT((ROW(DATABASE!$AV$14:$AV$968)) * (DATABASE!$AV$14:AZ$968='Résultats observations'!$A13 ) * (DATABASE!$AW$14:$AW$968= G$4))-ROW(DATABASE!$AV$14)+1,G$5)),"")} | H13: {=IFERROR(_xlfn.SINGLE(INDEX(DATABASE!$AV$14:$BC$968,SUMPRODUCT((ROW(DATABASE!$AV$14:$AV$968)) * (DATABASE!$AV$14:BA$968='Résultats observations'!$A13 ) * (DATABASE!$AW$14:$AW$968= H$4))-ROW(DATABASE!$AV$14)+1,H$5)),"")} | I13: {=IFERROR(_xlfn.SINGLE(INDEX(DATABASE!$AV$14:$BC$968,SUMPRODUCT((ROW(DATABASE!$AV$14:$AV$968)) * (DATABASE!$AV$14:BB$968='Résultats observations'!$A13 ) * (DATABASE!$AW$14:$AW$968= I$4))-ROW(DATABASE!$AV$14)+1,I$5)),"")} | J13: {=IFERROR(_xlfn.SINGLE(INDEX(DATABASE!$AV$14:$BC$968,SUMPRODUCT((ROW(DATABASE!$AV$14:$AV$968)) * (DATABASE!$AV$14:BC$968='Résultats observations'!$A13 ) * (DATABASE!$AW$14:$AW$968= J$4))-ROW(DATABASE!$AV$14)+1,J$5)),"")} | K13: {=IFERROR(_xlfn.SINGLE(INDEX(DATABASE!$AV$14:$BC$968,SUMPRODUCT((ROW(DATABASE!$AV$14:$AV$968)) * (DATABASE!$AV$14:BD$968='Résultats observations'!$A13 ) * (DATABASE!$AW$14:$AW$968= K$4))-ROW(DATABASE!$AV$14)+1,K$5)),"")} | ... N13: {=IFERROR(_xlfn.SINGLE(INDEX(DATABASE!$AV$14:$BC$968,SUMPRODUCT((ROW(DATABASE!$AV$14:$AV$968)) * (DATABASE!$AV$14:BG$968='Résultats observations'!$A13 ) * (DATABASE!$AW$14:$AW$968= N$4))-ROW(DATABASE!$AV$14)+1,N$5)),"")}
A14: 45552 | B14: =A14-A$10 | C14: {=IFERROR(_xlfn.SINGLE(INDEX(DATABASE!$AV$14:$BC$968,SUMPRODUCT((ROW(DATABASE!$AV$14:$AV$968)) * (DATABASE!AV$14:$AV$968='Résultats observations'!$A14 ) * (DATABASE!$AW$14:$AW$968= C$4))-ROW(DATABASE!$AV$14)+1,C$5)),"")} | D14: {=IFERROR(_xlfn.SINGLE(INDEX(DATABASE!$AV$14:$BC$968,SUMPRODUCT((ROW(DATABASE!$AV$14:$AV$968)) * (DATABASE!$AV$14:AW$968='Résultats observations'!$A14 ) * (DATABASE!$AW$14:$AW$968= D$4))-ROW(DATABASE!$AV$14)+1,D$5)),"")} | E14: {=IFERROR(_xlfn.SINGLE(INDEX(DATABASE!$AV$14:$BC$968,SUMPRODUCT((ROW(DATABASE!$AV$14:$AV$968)) * (DATABASE!$AV$14:AX$968='Résultats observations'!$A14 ) * (DATABASE!$AW$14:$AW$968= E$4))-ROW(DATABASE!$AV$14)+1,E$5)),"")} | F14: {=IFERROR(_xlfn.SINGLE(INDEX(DATABASE!$AV$14:$BC$968,SUMPRODUCT((ROW(DATABASE!$AV$14:$AV$968)) * (DATABASE!$AV$14:AY$968='Résultats observations'!$A14 ) * (DATABASE!$AW$14:$AW$968= F$4))-ROW(DATABASE!$AV$14)+1,F$5)),"")} | G14: {=IFERROR(_xlfn.SINGLE(INDEX(DATABASE!$AV$14:$BC$968,SUMPRODUCT((ROW(DATABASE!$AV$14:$AV$968)) * (DATABASE!$AV$14:AZ$968='Résultats observations'!$A14 ) * (DATABASE!$AW$14:$AW$968= G$4))-ROW(DATABASE!$AV$14)+1,G$5)),"")} | H14: {=IFERROR(_xlfn.SINGLE(INDEX(DATABASE!$AV$14:$BC$968,SUMPRODUCT((ROW(DATABASE!$AV$14:$AV$968)) * (DATABASE!$AV$14:BA$968='Résultats observations'!$A14 ) * (DATABASE!$AW$14:$AW$968= H$4))-ROW(DATABASE!$AV$14)+1,H$5)),"")} | I14: {=IFERROR(_xlfn.SINGLE(INDEX(DATABASE!$AV$14:$BC$968,SUMPRODUCT((ROW(DATABASE!$AV$14:$AV$968)) * (DATABASE!$AV$14:BB$968='Résultats observations'!$A14 ) * (DATABASE!$AW$14:$AW$968= I$4))-ROW(DATABASE!$AV$14)+1,I$5)),"")} | J14: {=IFERROR(_xlfn.SINGLE(INDEX(DATABASE!$AV$14:$BC$968,SUMPRODUCT((ROW(DATABASE!$AV$14:$AV$968)) * (DATABASE!$AV$14:BC$968='Résultats observations'!$A14 ) * (DATABASE!$AW$14:$AW$968= J$4))-ROW(DATABASE!$AV$14)+1,J$5)),"")} | K14: {=IFERROR(_xlfn.SINGLE(INDEX(DATABASE!$AV$14:$BC$968,SUMPRODUCT((ROW(DATABASE!$AV$14:$AV$968)) * (DATABASE!$AV$14:BD$968='Résultats observations'!$A14 ) * (DATABASE!$AW$14:$AW$968= K$4))-ROW(DATABASE!$AV$14)+1,K$5)),"")} | ... N14: {=IFERROR(_xlfn.SINGLE(INDEX(DATABASE!$AV$14:$BC$968,SUMPRODUCT((ROW(DATABASE!$AV$14:$AV$968)) * (DATABASE!$AV$14:BG$968='Résultats observations'!$A14 ) * (DATABASE!$AW$14:$AW$968= N$4))-ROW(DATABASE!$AV$14)+1,N$5)),"")}
A15: 45553 | B15: =A15-A$10 | C15: {=IFERROR(_xlfn.SINGLE(INDEX(DATABASE!$AV$14:$BC$968,SUMPRODUCT((ROW(DATABASE!$AV$14:$AV$968)) * (DATABASE!AV$14:$AV$968='Résultats observations'!$A15 ) * (DATABASE!$AW$14:$AW$968= C$4))-ROW(DATABASE!$AV$14)+1,C$5)),"")} | D15: {=IFERROR(_xlfn.SINGLE(INDEX(DATABASE!$AV$14:$BC$968,SUMPRODUCT((ROW(DATABASE!$AV$14:$AV$968)) * (DATABASE!$AV$14:AW$968='Résultats observations'!$A15 ) * (DATABASE!$AW$14:$AW$968= D$4))-ROW(DATABASE!$AV$14)+1,D$5)),"")} | E15: {=IFERROR(_xlfn.SINGLE(INDEX(DATABASE!$AV$14:$BC$968,SUMPRODUCT((ROW(DATABASE!$AV$14:$AV$968)) * (DATABASE!$AV$14:AX$968='Résultats observations'!$A15 ) * (DATABASE!$AW$14:$AW$968= E$4))-ROW(DATABASE!$AV$14)+1,E$5)),"")} | F15: {=IFERROR(_xlfn.SINGLE(INDEX(DATABASE!$AV$14:$BC$968,SUMPRODUCT((ROW(DATABASE!$AV$14:$AV$968)) * (DATABASE!$AV$14:AY$968='Résultats observations'!$A15 ) * (DATABASE!$AW$14:$AW$968= F$4))-ROW(DATABASE!$AV$14)+1,F$5)),"")} | G15: {=IFERROR(_xlfn.SINGLE(INDEX(DATABASE!$AV$14:$BC$968,SUMPRODUCT((ROW(DATABASE!$AV$14:$AV$968)) * (DATABASE!$AV$14:AZ$968='Résultats observations'!$A15 ) * (DATABASE!$AW$14:$AW$968= G$4))-ROW(DATABASE!$AV$14)+1,G$5)),"")} | H15: {=IFERROR(_xlfn.SINGLE(INDEX(DATABASE!$AV$14:$BC$968,SUMPRODUCT((ROW(DATABASE!$AV$14:$AV$968)) * (DATABASE!$AV$14:BA$968='Résultats observations'!$A15 ) * (DATABASE!$AW$14:$AW$968= H$4))-ROW(DATABASE!$AV$14)+1,H$5)),"")} | I15: {=IFERROR(_xlfn.SINGLE(INDEX(DATABASE!$AV$14:$BC$968,SUMPRODUCT((ROW(DATABASE!$AV$14:$AV$968)) * (DATABASE!$AV$14:BB$968='Résultats observations'!$A15 ) * (DATABASE!$AW$14:$AW$968= I$4))-ROW(DATABASE!$AV$14)+1,I$5)),"")} | J15: {=IFERROR(_xlfn.SINGLE(INDEX(DATABASE!$AV$14:$BC$968,SUMPRODUCT((ROW(DATABASE!$AV$14:$AV$968)) * (DATABASE!$AV$14:BC$968='Résultats observations'!$A15 ) * (DATABASE!$AW$14:$AW$968= J$4))-ROW(DATABASE!$AV$14)+1,J$5)),"")} | K15: {=IFERROR(_xlfn.SINGLE(INDEX(DATABASE!$AV$14:$BC$968,SUMPRODUCT((ROW(DATABASE!$AV$14:$AV$968)) * (DATABASE!$AV$14:BD$968='Résultats observations'!$A15 ) * (DATABASE!$AW$14:$AW$968= K$4))-ROW(DATABASE!$AV$14)+1,K$5)),"")} | ... N15: {=IFERROR(_xlfn.SINGLE(INDEX(DATABASE!$AV$14:$BC$968,SUMPRODUCT((ROW(DATABASE!$AV$14:$AV$968)) * (DATABASE!$AV$14:BG$968='Résultats observations'!$A15 ) * (DATABASE!$AW$14:$AW$968= N$4))-ROW(DATABASE!$AV$14)+1,N$5)),"")}
A16: 45554 | B16: =A16-A$10 | C16: {=IFERROR(_xlfn.SINGLE(INDEX(DATABASE!$AV$14:$BC$968,SUMPRODUCT((ROW(DATABASE!$AV$14:$AV$968)) * (DATABASE!AV$14:$AV$968='Résultats observations'!$A16 ) * (DATABASE!$AW$14:$AW$968= C$4))-ROW(DATABASE!$AV$14)+1,C$5)),"")} | D16: {=IFERROR(_xlfn.SINGLE(INDEX(DATABASE!$AV$14:$BC$968,SUMPRODUCT((ROW(DATABASE!$AV$14:$AV$968)) * (DATABASE!$AV$14:AW$968='Résultats observations'!$A16 ) * (DATABASE!$AW$14:$AW$968= D$4))-ROW(DATABASE!$AV$14)+1,D$5)),"")} | E16: {=IFERROR(_xlfn.SINGLE(INDEX(DATABASE!$AV$14:$BC$968,SUMPRODUCT((ROW(DATABASE!$AV$14:$AV$968)) * (DATABASE!$AV$14:AX$968='Résultats observations'!$A16 ) * (DATABASE!$AW$14:$AW$968= E$4))-ROW(DATABASE!$AV$14)+1,E$5)),"")} | F16: {=IFERROR(_xlfn.SINGLE(INDEX(DATABASE!$AV$14:$BC$968,SUMPRODUCT((ROW(DATABASE!$AV$14:$AV$968)) * (DATABASE!$AV$14:AY$968='Résultats observations'!$A16 ) * (DATABASE!$AW$14:$AW$968= F$4))-ROW(DATABASE!$AV$14)+1,F$5)),"")} | G16: {=IFERROR(_xlfn.SINGLE(INDEX(DATABASE!$AV$14:$BC$968,SUMPRODUCT((ROW(DATABASE!$AV$14:$AV$968)) * (DATABASE!$AV$14:AZ$968='Résultats observations'!$A16 ) * (DATABASE!$AW$14:$AW$968= G$4))-ROW(DATABASE!$AV$14)+1,G$5)),"")} | H16: {=IFERROR(_xlfn.SINGLE(INDEX(DATABASE!$AV$14:$BC$968,SUMPRODUCT((ROW(DATABASE!$AV$14:$AV$968)) * (DATABASE!$AV$14:BA$968='Résultats observations'!$A16 ) * (DATABASE!$AW$14:$AW$968= H$4))-ROW(DATABASE!$AV$14)+1,H$5)),"")} | I16: {=IFERROR(_xlfn.SINGLE(INDEX(DATABASE!$AV$14:$BC$968,SUMPRODUCT((ROW(DATABASE!$AV$14:$AV$968)) * (DATABASE!$AV$14:BB$968='Résultats observations'!$A16 ) * (DATABASE!$AW$14:$AW$968= I$4))-ROW(DATABASE!$AV$14)+1,I$5)),"")} | J16: {=IFERROR(_xlfn.SINGLE(INDEX(DATABASE!$AV$14:$BC$968,SUMPRODUCT((ROW(DATABASE!$AV$14:$AV$968)) * (DATABASE!$AV$14:BC$968='Résultats observations'!$A16 ) * (DATABASE!$AW$14:$AW$968= J$4))-ROW(DATABASE!$AV$14)+1,J$5)),"")} | K16: {=IFERROR(_xlfn.SINGLE(INDEX(DATABASE!$AV$14:$BC$968,SUMPRODUCT((ROW(DATABASE!$AV$14:$AV$968)) * (DATABASE!$AV$14:BD$968='Résultats observations'!$A16 ) * (DATABASE!$AW$14:$AW$968= K$4))-ROW(DATABASE!$AV$14)+1,K$5)),"")} | ... N16: {=IFERROR(_xlfn.SINGLE(INDEX(DATABASE!$AV$14:$BC$968,SUMPRODUCT((ROW(DATABASE!$AV$14:$AV$968)) * (DATABASE!$AV$14:BG$968='Résultats observations'!$A16 ) * (DATABASE!$AW$14:$AW$968= N$4))-ROW(DATABASE!$AV$14)+1,N$5)),"")}
A17: 45557 | B17: =A17-A$10 | C17: {=IFERROR(_xlfn.SINGLE(INDEX(DATABASE!$AV$14:$BC$968,SUMPRODUCT((ROW(DATABASE!$AV$14:$AV$968)) * (DATABASE!AV$14:$AV$968='Résultats observations'!$A17 ) * (DATABASE!$AW$14:$AW$968= C$4))-ROW(DATABASE!$AV$14)+1,C$5)),"")} | D17: {=IFERROR(_xlfn.SINGLE(INDEX(DATABASE!$AV$14:$BC$968,SUMPRODUCT((ROW(DATABASE!$AV$14:$AV$968)) * (DATABASE!$AV$14:AW$968='Résultats observations'!$A17 ) * (DATABASE!$AW$14:$AW$968= D$4))-ROW(DATABASE!$AV$14)+1,D$5)),"")} | E17: {=IFERROR(_xlfn.SINGLE(INDEX(DATABASE!$AV$14:$BC$968,SUMPRODUCT((ROW(DATABASE!$AV$14:$AV$968)) * (DATABASE!$AV$14:AX$968='Résultats observations'!$A17 ) * (DATABASE!$AW$14:$AW$968= E$4))-ROW(DATABASE!$AV$14)+1,E$5)),"")} | F17: {=IFERROR(_xlfn.SINGLE(INDEX(DATABASE!$AV$14:$BC$968,SUMPRODUCT((ROW(DATABASE!$AV$14:$AV$968)) * (DATABASE!$AV$14:AY$968='Résultats observations'!$A17 ) * (DATABASE!$AW$14:$AW$968= F$4))-ROW(DATABASE!$AV$14)+1,F$5)),"")} | G17: {=IFERROR(_xlfn.SINGLE(INDEX(DATABASE!$AV$14:$BC$968,SUMPRODUCT((ROW(DATABASE!$AV$14:$AV$968)) * (DATABASE!$AV$14:AZ$968='Résultats observations'!$A17 ) * (DATABASE!$AW$14:$AW$968= G$4))-ROW(DATABASE!$AV$14)+1,G$5)),"")} | H17: {=IFERROR(_xlfn.SINGLE(INDEX(DATABASE!$AV$14:$BC$968,SUMPRODUCT((ROW(DATABASE!$AV$14:$AV$968)) * (DATABASE!$AV$14:BA$968='Résultats observations'!$A17 ) * (DATABASE!$AW$14:$AW$968= H$4))-ROW(DATABASE!$AV$14)+1,H$5)),"")} | I17: {=IFERROR(_xlfn.SINGLE(INDEX(DATABASE!$AV$14:$BC$968,SUMPRODUCT((ROW(DATABASE!$AV$14:$AV$968)) * (DATABASE!$AV$14:BB$968='Résultats observations'!$A17 ) * (DATABASE!$AW$14:$AW$968= I$4))-ROW(DATABASE!$AV$14)+1,I$5)),"")} | J17: {=IFERROR(_xlfn.SINGLE(INDEX(DATABASE!$AV$14:$BC$968,SUMPRODUCT((ROW(DATABASE!$AV$14:$AV$968)) * (DATABASE!$AV$14:BC$968='Résultats observations'!$A17 ) * (DATABASE!$AW$14:$AW$968= J$4))-ROW(DATABASE!$AV$14)+1,J$5)),"")} | K17: {=IFERROR(_xlfn.SINGLE(INDEX(DATABASE!$AV$14:$BC$968,SUMPRODUCT((ROW(DATABASE!$AV$14:$AV$968)) * (DATABASE!$AV$14:BD$968='Résultats observations'!$A17 ) * (DATABASE!$AW$14:$AW$968= K$4))-ROW(DATABASE!$AV$14)+1,K$5)),"")} | ... N17: {=IFERROR(_xlfn.SINGLE(INDEX(DATABASE!$AV$14:$BC$968,SUMPRODUCT((ROW(DATABASE!$AV$14:$AV$968)) * (DATABASE!$AV$14:BG$968='Résultats observations'!$A17 ) * (DATABASE!$AW$14:$AW$968= N$4))-ROW(DATABASE!$AV$14)+1,N$5)),"")}
A18: 45558 | B18: =A18-A$10 | C18: {=IFERROR(_xlfn.SINGLE(INDEX(DATABASE!$AV$14:$BC$968,SUMPRODUCT((ROW(DATABASE!$AV$14:$AV$968)) * (DATABASE!AV$14:$AV$968='Résultats observations'!$A18 ) * (DATABASE!$AW$14:$AW$968= C$4))-ROW(DATABASE!$AV$14)+1,C$5)),"")} | D18: {=IFERROR(_xlfn.SINGLE(INDEX(DATABASE!$AV$14:$BC$968,SUMPRODUCT((ROW(DATABASE!$AV$14:$AV$968)) * (DATABASE!$AV$14:AW$968='Résultats observations'!$A18 ) * (DATABASE!$AW$14:$AW$968= D$4))-ROW(DATABASE!$AV$14)+1,D$5)),"")} | E18: {=IFERROR(_xlfn.SINGLE(INDEX(DATABASE!$AV$14:$BC$968,SUMPRODUCT((ROW(DATABASE!$AV$14:$AV$968)) * (DATABASE!$AV$14:AX$968='Résultats observations'!$A18 ) * (DATABASE!$AW$14:$AW$968= E$4))-ROW(DATABASE!$AV$14)+1,E$5)),"")} | F18: {=IFERROR(_xlfn.SINGLE(INDEX(DATABASE!$AV$14:$BC$968,SUMPRODUCT((ROW(DATABASE!$AV$14:$AV$968)) * (DATABASE!$AV$14:AY$968='Résultats observations'!$A18 ) * (DATABASE!$AW$14:$AW$968= F$4))-ROW(DATABASE!$AV$14)+1,F$5)),"")} | G18: {=IFERROR(_xlfn.SINGLE(INDEX(DATABASE!$AV$14:$BC$968,SUMPRODUCT((ROW(DATABASE!$AV$14:$AV$968)) * (DATABASE!$AV$14:AZ$968='Résultats observations'!$A18 ) * (DATABASE!$AW$14:$AW$968= G$4))-ROW(DATABASE!$AV$14)+1,G$5)),"")} | H18: {=IFERROR(_xlfn.SINGLE(INDEX(DATABASE!$AV$14:$BC$968,SUMPRODUCT((ROW(DATABASE!$AV$14:$AV$968)) * (DATABASE!$AV$14:BA$968='Résultats observations'!$A18 ) * (DATABASE!$AW$14:$AW$968= H$4))-ROW(DATABASE!$AV$14)+1,H$5)),"")} | I18: {=IFERROR(_xlfn.SINGLE(INDEX(DATABASE!$AV$14:$BC$968,SUMPRODUCT((ROW(DATABASE!$AV$14:$AV$968)) * (DATABASE!$AV$14:BB$968='Résultats observations'!$A18 ) * (DATABASE!$AW$14:$AW$968= I$4))-ROW(DATABASE!$AV$14)+1,I$5)),"")} | J18: {=IFERROR(_xlfn.SINGLE(INDEX(DATABASE!$AV$14:$BC$968,SUMPRODUCT((ROW(DATABASE!$AV$14:$AV$968)) * (DATABASE!$AV$14:BC$968='Résultats observations'!$A18 ) * (DATABASE!$AW$14:$AW$968= J$4))-ROW(DATABASE!$AV$14)+1,J$5)),"")} | K18: {=IFERROR(_xlfn.SINGLE(INDEX(DATABASE!$AV$14:$BC$968,SUMPRODUCT((ROW(DATABASE!$AV$14:$AV$968)) * (DATABASE!$AV$14:BD$968='Résultats observations'!$A18 ) * (DATABASE!$AW$14:$AW$968= K$4))-ROW(DATABASE!$AV$14)+1,K$5)),"")} | ... N18: {=IFERROR(_xlfn.SINGLE(INDEX(DATABASE!$AV$14:$BC$968,SUMPRODUCT((ROW(DATABASE!$AV$14:$AV$968)) * (DATABASE!$AV$14:BG$968='Résultats observations'!$A18 ) * (DATABASE!$AW$14:$AW$968= N$4))-ROW(DATABASE!$AV$14)+1,N$5)),"")}
A19: 45559 | B19: =A19-A$10 | C19: {=IFERROR(_xlfn.SINGLE(INDEX(DATABASE!$AV$14:$BC$968,SUMPRODUCT((ROW(DATABASE!$AV$14:$AV$968)) * (DATABASE!AV$14:$AV$968='Résultats observations'!$A19 ) * (DATABASE!$AW$14:$AW$968= C$4))-ROW(DATABASE!$AV$14)+1,C$5)),"")} | D19: {=IFERROR(_xlfn.SINGLE(INDEX(DATABASE!$AV$14:$BC$968,SUMPRODUCT((ROW(DATABASE!$AV$14:$AV$968)) * (DATABASE!$AV$14:AW$968='Résultats observations'!$A19 ) * (DATABASE!$AW$14:$AW$968= D$4))-ROW(DATABASE!$AV$14)+1,D$5)),"")} | E19: {=IFERROR(_xlfn.SINGLE(INDEX(DATABASE!$AV$14:$BC$968,SUMPRODUCT((ROW(DATABASE!$AV$14:$AV$968)) * (DATABASE!$AV$14:AX$968='Résultats observations'!$A19 ) * (DATABASE!$AW$14:$AW$968= E$4))-ROW(DATABASE!$AV$14)+1,E$5)),"")} | F19: {=IFERROR(_xlfn.SINGLE(INDEX(DATABASE!$AV$14:$BC$968,SUMPRODUCT((ROW(DATABASE!$AV$14:$AV$968)) * (DATABASE!$AV$14:AY$968='Résultats observations'!$A19 ) * (DATABASE!$AW$14:$AW$968= F$4))-ROW(DATABASE!$AV$14)+1,F$5)),"")} | G19: {=IFERROR(_xlfn.SINGLE(INDEX(DATABASE!$AV$14:$BC$968,SUMPRODUCT((ROW(DATABASE!$AV$14:$AV$968)) * (DATABASE!$AV$14:AZ$968='Résultats observations'!$A19 ) * (DATABASE!$AW$14:$AW$968= G$4))-ROW(DATABASE!$AV$14)+1,G$5)),"")} | H19: {=IFERROR(_xlfn.SINGLE(INDEX(DATABASE!$AV$14:$BC$968,SUMPRODUCT((ROW(DATABASE!$AV$14:$AV$968)) * (DATABASE!$AV$14:BA$968='Résultats observations'!$A19 ) * (DATABASE!$AW$14:$AW$968= H$4))-ROW(DATABASE!$AV$14)+1,H$5)),"")} | I19: {=IFERROR(_xlfn.SINGLE(INDEX(DATABASE!$AV$14:$BC$968,SUMPRODUCT((ROW(DATABASE!$AV$14:$AV$968)) * (DATABASE!$AV$14:BB$968='Résultats observations'!$A19 ) * (DATABASE!$AW$14:$AW$968= I$4))-ROW(DATABASE!$AV$14)+1,I$5)),"")} | J19: {=IFERROR(_xlfn.SINGLE(INDEX(DATABASE!$AV$14:$BC$968,SUMPRODUCT((ROW(DATABASE!$AV$14:$AV$968)) * (DATABASE!$AV$14:BC$968='Résultats observations'!$A19 ) * (DATABASE!$AW$14:$AW$968= J$4))-ROW(DATABASE!$AV$14)+1,J$5)),"")} | K19: {=IFERROR(_xlfn.SINGLE(INDEX(DATABASE!$AV$14:$BC$968,SUMPRODUCT((ROW(DATABASE!$AV$14:$AV$968)) * (DATABASE!$AV$14:BD$968='Résultats observations'!$A19 ) * (DATABASE!$AW$14:$AW$968= K$4))-ROW(DATABASE!$AV$14)+1,K$5)),"")} | ... N19: {=IFERROR(_xlfn.SINGLE(INDEX(DATABASE!$AV$14:$BC$968,SUMPRODUCT((ROW(DATABASE!$AV$14:$AV$968)) * (DATABASE!$AV$14:BG$968='Résultats observations'!$A19 ) * (DATABASE!$AW$14:$AW$968= N$4))-ROW(DATABASE!$AV$14)+1,N$5)),"")}
A20: 45560 | B20: =A20-A$10 | C20: {=IFERROR(_xlfn.SINGLE(INDEX(DATABASE!$AV$14:$BC$968,SUMPRODUCT((ROW(DATABASE!$AV$14:$AV$968)) * (DATABASE!AV$14:$AV$968='Résultats observations'!$A20 ) * (DATABASE!$AW$14:$AW$968= C$4))-ROW(DATABASE!$AV$14)+1,C$5)),"")} | D20: {=IFERROR(_xlfn.SINGLE(INDEX(DATABASE!$AV$14:$BC$968,SUMPRODUCT((ROW(DATABASE!$AV$14:$AV$968)) * (DATABASE!$AV$14:AW$968='Résultats observations'!$A20 ) * (DATABASE!$AW$14:$AW$968= D$4))-ROW(DATABASE!$AV$14)+1,D$5)),"")} | E20: {=IFERROR(_xlfn.SINGLE(INDEX(DATABASE!$AV$14:$BC$968,SUMPRODUCT((ROW(DATABASE!$AV$14:$AV$968)) * (DATABASE!$AV$14:AX$968='Résultats observations'!$A20 ) * (DATABASE!$AW$14:$AW$968= E$4))-ROW(DATABASE!$AV$14)+1,E$5)),"")} | F20: {=IFERROR(_xlfn.SINGLE(INDEX(DATABASE!$AV$14:$BC$968,SUMPRODUCT((ROW(DATABASE!$AV$14:$AV$968)) * (DATABASE!$AV$14:AY$968='Résultats observations'!$A20 ) * (DATABASE!$AW$14:$AW$968= F$4))-ROW(DATABASE!$AV$14)+1,F$5)),"")} | G20: {=IFERROR(_xlfn.SINGLE(INDEX(DATABASE!$AV$14:$BC$968,SUMPRODUCT((ROW(DATABASE!$AV$14:$AV$968)) * (DATABASE!$AV$14:AZ$968='Résultats observations'!$A20 ) * (DATABASE!$AW$14:$AW$968= G$4))-ROW(DATABASE!$AV$14)+1,G$5)),"")} | H20: {=IFERROR(_xlfn.SINGLE(INDEX(DATABASE!$AV$14:$BC$968,SUMPRODUCT((ROW(DATABASE!$AV$14:$AV$968)) * (DATABASE!$AV$14:BA$968='Résultats observations'!$A20 ) * (DATABASE!$AW$14:$AW$968= H$4))-ROW(DATABASE!$AV$14)+1,H$5)),"")} | I20: {=IFERROR(_xlfn.SINGLE(INDEX(DATABASE!$AV$14:$BC$968,SUMPRODUCT((ROW(DATABASE!$AV$14:$AV$968)) * (DATABASE!$AV$14:BB$968='Résultats observations'!$A20 ) * (DATABASE!$AW$14:$AW$968= I$4))-ROW(DATABASE!$AV$14)+1,I$5)),"")} | J20: {=IFERROR(_xlfn.SINGLE(INDEX(DATABASE!$AV$14:$BC$968,SUMPRODUCT((ROW(DATABASE!$AV$14:$AV$968)) * (DATABASE!$AV$14:BC$968='Résultats observations'!$A20 ) * (DATABASE!$AW$14:$AW$968= J$4))-ROW(DATABASE!$AV$14)+1,J$5)),"")} | K20: {=IFERROR(_xlfn.SINGLE(INDEX(DATABASE!$AV$14:$BC$968,SUMPRODUCT((ROW(DATABASE!$AV$14:$AV$968)) * (DATABASE!$AV$14:BD$968='Résultats observations'!$A20 ) * (DATABASE!$AW$14:$AW$968= K$4))-ROW(DATABASE!$AV$14)+1,K$5)),"")} | ... N20: {=IFERROR(_xlfn.SINGLE(INDEX(DATABASE!$AV$14:$BC$968,SUMPRODUCT((ROW(DATABASE!$AV$14:$AV$968)) * (DATABASE!$AV$14:BG$968='Résultats observations'!$A20 ) * (DATABASE!$AW$14:$AW$968= N$4))-ROW(DATABASE!$AV$14)+1,N$5)),"")}
A21: 45562 | B21: =A21-A$10 | C21: {=IFERROR(_xlfn.SINGLE(INDEX(DATABASE!$AV$14:$BC$968,SUMPRODUCT((ROW(DATABASE!$AV$14:$AV$968)) * (DATABASE!AV$14:$AV$968='Résultats observations'!$A21 ) * (DATABASE!$AW$14:$AW$968= C$4))-ROW(DATABASE!$AV$14)+1,C$5)),"")} | D21: {=IFERROR(_xlfn.SINGLE(INDEX(DATABASE!$AV$14:$BC$968,SUMPRODUCT((ROW(DATABASE!$AV$14:$AV$968)) * (DATABASE!$AV$14:AW$968='Résultats observations'!$A21 ) * (DATABASE!$AW$14:$AW$968= D$4))-ROW(DATABASE!$AV$14)+1,D$5)),"")} | E21: {=IFERROR(_xlfn.SINGLE(INDEX(DATABASE!$AV$14:$BC$968,SUMPRODUCT((ROW(DATABASE!$AV$14:$AV$968)) * (DATABASE!$AV$14:AX$968='Résultats observations'!$A21 ) * (DATABASE!$AW$14:$AW$968= E$4))-ROW(DATABASE!$AV$14)+1,E$5)),"")} | F21: {=IFERROR(_xlfn.SINGLE(INDEX(DATABASE!$AV$14:$BC$968,SUMPRODUCT((ROW(DATABASE!$AV$14:$AV$968)) * (DATABASE!$AV$14:AY$968='Résultats observations'!$A21 ) * (DATABASE!$AW$14:$AW$968= F$4))-ROW(DATABASE!$AV$14)+1,F$5)),"")} | G21: {=IFERROR(_xlfn.SINGLE(INDEX(DATABASE!$AV$14:$BC$968,SUMPRODUCT((ROW(DATABASE!$AV$14:$AV$968)) * (DATABASE!$AV$14:AZ$968='Résultats observations'!$A21 ) * (DATABASE!$AW$14:$AW$968= G$4))-ROW(DATABASE!$AV$14)+1,G$5)),"")} | H21: {=IFERROR(_xlfn.SINGLE(INDEX(DATABASE!$AV$14:$BC$968,SUMPRODUCT((ROW(DATABASE!$AV$14:$AV$968)) * (DATABASE!$AV$14:BA$968='Résultats observations'!$A21 ) * (DATABASE!$AW$14:$AW$968= H$4))-ROW(DATABASE!$AV$14)+1,H$5)),"")} | I21: {=IFERROR(_xlfn.SINGLE(INDEX(DATABASE!$AV$14:$BC$968,SUMPRODUCT((ROW(DATABASE!$AV$14:$AV$968)) * (DATABASE!$AV$14:BB$968='Résultats observations'!$A21 ) * (DATABASE!$AW$14:$AW$968= I$4))-ROW(DATABASE!$AV$14)+1,I$5)),"")} | J21: {=IFERROR(_xlfn.SINGLE(INDEX(DATABASE!$AV$14:$BC$968,SUMPRODUCT((ROW(DATABASE!$AV$14:$AV$968)) * (DATABASE!$AV$14:BC$968='Résultats observations'!$A21 ) * (DATABASE!$AW$14:$AW$968= J$4))-ROW(DATABASE!$AV$14)+1,J$5)),"")} | K21: {=IFERROR(_xlfn.SINGLE(INDEX(DATABASE!$AV$14:$BC$968,SUMPRODUCT((ROW(DATABASE!$AV$14:$AV$968)) * (DATABASE!$AV$14:BD$968='Résultats observations'!$A21 ) * (DATABASE!$AW$14:$AW$968= K$4))-ROW(DATABASE!$AV$14)+1,K$5)),"")} | ... N21: {=IFERROR(_xlfn.SINGLE(INDEX(DATABASE!$AV$14:$BC$968,SUMPRODUCT((ROW(DATABASE!$AV$14:$AV$968)) * (DATABASE!$AV$14:BG$968='Résultats observations'!$A21 ) * (DATABASE!$AW$14:$AW$968= N$4))-ROW(DATABASE!$AV$14)+1,N$5)),"")}
A22: 45565 | B22: =A22-A$10 | C22: {=IFERROR(_xlfn.SINGLE(INDEX(DATABASE!$AV$14:$BC$968,SUMPRODUCT((ROW(DATABASE!$AV$14:$AV$968)) * (DATABASE!AV$14:$AV$968='Résultats observations'!$A22 ) * (DATABASE!$AW$14:$AW$968= C$4))-ROW(DATABASE!$AV$14)+1,C$5)),"")} | D22: {=IFERROR(_xlfn.SINGLE(INDEX(DATABASE!$AV$14:$BC$968,SUMPRODUCT((ROW(DATABASE!$AV$14:$AV$968)) * (DATABASE!$AV$14:AW$968='Résultats observations'!$A22 ) * (DATABASE!$AW$14:$AW$968= D$4))-ROW(DATABASE!$AV$14)+1,D$5)),"")} | E22: {=IFERROR(_xlfn.SINGLE(INDEX(DATABASE!$AV$14:$BC$968,SUMPRODUCT((ROW(DATABASE!$AV$14:$AV$968)) * (DATABASE!$AV$14:AX$968='Résultats observations'!$A22 ) * (DATABASE!$AW$14:$AW$968= E$4))-ROW(DATABASE!$AV$14)+1,E$5)),"")} | F22: {=IFERROR(_xlfn.SINGLE(INDEX(DATABASE!$AV$14:$BC$968,SUMPRODUCT((ROW(DATABASE!$AV$14:$AV$968)) * (DATABASE!$AV$14:AY$968='Résultats observations'!$A22 ) * (DATABASE!$AW$14:$AW$968= F$4))-ROW(DATABASE!$AV$14)+1,F$5)),"")} | G22: {=IFERROR(_xlfn.SINGLE(INDEX(DATABASE!$AV$14:$BC$968,SUMPRODUCT((ROW(DATABASE!$AV$14:$AV$968)) * (DATABASE!$AV$14:AZ$968='Résultats observations'!$A22 ) * (DATABASE!$AW$14:$AW$968= G$4))-ROW(DATABASE!$AV$14)+1,G$5)),"")} | H22: {=IFERROR(_xlfn.SINGLE(INDEX(DATABASE!$AV$14:$BC$968,SUMPRODUCT((ROW(DATABASE!$AV$14:$AV$968)) * (DATABASE!$AV$14:BA$968='Résultats observations'!$A22 ) * (DATABASE!$AW$14:$AW$968= H$4))-ROW(DATABASE!$AV$14)+1,H$5)),"")} | I22: {=IFERROR(_xlfn.SINGLE(INDEX(DATABASE!$AV$14:$BC$968,SUMPRODUCT((ROW(DATABASE!$AV$14:$AV$968)) * (DATABASE!$AV$14:BB$968='Résultats observations'!$A22 ) * (DATABASE!$AW$14:$AW$968= I$4))-ROW(DATABASE!$AV$14)+1,I$5)),"")} | J22: {=IFERROR(_xlfn.SINGLE(INDEX(DATABASE!$AV$14:$BC$968,SUMPRODUCT((ROW(DATABASE!$AV$14:$AV$968)) * (DATABASE!$AV$14:BC$968='Résultats observations'!$A22 ) * (DATABASE!$AW$14:$AW$968= J$4))-ROW(DATABASE!$AV$14)+1,J$5)),"")} | K22: {=IFERROR(_xlfn.SINGLE(INDEX(DATABASE!$AV$14:$BC$968,SUMPRODUCT((ROW(DATABASE!$AV$14:$AV$968)) * (DATABASE!$AV$14:BD$968='Résultats observations'!$A22 ) * (DATABASE!$AW$14:$AW$968= K$4))-ROW(DATABASE!$AV$14)+1,K$5)),"")} | ... N22: {=IFERROR(_xlfn.SINGLE(INDEX(DATABASE!$AV$14:$BC$968,SUMPRODUCT((ROW(DATABASE!$AV$14:$AV$968)) * (DATABASE!$AV$14:BG$968='Résultats observations'!$A22 ) * (DATABASE!$AW$14:$AW$968= N$4))-ROW(DATABASE!$AV$14)+1,N$5)),"")}
... A32: 45644 | B32: =A32-A$10 | C32: {=IFERROR(_xlfn.SINGLE(INDEX(DATABASE!$AV$14:$BC$968,SUMPRODUCT((ROW(DATABASE!$AV$14:$AV$968)) * (DATABASE!AV$14:$AV$968='Résultats observations'!$A32 ) * (DATABASE!$AW$14:$AW$968= C$4))-ROW(DATABASE!$AV$14)+1,C$5)),"")} | D32: {=IFERROR(_xlfn.SINGLE(INDEX(DATABASE!$AV$14:$BC$968,SUMPRODUCT((ROW(DATABASE!$AV$14:$AV$968)) * (DATABASE!$AV$14:AW$968='Résultats observations'!$A32 ) * (DATABASE!$AW$14:$AW$968= D$4))-ROW(DATABASE!$AV$14)+1,D$5)),"")} | E32: {=IFERROR(_xlfn.SINGLE(INDEX(DATABASE!$AV$14:$BC$968,SUMPRODUCT((ROW(DATABASE!$AV$14:$AV$968)) * (DATABASE!$AV$14:AX$968='Résultats observations'!$A32 ) * (DATABASE!$AW$14:$AW$968= E$4))-ROW(DATABASE!$AV$14)+1,E$5)),"")} | F32: {=IFERROR(_xlfn.SINGLE(INDEX(DATABASE!$AV$14:$BC$968,SUMPRODUCT((ROW(DATABASE!$AV$14:$AV$968)) * (DATABASE!$AV$14:AY$968='Résultats observations'!$A32 ) * (DATABASE!$AW$14:$AW$968= F$4))-ROW(DATABASE!$AV$14)+1,F$5)),"")} | G32: {=IFERROR(_xlfn.SINGLE(INDEX(DATABASE!$AV$14:$BC$968,SUMPRODUCT((ROW(DATABASE!$AV$14:$AV$968)) * (DATABASE!$AV$14:AZ$968='Résultats observations'!$A32 ) * (DATABASE!$AW$14:$AW$968= G$4))-ROW(DATABASE!$AV$14)+1,G$5)),"")} | H32: {=IFERROR(_xlfn.SINGLE(INDEX(DATABASE!$AV$14:$BC$968,SUMPRODUCT((ROW(DATABASE!$AV$14:$AV$968)) * (DATABASE!$AV$14:BA$968='Résultats observations'!$A32 ) * (DATABASE!$AW$14:$AW$968= H$4))-ROW(DATABASE!$AV$14)+1,H$5)),"")} | I32: {=IFERROR(_xlfn.SINGLE(INDEX(DATABASE!$AV$14:$BC$968,SUMPRODUCT((ROW(DATABASE!$AV$14:$AV$968)) * (DATABASE!$AV$14:BB$968='Résultats observations'!$A32 ) * (DATABASE!$AW$14:$AW$968= I$4))-ROW(DATABASE!$AV$14)+1,I$5)),"")} | J32: {=IFERROR(_xlfn.SINGLE(INDEX(DATABASE!$AV$14:$BC$968,SUMPRODUCT((ROW(DATABASE!$AV$14:$AV$968)) * (DATABASE!$AV$14:BC$968='Résultats observations'!$A32 ) * (DATABASE!$AW$14:$AW$968= J$4))-ROW(DATABASE!$AV$14)+1,J$5)),"")} | K32: {=IFERROR(_xlfn.SINGLE(INDEX(DATABASE!$AV$14:$BC$968,SUMPRODUCT((ROW(DATABASE!$AV$14:$AV$968)) * (DATABASE!$AV$14:BD$968='Résultats observations'!$A32 ) * (DATABASE!$AW$14:$AW$968= K$4))-ROW(DATABASE!$AV$14)+1,K$5)),"")} | ... N32: {=IFERROR(_xlfn.SINGLE(INDEX(DATABASE!$AV$14:$BC$968,SUMPRODUCT((ROW(DATABASE!$AV$14:$AV$968)) * (DATABASE!$AV$14:BG$968='Résultats observations'!$A32 ) * (DATABASE!$AW$14:$AW$968= N$4))-ROW(DATABASE!$AV$14)+1,N$5)),"")}
A33: 45663 | B33: =A33-A$10 | C33: {=IFERROR(_xlfn.SINGLE(INDEX(DATABASE!$AV$14:$BC$968,SUMPRODUCT((ROW(DATABASE!$AV$14:$AV$968)) * (DATABASE!AV$14:$AV$968='Résultats observations'!$A33 ) * (DATABASE!$AW$14:$AW$968= C$4))-ROW(DATABASE!$AV$14)+1,C$5)),"")} | D33: {=IFERROR(_xlfn.SINGLE(INDEX(DATABASE!$AV$14:$BC$968,SUMPRODUCT((ROW(DATABASE!$AV$14:$AV$968)) * (DATABASE!$AV$14:AW$968='Résultats observations'!$A33 ) * (DATABASE!$AW$14:$AW$968= D$4))-ROW(DATABASE!$AV$14)+1,D$5)),"")} | E33: {=IFERROR(_xlfn.SINGLE(INDEX(DATABASE!$AV$14:$BC$968,SUMPRODUCT((ROW(DATABASE!$AV$14:$AV$968)) * (DATABASE!$AV$14:AX$968='Résultats observations'!$A33 ) * (DATABASE!$AW$14:$AW$968= E$4))-ROW(DATABASE!$AV$14)+1,E$5)),"")} | F33: {=IFERROR(_xlfn.SINGLE(INDEX(DATABASE!$AV$14:$BC$968,SUMPRODUCT((ROW(DATABASE!$AV$14:$AV$968)) * (DATABASE!$AV$14:AY$968='Résultats observations'!$A33 ) * (DATABASE!$AW$14:$AW$968= F$4))-ROW(DATABASE!$AV$14)+1,F$5)),"")} | G33: {=IFERROR(_xlfn.SINGLE(INDEX(DATABASE!$AV$14:$BC$968,SUMPRODUCT((ROW(DATABASE!$AV$14:$AV$968)) * (DATABASE!$AV$14:AZ$968='Résultats observations'!$A33 ) * (DATABASE!$AW$14:$AW$968= G$4))-ROW(DATABASE!$AV$14)+1,G$5)),"")} | H33: {=IFERROR(_xlfn.SINGLE(INDEX(DATABASE!$AV$14:$BC$968,SUMPRODUCT((ROW(DATABASE!$AV$14:$AV$968)) * (DATABASE!$AV$14:BA$968='Résultats observations'!$A33 ) * (DATABASE!$AW$14:$AW$968= H$4))-ROW(DATABASE!$AV$14)+1,H$5)),"")} | I33: {=IFERROR(_xlfn.SINGLE(INDEX(DATABASE!$AV$14:$BC$968,SUMPRODUCT((ROW(DATABASE!$AV$14:$AV$968)) * (DATABASE!$AV$14:BB$968='Résultats observations'!$A33 ) * (DATABASE!$AW$14:$AW$968= I$4))-ROW(DATABASE!$AV$14)+1,I$5)),"")} | J33: {=IFERROR(_xlfn.SINGLE(INDEX(DATABASE!$AV$14:$BC$968,SUMPRODUCT((ROW(DATABASE!$AV$14:$AV$968)) * (DATABASE!$AV$14:BC$968='Résultats observations'!$A33 ) * (DATABASE!$AW$14:$AW$968= J$4))-ROW(DATABASE!$AV$14)+1,J$5)),"")} | K33: {=IFERROR(_xlfn.SINGLE(INDEX(DATABASE!$AV$14:$BC$968,SUMPRODUCT((ROW(DATABASE!$AV$14:$AV$968)) * (DATABASE!$AV$14:BD$968='Résultats observations'!$A33 ) * (DATABASE!$AW$14:$AW$968= K$4))-ROW(DATABASE!$AV$14)+1,K$5)),"")} | ... BJ33: {=IFERROR(_xlfn.SINGLE(INDEX(DATABASE!$AV$14:$BC$968,SUMPRODUCT((ROW(DATABASE!$AV$14:$AV$968)) * (DATABASE!$AV$14:DC$968='Résultats observations'!$A33 ) * (DATABASE!$AW$14:$AW$968= BJ$4))-ROW(DATABASE!$AV$14)+1,BJ$5)),"")}
A34: 45666 | B34: =A34-A$10 | C34: {=IFERROR(_xlfn.SINGLE(INDEX(DATABASE!$AV$14:$BC$968,SUMPRODUCT((ROW(DATABASE!$AV$14:$AV$968)) * (DATABASE!AV$14:$AV$968='Résultats observations'!$A34 ) * (DATABASE!$AW$14:$AW$968= C$4))-ROW(DATABASE!$AV$14)+1,C$5)),"")} | D34: {=IFERROR(_xlfn.SINGLE(INDEX(DATABASE!$AV$14:$BC$968,SUMPRODUCT((ROW(DATABASE!$AV$14:$AV$968)) * (DATABASE!$AV$14:AW$968='Résultats observations'!$A34 ) * (DATABASE!$AW$14:$AW$968= D$4))-ROW(DATABASE!$AV$14)+1,D$5)),"")} | E34: {=IFERROR(_xlfn.SINGLE(INDEX(DATABASE!$AV$14:$BC$968,SUMPRODUCT((ROW(DATABASE!$AV$14:$AV$968)) * (DATABASE!$AV$14:AX$968='Résultats observations'!$A34 ) * (DATABASE!$AW$14:$AW$968= E$4))-ROW(DATABASE!$AV$14)+1,E$5)),"")} | F34: {=IFERROR(_xlfn.SINGLE(INDEX(DATABASE!$AV$14:$BC$968,SUMPRODUCT((ROW(DATABASE!$AV$14:$AV$968)) * (DATABASE!$AV$14:AY$968='Résultats observations'!$A34 ) * (DATABASE!$AW$14:$AW$968= F$4))-ROW(DATABASE!$AV$14)+1,F$5)),"")} | G34: {=IFERROR(_xlfn.SINGLE(INDEX(DATABASE!$AV$14:$BC$968,SUMPRODUCT((ROW(DATABASE!$AV$14:$AV$968)) * (DATABASE!$AV$14:AZ$968='Résultats observations'!$A34 ) * (DATABASE!$AW$14:$AW$968= G$4))-ROW(DATABASE!$AV$14)+1,G$5)),"")} | H34: {=IFERROR(_xlfn.SINGLE(INDEX(DATABASE!$AV$14:$BC$968,SUMPRODUCT((ROW(DATABASE!$AV$14:$AV$968)) * (DATABASE!$AV$14:BA$968='Résultats observations'!$A34 ) * (DATABASE!$AW$14:$AW$968= H$4))-ROW(DATABASE!$AV$14)+1,H$5)),"")} | I34: {=IFERROR(_xlfn.SINGLE(INDEX(DATABASE!$AV$14:$BC$968,SUMPRODUCT((ROW(DATABASE!$AV$14:$AV$968)) * (DATABASE!$AV$14:BB$968='Résultats observations'!$A34 ) * (DATABASE!$AW$14:$AW$968= I$4))-ROW(DATABASE!$AV$14)+1,I$5)),"")} | J34: {=IFERROR(_xlfn.SINGLE(INDEX(DATABASE!$AV$14:$BC$968,SUMPRODUCT((ROW(DATABASE!$AV$14:$AV$968)) * (DATABASE!$AV$14:BC$968='Résultats observations'!$A34 ) * (DATABASE!$AW$14:$AW$968= J$4))-ROW(DATABASE!$AV$14)+1,J$5)),"")} | K34: {=IFERROR(_xlfn.SINGLE(INDEX(DATABASE!$AV$14:$BC$968,SUMPRODUCT((ROW(DATABASE!$AV$14:$AV$968)) * (DATABASE!$AV$14:BD$968='Résultats observations'!$A34 ) * (DATABASE!$AW$14:$AW$968= K$4))-ROW(DATABASE!$AV$14)+1,K$5)),"")} | ... BJ34: {=IFERROR(_xlfn.SINGLE(INDEX(DATABASE!$AV$14:$BC$968,SUMPRODUCT((ROW(DATABASE!$AV$14:$AV$968)) * (DATABASE!$AV$14:DC$968='Résultats observations'!$A34 ) * (DATABASE!$AW$14:$AW$968= BJ$4))-ROW(DATABASE!$AV$14)+1,BJ$5)),"")}
A35: 45670 | B35: =A35-A$10 | C35: {=IFERROR(_xlfn.SINGLE(INDEX(DATABASE!$AV$14:$BC$968,SUMPRODUCT((ROW(DATABASE!$AV$14:$AV$968)) * (DATABASE!AV$14:$AV$968='Résultats observations'!$A35 ) * (DATABASE!$AW$14:$AW$968= C$4))-ROW(DATABASE!$AV$14)+1,C$5)),"")} | D35: {=IFERROR(_xlfn.SINGLE(INDEX(DATABASE!$AV$14:$BC$968,SUMPRODUCT((ROW(DATABASE!$AV$14:$AV$968)) * (DATABASE!$AV$14:AW$968='Résultats observations'!$A35 ) * (DATABASE!$AW$14:$AW$968= D$4))-ROW(DATABASE!$AV$14)+1,D$5)),"")} | E35: {=IFERROR(_xlfn.SINGLE(INDEX(DATABASE!$AV$14:$BC$968,SUMPRODUCT((ROW(DATABASE!$AV$14:$AV$968)) * (DATABASE!$AV$14:AX$968='Résultats observations'!$A35 ) * (DATABASE!$AW$14:$AW$968= E$4))-ROW(DATABASE!$AV$14)+1,E$5)),"")} | F35: {=IFERROR(_xlfn.SINGLE(INDEX(DATABASE!$AV$14:$BC$968,SUMPRODUCT((ROW(DATABASE!$AV$14:$AV$968)) * (DATABASE!$AV$14:AY$968='Résultats observations'!$A35 ) * (DATABASE!$AW$14:$AW$968= F$4))-ROW(DATABASE!$AV$14)+1,F$5)),"")} | G35: {=IFERROR(_xlfn.SINGLE(INDEX(DATABASE!$AV$14:$BC$968,SUMPRODUCT((ROW(DATABASE!$AV$14:$AV$968)) * (DATABASE!$AV$14:AZ$968='Résultats observations'!$A35 ) * (DATABASE!$AW$14:$AW$968= G$4))-ROW(DATABASE!$AV$14)+1,G$5)),"")} | H35: {=IFERROR(_xlfn.SINGLE(INDEX(DATABASE!$AV$14:$BC$968,SUMPRODUCT((ROW(DATABASE!$AV$14:$AV$968)) * (DATABASE!$AV$14:BA$968='Résultats observations'!$A35 ) * (DATABASE!$AW$14:$AW$968= H$4))-ROW(DATABASE!$AV$14)+1,H$5)),"")} | I35: {=IFERROR(_xlfn.SINGLE(INDEX(DATABASE!$AV$14:$BC$968,SUMPRODUCT((ROW(DATABASE!$AV$14:$AV$968)) * (DATABASE!$AV$14:BB$968='Résultats observations'!$A35 ) * (DATABASE!$AW$14:$AW$968= I$4))-ROW(DATABASE!$AV$14)+1,I$5)),"")} | J35: {=IFERROR(_xlfn.SINGLE(INDEX(DATABASE!$AV$14:$BC$968,SUMPRODUCT((ROW(DATABASE!$AV$14:$AV$968)) * (DATABASE!$AV$14:BC$968='Résultats observations'!$A35 ) * (DATABASE!$AW$14:$AW$968= J$4))-ROW(DATABASE!$AV$14)+1,J$5)),"")} | K35: {=IFERROR(_xlfn.SINGLE(INDEX(DATABASE!$AV$14:$BC$968,SUMPRODUCT((ROW(DATABASE!$AV$14:$AV$968)) * (DATABASE!$AV$14:BD$968='Résultats observations'!$A35 ) * (DATABASE!$AW$14:$AW$968= K$4))-ROW(DATABASE!$AV$14)+1,K$5)),"")} | ... BJ35: {=IFERROR(_xlfn.SINGLE(INDEX(DATABASE!$AV$14:$BC$968,SUMPRODUCT((ROW(DATABASE!$AV$14:$AV$968)) * (DATABASE!$AV$14:DC$968='Résultats observations'!$A35 ) * (DATABASE!$AW$14:$AW$968= BJ$4))-ROW(DATABASE!$AV$14)+1,BJ$5)),"")}
A36: 45674 | B36: =A36-A$10 | C36: {=IFERROR(_xlfn.SINGLE(INDEX(DATABASE!$AV$14:$BC$968,SUMPRODUCT((ROW(DATABASE!$AV$14:$AV$968)) * (DATABASE!AV$14:$AV$968='Résultats observations'!$A36 ) * (DATABASE!$AW$14:$AW$968= C$4))-ROW(DATABASE!$AV$14)+1,C$5)),"")} | D36: {=IFERROR(_xlfn.SINGLE(INDEX(DATABASE!$AV$14:$BC$968,SUMPRODUCT((ROW(DATABASE!$AV$14:$AV$968)) * (DATABASE!$AV$14:AW$968='Résultats observations'!$A36 ) * (DATABASE!$AW$14:$AW$968= D$4))-ROW(DATABASE!$AV$14)+1,D$5)),"")} | E36: {=IFERROR(_xlfn.SINGLE(INDEX(DATABASE!$AV$14:$BC$968,SUMPRODUCT((ROW(DATABASE!$AV$14:$AV$968)) * (DATABASE!$AV$14:AX$968='Résultats observations'!$A36 ) * (DATABASE!$AW$14:$AW$968= E$4))-ROW(DATABASE!$AV$14)+1,E$5)),"")} | F36: {=IFERROR(_xlfn.SINGLE(INDEX(DATABASE!$AV$14:$BC$968,SUMPRODUCT((ROW(DATABASE!$AV$14:$AV$968)) * (DATABASE!$AV$14:AY$968='Résultats observations'!$A36 ) * (DATABASE!$AW$14:$AW$968= F$4))-ROW(DATABASE!$AV$14)+1,F$5)),"")} | G36: {=IFERROR(_xlfn.SINGLE(INDEX(DATABASE!$AV$14:$BC$968,SUMPRODUCT((ROW(DATABASE!$AV$14:$AV$968)) * (DATABASE!$AV$14:AZ$968='Résultats observations'!$A36 ) * (DATABASE!$AW$14:$AW$968= G$4))-ROW(DATABASE!$AV$14)+1,G$5)),"")} | H36: {=IFERROR(_xlfn.SINGLE(INDEX(DATABASE!$AV$14:$BC$968,SUMPRODUCT((ROW(DATABASE!$AV$14:$AV$968)) * (DATABASE!$AV$14:BA$968='Résultats observations'!$A36 ) * (DATABASE!$AW$14:$AW$968= H$4))-ROW(DATABASE!$AV$14)+1,H$5)),"")} | I36: {=IFERROR(_xlfn.SINGLE(INDEX(DATABASE!$AV$14:$BC$968,SUMPRODUCT((ROW(DATABASE!$AV$14:$AV$968)) * (DATABASE!$AV$14:BB$968='Résultats observations'!$A36 ) * (DATABASE!$AW$14:$AW$968= I$4))-ROW(DATABASE!$AV$14)+1,I$5)),"")} | J36: {=IFERROR(_xlfn.SINGLE(INDEX(DATABASE!$AV$14:$BC$968,SUMPRODUCT((ROW(DATABASE!$AV$14:$AV$968)) * (DATABASE!$AV$14:BC$968='Résultats observations'!$A36 ) * (DATABASE!$AW$14:$AW$968= J$4))-ROW(DATABASE!$AV$14)+1,J$5)),"")} | K36: {=IFERROR(_xlfn.SINGLE(INDEX(DATABASE!$AV$14:$BC$968,SUMPRODUCT((ROW(DATABASE!$AV$14:$AV$968)) * (DATABASE!$AV$14:BD$968='Résultats observations'!$A36 ) * (DATABASE!$AW$14:$AW$968= K$4))-ROW(DATABASE!$AV$14)+1,K$5)),"")} | ... BJ36: {=IFERROR(_xlfn.SINGLE(INDEX(DATABASE!$AV$14:$BC$968,SUMPRODUCT((ROW(DATABASE!$AV$14:$AV$968)) * (DATABASE!$AV$14:DC$968='Résultats observations'!$A36 ) * (DATABASE!$AW$14:$AW$968= BJ$4))-ROW(DATABASE!$AV$14)+1,BJ$5)),"")}
A37: 45681 | B37: =A37-A$10 | C37: {=IFERROR(_xlfn.SINGLE(INDEX(DATABASE!$AV$14:$BC$968,SUMPRODUCT((ROW(DATABASE!$AV$14:$AV$968)) * (DATABASE!AV$14:$AV$968='Résultats observations'!$A37 ) * (DATABASE!$AW$14:$AW$968= C$4))-ROW(DATABASE!$AV$14)+1,C$5)),"")} | D37: {=IFERROR(_xlfn.SINGLE(INDEX(DATABASE!$AV$14:$BC$968,SUMPRODUCT((ROW(DATABASE!$AV$14:$AV$968)) * (DATABASE!$AV$14:AW$968='Résultats observations'!$A37 ) * (DATABASE!$AW$14:$AW$968= D$4))-ROW(DATABASE!$AV$14)+1,D$5)),"")} | E37: {=IFERROR(_xlfn.SINGLE(INDEX(DATABASE!$AV$14:$BC$968,SUMPRODUCT((ROW(DATABASE!$AV$14:$AV$968)) * (DATABASE!$AV$14:AX$968='Résultats observations'!$A37 ) * (DATABASE!$AW$14:$AW$968= E$4))-ROW(DATABASE!$AV$14)+1,E$5)),"")} | F37: {=IFERROR(_xlfn.SINGLE(INDEX(DATABASE!$AV$14:$BC$968,SUMPRODUCT((ROW(DATABASE!$AV$14:$AV$968)) * (DATABASE!$AV$14:AY$968='Résultats observations'!$A37 ) * (DATABASE!$AW$14:$AW$968= F$4))-ROW(DATABASE!$AV$14)+1,F$5)),"")} | G37: {=IFERROR(_xlfn.SINGLE(INDEX(DATABASE!$AV$14:$BC$968,SUMPRODUCT((ROW(DATABASE!$AV$14:$AV$968)) * (DATABASE!$AV$14:AZ$968='Résultats observations'!$A37 ) * (DATABASE!$AW$14:$AW$968= G$4))-ROW(DATABASE!$AV$14)+1,G$5)),"")} | H37: {=IFERROR(_xlfn.SINGLE(INDEX(DATABASE!$AV$14:$BC$968,SUMPRODUCT((ROW(DATABASE!$AV$14:$AV$968)) * (DATABASE!$AV$14:BA$968='Résultats observations'!$A37 ) * (DATABASE!$AW$14:$AW$968= H$4))-ROW(DATABASE!$AV$14)+1,H$5)),"")} | I37: {=IFERROR(_xlfn.SINGLE(INDEX(DATABASE!$AV$14:$BC$968,SUMPRODUCT((ROW(DATABASE!$AV$14:$AV$968)) * (DATABASE!$AV$14:BB$968='Résultats observations'!$A37 ) * (DATABASE!$AW$14:$AW$968= I$4))-ROW(DATABASE!$AV$14)+1,I$5)),"")} | J37: {=IFERROR(_xlfn.SINGLE(INDEX(DATABASE!$AV$14:$BC$968,SUMPRODUCT((ROW(DATABASE!$AV$14:$AV$968)) * (DATABASE!$AV$14:BC$968='Résultats observations'!$A37 ) * (DATABASE!$AW$14:$AW$968= J$4))-ROW(DATABASE!$AV$14)+1,J$5)),"")} | K37: {=IFERROR(_xlfn.SINGLE(INDEX(DATABASE!$AV$14:$BC$968,SUMPRODUCT((ROW(DATABASE!$AV$14:$AV$968)) * (DATABASE!$AV$14:BD$968='Résultats observations'!$A37 ) * (DATABASE!$AW$14:$AW$968= K$4))-ROW(DATABASE!$AV$14)+1,K$5)),"")} | ... BJ37: {=IFERROR(_xlfn.SINGLE(INDEX(DATABASE!$AV$14:$BC$968,SUMPRODUCT((ROW(DATABASE!$AV$14:$AV$968)) * (DATABASE!$AV$14:DC$968='Résultats observations'!$A37 ) * (DATABASE!$AW$14:$AW$968= BJ$4))-ROW(DATABASE!$AV$14)+1,BJ$5)),"")}
A38: 45686 | B38: =A38-A$10 | C38: {=IFERROR(_xlfn.SINGLE(INDEX(DATABASE!$AV$14:$BC$968,SUMPRODUCT((ROW(DATABASE!$AV$14:$AV$968)) * (DATABASE!AV$14:$AV$968='Résultats observations'!$A38 ) * (DATABASE!$AW$14:$AW$968= C$4))-ROW(DATABASE!$AV$14)+1,C$5)),"")} | D38: {=IFERROR(_xlfn.SINGLE(INDEX(DATABASE!$AV$14:$BC$968,SUMPRODUCT((ROW(DATABASE!$AV$14:$AV$968)) * (DATABASE!$AV$14:AW$968='Résultats observations'!$A38 ) * (DATABASE!$AW$14:$AW$968= D$4))-ROW(DATABASE!$AV$14)+1,D$5)),"")} | E38: {=IFERROR(_xlfn.SINGLE(INDEX(DATABASE!$AV$14:$BC$968,SUMPRODUCT((ROW(DATABASE!$AV$14:$AV$968)) * (DATABASE!$AV$14:AX$968='Résultats observations'!$A38 ) * (DATABASE!$AW$14:$AW$968= E$4))-ROW(DATABASE!$AV$14)+1,E$5)),"")} | F38: {=IFERROR(_xlfn.SINGLE(INDEX(DATABASE!$AV$14:$BC$968,SUMPRODUCT((ROW(DATABASE!$AV$14:$AV$968)) * (DATABASE!$AV$14:AY$968='Résultats observations'!$A38 ) * (DATABASE!$AW$14:$AW$968= F$4))-ROW(DATABASE!$AV$14)+1,F$5)),"")} | G38: {=IFERROR(_xlfn.SINGLE(INDEX(DATABASE!$AV$14:$BC$968,SUMPRODUCT((ROW(DATABASE!$AV$14:$AV$968)) * (DATABASE!$AV$14:AZ$968='Résultats observations'!$A38 ) * (DATABASE!$AW$14:$AW$968= G$4))-ROW(DATABASE!$AV$14)+1,G$5)),"")} | H38: {=IFERROR(_xlfn.SINGLE(INDEX(DATABASE!$AV$14:$BC$968,SUMPRODUCT((ROW(DATABASE!$AV$14:$AV$968)) * (DATABASE!$AV$14:BA$968='Résultats observations'!$A38 ) * (DATABASE!$AW$14:$AW$968= H$4))-ROW(DATABASE!$AV$14)+1,H$5)),"")} | I38: {=IFERROR(_xlfn.SINGLE(INDEX(DATABASE!$AV$14:$BC$968,SUMPRODUCT((ROW(DATABASE!$AV$14:$AV$968)) * (DATABASE!$AV$14:BB$968='Résultats observations'!$A38 ) * (DATABASE!$AW$14:$AW$968= I$4))-ROW(DATABASE!$AV$14)+1,I$5)),"")} | J38: {=IFERROR(_xlfn.SINGLE(INDEX(DATABASE!$AV$14:$BC$968,SUMPRODUCT((ROW(DATABASE!$AV$14:$AV$968)) * (DATABASE!$AV$14:BC$968='Résultats observations'!$A38 ) * (DATABASE!$AW$14:$AW$968= J$4))-ROW(DATABASE!$AV$14)+1,J$5)),"")} | K38: {=IFERROR(_xlfn.SINGLE(INDEX(DATABASE!$AV$14:$BC$968,SUMPRODUCT((ROW(DATABASE!$AV$14:$AV$968)) * (DATABASE!$AV$14:BD$968='Résultats observations'!$A38 ) * (DATABASE!$AW$14:$AW$968= K$4))-ROW(DATABASE!$AV$14)+1,K$5)),"")} | ... BJ38: {=IFERROR(_xlfn.SINGLE(INDEX(DATABASE!$AV$14:$BC$968,SUMPRODUCT((ROW(DATABASE!$AV$14:$AV$968)) * (DATABASE!$AV$14:DC$968='Résultats observations'!$A38 ) * (DATABASE!$AW$14:$AW$968= BJ$4))-ROW(DATABASE!$AV$14)+1,BJ$5)),"")}
A39: 45695 | B39: =A39-A$10 | C39: {=IFERROR(_xlfn.SINGLE(INDEX(DATABASE!$AV$14:$BC$968,SUMPRODUCT((ROW(DATABASE!$AV$14:$AV$968)) * (DATABASE!AV$14:$AV$968='Résultats observations'!$A39 ) * (DATABASE!$AW$14:$AW$968= C$4))-ROW(DATABASE!$AV$14)+1,C$5)),"")} | D39: {=IFERROR(_xlfn.SINGLE(INDEX(DATABASE!$AV$14:$BC$968,SUMPRODUCT((ROW(DATABASE!$AV$14:$AV$968)) * (DATABASE!$AV$14:AW$968='Résultats observations'!$A39 ) * (DATABASE!$AW$14:$AW$968= D$4))-ROW(DATABASE!$AV$14)+1,D$5)),"")} | E39: {=IFERROR(_xlfn.SINGLE(INDEX(DATABASE!$AV$14:$BC$968,SUMPRODUCT((ROW(DATABASE!$AV$14:$AV$968)) * (DATABASE!$AV$14:AX$968='Résultats observations'!$A39 ) * (DATABASE!$AW$14:$AW$968= E$4))-ROW(DATABASE!$AV$14)+1,E$5)),"")} | F39: {=IFERROR(_xlfn.SINGLE(INDEX(DATABASE!$AV$14:$BC$968,SUMPRODUCT((ROW(DATABASE!$AV$14:$AV$968)) * (DATABASE!$AV$14:AY$968='Résultats observations'!$A39 ) * (DATABASE!$AW$14:$AW$968= F$4))-ROW(DATABASE!$AV$14)+1,F$5)),"")} | G39: {=IFERROR(_xlfn.SINGLE(INDEX(DATABASE!$AV$14:$BC$968,SUMPRODUCT((ROW(DATABASE!$AV$14:$AV$968)) * (DATABASE!$AV$14:AZ$968='Résultats observations'!$A39 ) * (DATABASE!$AW$14:$AW$968= G$4))-ROW(DATABASE!$AV$14)+1,G$5)),"")} | H39: {=IFERROR(_xlfn.SINGLE(INDEX(DATABASE!$AV$14:$BC$968,SUMPRODUCT((ROW(DATABASE!$AV$14:$AV$968)) * (DATABASE!$AV$14:BA$968='Résultats observations'!$A39 ) * (DATABASE!$AW$14:$AW$968= H$4))-ROW(DATABASE!$AV$14)+1,H$5)),"")} | I39: {=IFERROR(_xlfn.SINGLE(INDEX(DATABASE!$AV$14:$BC$968,SUMPRODUCT((ROW(DATABASE!$AV$14:$AV$968)) * (DATABASE!$AV$14:BB$968='Résultats observations'!$A39 ) * (DATABASE!$AW$14:$AW$968= I$4))-ROW(DATABASE!$AV$14)+1,I$5)),"")} | J39: {=IFERROR(_xlfn.SINGLE(INDEX(DATABASE!$AV$14:$BC$968,SUMPRODUCT((ROW(DATABASE!$AV$14:$AV$968)) * (DATABASE!$AV$14:BC$968='Résultats observations'!$A39 ) * (DATABASE!$AW$14:$AW$968= J$4))-ROW(DATABASE!$AV$14)+1,J$5)),"")} | K39: {=IFERROR(_xlfn.SINGLE(INDEX(DATABASE!$AV$14:$BC$968,SUMPRODUCT((ROW(DATABASE!$AV$14:$AV$968)) * (DATABASE!$AV$14:BD$968='Résultats observations'!$A39 ) * (DATABASE!$AW$14:$AW$968= K$4))-ROW(DATABASE!$AV$14)+1,K$5)),"")} | ... BJ39: {=IFERROR(_xlfn.SINGLE(INDEX(DATABASE!$AV$14:$BC$968,SUMPRODUCT((ROW(DATABASE!$AV$14:$AV$968)) * (DATABASE!$AV$14:DC$968='Résultats observations'!$A39 ) * (DATABASE!$AW$14:$AW$968= BJ$4))-ROW(DATABASE!$AV$14)+1,BJ$5)),"")}
A40: 45701 | B40: =A40-A$10 | C40: {=IFERROR(_xlfn.SINGLE(INDEX(DATABASE!$AV$14:$BC$968,SUMPRODUCT((ROW(DATABASE!$AV$14:$AV$968)) * (DATABASE!AV$14:$AV$968='Résultats observations'!$A40 ) * (DATABASE!$AW$14:$AW$968= C$4))-ROW(DATABASE!$AV$14)+1,C$5)),"")} | D40: {=IFERROR(_xlfn.SINGLE(INDEX(DATABASE!$AV$14:$BC$968,SUMPRODUCT((ROW(DATABASE!$AV$14:$AV$968)) * (DATABASE!$AV$14:AW$968='Résultats observations'!$A40 ) * (DATABASE!$AW$14:$AW$968= D$4))-ROW(DATABASE!$AV$14)+1,D$5)),"")} | E40: {=IFERROR(_xlfn.SINGLE(INDEX(DATABASE!$AV$14:$BC$968,SUMPRODUCT((ROW(DATABASE!$AV$14:$AV$968)) * (DATABASE!$AV$14:AX$968='Résultats observations'!$A40 ) * (DATABASE!$AW$14:$AW$968= E$4))-ROW(DATABASE!$AV$14)+1,E$5)),"")} | F40: {=IFERROR(_xlfn.SINGLE(INDEX(DATABASE!$AV$14:$BC$968,SUMPRODUCT((ROW(DATABASE!$AV$14:$AV$968)) * (DATABASE!$AV$14:AY$968='Résultats observations'!$A40 ) * (DATABASE!$AW$14:$AW$968= F$4))-ROW(DATABASE!$AV$14)+1,F$5)),"")} | G40: {=IFERROR(_xlfn.SINGLE(INDEX(DATABASE!$AV$14:$BC$968,SUMPRODUCT((ROW(DATABASE!$AV$14:$AV$968)) * (DATABASE!$AV$14:AZ$968='Résultats observations'!$A40 ) * (DATABASE!$AW$14:$AW$968= G$4))-ROW(DATABASE!$AV$14)+1,G$5)),"")} | H40: {=IFERROR(_xlfn.SINGLE(INDEX(DATABASE!$AV$14:$BC$968,SUMPRODUCT((ROW(DATABASE!$AV$14:$AV$968)) * (DATABASE!$AV$14:BA$968='Résultats observations'!$A40 ) * (DATABASE!$AW$14:$AW$968= H$4))-ROW(DATABASE!$AV$14)+1,H$5)),"")} | I40: {=IFERROR(_xlfn.SINGLE(INDEX(DATABASE!$AV$14:$BC$968,SUMPRODUCT((ROW(DATABASE!$AV$14:$AV$968)) * (DATABASE!$AV$14:BB$968='Résultats observations'!$A40 ) * (DATABASE!$AW$14:$AW$968= I$4))-ROW(DATABASE!$AV$14)+1,I$5)),"")} | J40: {=IFERROR(_xlfn.SINGLE(INDEX(DATABASE!$AV$14:$BC$968,SUMPRODUCT((ROW(DATABASE!$AV$14:$AV$968)) * (DATABASE!$AV$14:BC$968='Résultats observations'!$A40 ) * (DATABASE!$AW$14:$AW$968= J$4))-ROW(DATABASE!$AV$14)+1,J$5)),"")} | K40: {=IFERROR(_xlfn.SINGLE(INDEX(DATABASE!$AV$14:$BC$968,SUMPRODUCT((ROW(DATABASE!$AV$14:$AV$968)) * (DATABASE!$AV$14:BD$968='Résultats observations'!$A40 ) * (DATABASE!$AW$14:$AW$968= K$4))-ROW(DATABASE!$AV$14)+1,K$5)),"")} | ... BJ40: {=IFERROR(_xlfn.SINGLE(INDEX(DATABASE!$AV$14:$BC$968,SUMPRODUCT((ROW(DATABASE!$AV$14:$AV$968)) * (DATABASE!$AV$14:DC$968='Résultats observations'!$A40 ) * (DATABASE!$AW$14:$AW$968= BJ$4))-ROW(DATABASE!$AV$14)+1,BJ$5)),"")}
A41: 45708 | B41: =A41-A$10 | C41: {=IFERROR(_xlfn.SINGLE(INDEX(DATABASE!$AV$14:$BC$968,SUMPRODUCT((ROW(DATABASE!$AV$14:$AV$968)) * (DATABASE!AV$14:$AV$968='Résultats observations'!$A41 ) * (DATABASE!$AW$14:$AW$968= C$4))-ROW(DATABASE!$AV$14)+1,C$5)),"")} | D41: {=IFERROR(_xlfn.SINGLE(INDEX(DATABASE!$AV$14:$BC$968,SUMPRODUCT((ROW(DATABASE!$AV$14:$AV$968)) * (DATABASE!$AV$14:AW$968='Résultats observations'!$A41 ) * (DATABASE!$AW$14:$AW$968= D$4))-ROW(DATABASE!$AV$14)+1,D$5)),"")} | E41: {=IFERROR(_xlfn.SINGLE(INDEX(DATABASE!$AV$14:$BC$968,SUMPRODUCT((ROW(DATABASE!$AV$14:$AV$968)) * (DATABASE!$AV$14:AX$968='Résultats observations'!$A41 ) * (DATABASE!$AW$14:$AW$968= E$4))-ROW(DATABASE!$AV$14)+1,E$5)),"")} | F41: {=IFERROR(_xlfn.SINGLE(INDEX(DATABASE!$AV$14:$BC$968,SUMPRODUCT((ROW(DATABASE!$AV$14:$AV$968)) * (DATABASE!$AV$14:AY$968='Résultats observations'!$A41 ) * (DATABASE!$AW$14:$AW$968= F$4))-ROW(DATABASE!$AV$14)+1,F$5)),"")} | G41: {=IFERROR(_xlfn.SINGLE(INDEX(DATABASE!$AV$14:$BC$968,SUMPRODUCT((ROW(DATABASE!$AV$14:$AV$968)) * (DATABASE!$AV$14:AZ$968='Résultats observations'!$A41 ) * (DATABASE!$AW$14:$AW$968= G$4))-ROW(DATABASE!$AV$14)+1,G$5)),"")} | H41: {=IFERROR(_xlfn.SINGLE(INDEX(DATABASE!$AV$14:$BC$968,SUMPRODUCT((ROW(DATABASE!$AV$14:$AV$968)) * (DATABASE!$AV$14:BA$968='Résultats observations'!$A41 ) * (DATABASE!$AW$14:$AW$968= H$4))-ROW(DATABASE!$AV$14)+1,H$5)),"")} | I41: {=IFERROR(_xlfn.SINGLE(INDEX(DATABASE!$AV$14:$BC$968,SUMPRODUCT((ROW(DATABASE!$AV$14:$AV$968)) * (DATABASE!$AV$14:BB$968='Résultats observations'!$A41 ) * (DATABASE!$AW$14:$AW$968= I$4))-ROW(DATABASE!$AV$14)+1,I$5)),"")} | J41: {=IFERROR(_xlfn.SINGLE(INDEX(DATABASE!$AV$14:$BC$968,SUMPRODUCT((ROW(DATABASE!$AV$14:$AV$968)) * (DATABASE!$AV$14:BC$968='Résultats observations'!$A41 ) * (DATABASE!$AW$14:$AW$968= J$4))-ROW(DATABASE!$AV$14)+1,J$5)),"")} | K41: {=IFERROR(_xlfn.SINGLE(INDEX(DATABASE!$AV$14:$BC$968,SUMPRODUCT((ROW(DATABASE!$AV$14:$AV$968)) * (DATABASE!$AV$14:BD$968='Résultats observations'!$A41 ) * (DATABASE!$AW$14:$AW$968= K$4))-ROW(DATABASE!$AV$14)+1,K$5)),"")} | ... BJ41: {=IFERROR(_xlfn.SINGLE(INDEX(DATABASE!$AV$14:$BC$968,SUMPRODUCT((ROW(DATABASE!$AV$14:$AV$968)) * (DATABASE!$AV$14:DC$968='Résultats observations'!$A41 ) * (DATABASE!$AW$14:$AW$968= BJ$4))-ROW(DATABASE!$AV$14)+1,BJ$5)),"")}
